<?xml version="1.0" ?>
<mujoco model="ufactory_lite6">
	<compiler meshdir="ufactory_lite6/meshes" texturedir="ufactory_lite6/textures" angle="radian" autolimits="true" balanceinertia="true" boundmass="0.000001" boundinertia="0.000001"/>
	<default>
		<default class="visual">
			<geom contype="0" conaffinity="0"/>
		</default>
		<default class="collision">
			<geom rgba="1.0 0.0 0.0 0.0"/>
		</default>
	</default>
	<asset>
		<mesh name="link_base" file="stl/link_base.stl" scale="1.0 1.0 1.0"/>
		<mesh name="link_base_c" file="stl/link_base_c.stl" scale="1.0 1.0 1.0"/>
		<mesh name="link1" file="stl/link1.stl" scale="1.0 1.0 1.0"/>
		<mesh name="link1_c" file="stl/link1_c.stl" scale="1.0 1.0 1.0"/>
		<mesh name="link2" file="stl/link2.stl" scale="1.0 1.0 1.0"/>
		<mesh name="link2_c" file="stl/link2_c.stl" scale="1.0 1.0 1.0"/>
		<mesh name="link3" file="stl/link3.stl" scale="1.0 1.0 1.0"/>
		<mesh name="link3_c" file="stl/link3_c.stl" scale="1.0 1.0 1.0"/>
		<mesh name="link4" file="stl/link4.stl" scale="1.0 1.0 1.0"/>
		<mesh name="link4_c" file="stl/link4_c.stl" scale="1.0 1.0 1.0"/>
		<mesh name="link5" file="stl/link5.stl" scale="1.0 1.0 1.0"/>
		<mesh name="link5_c" file="stl/link5_c.stl" scale="1.0 1.0 1.0"/>
		<mesh name="link6" file="stl/link6.stl" scale="1.0 1.0 1.0"/>
		<mesh name="link6_c" file="stl/link6_c.stl" scale="1.0 1.0 1.0"/>
		<material name="white" rgba="1.0 1.0 1.0 1.0" emission="0.0" specular="0.5"/>
		<material name="silver" rgba="0.753000020980835 0.753000020980835 0.753000020980835 1.0" emission="0.0" specular="0.5"/>
	</asset>
	<worldbody>
		<body name="ufactory_lite6" pos="0.0 0.0 0.0" quat="1.0 0.0 0.0 0.0">
			<body name="link_base" pos="0.0 0.0 0.0" quat="1.0 0.0 0.0 0.0">
				<geom name="Geom_0" type="mesh" pos="-0.00811403151601553 0.00012629086268134415 0.060304343700408936" quat="0.7137697339057922 0.0576835535466671 0.05623916536569595 0.6957316994667053" mesh="link_base" material="white" class="visual"/>
				<geom name="Geom_1" type="mesh" pos="-0.008289423771202564 0.0001413146819686517 0.06018092855811119" quat="0.7142898440361023 0.05834497511386871 0.056573424488306046 0.695115327835083" mesh="link_base_c" class="collision"/>
				<body name="link1" pos="0.0 0.0 0.2434999942779541" quat="1.0 0.0 0.0 0.0">
					<inertial mass="1.4110000133514404" pos="-0.0003600000054575503 0.04194999858736992 -0.0024999999441206455" quat="0.6080588698387146 0.7923488020896912 -0.04387069121003151 0.022871794179081917" diaginertia="0.001452759956009686 0.0013527499977499247 0.0008533549844287336"/>
					<geom name="Geom_2" type="mesh" pos="-1.670528763497714e-05 0.018966035917401314 -0.012274348177015781" quat="0.4585404694080353 0.8886730670928955 -0.0008872973266988993 1.001599866867764e-05" mesh="link1" material="white" class="visual"/>
					<geom name="Geom_3" type="mesh" pos="-7.627058948855847e-05 0.018666492775082588 -0.012476584874093533" quat="0.4599464535713196 0.8879438638687134 -0.002075828844681382 0.0007998690125532448" mesh="link1_c" class="collision"/>
					<joint name="joint1" type="hinge" pos="0.0 0.0 0.0" range="-6.28318977355957 6.28318977355957" axis="0.0 0.0 1.0"/>
					<body name="link2" pos="0.0 0.0 0.0" quat="-0.5 0.5 0.5 0.5">
						<inertial mass="1.340000033378601" pos="0.17900000512599945 0.0 0.058400001376867294" quat="0.41756099462509155 0.5716190338134766 0.5695850253105164 0.41769298911094666" diaginertia="0.005609709769487381 0.005215200129896402 0.0012201799545437098"/>
						<geom name="Geom_4" type="mesh" pos="0.11914435029029846 -2.0014167034787533e-07 0.09462665766477585" quat="0.4695463478565216 0.528713583946228 0.5286215543746948 0.46962475776672363" mesh="link2" material="white" class="visual"/>
						<geom name="Geom_5" type="mesh" pos="0.11872807890176773 -3.716583159985021e-05 0.09475217014551163" quat="0.47368741035461426 0.5243798494338989 0.5319745540618896 0.4665287733078003" mesh="link2_c" class="collision"/>
						<joint name="joint2" type="hinge" pos="0.0 0.0 0.0" range="-2.617990016937256 2.617990016937256" axis="0.0 0.0 1.0"/>
						<body name="link3" pos="0.20020000636577606 0.0 0.0" quat="-2.5973411084123654e-06 -0.707105278968811 -0.7071082592010498 -2.597351112854085e-06">
							<inertial mass="0.953000009059906" pos="0.07199999690055847 -0.0357000008225441 -0.0010000000474974513" quat="0.12825897336006165 0.6629629135131836 -0.1672559678554535 0.7183699011802673" diaginertia="0.0018521000165492296 0.0017554600490257144 0.0007038069888949394"/>
							<geom name="Geom_6" type="mesh" pos="0.03540295362472534 -0.0005778800114057958 -0.0002281995548401028" quat="0.537189781665802 0.48910239338874817 0.49653613567352295 0.47503456473350525" mesh="link3" material="white" class="visual"/>
							<geom name="Geom_7" type="mesh" pos="0.035833150148391724 -0.0006497979629784822 -0.0007481405045837164" quat="0.542108952999115 0.4854326546192169 0.4935319125652313 0.4763394296169281" mesh="link3_c" class="collision"/>
							<joint name="joint3" type="hinge" pos="0.0 0.0 0.0" range="-0.061087001115083694 5.235990047454834" axis="0.0 0.0 1.0"/>
							<body name="link4" pos="0.08699999749660492 -0.2276100069284439 0.0" quat="0.707105278968811 0.7071082592010498 0.0 0.0">
								<inertial mass="1.284000039100647" pos="-0.0020000000949949026 -0.02850000001490116 -0.08129999786615372" quat="0.9752478003501892 0.2210899442434311 0.0020349796395748854 -0.002621779451146722" diaginertia="0.0037050300743430853 0.0034909099340438843 0.001095860032364726"/>
								<geom name="Geom_8" type="mesh" pos="6.908006184858095e-07 -0.02948177233338356 -0.08226402848958969" quat="0.9724439382553101 0.23313680291175842 8.74612760526361e-06 9.16273711482063e-05" mesh="link4" material="white" class="visual"/>
								<geom name="Geom_9" type="mesh" pos="-0.0004215897643007338 -0.027776189148426056 -0.08668722212314606" quat="0.9733046293258667 0.22926412522792816 -0.00900206994265318 0.005916018504649401" mesh="link4_c" class="collision"/>
								<joint name="joint4" type="hinge" pos="0.0 0.0 0.0" range="-6.28318977355957 6.28318977355957" axis="0.0 0.0 1.0"/>
								<body name="link5" pos="0.0 0.0 0.0" quat="0.7071067690849304 0.7071067690849304 0.0 0.0">
									<inertial mass="0.8040000200271606" pos="0.0 0.009999999776482582 0.0019000000320374966" quat="0.714230477809906 0.6963884234428406 -0.053193334490060806 0.04569973051548004" diaginertia="0.0005675529828295112 0.0005292660207487643 0.000507680990267545"/>
									<geom name="Geom_10" type="mesh" pos="-1.1146202041345532e-06 -0.0012134675635024905 0.00042929037590511143" quat="0.5423890948295593 0.45218273997306824 -0.45334842801094055 0.5438933968544006" mesh="link5" material="white" class="visual"/>
									<geom name="Geom_11" type="mesh" pos="-1.1064570571761578e-05 -0.0012402086285874248 0.00046095746802166104" quat="0.5538026094436646 0.4588753581047058 -0.44382670521736145 0.5345596075057983" mesh="link5_c" class="collision"/>
									<joint name="joint5" type="hinge" pos="0.0 0.0 0.0" range="-2.1642000675201416 2.1642000675201416" axis="0.0 0.0 1.0"/>
									<body name="link6" pos="0.0 0.0625 0.0" quat="0.7071067690849304 -0.7071067690849304 0.0 0.0">
										<inertial mass="0.12999999523162842" pos="0.0 -0.0019399999873712659 -0.010200000368058681" quat="-0.03760230168700218 0.7040570378303528 0.044683802872896194 0.7077380418777466" diaginertia="0.00014814799942541867 8.57756967889145e-05 7.71412014728412e-05"/>
										<geom name="Geom_12" type="mesh" pos="-3.579038931889045e-08 0.0011157860280945897 -0.011585084721446037" quat="0.49810266494750977 0.5018901824951172 -0.5018754601478577 0.49811747670173645" mesh="link6" material="silver" class="visual"/>
										<geom name="Geom_13" type="mesh" pos="5.991408397676423e-05 3.235737676732242e-05 -0.011802943423390388" quat="0.2927654981613159 0.6427192091941833 -0.29457399249076843 0.6437597274780273" mesh="link6_c" class="collision"/>
										<joint name="joint6" type="hinge" pos="0.0 0.0 0.0" range="-6.28318977355957 6.28318977355957" axis="0.0 0.0 1.0"/>
									</body>
								</body>
							</body>
						</body>
					</body>
				</body>
			</body>
		</body>
	</worldbody>
	<equality/>
</mujoco>
