<?xml version="1.0" ?>
<mujoco model="a1">
	<compiler meshdir="a1/meshes" texturedir="a1/textures" angle="radian" autolimits="true" balanceinertia="true" boundmass="0.000001" boundinertia="0.000001"/>
	<default>
		<default class="visual">
			<geom contype="0" conaffinity="0"/>
		</default>
		<default class="collision">
			<geom rgba="1.0 0.0 0.0 0.0"/>
		</default>
	</default>
	<asset>
		<mesh name="trunk" file="obj/trunk.obj" scale="1.0 1.0 1.0"/>
		<mesh name="hip" file="stl/hip.stl" scale="1.0 1.0 1.0"/>
		<mesh name="thigh_mirror" file="stl/thigh_mirror.stl" scale="1.0 1.0 1.0"/>
		<mesh name="calf" file="stl/calf.stl" scale="1.0 1.0 1.0"/>
		<mesh name="thigh" file="stl/thigh.stl" scale="1.0 1.0 1.0"/>
		<material name="carbonfibre" texture="trunk_A1"/>
		<material name="dark" rgba="0.20000000298023224 0.20000000298023224 0.20000000298023224 1.0" emission="0.0" specular="0.0"/>
		<texture name="trunk_A1" type="2d" file="trunk_A1.png"/>
	</asset>
	<worldbody>
		<body name="a1" pos="0.0 0.0 0.0" quat="1.0 0.0 0.0 0.0">
			<body name="trunk" pos="0.0 0.0 0.0" quat="1.0 0.0 0.0 0.0">
				<geom name="Geom_0" type="mesh" pos="0.052101269364356995 -0.004562626592814922 0.00041792113916017115" quat="-0.010320212692022324 0.7039735317230225 0.01097667682915926 0.7100664377212524" mesh="trunk" material="carbonfibre" class="visual"/>
				<geom name="Geom_1" type="box" pos="0.0 0.0 0.0" quat="1.0 0.0 0.0 0.0" size="0.125 0.03999999910593033 0.05700000002980232" class="collision"/>
				<geom name="Geom_2" type="cylinder" pos="0.0 -0.03999999910593033 0.0" quat="0.7071067690849304 0.0 0.7071067690849304 0.0" size="0.057999998331069946 0.125 0.0" class="collision"/>
				<geom name="Geom_3" type="cylinder" pos="0.0 0.03999999910593033 0.0" quat="0.7071067690849304 0.0 0.7071067690849304 0.0" size="0.057999998331069946 0.125 0.0" class="collision"/>
				<geom name="Geom_4" type="box" pos="0.25 0.0 0.0" quat="1.0 0.0 0.0 0.0" size="0.004999999888241291 0.05999999865889549 0.05000000074505806" class="collision"/>
				<geom name="Geom_5" type="capsule" pos="0.25 0.05999999865889549 -0.009999999776482582" quat="1.0 0.0 0.0 0.0" size="0.008999999612569809 0.03500000014901161 0.0" class="collision"/>
				<geom name="Geom_6" type="capsule" pos="0.25 -0.05999999865889549 -0.009999999776482582" quat="1.0 0.0 0.0 0.0" size="0.008999999612569809 0.03500000014901161 0.0" class="collision"/>
				<geom name="Geom_7" type="capsule" pos="0.25 0.0 -0.05000000074505806" quat="0.7071067690849304 0.7071067690849304 0.0 0.0" size="0.004999999888241291 0.05999999865889549 0.0" class="collision"/>
				<geom name="Geom_8" type="capsule" pos="0.2549999952316284 0.0 0.03550000116229057" quat="0.7071067690849304 0.7071067690849304 0.0 0.0" size="0.020999999716877937 0.052000001072883606 0.0" class="collision"/>
				<body name="FL_hip" pos="0.18299999833106995 0.04699999839067459 0.0" quat="1.0 0.0 0.0 0.0">
					<inertial mass="0.6959999799728394" pos="-0.0033110000658780336 0.0006350000039674342 3.099999958067201e-05" quat="0.4944989085197449 0.4915069043636322 0.5062679052352905 0.5075278878211975" diaginertia="0.0008077520178630948 0.000552929996047169 0.00046898299478925765"/>
					<geom name="Geom_19" type="mesh" pos="-0.008014652878046036 0.00012613194121513516 -1.8650268884812249e-06" quat="0.49897071719169617 0.49886655807495117 0.5010176301002502 0.5011404156684875" mesh="hip" material="dark" class="visual"/>
					<geom name="Geom_20" type="cylinder" pos="0.0 0.054999999701976776 0.0" quat="0.7071067690849304 0.7071067690849304 0.0 0.0" size="0.03999999910593033 0.03999999910593033 0.0" class="collision"/>
					<geom name="Geom_21" type="cylinder" pos="0.0 0.054999999701976776 0.0" quat="0.7071067690849304 0.7071067690849304 0.0 0.0" size="0.03999999910593033 0.03999999910593033 0.0" class="collision"/>
					<joint name="FL_hip_joint" type="hinge" pos="0.0 0.0 0.0" range="-0.8028510212898254 0.8028510212898254" axis="1.0 0.0 0.0"/>
					<body name="FL_thigh" pos="0.0 0.08505000174045563 0.0" quat="1.0 0.0 0.0 0.0">
						<inertial mass="1.0130000114440918" pos="-0.0032369999680668116 -0.02232700027525425 -0.027326000854372978" quat="0.9991252422332764 0.002563930582255125 -0.04095311090350151 0.008060911670327187" diaginertia="0.005557389929890633 0.005139360204339027 0.0013394400011748075"/>
						<geom name="Geom_22" type="mesh" pos="-0.003107831347733736 -0.02179619111120701 -0.02706850692629814" quat="0.7560091614723206 0.09584572911262512 -0.024577196687459946 0.6470391750335693" mesh="thigh" material="dark" class="visual"/>
						<geom name="Geom_23" type="capsule" pos="-0.019999999552965164 0.0 -0.07999999821186066" quat="1.0 0.0 0.0 0.0" size="0.014999999664723873 0.07999999821186066 0.0" class="collision"/>
						<geom name="Geom_24" type="capsule" pos="-0.009999999776482582 0.0 -0.05000000074505806" quat="0.9951333403587341 0.0 0.0985376164317131 0.0" size="0.014999999664723873 0.05099019408226013 0.0" class="collision"/>
						<geom name="Geom_25" type="capsule" pos="-0.009999999776482582 0.0 -0.18000000715255737" quat="0.9732490181922913 0.0 -0.22975291311740875 0.0" size="0.014999999664723873 0.022360680624842644 0.0" class="collision"/>
						<joint name="FL_thigh_joint" type="hinge" pos="0.0 0.0 0.0" range="-1.0471999645233154 4.1887898445129395" axis="0.0 1.0 0.0"/>
						<body name="FL_calf" pos="0.0 0.0 -0.20000000298023224" quat="1.0 0.0 0.0 0.0">
							<inertial mass="0.22599999606609344" pos="0.004726590123027563 0.0 -0.131974995136261" quat="0.7068864107131958 0.017653008922934532 0.017653008922934532 0.7068864107131958" diaginertia="0.003403439885005355 0.0033939299173653126 3.548340100678615e-05"/>
							<geom name="Geom_26" type="mesh" pos="0.006395931821316481 2.4358414520975202e-05 -0.12493624538183212" quat="0.7065389752388 -0.000910990172997117 -0.0007131483871489763 0.707673192024231" mesh="calf" material="dark" class="visual"/>
							<geom name="Geom_27" type="capsule" pos="0.009999999776482582 0.0 -0.06499999761581421" quat="0.9970886707305908 0.0 -0.0762505829334259 0.0" size="0.009999999776482582 0.06576473265886307 0.0" class="collision"/>
							<geom name="Geom_28" type="capsule" pos="0.009999999776482582 0.0 -0.16500000655651093" quat="0.9903342723846436 0.0 0.13870121538639069 0.0" size="0.009999999776482582 0.03640054911375046 0.0" class="collision"/>
							<geom name="Geom_29" type="sphere" pos="0.0 0.0 -0.20000000298023224" quat="1.0 0.0 0.0 0.0" size="0.019999999552965164 0.0 0.0" class="collision"/>
							<joint name="FL_calf_joint" type="hinge" pos="0.0 0.0 0.0" range="-2.6965301036834717 -0.916297972202301" axis="0.0 1.0 0.0"/>
						</body>
					</body>
				</body>
				<body name="RR_hip" pos="-0.18299999833106995 -0.04699999839067459 0.0" quat="1.0 0.0 0.0 0.0">
					<inertial mass="0.6959999799728394" pos="0.0033110000658780336 -0.0006350000039674342 3.099999958067201e-05" quat="0.4915069043636322 0.4944989085197449 0.5075278878211975 0.5062679052352905" diaginertia="0.0008077520178630948 0.000552929996047169 0.00046898299478925765"/>
					<geom name="Geom_30" type="mesh" pos="0.008014652878046036 -0.00012613194121513516 -1.8650268884812249e-06" quat="0.5011404156684875 0.5010176301002502 -0.49886655807495117 -0.49897071719169617" mesh="hip" material="dark" class="visual"/>
					<geom name="Geom_31" type="cylinder" pos="0.0 -0.054999999701976776 0.0" quat="0.7071067690849304 0.7071067690849304 0.0 0.0" size="0.03999999910593033 0.03999999910593033 0.0" class="collision"/>
					<joint name="RR_hip_joint" type="hinge" pos="0.0 0.0 0.0" range="-0.8028510212898254 0.8028510212898254" axis="1.0 0.0 0.0"/>
					<body name="RR_thigh" pos="0.0 -0.08505000174045563 0.0" quat="1.0 0.0 0.0 0.0">
						<inertial mass="1.0130000114440918" pos="-0.0032369999680668116 0.02232700027525425 -0.027326000854372978" quat="0.9991252422332764 -0.002563930582255125 -0.04095311090350151 -0.008060911670327187" diaginertia="0.005557389929890633 0.005139360204339027 0.0013394400011748075"/>
						<geom name="Geom_32" type="mesh" pos="-0.0031076984014362097 0.021799704059958458 -0.027041105553507805" quat="0.6470721960067749 -0.024537459015846252 0.09590362757444382 0.7559748291969299" mesh="thigh_mirror" material="dark" class="visual"/>
						<geom name="Geom_33" type="capsule" pos="-0.019999999552965164 0.0 -0.07999999821186066" quat="1.0 0.0 0.0 0.0" size="0.014999999664723873 0.07999999821186066 0.0" class="collision"/>
						<geom name="Geom_34" type="capsule" pos="-0.009999999776482582 0.0 -0.05000000074505806" quat="0.9951333403587341 0.0 0.0985376164317131 0.0" size="0.014999999664723873 0.05099019408226013 0.0" class="collision"/>
						<geom name="Geom_35" type="capsule" pos="-0.009999999776482582 0.0 -0.18000000715255737" quat="0.9732490181922913 0.0 -0.22975291311740875 0.0" size="0.014999999664723873 0.022360680624842644 0.0" class="collision"/>
						<joint name="RR_thigh_joint" type="hinge" pos="0.0 0.0 0.0" range="-1.0471999645233154 4.1887898445129395" axis="0.0 1.0 0.0"/>
						<body name="RR_calf" pos="0.0 0.0 -0.20000000298023224" quat="1.0 0.0 0.0 0.0">
							<inertial mass="0.22599999606609344" pos="0.004726590123027563 0.0 -0.131974995136261" quat="0.7068864107131958 0.017653008922934532 0.017653008922934532 0.7068864107131958" diaginertia="0.003403439885005355 0.0033939299173653126 3.548340100678615e-05"/>
							<geom name="Geom_36" type="mesh" pos="0.006395931821316481 2.4358414520975202e-05 -0.12493624538183212" quat="0.7065389752388 -0.000910990172997117 -0.0007131483871489763 0.707673192024231" mesh="calf" material="dark" class="visual"/>
							<geom name="Geom_37" type="capsule" pos="0.009999999776482582 0.0 -0.06499999761581421" quat="0.9970886707305908 0.0 -0.0762505829334259 0.0" size="0.009999999776482582 0.06576473265886307 0.0" class="collision"/>
							<geom name="Geom_38" type="capsule" pos="0.009999999776482582 0.0 -0.16500000655651093" quat="0.9903342723846436 0.0 0.13870121538639069 0.0" size="0.009999999776482582 0.03640054911375046 0.0" class="collision"/>
							<geom name="Geom_39" type="sphere" pos="0.0 0.0 -0.20000000298023224" quat="1.0 0.0 0.0 0.0" size="0.019999999552965164 0.0 0.0" class="collision"/>
							<joint name="RR_calf_joint" type="hinge" pos="0.0 0.0 0.0" range="-2.6965301036834717 -0.916297972202301" axis="0.0 1.0 0.0"/>
						</body>
					</body>
				</body>
				<body name="RL_hip" pos="-0.18299999833106995 0.04699999839067459 0.0" quat="1.0 0.0 0.0 0.0">
					<inertial mass="0.6959999799728394" pos="0.0033110000658780336 0.0006350000039674342 3.099999958067201e-05" quat="0.5062679052352905 0.5075278878211975 0.4944989085197449 0.4915069043636322" diaginertia="0.0008077520178630948 0.000552929996047169 0.00046898299478925765"/>
					<geom name="Geom_40" type="mesh" pos="0.008014652878046036 0.00012613194121513516 1.8650268884812249e-06" quat="-0.5010176301002502 0.5011404156684875 0.49897071719169617 -0.49886655807495117" mesh="hip" material="dark" class="visual"/>
					<geom name="Geom_41" type="cylinder" pos="0.0 0.054999999701976776 0.0" quat="0.7071067690849304 0.7071067690849304 0.0 0.0" size="0.03999999910593033 0.03999999910593033 0.0" class="collision"/>
					<joint name="RL_hip_joint" type="hinge" pos="0.0 0.0 0.0" range="-0.8028510212898254 0.8028510212898254" axis="1.0 0.0 0.0"/>
					<body name="RL_thigh" pos="0.0 0.08505000174045563 0.0" quat="1.0 0.0 0.0 0.0">
						<inertial mass="1.0130000114440918" pos="-0.0032369999680668116 -0.02232700027525425 -0.027326000854372978" quat="0.9991252422332764 0.002563930582255125 -0.04095311090350151 0.008060911670327187" diaginertia="0.005557389929890633 0.005139360204339027 0.0013394400011748075"/>
						<geom name="Geom_42" type="mesh" pos="-0.003107831347733736 -0.02179619111120701 -0.02706850692629814" quat="0.7560091614723206 0.09584572911262512 -0.024577196687459946 0.6470391750335693" mesh="thigh" material="dark" class="visual"/>
						<geom name="Geom_43" type="capsule" pos="-0.019999999552965164 0.0 -0.07999999821186066" quat="1.0 0.0 0.0 0.0" size="0.014999999664723873 0.07999999821186066 0.0" class="collision"/>
						<geom name="Geom_44" type="capsule" pos="-0.009999999776482582 0.0 -0.05000000074505806" quat="0.9951333403587341 0.0 0.0985376164317131 0.0" size="0.014999999664723873 0.05099019408226013 0.0" class="collision"/>
						<geom name="Geom_45" type="capsule" pos="-0.009999999776482582 0.0 -0.18000000715255737" quat="0.9732490181922913 0.0 -0.22975291311740875 0.0" size="0.014999999664723873 0.022360680624842644 0.0" class="collision"/>
						<joint name="RL_thigh_joint" type="hinge" pos="0.0 0.0 0.0" range="-1.0471999645233154 4.1887898445129395" axis="0.0 1.0 0.0"/>
						<body name="RL_calf" pos="0.0 0.0 -0.20000000298023224" quat="1.0 0.0 0.0 0.0">
							<inertial mass="0.22599999606609344" pos="0.004726590123027563 0.0 -0.131974995136261" quat="0.7068864107131958 0.017653008922934532 0.017653008922934532 0.7068864107131958" diaginertia="0.003403439885005355 0.0033939299173653126 3.548340100678615e-05"/>
							<geom name="Geom_46" type="mesh" pos="0.006395931821316481 2.4358414520975202e-05 -0.12493624538183212" quat="0.7065389752388 -0.000910990172997117 -0.0007131483871489763 0.707673192024231" mesh="calf" material="dark" class="visual"/>
							<geom name="Geom_47" type="capsule" pos="0.009999999776482582 0.0 -0.06499999761581421" quat="0.9970886707305908 0.0 -0.0762505829334259 0.0" size="0.009999999776482582 0.06576473265886307 0.0" class="collision"/>
							<geom name="Geom_48" type="capsule" pos="0.009999999776482582 0.0 -0.16500000655651093" quat="0.9903342723846436 0.0 0.13870121538639069 0.0" size="0.009999999776482582 0.03640054911375046 0.0" class="collision"/>
							<geom name="Geom_49" type="sphere" pos="0.0 0.0 -0.20000000298023224" quat="1.0 0.0 0.0 0.0" size="0.019999999552965164 0.0 0.0" class="collision"/>
							<joint name="RL_calf_joint" type="hinge" pos="0.0 0.0 0.0" range="-2.6965301036834717 -0.916297972202301" axis="0.0 1.0 0.0"/>
						</body>
					</body>
				</body>
				<body name="FR_hip" pos="0.18299999833106995 -0.04699999839067459 0.0" quat="1.0 0.0 0.0 0.0">
					<inertial mass="0.6959999799728394" pos="-0.0033110000658780336 -0.0006350000039674342 3.099999958067201e-05" quat="0.5075278878211975 0.5062679052352905 0.4915069043636322 0.4944989085197449" diaginertia="0.0008077520178630948 0.000552929996047169 0.00046898299478925765"/>
					<geom name="Geom_9" type="mesh" pos="-0.008014652878046036 -0.00012613194121513516 1.8650268884812249e-06" quat="-0.49886655807495117 0.49897071719169617 -0.5011404156684875 0.5010176301002502" mesh="hip" material="dark" class="visual"/>
					<geom name="Geom_10" type="cylinder" pos="0.0 -0.054999999701976776 0.0" quat="0.7071067690849304 0.7071067690849304 0.0 0.0" size="0.03999999910593033 0.03999999910593033 0.0" class="collision"/>
					<joint name="FR_hip_joint" type="hinge" pos="0.0 0.0 0.0" range="-0.8028510212898254 0.8028510212898254" axis="1.0 0.0 0.0"/>
					<body name="FR_thigh" pos="0.0 -0.08505000174045563 0.0" quat="1.0 0.0 0.0 0.0">
						<inertial mass="1.0130000114440918" pos="-0.0032369999680668116 0.02232700027525425 -0.027326000854372978" quat="0.9991252422332764 -0.002563930582255125 -0.04095311090350151 -0.008060911670327187" diaginertia="0.005557389929890633 0.005139360204339027 0.0013394400011748075"/>
						<geom name="Geom_11" type="mesh" pos="-0.0031076984014362097 0.021799704059958458 -0.027041105553507805" quat="0.6470721960067749 -0.024537459015846252 0.09590362757444382 0.7559748291969299" mesh="thigh_mirror" material="dark" class="visual"/>
						<geom name="Geom_12" type="capsule" pos="-0.019999999552965164 0.0 -0.07999999821186066" quat="1.0 0.0 0.0 0.0" size="0.014999999664723873 0.07999999821186066 0.0" class="collision"/>
						<geom name="Geom_13" type="capsule" pos="-0.009999999776482582 0.0 -0.05000000074505806" quat="0.9951333403587341 0.0 0.0985376164317131 0.0" size="0.014999999664723873 0.05099019408226013 0.0" class="collision"/>
						<geom name="Geom_14" type="capsule" pos="-0.009999999776482582 0.0 -0.18000000715255737" quat="0.9732490181922913 0.0 -0.22975291311740875 0.0" size="0.014999999664723873 0.022360680624842644 0.0" class="collision"/>
						<joint name="FR_thigh_joint" type="hinge" pos="0.0 0.0 0.0" range="-1.0471999645233154 4.1887898445129395" axis="0.0 1.0 0.0"/>
						<body name="FR_calf" pos="0.0 0.0 -0.20000000298023224" quat="1.0 0.0 0.0 0.0">
							<inertial mass="0.22599999606609344" pos="0.004726590123027563 0.0 -0.131974995136261" quat="0.7068864107131958 0.017653008922934532 0.017653008922934532 0.7068864107131958" diaginertia="0.003403439885005355 0.0033939299173653126 3.548340100678615e-05"/>
							<geom name="Geom_15" type="mesh" pos="0.006395931821316481 2.4358414520975202e-05 -0.12493624538183212" quat="0.7065389752388 -0.000910990172997117 -0.0007131483871489763 0.707673192024231" mesh="calf" material="dark" class="visual"/>
							<geom name="Geom_16" type="capsule" pos="0.009999999776482582 0.0 -0.06499999761581421" quat="0.9970886707305908 0.0 -0.0762505829334259 0.0" size="0.009999999776482582 0.06576473265886307 0.0" class="collision"/>
							<geom name="Geom_17" type="capsule" pos="0.009999999776482582 0.0 -0.16500000655651093" quat="0.9903342723846436 0.0 0.13870121538639069 0.0" size="0.009999999776482582 0.03640054911375046 0.0" class="collision"/>
							<geom name="Geom_18" type="sphere" pos="0.0 0.0 -0.20000000298023224" quat="1.0 0.0 0.0 0.0" size="0.019999999552965164 0.0 0.0" class="collision"/>
							<joint name="FR_calf_joint" type="hinge" pos="0.0 0.0 0.0" range="-2.6965301036834717 -0.916297972202301" axis="0.0 1.0 0.0"/>
						</body>
					</body>
				</body>
			</body>
		</body>
	</worldbody>
	<equality/>
</mujoco>
