<?xml version="1.0" ?>
<mujoco model="xarm7">
	<compiler meshdir="xarm7/meshes" texturedir="xarm7/textures" angle="radian" autolimits="true" balanceinertia="true" boundmass="0.000001" boundinertia="0.000001"/>
	<default>
		<default class="visual">
			<geom contype="0" conaffinity="0"/>
		</default>
		<default class="collision">
			<geom rgba=".9 .9 .9 1.0"/>
		</default>
	</default>
	<asset>
		<mesh name="link_base" file="stl/link_base.stl" scale="1.0 1.0 1.0"/>
		<mesh name="link1" file="stl/link1.stl" scale="1.0 1.0 1.0"/>
		<mesh name="link2" file="stl/link2.stl" scale="1.0 1.0 1.0"/>
		<mesh name="link3" file="stl/link3.stl" scale="1.0 1.0 1.0"/>
		<mesh name="link4" file="stl/link4.stl" scale="1.0 1.0 1.0"/>
		<mesh name="link5" file="stl/link5.stl" scale="1.0 1.0 1.0"/>
		<mesh name="link6" file="stl/link6.stl" scale="1.0 1.0 1.0"/>
		<mesh name="end_tool" file="stl/end_tool.stl" scale="1.0 1.0 1.0"/>
		<mesh name="base_link" file="stl/base_link.stl" scale="1.0 1.0 1.0"/>
		<mesh name="left_outer_knuckle" file="stl/left_outer_knuckle.stl" scale="1.0 1.0 1.0"/>
		<mesh name="left_finger" file="stl/left_finger.stl" scale="1.0 1.0 1.0"/>
		<mesh name="left_inner_knuckle" file="stl/left_inner_knuckle.stl" scale="1.0 1.0 1.0"/>
		<mesh name="right_outer_knuckle" file="stl/right_outer_knuckle.stl" scale="1.0 1.0 1.0"/>
		<mesh name="right_finger" file="stl/right_finger.stl" scale="1.0 1.0 1.0"/>
		<mesh name="right_inner_knuckle" file="stl/right_inner_knuckle.stl" scale="1.0 1.0 1.0"/>
		<material name="white" rgba="1.0 1.0 1.0 1.0" emission="0.0" specular="0.5"/>
		<material name="gray" rgba="0.753000020980835 0.753000020980835 0.753000020980835 1.0" emission="0.0" specular="0.5"/>
		<material name="black" rgba="0.14900000393390656 0.14900000393390656 0.14900000393390656 1.0" emission="0.0" specular="0.5"/>
	</asset>
	<worldbody>
		<body name="xarm7" pos="0.0 0.0 0.0" quat="1.0 0.0 0.0 0.0">
			<body name="link_base" pos="0.0 0.0 0.0" quat="1.0 0.0 0.0 0.0">
				<geom name="Geom_0" type="mesh" pos="-0.0023309208918362856 7.635034125996754e-05 0.06466086208820343" quat="0.724604606628418 0.018935956060886383 0.017714353278279305 0.6886768341064453" mesh="link_base" material="white" class="collision"/>
				<body name="link1" pos="0.0 0.0 0.2669999897480011" quat="1.0 0.0 0.0 0.0">
					<inertial mass="2.381999969482422" pos="-0.00019999999494757503 0.02905000001192093 -0.012330000288784504" quat="0.9789528846740723 -0.2027689814567566 -0.004416169598698616 -0.022726397961378098" diaginertia="0.005691269878298044 0.005333839915692806 0.002938650082796812"/>
					<geom name="Geom_1" type="mesh" pos="-0.00014185543113853782 0.007463847286999226 -0.02711421065032482" quat="0.9861190319061279 -0.16602441668510437 0.002235614927485585 -0.00031846127239987254" mesh="link1" material="white" class="collision"/>
					<joint name="joint1" type="hinge" pos="0.0 0.0 0.0" range="-6.28318977355957 6.28318977355957" axis="0.0 0.0 1.0"/>
					<body name="link2" pos="0.0 0.0 0.0" quat="0.7071067690849304 -0.7071067690849304 0.0 0.0">
						<inertial mass="1.86899995803833" pos="0.00022000000171829015 -0.12856000661849976 0.017349999397993088" quat="0.5019803047180176 0.864830493927002 -0.007788414601236582 0.004832852631807327" diaginertia="0.009598979726433754 0.009377170354127884 0.002013149904087186"/>
						<geom name="Geom_2" type="mesh" pos="-8.518074173480272e-05 -0.09124548733234406 0.0484553687274456" quat="0.46958431601524353 0.8828866481781006 -0.0012075769482180476 0.0005315205198712647" mesh="link2" material="white" class="collision"/>
						<joint name="joint2" type="hinge" pos="0.0 0.0 0.0" range="-2.059000015258789 2.094399929046631" axis="0.0 0.0 1.0"/>
						<body name="link3" pos="0.0 -0.2930000126361847 0.0" quat="0.7071067690849304 0.7071067690849304 0.0 0.0">
							<inertial mass="1.6382999420166016" pos="0.04659999907016754 -0.024630000814795494 -0.007679999805986881" quat="0.9138187170028687 0.28977492451667786 0.28148090839385986 -0.041645485907793045" diaginertia="0.003517210017889738 0.0029408899135887623 0.0019586801063269377"/>
							<geom name="Geom_3" type="mesh" pos="0.031160490587353706 0.0020180908031761646 -0.022566212341189384" quat="0.9348522424697876 0.15439170598983765 0.31362614035606384 0.06207319349050522" mesh="link3" material="white" class="collision"/>
							<joint name="joint3" type="hinge" pos="0.0 0.0 0.0" range="-6.28318977355957 6.28318977355957" axis="0.0 0.0 1.0"/>
							<body name="link4" pos="0.05249999836087227 0.0 0.0" quat="0.7071067690849304 0.7071067690849304 0.0 0.0">
								<inertial mass="1.7268999814987183" pos="0.07046999782323837 -0.11574999988079071 0.012000000104308128" quat="0.4221080541610718 0.852026104927063 -0.1260250210762024 0.2828320264816284" diaginertia="0.006571370176970959 0.006479479838162661 0.0018676300533115864"/>
								<geom name="Geom_4" type="mesh" pos="0.0589485689997673 -0.07610493153333664 0.04029048979282379" quat="0.47769883275032043 0.8121448159217834 0.32426926493644714 0.08410734683275223" mesh="link4" material="white" class="collision"/>
								<joint name="joint4" type="hinge" pos="0.0 0.0 0.0" range="-0.1919800043106079 3.927000045776367" axis="0.0 0.0 1.0"/>
								<body name="link5" pos="0.07750000059604645 -0.3425000011920929 0.0" quat="0.7071067690849304 0.7071067690849304 0.0 0.0">
									<inertial mass="1.3202999830245972" pos="-0.00031999999191612005 0.016039999201893806 -0.026000000536441803" quat="0.9993112087249756 -0.030445707961916924 0.0005770671414211392 0.021208204329013824" diaginertia="0.005347290076315403 0.004990759771317244 0.001348900026641786"/>
									<geom name="Geom_5" type="mesh" pos="-0.0001655187807045877 0.03179182857275009 -0.07229184359312057" quat="0.9894816875457764 -0.1444227695465088 0.0006865308969281614 0.008220445364713669" mesh="link5" material="white" class="collision"/>
									<joint name="joint5" type="hinge" pos="0.0 0.0 0.0" range="-6.28318977355957 6.28318977355957" axis="0.0 0.0 1.0"/>
									<body name="link6" pos="0.0 0.0 0.0" quat="0.7071067690849304 0.7071067690849304 0.0 0.0">
										<inertial mass="1.3250000476837158" pos="0.064690001308918 0.0327799990773201 0.021409999579191208" quat="-0.21767203509807587 0.7724190950393677 0.16258002817630768 0.574069082736969" diaginertia="0.0024542100727558136 0.0022164599504321814 0.0010727300541475415"/>
										<geom name="Geom_6" type="mesh" pos="0.048996806144714355 0.011248594149947166 0.00904772151261568" quat="-0.11064780503511429 0.7942664623260498 0.09746310114860535 0.5894054174423218" mesh="link6" material="white" class="collision"/>
										<joint name="joint6" type="hinge" pos="0.0 0.0 0.0" range="-1.6929700374603271 3.141590118408203" axis="0.0 0.0 1.0"/>
										<body name="link7" pos="0.07599999755620956 0.09700000286102295 0.0" quat="0.7071067690849304 -0.7071067690849304 0.0 0.0">
											<inertial mass="0.17000000178813934" pos="0.0 -0.006769999861717224 -0.010979999788105488" quat="0.48761221766471863 0.5120882391929626 -0.5120882391929626 0.48761221766471863" diaginertia="0.0001321760064456612 9.300000237999484e-05 5.852360118296929e-05"/>
											<geom name="Geom_7" type="mesh" pos="3.4268701654127653e-08 -0.0014353044098243117 -0.013516015373170376" quat="0.49949541687965393 0.5005040764808655 -0.5004957914352417 0.4995037019252777" mesh="end_tool" material="gray" class="collision"/>
											<joint name="joint7" type="hinge" pos="0.0 0.0 0.0" range="-6.28318977355957 6.28318977355957" axis="0.0 0.0 1.0"/>
											<body name="xarm_gripper_base_link" pos="0.0 0.0 0.0" quat="0.0 0.0 0.0 1.0">
												<inertial mass="0.5415599942207336" pos="-0.0006548900273628533 -0.0018496999982744455 0.04802799969911575" quat="0.9974032640457153 -0.07175122201442719 -0.006183601915836334 0.00047747913049533963" diaginertia="0.0004710929933935404 0.0003323070122860372 0.00025479900068603456"/>
												<geom name="Geom_8" type="mesh" pos="-0.0013675233349204063 0.00018071029626298696 0.04590832069516182" quat="0.99934321641922 0.017822450026869774 -0.031549274921417236 0.00034013341064564884" mesh="base_link" material="white" class="collision"/>
												<body name="left_inner_knuckle" pos="0.0 0.019999999552965164 0.07409799844026566" quat="1.0 0.0 0.0 0.0">
													<inertial mass="0.02301260083913803" pos="1.8660100522538414e-06 0.022046800702810287 0.026133500039577484" quat="0.6641393303871155 -0.24273212254047394 0.24271312355995178 0.664146363735199" diaginertia="8.342160072061233e-06 6.094900072639575e-06 2.7560099624679424e-06"/>
													<geom name="Geom_11" type="mesh" pos="2.847784708137624e-05 0.02092375047504902 0.024802643805742264" quat="0.6645216345787048 -0.24177679419517517 0.2436622679233551 0.6637647747993469" mesh="left_inner_knuckle" material="black" class="collision"/>
													<joint name="left_inner_knuckle_joint" type="hinge" pos="0.0 0.0 0.0" range="0.0 0.8500000238418579" axis="1.0 0.0 0.0"/>
												</body>
												<body name="right_inner_knuckle" pos="0.0 -0.019999999552965164 0.07409799844026566" quat="1.0 0.0 0.0 0.0">
													<inertial mass="0.023012999445199966" pos="1.866000047812122e-06 -0.022047000005841255 0.02613300085067749" quat="0.6641499400138855 0.24270197749137878 -0.24272097647190094 0.6641439199447632" diaginertia="8.342090040969197e-06 6.094900072639575e-06 2.7560099624679424e-06"/>
													<geom name="Geom_14" type="mesh" pos="-3.434382279010606e-06 -0.020921964198350906 0.02480097860097885" quat="0.6641914248466492 0.24258089065551758 -0.24283336102962494 0.6641055941581726" mesh="right_inner_knuckle" material="black" class="collision"/>
													<joint name="right_inner_knuckle_joint" type="hinge" pos="0.0 0.0 0.0" range="0.0 0.8500000238418579" axis="-1.0 0.0 0.0"/>
												</body>
												<body name="left_outer_knuckle" pos="0.0 0.03500000014901161 0.059098001569509506" quat="1.0 0.0 0.0 0.0">
													<inertial mass="0.03361799940466881" pos="0.0 0.02155900001525879 0.015181000344455242" quat="0.47788986563682556 0.8784197568893433 0.0 0.0" diaginertia="1.9110999346594326e-05 1.7908900190377608e-05 1.9016699752683053e-06"/>
													<geom name="Geom_9" type="mesh" pos="2.459128733978133e-11 0.017327455803751945 0.01510738953948021" quat="0.4820828437805176 0.8761256337165833 0.0 0.0" mesh="left_outer_knuckle" material="black" class="collision"/>
													<joint name="left_driver_joint" type="hinge" pos="0.0 0.0 0.0" range="0.0 0.8500000238418579" axis="1.0 0.0 0.0"/>
													<body name="left_finger" pos="0.0 0.035464998334646225 0.04203899949789047" quat="1.0 0.0 0.0 0.0">
														<inertial mass="0.0483039990067482" pos="0.0 -0.016412999480962753 0.0292579997330904" quat="0.6976343393325806 0.1153530552983284 -0.1153530552983284 0.6976343393325806" diaginertia="1.880369927675929e-05 1.749299917719327e-05 3.5679199754667934e-06"/>
														<geom name="Geom_10" type="mesh" pos="1.480761966377031e-05 -0.015549806877970695 0.028040098026394844" quat="0.6948176622390747 0.12783899903297424 -0.12892542779445648 0.6958906650543213" mesh="left_finger" material="black" class="collision"/>
														<joint name="left_finger_joint" type="hinge" pos="0.0 0.0 0.0" range="0.0 0.8500000238418579" axis="-1.0 0.0 0.0"/>
													</body>
												</body>
												<body name="right_outer_knuckle" pos="0.0 -0.03500000014901161 0.059098001569509506" quat="1.0 0.0 0.0 0.0">
													<inertial mass="0.03361799940466881" pos="0.0 -0.02155900001525879 0.015181000344455242" quat="0.8784197568893433 0.47788986563682556 0.0 0.0" diaginertia="1.9110999346594326e-05 1.7908900190377608e-05 1.9016699752683053e-06"/>
													<geom name="Geom_12" type="mesh" pos="-2.459128733978133e-11 -0.017327455803751945 0.01510738953948021" quat="0.8761256337165833 0.4820828437805176 0.0 0.0" mesh="right_outer_knuckle" material="black" class="collision"/>
													<joint name="right_driver_joint" type="hinge" pos="0.0 0.0 0.0" range="0.0 0.8500000238418579" axis="-1.0 0.0 0.0"/>
													<body name="right_finger" pos="0.0 -0.035464998334646225 0.04203899949789047" quat="1.0 0.0 0.0 0.0">
														<inertial mass="0.0483039990067482" pos="0.0 0.016412999480962753 0.0292579997330904" quat="0.6976338624954224 -0.1153559759259224 0.1153559759259224 0.6976338624954224" diaginertia="1.8803799321176484e-05 1.749299917719327e-05 3.56778991772444e-06"/>
														<geom name="Geom_13" type="mesh" pos="2.8375270630931482e-05 0.015532153658568859 0.028008582070469856" quat="0.6963784694671631 -0.12952396273612976 0.1274515837430954 0.6942886114120483" mesh="right_finger" material="black" class="collision"/>
														<joint name="right_finger_joint" type="hinge" pos="0.0 0.0 0.0" range="0.0 0.8500000238418579" axis="1.0 0.0 0.0"/>
													</body>
												</body>
											</body>
										</body>
									</body>
								</body>
							</body>
						</body>
					</body>
				</body>
			</body>
		</body>
	</worldbody>
	<equality>
		<joint name="Equality_2" joint1="left_driver_joint" joint2="right_driver_joint" polycoef="0.0 1.0 0.0 0.0 0.0"/>
	</equality>
</mujoco>
