<?xml version="1.0" ?>
<mujoco model="allegro_right">
	<compiler meshdir="allegro_right/meshes" texturedir="allegro_right/textures" angle="radian" autolimits="true" balanceinertia="true" boundmass="0.000001" boundinertia="0.000001"/>
	<default>
		<default class="visual">
			<geom contype="0" conaffinity="0"/>
		</default>
		<default class="collision">
			<geom rgba="1.0 0.0 0.0 0.0"/>
		</default>
	</default>
	<asset>
		<mesh name="base_link" file="stl/base_link.stl" scale="1.0 1.0 1.0"/>
		<mesh name="link_0_0" file="stl/link_0_0.stl" scale="1.0 1.0 1.0"/>
		<mesh name="link_1_0" file="stl/link_1_0.stl" scale="1.0 1.0 1.0"/>
		<mesh name="link_2_0" file="stl/link_2_0.stl" scale="1.0 1.0 1.0"/>
		<mesh name="link_3_0" file="stl/link_3_0.stl" scale="1.0 1.0 1.0"/>
		<mesh name="link_3_0_tip" file="stl/link_3_0_tip.stl" scale="1.0 1.0 1.0"/>
		<mesh name="link_12_0_right" file="stl/link_12_0_right.stl" scale="1.0 1.0 1.0"/>
		<mesh name="link_13_0" file="stl/link_13_0.stl" scale="1.0 1.0 1.0"/>
		<mesh name="link_14_0" file="stl/link_14_0.stl" scale="1.0 1.0 1.0"/>
		<mesh name="link_15_0" file="stl/link_15_0.stl" scale="1.0 1.0 1.0"/>
		<mesh name="link_15_0_tip" file="stl/link_15_0_tip.stl" scale="1.0 1.0 1.0"/>
		<material name="black" rgba="0.20000000298023224 0.20000000298023224 0.20000000298023224 1.0" emission="0.0" specular="0.5"/>
		<material name="white" rgba="0.8999999761581421 0.8999999761581421 0.8999999761581421 1.0" emission="0.0" specular="0.5"/>
	</asset>
	<worldbody>
		<body name="allegro_right" pos="0.0 0.0 0.0" quat="1.0 0.0 0.0 0.0">
			<body name="palm" pos="0.0 0.0 0.0" quat="1.0 0.0 0.0 0.0">
				<geom name="Geom_0" type="mesh" pos="-0.008985614404082298 -0.003957097418606281 -0.04026927426457405" quat="0.47179779410362244 0.8816921710968018 0.003048064885661006 -0.0040611447766423225" mesh="base_link" material="black" class="visual"/>
				<geom name="Geom_1" type="box" pos="-0.00930000003427267 0.0 -0.04749999940395355" quat="1.0 0.0 0.0 0.0" size="0.020400000736117363 0.05649999901652336 0.04749999940395355" class="collision"/>
				<body name="mf_base" pos="0.0 0.0 0.000699999975040555" quat="1.0 0.0 0.0 0.0">
					<inertial mass="0.007232016418129206" pos="-0.0007781272288411856 -1.0286681572324596e-05 0.00828249379992485" quat="0.6841335892677307 0.6859369277954102 -0.17537076771259308 0.1752052754163742" diaginertia="7.653767397641786e-07 6.888429311402433e-07 3.550456995071727e-07"/>
					<geom name="Geom_12" type="mesh" pos="-0.0007781272288411856 -1.0286681572324596e-05 0.00828249379992485" quat="0.6841325759887695 0.685935914516449 -0.1753745824098587 0.17520909011363983" mesh="link_0_0" material="black" class="visual"/>
					<geom name="Geom_13" type="box" pos="0.0 0.0 0.008200000040233135" quat="1.0 0.0 0.0 0.0" size="0.009800000116229057 0.013749999925494194 0.008200000040233135" class="collision"/>
					<joint name="mfj0" type="hinge" pos="0.0 0.0 0.0" range="-0.4699999988079071 0.4699999988079071" axis="0.0 0.0 1.0"/>
					<body name="mf_proximal" pos="0.0 0.0 0.01640000008046627" quat="1.0 0.0 0.0 0.0">
						<inertial mass="0.02727612294256687" pos="2.752533312389005e-08 -9.059566946234554e-05 0.02699976973235607" quat="1.0 -3.062632686123834e-06 1.740644087200316e-11 5.683489234797889e-06" diaginertia="1.1862359315273352e-05 1.1276808436377905e-05 2.2658684883936075e-06"/>
						<geom name="Geom_14" type="mesh" pos="2.752533312389005e-08 -9.059566946234554e-05 0.02699976973235607" quat="1.0 -3.062632686123834e-06 1.740644087200316e-11 5.683489234797889e-06" mesh="link_1_0" material="black" class="visual"/>
						<geom name="Geom_15" type="box" pos="0.0 0.0 0.027000000700354576" quat="1.0 0.0 0.0 0.0" size="0.009800000116229057 0.013749999925494194 0.027000000700354576" class="collision"/>
						<joint name="mfj1" type="hinge" pos="0.0 0.0 0.0" range="-0.19599999487400055 1.6100000143051147" axis="0.0 1.0 0.0"/>
						<body name="mf_medial" pos="0.0 0.0 0.05400000140070915" quat="1.0 0.0 0.0 0.0">
							<inertial mass="0.018463745713233948" pos="-0.0001928815763676539 -7.79042748035863e-05 0.02258601225912571" quat="0.9999030232429504 -0.0002869980817195028 0.013923503458499908 0.00017008630675263703" diaginertia="4.287327556085074e-06 3.6356423152028583e-06 1.6736697716623894e-06"/>
							<geom name="Geom_16" type="mesh" pos="-0.0001928815763676539 -7.79042748035863e-05 0.02258601225912571" quat="0.9999030232429504 -0.0002869980817195028 0.013923479244112968 0.00017008632130455226" mesh="link_2_0" material="black" class="visual"/>
							<geom name="Geom_17" type="box" pos="0.0 0.0 0.019200000911951065" quat="1.0 0.0 0.0 0.0" size="0.009800000116229057 0.013749999925494194 0.019200000911951065" class="collision"/>
							<joint name="mfj2" type="hinge" pos="0.0 0.0 0.0" range="-0.17399999499320984 1.7089999914169312" axis="0.0 1.0 0.0"/>
							<body name="mf_distal" pos="0.0 0.0 0.03840000182390213" quat="1.0 0.0 0.0 0.0">
								<inertial mass="0.007512311451137066" pos="-0.0005208061193116009 -3.324988711028709e-06 0.007251289673149586" quat="0.687752366065979 0.6877181529998779 0.16445226967334747 -0.16430427134037018" diaginertia="7.963795383147954e-07 7.281657872226788e-07 3.777521158099262e-07"/>
								<geom name="Geom_18" type="mesh" pos="-0.0005208061193116009 -3.324988711028709e-06 0.007251289673149586" quat="0.687752366065979 0.6877181529998779 0.16445223987102509 -0.1643042415380478" mesh="link_3_0" material="black" class="visual"/>
								<geom name="Geom_19" type="box" pos="0.0 0.0 0.00800000037997961" quat="1.0 0.0 0.0 0.0" size="0.009800000116229057 0.013749999925494194 0.00800000037997961" class="collision"/>
								<joint name="mfj3" type="hinge" pos="0.0 0.0 0.0" range="-0.22699999809265137 1.6180000305175781" axis="0.0 1.0 0.0"/>
								<body name="mf_tip" pos="0.0 0.0 0.0" quat="1.0 0.0 0.0 0.0">
									<inertial mass="0.006844521500170231" pos="2.0724932187077272e-11 -1.1561289881001358e-07 0.025402763858437538" quat="1.0 0.0 0.0 0.0" diaginertia="4.558230841666955e-07 4.558135913157457e-07 4.4955876887797785e-07"/>
									<geom name="Geom_20" type="mesh" pos="2.0724932187077272e-11 -1.1561289881001358e-07 0.025402763858437538" quat="1.0 0.0 0.0 0.0" mesh="link_3_0_tip" material="white" class="visual"/>
									<geom name="Geom_21" type="capsule" pos="0.0 0.0 0.01899999938905239" quat="1.0 0.0 0.0 0.0" size="0.012000000104308128 0.009999999776482582 0.0" class="collision"/>
								</body>
							</body>
						</body>
					</body>
				</body>
				<body name="rf_base" pos="0.0 -0.04349999874830246 -0.001541999983601272" quat="0.9990482330322266 0.04361940920352936 0.0 0.0">
					<inertial mass="0.007232016418129206" pos="-0.0007781272288411856 -1.0286681572324596e-05 0.00828249379992485" quat="0.6841335892677307 0.6859369277954102 -0.17537076771259308 0.1752052754163742" diaginertia="7.653767397641786e-07 6.888429311402433e-07 3.550456995071727e-07"/>
					<geom name="Geom_22" type="mesh" pos="-0.0007781272288411856 -1.0286681572324596e-05 0.00828249379992485" quat="0.6841325759887695 0.685935914516449 -0.1753745824098587 0.17520909011363983" mesh="link_0_0" material="black" class="visual"/>
					<geom name="Geom_23" type="box" pos="0.0 0.0 0.008200000040233135" quat="1.0 0.0 0.0 0.0" size="0.009800000116229057 0.013749999925494194 0.008200000040233135" class="collision"/>
					<joint name="rfj0" type="hinge" pos="0.0 0.0 0.0" range="-0.4699999988079071 0.4699999988079071" axis="0.0 0.0 1.0"/>
					<body name="rf_proximal" pos="0.0 0.0 0.01640000008046627" quat="1.0 0.0 0.0 0.0">
						<inertial mass="0.02727612294256687" pos="2.752533312389005e-08 -9.059566946234554e-05 0.02699976973235607" quat="1.0 -3.062632686123834e-06 1.740644087200316e-11 5.683489234797889e-06" diaginertia="1.1862359315273352e-05 1.1276808436377905e-05 2.2658684883936075e-06"/>
						<geom name="Geom_24" type="mesh" pos="2.752533312389005e-08 -9.059566946234554e-05 0.02699976973235607" quat="1.0 -3.062632686123834e-06 1.740644087200316e-11 5.683489234797889e-06" mesh="link_1_0" material="black" class="visual"/>
						<geom name="Geom_25" type="box" pos="0.0 0.0 0.027000000700354576" quat="1.0 0.0 0.0 0.0" size="0.009800000116229057 0.013749999925494194 0.027000000700354576" class="collision"/>
						<joint name="rfj1" type="hinge" pos="0.0 0.0 0.0" range="-0.19599999487400055 1.6100000143051147" axis="0.0 1.0 0.0"/>
						<body name="rf_medial" pos="0.0 0.0 0.05400000140070915" quat="1.0 0.0 0.0 0.0">
							<inertial mass="0.018463745713233948" pos="-0.0001928815763676539 -7.79042748035863e-05 0.02258601225912571" quat="0.9999030232429504 -0.0002869980817195028 0.013923503458499908 0.00017008630675263703" diaginertia="4.287327556085074e-06 3.6356423152028583e-06 1.6736697716623894e-06"/>
							<geom name="Geom_26" type="mesh" pos="-0.0001928815763676539 -7.79042748035863e-05 0.02258601225912571" quat="0.9999030232429504 -0.0002869980817195028 0.013923479244112968 0.00017008632130455226" mesh="link_2_0" material="black" class="visual"/>
							<geom name="Geom_27" type="box" pos="0.0 0.0 0.019200000911951065" quat="1.0 0.0 0.0 0.0" size="0.009800000116229057 0.013749999925494194 0.019200000911951065" class="collision"/>
							<joint name="rfj2" type="hinge" pos="0.0 0.0 0.0" range="-0.17399999499320984 1.7089999914169312" axis="0.0 1.0 0.0"/>
							<body name="rf_distal" pos="0.0 0.0 0.03840000182390213" quat="1.0 0.0 0.0 0.0">
								<inertial mass="0.007512311451137066" pos="-0.0005208061193116009 -3.324988711028709e-06 0.007251289673149586" quat="0.687752366065979 0.6877181529998779 0.16445226967334747 -0.16430427134037018" diaginertia="7.963795383147954e-07 7.281657872226788e-07 3.777521158099262e-07"/>
								<geom name="Geom_28" type="mesh" pos="-0.0005208061193116009 -3.324988711028709e-06 0.007251289673149586" quat="0.687752366065979 0.6877181529998779 0.16445223987102509 -0.1643042415380478" mesh="link_3_0" material="black" class="visual"/>
								<geom name="Geom_29" type="box" pos="0.0 0.0 0.00800000037997961" quat="1.0 0.0 0.0 0.0" size="0.009800000116229057 0.013749999925494194 0.00800000037997961" class="collision"/>
								<joint name="rfj3" type="hinge" pos="0.0 0.0 0.0" range="-0.22699999809265137 1.6180000305175781" axis="0.0 1.0 0.0"/>
								<body name="rf_tip" pos="0.0 0.0 0.0" quat="1.0 0.0 0.0 0.0">
									<inertial mass="0.006844521500170231" pos="2.0724932187077272e-11 -1.1561289881001358e-07 0.025402763858437538" quat="1.0 0.0 0.0 0.0" diaginertia="4.558230841666955e-07 4.558135913157457e-07 4.4955876887797785e-07"/>
									<geom name="Geom_30" type="mesh" pos="2.0724932187077272e-11 -1.1561289881001358e-07 0.025402763858437538" quat="1.0 0.0 0.0 0.0" mesh="link_3_0_tip" material="white" class="visual"/>
									<geom name="Geom_31" type="capsule" pos="0.0 0.0 0.01899999938905239" quat="1.0 0.0 0.0 0.0" size="0.012000000104308128 0.009999999776482582 0.0" class="collision"/>
								</body>
							</body>
						</body>
					</body>
				</body>
				<body name="th_base" pos="-0.018200000748038292 0.019332999363541603 -0.045986998826265335" quat="0.47771409153938293 -0.5213341116905212 -0.5213341116905212 -0.47771409153938293">
					<inertial mass="0.0382581427693367" pos="-0.01791512966156006 0.008024410344660282 0.012314137071371078" quat="0.7009028792381287 0.059141431003808975 -0.06316526234149933 0.707988440990448" diaginertia="1.0753209608083125e-05 9.165586561721284e-06 7.109078524081269e-06"/>
					<geom name="Geom_32" type="mesh" pos="-0.01791512966156006 0.008024410344660282 0.012314137071371078" quat="0.7009027600288391 0.05914142355322838 -0.06316527724266052 0.7079885601997375" mesh="link_12_0_right" material="black" class="visual"/>
					<geom name="Geom_33" type="box" pos="-0.017899999395012856 0.008999999612569809 0.014499999582767487" quat="1.0 0.0 0.0 0.0" size="0.017899999395012856 0.017000000923871994 0.022749999538064003" class="collision"/>
					<joint name="thj0" type="hinge" pos="0.0 0.0 0.0" range="0.2630000114440918 1.3960000276565552" axis="-1.0 0.0 0.0"/>
					<body name="th_proximal" pos="-0.027000000700354576 0.004999999888241291 0.039900001138448715" quat="1.0 0.0 0.0 0.0">
						<inertial mass="0.007219312246888876" pos="-0.0007820269092917442 -1.0249381375615485e-05 0.008104545064270496" quat="0.6839194893836975 0.6857205629348755 -0.17621275782585144 0.17604133486747742" diaginertia="7.637485737177485e-07 6.87399847265624e-07 3.53931511654082e-07"/>
						<geom name="Geom_34" type="mesh" pos="-0.0007820269092917442 -1.0249381375615485e-05 0.008104545064270496" quat="0.6839184761047363 0.6857195496559143 -0.17621660232543945 0.17604517936706543" mesh="link_13_0" material="black" class="visual"/>
						<geom name="Geom_35" type="box" pos="0.0 0.0 0.008849999867379665" quat="1.0 0.0 0.0 0.0" size="0.009800000116229057 0.013749999925494194 0.008849999867379665" class="collision"/>
						<joint name="thj1" type="hinge" pos="0.0 0.0 0.0" range="-0.10499999672174454 1.1629999876022339" axis="0.0 0.0 1.0"/>
						<body name="th_medial" pos="0.0 0.0 0.01769999973475933" quat="1.0 0.0 0.0 0.0">
							<inertial mass="0.022496473044157028" pos="-0.0001643362920731306 1.714846075628884e-05 0.02111191675066948" quat="0.9999598264694214 3.035604277101811e-05 -0.008964241482317448 0.00011317774624330923" diaginertia="7.527637080784189e-06 6.583326012332691e-06 2.14106444218487e-06"/>
							<geom name="Geom_36" type="mesh" pos="-0.0001643362920731306 1.714846075628884e-05 0.02111191675066948" quat="0.9999598264694214 3.035604277101811e-05 -0.008964239619672298 0.00011317774624330923" mesh="link_14_0" material="black" class="visual"/>
							<geom name="Geom_37" type="box" pos="0.0 0.0 0.025699999183416367" quat="1.0 0.0 0.0 0.0" size="0.009800000116229057 0.013749999925494194 0.025699999183416367" class="collision"/>
							<joint name="thj2" type="hinge" pos="0.0 0.0 0.0" range="-0.1889999955892563 1.6440000534057617" axis="0.0 1.0 0.0"/>
							<body name="th_distal" pos="0.0 0.0 0.05139999836683273" quat="1.0 0.0 0.0 0.0">
								<inertial mass="0.016334496438503265" pos="-6.764516030655088e-12 3.6771950817637844e-06 0.013075033202767372" quat="0.9999980926513672 0.0019454479916021228 0.0 0.0" diaginertia="2.913777279900387e-06 2.590203166619176e-06 1.3565170320362085e-06"/>
								<geom name="Geom_38" type="mesh" pos="-6.764516030655088e-12 3.6771950817637844e-06 0.013075033202767372" quat="0.9999980926513672 0.0019454479916021228 0.0 0.0" mesh="link_15_0" material="black" class="visual"/>
								<geom name="Geom_39" type="box" pos="0.0 0.0 0.015699999406933784" quat="1.0 0.0 0.0 0.0" size="0.009800000116229057 0.013749999925494194 0.015699999406933784" class="collision"/>
								<joint name="thj3" type="hinge" pos="0.0 0.0 0.0" range="-0.16200000047683716 1.718999981880188" axis="0.0 1.0 0.0"/>
								<body name="th_tip" pos="0.0 0.0 0.0" quat="1.0 0.0 0.0 0.0">
									<inertial mass="0.006844521500170231" pos="2.0724932187077272e-11 -1.1561289881001358e-07 0.04100276529788971" quat="1.0 0.0 0.0 0.0" diaginertia="4.558230841666955e-07 4.558135913157457e-07 4.4955876887797785e-07"/>
									<geom name="Geom_40" type="mesh" pos="2.0724932187077272e-11 -1.1561289881001358e-07 0.04100276529788971" quat="1.0 0.0 0.0 0.0" mesh="link_15_0_tip" material="white" class="visual"/>
									<geom name="Geom_41" type="capsule" pos="0.0 0.0 0.03500000014901161" quat="1.0 0.0 0.0 0.0" size="0.012000000104308128 0.00800000037997961 0.0" class="collision"/>
								</body>
							</body>
						</body>
					</body>
				</body>
				<body name="ff_base" pos="0.0 0.04349999874830246 -0.001541999983601272" quat="0.9990482330322266 -0.04361940920352936 0.0 0.0">
					<inertial mass="0.007232016418129206" pos="-0.0007781272288411856 -1.0286681572324596e-05 0.00828249379992485" quat="0.6841335892677307 0.6859369277954102 -0.17537076771259308 0.1752052754163742" diaginertia="7.653767397641786e-07 6.888429311402433e-07 3.550456995071727e-07"/>
					<geom name="Geom_2" type="mesh" pos="-0.0007781272288411856 -1.0286681572324596e-05 0.00828249379992485" quat="0.6841325759887695 0.685935914516449 -0.1753745824098587 0.17520909011363983" mesh="link_0_0" material="black" class="visual"/>
					<geom name="Geom_3" type="box" pos="0.0 0.0 0.008200000040233135" quat="1.0 0.0 0.0 0.0" size="0.009800000116229057 0.013749999925494194 0.008200000040233135" class="collision"/>
					<joint name="ffj0" type="hinge" pos="0.0 0.0 0.0" range="-0.4699999988079071 0.4699999988079071" axis="0.0 0.0 1.0"/>
					<body name="ff_proximal" pos="0.0 0.0 0.01640000008046627" quat="1.0 0.0 0.0 0.0">
						<inertial mass="0.02727612294256687" pos="2.752533312389005e-08 -9.059566946234554e-05 0.02699976973235607" quat="1.0 -3.062632686123834e-06 1.740644087200316e-11 5.683489234797889e-06" diaginertia="1.1862359315273352e-05 1.1276808436377905e-05 2.2658684883936075e-06"/>
						<geom name="Geom_4" type="mesh" pos="2.752533312389005e-08 -9.059566946234554e-05 0.02699976973235607" quat="1.0 -3.062632686123834e-06 1.740644087200316e-11 5.683489234797889e-06" mesh="link_1_0" material="black" class="visual"/>
						<geom name="Geom_5" type="box" pos="0.0 0.0 0.027000000700354576" quat="1.0 0.0 0.0 0.0" size="0.009800000116229057 0.013749999925494194 0.027000000700354576" class="collision"/>
						<joint name="ffj1" type="hinge" pos="0.0 0.0 0.0" range="-0.19599999487400055 1.6100000143051147" axis="0.0 1.0 0.0"/>
						<body name="ff_medial" pos="0.0 0.0 0.05400000140070915" quat="1.0 0.0 0.0 0.0">
							<inertial mass="0.018463745713233948" pos="-0.0001928815763676539 -7.79042748035863e-05 0.02258601225912571" quat="0.9999030232429504 -0.0002869980817195028 0.013923503458499908 0.00017008630675263703" diaginertia="4.287327556085074e-06 3.6356423152028583e-06 1.6736697716623894e-06"/>
							<geom name="Geom_6" type="mesh" pos="-0.0001928815763676539 -7.79042748035863e-05 0.02258601225912571" quat="0.9999030232429504 -0.0002869980817195028 0.013923479244112968 0.00017008632130455226" mesh="link_2_0" material="black" class="visual"/>
							<geom name="Geom_7" type="box" pos="0.0 0.0 0.019200000911951065" quat="1.0 0.0 0.0 0.0" size="0.009800000116229057 0.013749999925494194 0.019200000911951065" class="collision"/>
							<joint name="ffj2" type="hinge" pos="0.0 0.0 0.0" range="-0.17399999499320984 1.7089999914169312" axis="0.0 1.0 0.0"/>
							<body name="ff_distal" pos="0.0 0.0 0.03840000182390213" quat="1.0 0.0 0.0 0.0">
								<inertial mass="0.007512311451137066" pos="-0.0005208061193116009 -3.324988711028709e-06 0.007251289673149586" quat="0.687752366065979 0.6877181529998779 0.16445226967334747 -0.16430427134037018" diaginertia="7.963795383147954e-07 7.281657872226788e-07 3.777521158099262e-07"/>
								<geom name="Geom_8" type="mesh" pos="-0.0005208061193116009 -3.324988711028709e-06 0.007251289673149586" quat="0.687752366065979 0.6877181529998779 0.16445223987102509 -0.1643042415380478" mesh="link_3_0" material="black" class="visual"/>
								<geom name="Geom_9" type="box" pos="0.0 0.0 0.00800000037997961" quat="1.0 0.0 0.0 0.0" size="0.009800000116229057 0.013749999925494194 0.00800000037997961" class="collision"/>
								<joint name="ffj3" type="hinge" pos="0.0 0.0 0.0" range="-0.22699999809265137 1.6180000305175781" axis="0.0 1.0 0.0"/>
								<body name="ff_tip" pos="0.0 0.0 0.0" quat="1.0 0.0 0.0 0.0">
									<inertial mass="0.006844521500170231" pos="2.0724932187077272e-11 -1.1561289881001358e-07 0.025402763858437538" quat="1.0 0.0 0.0 0.0" diaginertia="4.558230841666955e-07 4.558135913157457e-07 4.4955876887797785e-07"/>
									<geom name="Geom_10" type="mesh" pos="2.0724932187077272e-11 -1.1561289881001358e-07 0.025402763858437538" quat="1.0 0.0 0.0 0.0" mesh="link_3_0_tip" material="white" class="visual"/>
									<geom name="Geom_11" type="capsule" pos="0.0 0.0 0.01899999938905239" quat="1.0 0.0 0.0 0.0" size="0.012000000104308128 0.009999999776482582 0.0" class="collision"/>
								</body>
							</body>
						</body>
					</body>
				</body>
			</body>
		</body>
	</worldbody>
	<equality/>
</mujoco>
