<?xml version="1.0" ?>
<robot name="allegro_right" version="1.0">
  <link name="allegro_right"/>
  <joint name="palm_joint" type="fixed">
    <origin xyz="0.0 0.0 0.0" rpy="0.0 0.0 0.0"/>
    <parent link="allegro_right"/>
    <child link="palm"/>
  </joint>
  <link name="palm">
    <visual name="Geom_0">
      <origin xyz="-0.008985614404082298 -0.003957097418606281 -0.04026927426457405" rpy="2.1589293479919434 0.01003766804933548 0.0015429097693413496"/>
      <geometry>
        <mesh filename="file://allegro_right/meshes/obj/base_link.obj" scale="1.0 1.0 1.0"/>
      </geometry>
    </visual>
    <collision name="Geom_1">
      <origin xyz="-0.00930000003427267 0.0 -0.04749999940395355" rpy="0.0 0.0 0.0"/>
      <geometry>
        <box size="0.040800001472234726 0.11299999803304672 0.0949999988079071"/>
      </geometry>
    </collision>
  </link>
  <joint name="ffj0" type="revolute">
    <origin xyz="0.0 0.04349999874830246 -0.001541999983601272" rpy="-0.08726650476455688 0.0 0.0"/>
    <axis xyz="0.0 0.0 1.0"/>
    <parent link="palm"/>
    <child link="ff_base"/>
    <limit effort="1000.0" lower="-0.4699999988079071" upper="0.4699999988079071" velocity="1000.0"/>
  </joint>
  <link name="ff_base">
    <inertial>
      <origin xyz="-0.0007781272288411856 -1.0286681572324596e-05 0.00828249379992485" rpy="1.5736793279647827 -0.5010122060775757 -0.000979302916675806"/>
      <mass value="0.007232016418129206"/>
      <inertia ixx="7.653767397641786e-07" ixy="0.0" ixz="0.0" iyy="6.888429311402433e-07" iyz="0.0" izz="3.550456995071727e-07"/>
    </inertial>
    <visual name="Geom_2">
      <origin xyz="-0.0007781272288411856 -1.0286681572324596e-05 0.00828249379992485" rpy="1.5736794471740723 -0.5010233521461487 -0.0009793322533369064"/>
      <geometry>
        <mesh filename="file://allegro_right/meshes/obj/link_0.0.obj" scale="1.0 1.0 1.0"/>
      </geometry>
    </visual>
    <collision name="Geom_3">
      <origin xyz="0.0 0.0 0.008200000040233135" rpy="0.0 0.0 0.0"/>
      <geometry>
        <box size="0.019600000232458115 0.027499999850988388 0.01640000008046627"/>
      </geometry>
    </collision>
  </link>
  <joint name="ffj1" type="revolute">
    <origin xyz="0.0 0.0 0.01640000008046627" rpy="0.0 0.0 0.0"/>
    <axis xyz="0.0 1.0 0.0"/>
    <parent link="ff_base"/>
    <child link="ff_proximal"/>
    <limit effort="1000.0" lower="-0.19599999487400055" upper="1.6100000143051147" velocity="1000.0"/>
  </joint>
  <link name="ff_proximal">
    <inertial>
      <origin xyz="2.752533312389005e-08 -9.059566946234554e-05 0.02699976973235607" rpy="-6.125265372247668e-06 6.962586063252729e-11 1.1366978469595779e-05"/>
      <mass value="0.02727612294256687"/>
      <inertia ixx="1.1862359315273352e-05" ixy="0.0" ixz="0.0" iyy="1.1276808436377905e-05" iyz="0.0" izz="2.2658684883936075e-06"/>
    </inertial>
    <visual name="Geom_4">
      <origin xyz="2.752533312389005e-08 -9.059566946234554e-05 0.02699976973235607" rpy="-6.125265372247668e-06 6.962586063252729e-11 1.1366978469595779e-05"/>
      <geometry>
        <mesh filename="file://allegro_right/meshes/obj/link_1.0.obj" scale="1.0 1.0 1.0"/>
      </geometry>
    </visual>
    <collision name="Geom_5">
      <origin xyz="0.0 0.0 0.027000000700354576" rpy="0.0 0.0 0.0"/>
      <geometry>
        <box size="0.019600000232458115 0.027499999850988388 0.05400000140070915"/>
      </geometry>
    </collision>
  </link>
  <joint name="ffj2" type="revolute">
    <origin xyz="0.0 0.0 0.05400000140070915" rpy="0.0 0.0 0.0"/>
    <axis xyz="0.0 1.0 0.0"/>
    <parent link="ff_proximal"/>
    <child link="ff_medial"/>
    <limit effort="1000.0" lower="-0.17399999499320984" upper="1.7089999914169312" velocity="1000.0"/>
  </joint>
  <link name="ff_medial">
    <inertial>
      <origin xyz="-0.0001928815763676539 -7.79042748035863e-05 0.02258601225912571" rpy="-0.0005694248829968274 0.027848001569509506 0.0003322764241602272"/>
      <mass value="0.018463745713233948"/>
      <inertia ixx="4.287327556085074e-06" ixy="0.0" ixz="0.0" iyy="3.6356423152028583e-06" iyz="0.0" izz="1.6736697716623894e-06"/>
    </inertial>
    <visual name="Geom_6">
      <origin xyz="-0.0001928815763676539 -7.79042748035863e-05 0.02258601225912571" rpy="-0.0005694249412044883 0.027847955003380775 0.00033227645326405764"/>
      <geometry>
        <mesh filename="file://allegro_right/meshes/obj/link_2.0.obj" scale="1.0 1.0 1.0"/>
      </geometry>
    </visual>
    <collision name="Geom_7">
      <origin xyz="0.0 0.0 0.019200000911951065" rpy="0.0 0.0 0.0"/>
      <geometry>
        <box size="0.019600000232458115 0.027499999850988388 0.03840000182390213"/>
      </geometry>
    </collision>
  </link>
  <joint name="ffj3" type="revolute">
    <origin xyz="0.0 0.0 0.03840000182390213" rpy="0.0 0.0 0.0"/>
    <axis xyz="0.0 1.0 0.0"/>
    <parent link="ff_medial"/>
    <child link="ff_distal"/>
    <limit effort="1000.0" lower="-0.22699999809265137" upper="1.6180000305175781" velocity="1000.0"/>
  </joint>
  <link name="ff_distal">
    <inertial>
      <origin xyz="-0.0005208061193116009 -3.324988711028709e-06 0.007251289673149586" rpy="1.5707981586456299 0.4692247211933136 0.00021562444453593343"/>
      <mass value="0.007512311451137066"/>
      <inertia ixx="7.963795383147954e-07" ixy="0.0" ixz="0.0" iyy="7.281657872226788e-07" iyz="0.0" izz="3.777521158099262e-07"/>
    </inertial>
    <visual name="Geom_8">
      <origin xyz="-0.0005208061193116009 -3.324988711028709e-06 0.007251289673149586" rpy="1.5707981586456299 0.46922463178634644 0.00021561773610301316"/>
      <geometry>
        <mesh filename="file://allegro_right/meshes/obj/link_3.0.obj" scale="1.0 1.0 1.0"/>
      </geometry>
    </visual>
    <collision name="Geom_9">
      <origin xyz="0.0 0.0 0.00800000037997961" rpy="0.0 0.0 0.0"/>
      <geometry>
        <box size="0.019600000232458115 0.027499999850988388 0.01600000075995922"/>
      </geometry>
    </collision>
  </link>
  <joint name="ff_tip_joint" type="fixed">
    <origin xyz="0.0 0.0 0.0" rpy="0.0 0.0 0.0"/>
    <parent link="ff_distal"/>
    <child link="ff_tip"/>
  </joint>
  <link name="ff_tip">
    <inertial>
      <origin xyz="2.0724932187077272e-11 -1.1561289881001358e-07 0.025402763858437538" rpy="0.0 0.0 0.0"/>
      <mass value="0.006844521500170231"/>
      <inertia ixx="4.558230841666955e-07" ixy="0.0" ixz="0.0" iyy="4.558135913157457e-07" iyz="0.0" izz="4.4955876887797785e-07"/>
    </inertial>
    <visual name="Geom_10">
      <origin xyz="2.0724932187077272e-11 -1.1561289881001358e-07 0.025402763858437538" rpy="0.0 0.0 0.0"/>
      <geometry>
        <mesh filename="file://allegro_right/meshes/obj/link_3.0_tip.obj" scale="1.0 1.0 1.0"/>
      </geometry>
    </visual>
    <collision name="Geom_11">
      <origin xyz="0.0 0.0 0.01899999938905239" rpy="0.0 0.0 0.0"/>
      <geometry>
        <cylinder radius="0.012000000104308128" length="0.019999999552965164"/>
      </geometry>
    </collision>
  </link>
  <joint name="mfj0" type="revolute">
    <origin xyz="0.0 0.0 0.000699999975040555" rpy="0.0 0.0 0.0"/>
    <axis xyz="0.0 0.0 1.0"/>
    <parent link="palm"/>
    <child link="mf_base"/>
    <limit effort="1000.0" lower="-0.4699999988079071" upper="0.4699999988079071" velocity="1000.0"/>
  </joint>
  <link name="mf_base">
    <inertial>
      <origin xyz="-0.0007781272288411856 -1.0286681572324596e-05 0.00828249379992485" rpy="1.5736793279647827 -0.5010122060775757 -0.000979302916675806"/>
      <mass value="0.007232016418129206"/>
      <inertia ixx="7.653767397641786e-07" ixy="0.0" ixz="0.0" iyy="6.888429311402433e-07" iyz="0.0" izz="3.550456995071727e-07"/>
    </inertial>
    <visual name="Geom_12">
      <origin xyz="-0.0007781272288411856 -1.0286681572324596e-05 0.00828249379992485" rpy="1.5736794471740723 -0.5010233521461487 -0.0009793322533369064"/>
      <geometry>
        <mesh filename="file://allegro_right/meshes/obj/link_0.0.obj" scale="1.0 1.0 1.0"/>
      </geometry>
    </visual>
    <collision name="Geom_13">
      <origin xyz="0.0 0.0 0.008200000040233135" rpy="0.0 0.0 0.0"/>
      <geometry>
        <box size="0.019600000232458115 0.027499999850988388 0.01640000008046627"/>
      </geometry>
    </collision>
  </link>
  <joint name="mfj1" type="revolute">
    <origin xyz="0.0 0.0 0.01640000008046627" rpy="0.0 0.0 0.0"/>
    <axis xyz="0.0 1.0 0.0"/>
    <parent link="mf_base"/>
    <child link="mf_proximal"/>
    <limit effort="1000.0" lower="-0.19599999487400055" upper="1.6100000143051147" velocity="1000.0"/>
  </joint>
  <link name="mf_proximal">
    <inertial>
      <origin xyz="2.752533312389005e-08 -9.059566946234554e-05 0.02699976973235607" rpy="-6.125265372247668e-06 6.962586063252729e-11 1.1366978469595779e-05"/>
      <mass value="0.02727612294256687"/>
      <inertia ixx="1.1862359315273352e-05" ixy="0.0" ixz="0.0" iyy="1.1276808436377905e-05" iyz="0.0" izz="2.2658684883936075e-06"/>
    </inertial>
    <visual name="Geom_14">
      <origin xyz="2.752533312389005e-08 -9.059566946234554e-05 0.02699976973235607" rpy="-6.125265372247668e-06 6.962586063252729e-11 1.1366978469595779e-05"/>
      <geometry>
        <mesh filename="file://allegro_right/meshes/obj/link_1.0.obj" scale="1.0 1.0 1.0"/>
      </geometry>
    </visual>
    <collision name="Geom_15">
      <origin xyz="0.0 0.0 0.027000000700354576" rpy="0.0 0.0 0.0"/>
      <geometry>
        <box size="0.019600000232458115 0.027499999850988388 0.05400000140070915"/>
      </geometry>
    </collision>
  </link>
  <joint name="mfj2" type="revolute">
    <origin xyz="0.0 0.0 0.05400000140070915" rpy="0.0 0.0 0.0"/>
    <axis xyz="0.0 1.0 0.0"/>
    <parent link="mf_proximal"/>
    <child link="mf_medial"/>
    <limit effort="1000.0" lower="-0.17399999499320984" upper="1.7089999914169312" velocity="1000.0"/>
  </joint>
  <link name="mf_medial">
    <inertial>
      <origin xyz="-0.0001928815763676539 -7.79042748035863e-05 0.02258601225912571" rpy="-0.0005694248829968274 0.027848001569509506 0.0003322764241602272"/>
      <mass value="0.018463745713233948"/>
      <inertia ixx="4.287327556085074e-06" ixy="0.0" ixz="0.0" iyy="3.6356423152028583e-06" iyz="0.0" izz="1.6736697716623894e-06"/>
    </inertial>
    <visual name="Geom_16">
      <origin xyz="-0.0001928815763676539 -7.79042748035863e-05 0.02258601225912571" rpy="-0.0005694249412044883 0.027847955003380775 0.00033227645326405764"/>
      <geometry>
        <mesh filename="file://allegro_right/meshes/obj/link_2.0.obj" scale="1.0 1.0 1.0"/>
      </geometry>
    </visual>
    <collision name="Geom_17">
      <origin xyz="0.0 0.0 0.019200000911951065" rpy="0.0 0.0 0.0"/>
      <geometry>
        <box size="0.019600000232458115 0.027499999850988388 0.03840000182390213"/>
      </geometry>
    </collision>
  </link>
  <joint name="mfj3" type="revolute">
    <origin xyz="0.0 0.0 0.03840000182390213" rpy="0.0 0.0 0.0"/>
    <axis xyz="0.0 1.0 0.0"/>
    <parent link="mf_medial"/>
    <child link="mf_distal"/>
    <limit effort="1000.0" lower="-0.22699999809265137" upper="1.6180000305175781" velocity="1000.0"/>
  </joint>
  <link name="mf_distal">
    <inertial>
      <origin xyz="-0.0005208061193116009 -3.324988711028709e-06 0.007251289673149586" rpy="1.5707981586456299 0.4692247211933136 0.00021562444453593343"/>
      <mass value="0.007512311451137066"/>
      <inertia ixx="7.963795383147954e-07" ixy="0.0" ixz="0.0" iyy="7.281657872226788e-07" iyz="0.0" izz="3.777521158099262e-07"/>
    </inertial>
    <visual name="Geom_18">
      <origin xyz="-0.0005208061193116009 -3.324988711028709e-06 0.007251289673149586" rpy="1.5707981586456299 0.46922463178634644 0.00021561773610301316"/>
      <geometry>
        <mesh filename="file://allegro_right/meshes/obj/link_3.0.obj" scale="1.0 1.0 1.0"/>
      </geometry>
    </visual>
    <collision name="Geom_19">
      <origin xyz="0.0 0.0 0.00800000037997961" rpy="0.0 0.0 0.0"/>
      <geometry>
        <box size="0.019600000232458115 0.027499999850988388 0.01600000075995922"/>
      </geometry>
    </collision>
  </link>
  <joint name="mf_tip_joint" type="fixed">
    <origin xyz="0.0 0.0 0.0" rpy="0.0 0.0 0.0"/>
    <parent link="mf_distal"/>
    <child link="mf_tip"/>
  </joint>
  <link name="mf_tip">
    <inertial>
      <origin xyz="2.0724932187077272e-11 -1.1561289881001358e-07 0.025402763858437538" rpy="0.0 0.0 0.0"/>
      <mass value="0.006844521500170231"/>
      <inertia ixx="4.558230841666955e-07" ixy="0.0" ixz="0.0" iyy="4.558135913157457e-07" iyz="0.0" izz="4.4955876887797785e-07"/>
    </inertial>
    <visual name="Geom_20">
      <origin xyz="2.0724932187077272e-11 -1.1561289881001358e-07 0.025402763858437538" rpy="0.0 0.0 0.0"/>
      <geometry>
        <mesh filename="file://allegro_right/meshes/obj/link_3.0_tip.obj" scale="1.0 1.0 1.0"/>
      </geometry>
    </visual>
    <collision name="Geom_21">
      <origin xyz="0.0 0.0 0.01899999938905239" rpy="0.0 0.0 0.0"/>
      <geometry>
        <cylinder radius="0.012000000104308128" length="0.019999999552965164"/>
      </geometry>
    </collision>
  </link>
  <joint name="rfj0" type="revolute">
    <origin xyz="0.0 -0.04349999874830246 -0.001541999983601272" rpy="0.08726650476455688 0.0 0.0"/>
    <axis xyz="0.0 0.0 1.0"/>
    <parent link="palm"/>
    <child link="rf_base"/>
    <limit effort="1000.0" lower="-0.4699999988079071" upper="0.4699999988079071" velocity="1000.0"/>
  </joint>
  <link name="rf_base">
    <inertial>
      <origin xyz="-0.0007781272288411856 -1.0286681572324596e-05 0.00828249379992485" rpy="1.5736793279647827 -0.5010122060775757 -0.000979302916675806"/>
      <mass value="0.007232016418129206"/>
      <inertia ixx="7.653767397641786e-07" ixy="0.0" ixz="0.0" iyy="6.888429311402433e-07" iyz="0.0" izz="3.550456995071727e-07"/>
    </inertial>
    <visual name="Geom_22">
      <origin xyz="-0.0007781272288411856 -1.0286681572324596e-05 0.00828249379992485" rpy="1.5736794471740723 -0.5010233521461487 -0.0009793322533369064"/>
      <geometry>
        <mesh filename="file://allegro_right/meshes/obj/link_0.0.obj" scale="1.0 1.0 1.0"/>
      </geometry>
    </visual>
    <collision name="Geom_23">
      <origin xyz="0.0 0.0 0.008200000040233135" rpy="0.0 0.0 0.0"/>
      <geometry>
        <box size="0.019600000232458115 0.027499999850988388 0.01640000008046627"/>
      </geometry>
    </collision>
  </link>
  <joint name="rfj1" type="revolute">
    <origin xyz="0.0 0.0 0.01640000008046627" rpy="0.0 0.0 0.0"/>
    <axis xyz="0.0 1.0 0.0"/>
    <parent link="rf_base"/>
    <child link="rf_proximal"/>
    <limit effort="1000.0" lower="-0.19599999487400055" upper="1.6100000143051147" velocity="1000.0"/>
  </joint>
  <link name="rf_proximal">
    <inertial>
      <origin xyz="2.752533312389005e-08 -9.059566946234554e-05 0.02699976973235607" rpy="-6.125265372247668e-06 6.962586063252729e-11 1.1366978469595779e-05"/>
      <mass value="0.02727612294256687"/>
      <inertia ixx="1.1862359315273352e-05" ixy="0.0" ixz="0.0" iyy="1.1276808436377905e-05" iyz="0.0" izz="2.2658684883936075e-06"/>
    </inertial>
    <visual name="Geom_24">
      <origin xyz="2.752533312389005e-08 -9.059566946234554e-05 0.02699976973235607" rpy="-6.125265372247668e-06 6.962586063252729e-11 1.1366978469595779e-05"/>
      <geometry>
        <mesh filename="file://allegro_right/meshes/obj/link_1.0.obj" scale="1.0 1.0 1.0"/>
      </geometry>
    </visual>
    <collision name="Geom_25">
      <origin xyz="0.0 0.0 0.027000000700354576" rpy="0.0 0.0 0.0"/>
      <geometry>
        <box size="0.019600000232458115 0.027499999850988388 0.05400000140070915"/>
      </geometry>
    </collision>
  </link>
  <joint name="rfj2" type="revolute">
    <origin xyz="0.0 0.0 0.05400000140070915" rpy="0.0 0.0 0.0"/>
    <axis xyz="0.0 1.0 0.0"/>
    <parent link="rf_proximal"/>
    <child link="rf_medial"/>
    <limit effort="1000.0" lower="-0.17399999499320984" upper="1.7089999914169312" velocity="1000.0"/>
  </joint>
  <link name="rf_medial">
    <inertial>
      <origin xyz="-0.0001928815763676539 -7.79042748035863e-05 0.02258601225912571" rpy="-0.0005694248829968274 0.027848001569509506 0.0003322764241602272"/>
      <mass value="0.018463745713233948"/>
      <inertia ixx="4.287327556085074e-06" ixy="0.0" ixz="0.0" iyy="3.6356423152028583e-06" iyz="0.0" izz="1.6736697716623894e-06"/>
    </inertial>
    <visual name="Geom_26">
      <origin xyz="-0.0001928815763676539 -7.79042748035863e-05 0.02258601225912571" rpy="-0.0005694249412044883 0.027847955003380775 0.00033227645326405764"/>
      <geometry>
        <mesh filename="file://allegro_right/meshes/obj/link_2.0.obj" scale="1.0 1.0 1.0"/>
      </geometry>
    </visual>
    <collision name="Geom_27">
      <origin xyz="0.0 0.0 0.019200000911951065" rpy="0.0 0.0 0.0"/>
      <geometry>
        <box size="0.019600000232458115 0.027499999850988388 0.03840000182390213"/>
      </geometry>
    </collision>
  </link>
  <joint name="rfj3" type="revolute">
    <origin xyz="0.0 0.0 0.03840000182390213" rpy="0.0 0.0 0.0"/>
    <axis xyz="0.0 1.0 0.0"/>
    <parent link="rf_medial"/>
    <child link="rf_distal"/>
    <limit effort="1000.0" lower="-0.22699999809265137" upper="1.6180000305175781" velocity="1000.0"/>
  </joint>
  <link name="rf_distal">
    <inertial>
      <origin xyz="-0.0005208061193116009 -3.324988711028709e-06 0.007251289673149586" rpy="1.5707981586456299 0.4692247211933136 0.00021562444453593343"/>
      <mass value="0.007512311451137066"/>
      <inertia ixx="7.963795383147954e-07" ixy="0.0" ixz="0.0" iyy="7.281657872226788e-07" iyz="0.0" izz="3.777521158099262e-07"/>
    </inertial>
    <visual name="Geom_28">
      <origin xyz="-0.0005208061193116009 -3.324988711028709e-06 0.007251289673149586" rpy="1.5707981586456299 0.46922463178634644 0.00021561773610301316"/>
      <geometry>
        <mesh filename="file://allegro_right/meshes/obj/link_3.0.obj" scale="1.0 1.0 1.0"/>
      </geometry>
    </visual>
    <collision name="Geom_29">
      <origin xyz="0.0 0.0 0.00800000037997961" rpy="0.0 0.0 0.0"/>
      <geometry>
        <box size="0.019600000232458115 0.027499999850988388 0.01600000075995922"/>
      </geometry>
    </collision>
  </link>
  <joint name="rf_tip_joint" type="fixed">
    <origin xyz="0.0 0.0 0.0" rpy="0.0 0.0 0.0"/>
    <parent link="rf_distal"/>
    <child link="rf_tip"/>
  </joint>
  <link name="rf_tip">
    <inertial>
      <origin xyz="2.0724932187077272e-11 -1.1561289881001358e-07 0.025402763858437538" rpy="0.0 0.0 0.0"/>
      <mass value="0.006844521500170231"/>
      <inertia ixx="4.558230841666955e-07" ixy="0.0" ixz="0.0" iyy="4.558135913157457e-07" iyz="0.0" izz="4.4955876887797785e-07"/>
    </inertial>
    <visual name="Geom_30">
      <origin xyz="2.0724932187077272e-11 -1.1561289881001358e-07 0.025402763858437538" rpy="0.0 0.0 0.0"/>
      <geometry>
        <mesh filename="file://allegro_right/meshes/obj/link_3.0_tip.obj" scale="1.0 1.0 1.0"/>
      </geometry>
    </visual>
    <collision name="Geom_31">
      <origin xyz="0.0 0.0 0.01899999938905239" rpy="0.0 0.0 0.0"/>
      <geometry>
        <cylinder radius="0.012000000104308128" length="0.019999999552965164"/>
      </geometry>
    </collision>
  </link>
  <joint name="thj0" type="revolute">
    <origin xyz="-0.018200000748038292 0.019332999363541603 -0.045986998826265335" rpy="3.1415927410125732 -1.4835286140441895 1.5707963705062866"/>
    <axis xyz="-1.0 0.0 0.0"/>
    <parent link="palm"/>
    <child link="th_base"/>
    <limit effort="1000.0" lower="0.2630000114440918" upper="1.3960000276565552" velocity="1000.0"/>
  </joint>
  <link name="th_base">
    <inertial>
      <origin xyz="-0.01791512966156006 0.008024410344660282 0.012314137071371078" rpy="-0.0066350167617201805 -0.17315225303173065 1.581430435180664"/>
      <mass value="0.0382581427693367"/>
      <inertia ixx="1.0753209608083125e-05" ixy="0.0" ixz="0.0" iyy="9.165586561721284e-06" iyz="0.0" izz="7.109078524081269e-06"/>
    </inertial>
    <visual name="Geom_32">
      <origin xyz="-0.01791512966156006 0.008024410344660282 0.012314137071371078" rpy="-0.006635074038058519 -0.17315226793289185 1.5814307928085327"/>
      <geometry>
        <mesh filename="file://allegro_right/meshes/obj/link_12.0_right.obj" scale="1.0 1.0 1.0"/>
      </geometry>
    </visual>
    <collision name="Geom_33">
      <origin xyz="-0.017899999395012856 0.008999999612569809 0.014499999582767487" rpy="0.0 0.0 0.0"/>
      <geometry>
        <box size="0.03579999879002571 0.03400000184774399 0.045499999076128006"/>
      </geometry>
    </collision>
  </link>
  <joint name="thj1" type="revolute">
    <origin xyz="-0.027000000700354576 0.004999999888241291 0.039900001138448715" rpy="0.0 0.0 0.0"/>
    <axis xyz="0.0 0.0 1.0"/>
    <parent link="th_base"/>
    <child link="th_proximal"/>
    <limit effort="1000.0" lower="-0.10500000417232513" upper="1.1630001068115234" velocity="1000.0"/>
  </joint>
  <link name="th_proximal">
    <inertial>
      <origin xyz="-0.0007820269092917442 -1.0249381375615485e-05 0.008104545064270496" rpy="1.5736815929412842 -0.5034621357917786 -0.0009923576144501567"/>
      <mass value="0.007219312246888876"/>
      <inertia ixx="7.637485737177485e-07" ixy="0.0" ixz="0.0" iyy="6.87399847265624e-07" iyz="0.0" izz="3.53931511654082e-07"/>
    </inertial>
    <visual name="Geom_34">
      <origin xyz="-0.0007820269092917442 -1.0249381375615485e-05 0.008104545064270496" rpy="1.5736815929412842 -0.5034734010696411 -0.0009923895122483373"/>
      <geometry>
        <mesh filename="file://allegro_right/meshes/obj/link_13.0.obj" scale="1.0 1.0 1.0"/>
      </geometry>
    </visual>
    <collision name="Geom_35">
      <origin xyz="0.0 0.0 0.008849999867379665" rpy="0.0 0.0 0.0"/>
      <geometry>
        <box size="0.019600000232458115 0.027499999850988388 0.01769999973475933"/>
      </geometry>
    </collision>
  </link>
  <joint name="thj2" type="revolute">
    <origin xyz="0.0 0.0 0.01769999973475933" rpy="0.0 0.0 0.0"/>
    <axis xyz="0.0 1.0 0.0"/>
    <parent link="th_proximal"/>
    <child link="th_medial"/>
    <limit effort="1000.0" lower="-0.1889999955892563" upper="1.6439999341964722" velocity="1000.0"/>
  </joint>
  <link name="th_medial">
    <inertial>
      <origin xyz="-0.0001643362920731306 1.714846075628884e-05 0.02111191675066948" rpy="5.8689973229775205e-05 -0.017928728833794594 0.00022583844838663936"/>
      <mass value="0.022496473044157028"/>
      <inertia ixx="7.527637080784189e-06" ixy="0.0" ixz="0.0" iyy="6.583326012332691e-06" iyz="0.0" izz="2.14106444218487e-06"/>
    </inertial>
    <visual name="Geom_36">
      <origin xyz="-0.0001643362920731306 1.714846075628884e-05 0.02111191675066948" rpy="5.8689973229775205e-05 -0.017928726971149445 0.00022583844838663936"/>
      <geometry>
        <mesh filename="file://allegro_right/meshes/obj/link_14.0.obj" scale="1.0 1.0 1.0"/>
      </geometry>
    </visual>
    <collision name="Geom_37">
      <origin xyz="0.0 0.0 0.025699999183416367" rpy="0.0 0.0 0.0"/>
      <geometry>
        <box size="0.019600000232458115 0.027499999850988388 0.05139999836683273"/>
      </geometry>
    </collision>
  </link>
  <joint name="thj3" type="revolute">
    <origin xyz="-1.3877787807814457e-17 0.0 0.05139999836683273" rpy="0.0 0.0 0.0"/>
    <axis xyz="0.0 1.0 0.0"/>
    <parent link="th_medial"/>
    <child link="th_distal"/>
    <limit effort="1000.0" lower="-0.16200000047683716" upper="1.7190001010894775" velocity="1000.0"/>
  </joint>
  <link name="th_distal">
    <inertial>
      <origin xyz="-6.764516030655088e-12 3.6771950817637844e-06 0.013075033202767372" rpy="0.0038908985443413258 0.0 0.0"/>
      <mass value="0.016334496438503265"/>
      <inertia ixx="2.913777279900387e-06" ixy="0.0" ixz="0.0" iyy="2.590203166619176e-06" iyz="0.0" izz="1.3565170320362085e-06"/>
    </inertial>
    <visual name="Geom_38">
      <origin xyz="-6.764516030655088e-12 3.6771950817637844e-06 0.013075033202767372" rpy="0.003890898311510682 0.0 0.0"/>
      <geometry>
        <mesh filename="file://allegro_right/meshes/obj/link_15.0.obj" scale="1.0 1.0 1.0"/>
      </geometry>
    </visual>
    <collision name="Geom_39">
      <origin xyz="0.0 0.0 0.015699999406933784" rpy="0.0 0.0 0.0"/>
      <geometry>
        <box size="0.019600000232458115 0.027499999850988388 0.03139999881386757"/>
      </geometry>
    </collision>
  </link>
  <joint name="th_tip_joint" type="fixed">
    <origin xyz="0.0 0.0 0.0" rpy="0.0 0.0 0.0"/>
    <parent link="th_distal"/>
    <child link="th_tip"/>
  </joint>
  <link name="th_tip">
    <inertial>
      <origin xyz="2.0724932187077272e-11 -1.1561289881001358e-07 0.04100276529788971" rpy="0.0 0.0 0.0"/>
      <mass value="0.006844521500170231"/>
      <inertia ixx="4.558230841666955e-07" ixy="0.0" ixz="0.0" iyy="4.558135913157457e-07" iyz="0.0" izz="4.4955876887797785e-07"/>
    </inertial>
    <visual name="Geom_40">
      <origin xyz="2.0724932187077272e-11 -1.1561289881001358e-07 0.04100276529788971" rpy="0.0 0.0 0.0"/>
      <geometry>
        <mesh filename="file://allegro_right/meshes/obj/link_15.0_tip.obj" scale="1.0 1.0 1.0"/>
      </geometry>
    </visual>
    <collision name="Geom_41">
      <origin xyz="0.0 0.0 0.03500000014901161" rpy="0.0 0.0 0.0"/>
      <geometry>
        <cylinder radius="0.012000000104308128" length="0.01600000075995922"/>
      </geometry>
    </collision>
  </link>
</robot>