<?xml version="1.0" ?>
<mujoco model="hsrb">
	<compiler meshdir="hsrb/meshes" texturedir="hsrb/textures" angle="radian" autolimits="true" balanceinertia="true" boundmass="0.000001" boundinertia="0.000001"/>
	<default>
		<default class="visual">
			<geom contype="0" conaffinity="0"/>
		</default>
		<default class="collision">
			<geom rgba="0.9 0.9 0.9 0.0"/>
		</default>
	</default>
	<asset>
		<mesh name="URG_003" file="obj/URG_003.obj" scale="1.0 1.0 1.0"/>
		<mesh name="Base_007" file="obj/Base_007.obj" scale="1.0 1.0 1.0"/>
		<mesh name="Torso_Base" file="obj/Torso_Base.obj" scale="1.0 1.0 1.0"/>
		<mesh name="base" file="stl/base.stl" scale="1.0 1.0 1.0"/>
		<mesh name="Cube_002" file="obj/Cube_002.obj" scale="1.0 1.0 1.0"/>
		<mesh name="laser" file="stl/laser.stl" scale="1.0 1.0 1.0"/>
		<mesh name="Torso_005" file="obj/Torso_005.obj" scale="1.0 1.0 1.0"/>
		<mesh name="torso" file="stl/torso.stl" scale="1.0 1.0 1.0"/>
		<mesh name="Head_Pan_002" file="obj/Head_Pan_002.obj" scale="1.0 1.0 1.0"/>
		<mesh name="head_pan" file="stl/head_pan.stl" scale="1.0 1.0 1.0"/>
		<mesh name="Head_Upper" file="obj/Head_Upper.obj" scale="1.0 1.0 1.0"/>
		<mesh name="Head_Tilt" file="obj/Head_Tilt.obj" scale="1.0 1.0 1.0"/>
		<mesh name="Simulator_TabletBase_DR017_S0150_A_000" file="obj/Simulator_TabletBase_DR017_S0150_A_000.obj" scale="1.0 1.0 1.0"/>
		<mesh name="head" file="stl/head.stl" scale="1.0 1.0 1.0"/>
		<mesh name="tablet" file="stl/tablet.stl" scale="1.0 1.0 1.0"/>
		<mesh name="Head_Camera" file="obj/Head_Camera.obj" scale="1.0 1.0 1.0"/>
		<mesh name="Rgbd_006" file="obj/Rgbd_006.obj" scale="1.0 1.0 1.0"/>
		<mesh name="rgbd" file="stl/rgbd.stl" scale="1.0 1.0 1.0"/>
		<mesh name="Shoulder" file="obj/Shoulder.obj" scale="1.0 1.0 1.0"/>
		<mesh name="shoulder" file="stl/shoulder.stl" scale="1.0 1.0 1.0"/>
		<mesh name="Arm_Flex_000" file="obj/Arm_Flex_000.obj" scale="1.0 1.0 1.0"/>
		<mesh name="arm_flex" file="stl/arm_flex.stl" scale="1.0 1.0 1.0"/>
		<mesh name="Arm_Roll_003" file="obj/Arm_Roll_003.obj" scale="1.0 1.0 1.0"/>
		<mesh name="arm_roll" file="stl/arm_roll.stl" scale="1.0 1.0 1.0"/>
		<mesh name="Wrist_Flex" file="obj/Wrist_Flex.obj" scale="1.0 1.0 1.0"/>
		<mesh name="Wrist_Roll" file="obj/Wrist_Roll.obj" scale="1.0 1.0 1.0"/>
		<mesh name="wrist_roll" file="stl/wrist_roll.stl" scale="1.0 1.0 1.0"/>
		<mesh name="palm" file="stl/palm.stl" scale="1.0 1.0 1.0"/>
		<mesh name="l_proximal" file="stl/l_proximal.stl" scale="1.0 1.0 1.0"/>
		<mesh name="l_distal" file="stl/l_distal.stl" scale="1.0 1.0 1.0"/>
		<mesh name="r_proximal" file="stl/r_proximal.stl" scale="1.0 1.0 1.0"/>
		<mesh name="r_distal" file="stl/r_distal.stl" scale="1.0 1.0 1.0"/>
		<material name="URG_Material_001" texture="gray"/>
		<material name="Material_003" texture="white"/>
		<material name="Material_001" texture="gray"/>
		<material name="Material_002" texture="white"/>
		<material name="Head_pan" texture="white"/>
		<material name="Material_001_007" texture="gray"/>
		<material name="Material_001_006" texture="white"/>
		<material name="tablet_base" texture="gray"/>
		<material name="Black_004" texture="rgbd"/>
		<material name="Glay_004" texture="gray"/>
		<material name="Material_001_001" texture="white"/>
		<material name="Material_001_001_001" texture="white"/>
		<texture name="gray" type="2d" file="gray.png"/>
		<texture name="white" type="2d" file="white.png"/>
		<texture name="rgbd" type="2d" file="rgbd.png"/>
	</asset>
	<worldbody>
		<body name="hsrb" pos="0.0 0.0 0.0" quat="1.0 0.0 0.0 0.0">
			<body name="base_footprint" pos="0.0 0.0 0.0" quat="1.0 0.0 0.0 0.0">
				<body name="base_link" pos="0.0 0.0 0.0" quat="1.0 0.0 0.0 0.0">
					<inertial mass="5.6116042137146" pos="-0.0005745029775425792 0.0030577853322029114 0.3212870657444" quat="0.7106751799583435 0.0026515182107686996 -0.7034216523170471 0.011479008011519909" diaginertia="0.10614228993654251 0.7799529433250427 0.8271230459213257"/>
					<geom name="base_link_geom_visual_0_URG_003" type="mesh" pos="0.0 0.0 0.0" quat="1.0 0.0 0.0 0.0" mesh="URG_003" material="URG_Material_001" class="visual"/>
					<geom name="base_link_geom_visual_1_Base_007" type="mesh" pos="0.0 0.0 0.0" quat="1.0 0.0 0.0 0.0" mesh="Base_007" material="Material_003" class="visual"/>
					<geom name="base_link_geom_visual_2_Torso_Base" type="mesh" pos="0.0 0.0 0.0" quat="1.0 0.0 0.0 0.0" mesh="Torso_Base" material="Material_001" class="visual"/>
					<geom name="base_link_geom_collision_0_base" type="mesh" pos="0.0 0.0 0.0" quat="1.0 0.0 0.0 0.0" mesh="base" class="collision"/>
					<body name="base_range_sensor_link" pos="0.16750000417232513 0.0 0.18440000712871552" quat="1.0 0.0 0.0 0.0">
						<inertial mass="0.13287509977817535" pos="0.16750000417232513 -2.1491329549316873e-10 0.17934991419315338" quat="0.25146082043647766 -0.6608838438987732 0.25146082043647766 0.6608838438987732" diaginertia="4.4946875277673826e-05 7.912974979262799e-05 7.912974979262799e-05"/>
						<geom name="base_range_sensor_link_geom_visual_0_Cube_002" type="mesh" pos="0.0 0.0 0.0" quat="1.0 0.0 0.0 0.0" mesh="Cube_002" material="Material_002" class="visual"/>
						<geom name="base_range_sensor_link_geom_collision_0_laser" type="mesh" pos="0.0 0.0 0.0" quat="1.0 0.0 0.0 0.0" mesh="laser" class="collision"/>
					</body>
					<body name="torso_lift_link" pos="0.0 0.0 0.7519999742507935" quat="1.0 0.0 0.0 0.0">
						<inertial mass="0.44477254152297974" pos="-0.029833918437361717 -0.0018695452017709613 0.4594580829143524" quat="0.49553731083869934 0.466982901096344 0.5301777720451355 -0.5052536725997925" diaginertia="0.0029828965198248625 0.05234883725643158 0.052781842648983"/>
						<geom name="torso_lift_link_geom_visual_0_Torso_005" type="mesh" pos="0.0 0.0 0.0" quat="1.0 0.0 0.0 0.0" mesh="Torso_005" material="Material_001" class="visual"/>
						<geom name="torso_lift_link_geom_collision_0_torso" type="mesh" pos="0.0 0.0 0.0" quat="1.0 0.0 0.0 0.0" mesh="torso" class="collision"/>
						<joint name="torso_lift_joint" type="slide" pos="0.0 0.0 0.0" range="0.0 0.3449999988079071" axis="0.0 0.0 1.0"/>
						<body name="head_pan_link" pos="0.0 0.0 0.0" quat="1.0 0.0 0.0 0.0">
							<inertial mass="0.31557589769363403" pos="-0.006927147973328829 -2.5756405648280634e-06 0.723492443561554" quat="-0.00023151653294917196 -0.5442028045654297 4.771801468450576e-05 0.8389536738395691" diaginertia="0.0003908935468643904 0.0005272923153825104 0.0006329496391117573"/>
							<geom name="head_pan_link_geom_visual_0_Head_Pan_002" type="mesh" pos="0.0 0.0 0.0" quat="1.0 0.0 0.0 0.0" mesh="Head_Pan_002" material="Head_pan" class="visual"/>
							<geom name="head_pan_link_geom_collision_0_head_pan" type="mesh" pos="0.0 0.0 0.0" quat="1.0 0.0 0.0 0.0" mesh="head_pan" class="collision"/>
							<joint name="head_pan_joint" type="hinge" pos="0.0 0.0 0.0" range="-3.8399999141693115 1.75" axis="0.0 0.0 1.0"/>
							<body name="head_tilt_link" pos="0.019999999552965164 0.0 0.0" quat="1.0 0.0 0.0 0.0">
								<inertial mass="1.2649989128112793" pos="-0.06645193696022034 -0.00011767786054406315 0.8911780714988708" quat="0.8721625208854675 8.743089711060748e-05 0.48921605944633484 0.000374553696019575" diaginertia="0.004195534624159336 0.039127983152866364 0.04236074909567833"/>
								<geom name="head_tilt_link_geom_visual_0_Head_Upper" type="mesh" pos="0.0 0.0 0.0" quat="1.0 0.0 0.0 0.0" mesh="Head_Upper" material="Material_001_007" class="visual"/>
								<geom name="head_tilt_link_geom_visual_1_Head_Tilt" type="mesh" pos="0.0 0.0 0.0" quat="1.0 0.0 0.0 0.0" mesh="Head_Tilt" material="Material_001_006" class="visual"/>
								<geom name="head_tilt_link_geom_visual_2_Simulator_TabletBase_DR017_S0150_A_000" type="mesh" pos="0.0 0.0 0.0" quat="1.0 0.0 0.0 0.0" mesh="Simulator_TabletBase_DR017_S0150_A_000" material="tablet_base" class="visual"/>
								<geom name="head_tilt_link_geom_collision_0_head" type="mesh" pos="0.0 0.0 0.0" quat="1.0 0.0 0.0 0.0" mesh="head" class="collision"/>
								<geom name="head_tilt_link_geom_collision_1_tablet" type="mesh" pos="0.0 0.0 0.0" quat="1.0 0.0 0.0 0.0" mesh="tablet" class="collision"/>
								<joint name="head_tilt_joint" type="hinge" pos="0.0 0.0 0.0" range="-1.5700000524520874 0.5200000405311584" axis="0.0 -1.0 0.0"/>
								<body name="head_r_stereo_camera_link" pos="0.019999999552965164 -0.07000000029802322 0.061000000685453415" quat="0.5 -0.5 0.5 -0.5">
									<inertial mass="0.038347601890563965" pos="0.00371176446788013 -0.07000334560871124 0.06099742650985718" quat="-0.7060102224349976 0.03255750611424446 0.7067009210586548 0.03260982036590576" diaginertia="6.267971002671402e-06 1.8796468793880194e-05 1.8810287656378932e-05"/>
									<geom name="head_r_stereo_camera_link_geom_visual_0_Head_Camera" type="mesh" pos="0.0 0.0 0.0" quat="1.0 0.0 0.0 0.0" mesh="Head_Camera" material="Material_001" class="visual"/>
									<body name="head_r_stereo_camera_gazebo_frame" pos="0.0 0.0 0.0" quat="0.5 0.5 -0.5 0.5"/>
								</body>
								<body name="head_center_camera_frame" pos="0.019500000402331352 0.0 0.061000000685453415" quat="0.5 -0.5 0.5 -0.5">
									<body name="head_center_camera_gazebo_frame" pos="0.0 0.0 0.0" quat="0.5 0.5 -0.5 0.5"/>
								</body>
								<body name="head_rgbd_sensor_link" pos="-0.07979600131511688 0.02199999988079071 0.21517199277877808" quat="0.5 -0.5 0.5 -0.5">
									<inertial mass="0.15930503606796265" pos="-0.09484199434518814 -1.4280316236181534e-06 0.21517214179039001" quat="0.7058272957801819 0.7058217525482178 0.04256319999694824 -0.042566291987895966" diaginertia="5.5428787163691595e-05 0.0004974461044184864 0.000536749605089426"/>
									<geom name="head_rgbd_sensor_link_geom_visual_0_Rgbd_006" type="mesh" pos="0.0 0.0 0.0" quat="1.0 0.0 0.0 0.0" mesh="Rgbd_006" material="Black_004" class="visual"/>
									<geom name="head_rgbd_sensor_link_geom_collision_0_rgbd" type="mesh" pos="0.0 0.0 0.0" quat="1.0 0.0 0.0 0.0" mesh="rgbd" class="collision"/>
									<body name="head_rgbd_sensor_gazebo_frame" pos="0.0 0.0 0.0" quat="0.5 0.5 -0.5 0.5"/>
								</body>
								<body name="head_l_stereo_camera_link" pos="0.019999999552965164 0.07000000029802322 0.061000000685453415" quat="0.5 -0.5 0.5 -0.5">
									<inertial mass="0.038347601890563965" pos="0.00371176446788013 0.0699966549873352 0.06099742650985718" quat="-0.7060102224349976 0.03255750611424446 0.7067009210586548 0.03260982036590576" diaginertia="6.267971002671402e-06 1.8796468793880194e-05 1.8810287656378932e-05"/>
									<geom name="head_l_stereo_camera_link_geom_visual_0_Head_Camera" type="mesh" pos="0.0 0.0 0.0" quat="1.0 0.0 0.0 0.0" mesh="Head_Camera" material="Material_001" class="visual"/>
									<body name="head_l_stereo_camera_gazebo_frame" pos="0.0 0.0 0.0" quat="0.5 0.5 -0.5 0.5"/>
								</body>
							</body>
						</body>
					</body>
					<body name="arm_lift_link" pos="0.0 0.0 0.3400000035762787" quat="1.0 0.0 0.0 0.0">
						<inertial mass="0.1369386464357376" pos="0.0813228189945221 0.026763053610920906 0.2917323708534241" quat="-0.2750156819820404 0.9039556980133057 0.13705113530158997 -0.2974012494087219" diaginertia="0.0009512149845249951 0.0017490539466962218 0.0022147856652736664"/>
						<geom name="arm_lift_link_geom_visual_0_Shoulder" type="mesh" pos="0.0 0.0 0.0" quat="1.0 0.0 0.0 0.0" mesh="Shoulder" material="Glay_004" class="visual"/>
						<geom name="arm_lift_link_geom_collision_0_shoulder" type="mesh" pos="0.0 0.0 0.0" quat="1.0 0.0 0.0 0.0" mesh="shoulder" class="collision"/>
						<joint name="arm_lift_joint" type="slide" pos="0.0 0.0 0.0" range="0.0 0.6899999976158142" axis="0.0 0.0 1.0"/>
						<body name="arm_flex_link" pos="0.14100000262260437 0.07800000160932541 0.0" quat="1.0 0.0 0.0 0.0">
							<inertial mass="0.0956273078918457" pos="0.1406947821378708 0.08575395494699478 0.46638625860214233" quat="0.020079733803868294 0.7093750834465027 -0.023775991052389145 -0.704143762588501" diaginertia="0.0002442473778501153 0.0022642638068646193 0.0023555909283459187"/>
							<geom name="arm_flex_link_geom_visual_0_Arm_Flex_000" type="mesh" pos="0.0 0.0 0.0" quat="1.0 0.0 0.0 0.0" mesh="Arm_Flex_000" material="Material_001_001" class="visual"/>
							<geom name="arm_flex_link_geom_collision_0_arm_flex" type="mesh" pos="0.0 0.0 0.0" quat="1.0 0.0 0.0 0.0" mesh="arm_flex" class="collision"/>
							<joint name="arm_flex_joint" type="hinge" pos="0.0 0.0 0.0" range="-2.620000123977661 0.0" axis="0.0 -1.0 0.0"/>
							<body name="arm_roll_link" pos="0.004999999888241291 0.0 0.3449999988079071" quat="1.0 0.0 0.0 0.0">
								<inertial mass="0.055637508630752563" pos="0.1384287178516388 0.08344055712223053 0.6361227631568909" quat="0.7513530850410461 0.049666766077280045 -0.6547154784202576 -0.06594984978437424" diaginertia="0.00013514167221728712 0.0002659598831087351 0.00031855120323598385"/>
								<geom name="arm_roll_link_geom_visual_0_Arm_Roll_003" type="mesh" pos="0.0 0.0 0.0" quat="1.0 0.0 0.0 0.0" mesh="Arm_Roll_003" material="Material_001_001_001" class="visual"/>
								<geom name="arm_roll_link_geom_collision_0_arm_roll" type="mesh" pos="0.0 0.0 0.0" quat="1.0 0.0 0.0 0.0" mesh="arm_roll" class="collision"/>
								<joint name="arm_roll_joint" type="hinge" pos="-4.336808689942018e-18 0.0 -5.551115123125783e-17" range="-2.0899999141693115 3.8399999141693115" axis="0.0 0.0 1.0"/>
								<body name="wrist_flex_link" pos="0.0 0.0 0.0" quat="1.0 0.0 0.0 0.0">
									<inertial mass="0.03307466208934784" pos="0.146077960729599 0.07799923419952393 0.7066903114318848" quat="0.5000905990600586 0.5006588697433472 0.4993296265602112 -0.4999200105667114" diaginertia="7.535738859587582e-06 3.692131576826796e-05 3.890189327648841e-05"/>
									<geom name="wrist_flex_link_geom_visual_0_Wrist_Flex" type="mesh" pos="0.0 0.0 0.0" quat="1.0 0.0 0.0 0.0" mesh="Wrist_Flex" material="Material_001" class="visual"/>
									<geom name="wrist_flex_link_geom_visual_1" type="cylinder" pos="0.0 0.0 0.03999999910593033" quat="1.0 0.0 0.0 0.0" size="0.017000000923871994 0.009999999776482582 0.0" class="visual"/>
									<geom name="wrist_flex_link_geom_collision_0" type="cylinder" pos="0.0 0.0 0.029999999329447746" quat="1.0 0.0 0.0 0.0" size="0.017000000923871994 0.019999999552965164 0.0" class="collision"/>
									<joint name="wrist_flex_joint" type="hinge" pos="0.0 0.0 0.0" range="-1.9199999570846558 1.21999990940094" axis="0.0 -1.0 0.0"/>
									<body name="wrist_roll_link" pos="0.0 0.0 0.0" quat="1.0 0.0 0.0 0.0">
										<inertial mass="0.06149858608841896" pos="0.13593338429927826 0.07797524333000183 0.7734910845756531" quat="-0.6550278663635254 2.011494871112518e-05 0.7556046843528748 0.0003620499628596008" diaginertia="0.00011161583825014532 0.0005890678730793297 0.000613926793448627"/>
										<geom name="wrist_roll_link_geom_visual_0_Wrist_Roll" type="mesh" pos="0.0 0.0 0.0" quat="1.0 0.0 0.0 0.0" mesh="Wrist_Roll" material="Material_002" class="visual"/>
										<geom name="wrist_roll_link_geom_collision_0_wrist_roll" type="mesh" pos="0.0 0.0 0.0" quat="1.0 0.0 0.0 0.0" mesh="wrist_roll" class="collision"/>
										<joint name="wrist_roll_joint" type="hinge" pos="0.0 0.0 0.0" range="-1.9199999570846558 3.6700000762939453" axis="0.0 0.0 1.0"/>
										<body name="hand_palm_link" pos="0.012000000104308128 0.0 0.1404999941587448" quat="-1.0341155557737347e-13 0.0 0.0 1.0">
											<inertial mass="0.08773984014987946" pos="0.01071222499012947 -0.00030466882162727416 0.11583888530731201" quat="-0.6860979795455933 -0.010482939891517162 0.7274026870727539 0.006707098800688982" diaginertia="3.0547216738341376e-05 7.715255196671933e-05 9.0780173195526e-05"/>
											<geom name="hand_palm_link_geom_visual_0_palm" type="mesh" pos="0.0 0.0 0.0" quat="1.0 0.0 0.0 0.0" mesh="palm" class="visual"/>
											<geom name="hand_palm_link_geom_collision_0_palm" type="mesh" pos="0.0 0.0 0.0" quat="1.0 0.0 0.0 0.0" mesh="palm" class="collision"/>
											<body name="hand_l_proximal_link" pos="-0.016750000417232513 -0.02449999935925007 -0.017500000074505806" quat="1.0 0.0 0.0 0.0">
												<joint name="hand_l_proximal_joint" type="hinge" pos="-1.3877787807814457e-17 -6.938893903907228e-18 -4.163336342344337e-17" range="-0.7979999780654907 1.2400000095367432" axis="1.0 0.0 0.0"/>
												<body name="hand_l_spring_proximal_link" pos="0.0 0.0 0.0" quat="1.0 0.0 0.0 0.0">
													<inertial mass="0.042135074734687805" pos="0.15599320828914642 0.1047016829252243 0.8386635780334473" quat="-0.5874428749084473 0.6060451865196228 0.3529996871948242 0.403746634721756" diaginertia="8.60757427290082e-06 7.024005753919482e-05 7.688956247875467e-05"/>
													<geom name="hand_l_spring_proximal_link_geom_visual_0_l_proximal" type="mesh" pos="0.0 0.0 0.0" quat="1.0 0.0 0.0 0.0" mesh="l_proximal" class="visual"/>
													<geom name="hand_l_spring_proximal_link_geom_collision_0_l_proximal" type="mesh" pos="0.0 0.0 0.0" quat="1.0 0.0 0.0 0.0" mesh="l_proximal" class="collision"/>
													<joint name="hand_l_spring_proximal_joint" type="hinge" pos="0.0 0.0 0.0" range="0.0 0.6980000138282776" axis="1.0 0.0 0.0"/>
													<body name="hand_l_mimic_distal_link" pos="0.0 0.0 0.07000000029802322" quat="1.0 0.0 0.0 0.0">
														<joint name="hand_l_mimic_distal_joint" type="hinge" pos="0.0 0.0 5.551115123125783e-17" range="-0.6980000138282776 -0.0" axis="1.0 0.0 0.0"/>
														<body name="hand_l_distal_link" pos="0.0 0.0 0.0" quat="1.0 0.0 0.0 0.0">
															<inertial mass="0.03458765894174576" pos="0.15949995815753937 0.09806831926107407 0.8973337411880493" quat="0.3817766010761261 0.23210614919662476 0.6331768035888672 -0.6320288777351379" diaginertia="6.055272024241276e-06 2.712272726057563e-05 2.945130836451426e-05"/>
															<geom name="hand_l_distal_link_geom_visual_0_l_distal" type="mesh" pos="0.0 0.0 0.0" quat="1.0 0.0 0.0 0.0" mesh="l_distal" class="visual"/>
															<geom name="hand_l_distal_link_geom_collision_0_l_distal" type="mesh" pos="0.0 0.0 0.0" quat="1.0 0.0 0.0 0.0" mesh="l_distal" class="collision"/>
															<joint name="hand_l_distal_joint" type="hinge" pos="0.0 0.0 0.0" range="-1.2400000095367432 0.7979999780654907" axis="1.0 0.0 0.0"/>
															<body name="hand_l_finger_vacuum_frame" pos="0.004749999847263098 -0.01153900008648634 0.03322000056505203" quat="0.9238795042037964 0.3826834261417389 0.0 0.0">
																<inertial mass="0.0012799999676644802" pos="0.004749999847263098 -0.004467932041734457 0.026148932054638863" quat="0.7071067690849304 0.0 0.7071067690849304 0.0" diaginertia="1.3653333574836779e-08 1.7749333380834287e-07 1.7749333380834287e-07"/>
																<geom name="hand_l_finger_vacuum_frame_geom_visual_0" type="box" pos="0.0 0.0 -0.009999999776482582" quat="1.0 0.0 0.0 0.0" size="0.004000000189989805 0.004000000189989805 0.009999999776482582" class="visual"/>
															</body>
															<body name="hand_l_finger_tip_frame" pos="0.016750000417232513 0.019300000742077827 0.03790000081062317" quat="-0.7071067690849304 0.7071067690849304 0.0 0.0"/>
														</body>
													</body>
												</body>
											</body>
											<body name="hand_r_proximal_link" pos="-0.016750000417232513 0.02449999935925007 -0.017500000074505806" quat="1.0 0.0 0.0 0.0">
												<joint name="hand_r_proximal_joint" type="hinge" pos="-1.3877787807814457e-17 2.8702472503576013e-30 -4.163336342344337e-17" range="-0.7979999780654907 1.2400000095367432" axis="-1.0 0.0 0.0"/>
												<body name="hand_r_spring_proximal_link" pos="0.0 0.0 0.0" quat="1.0 0.0 0.0 0.0">
													<inertial mass="0.04147995635867119" pos="0.15662232041358948 0.05133400484919548 0.8388575911521912" quat="0.6110666990280151 -0.5782454013824463 -0.411460280418396 -0.3506140410900116" diaginertia="7.921276846900582e-06 6.877347186673433e-05 7.483593799406663e-05"/>
													<geom name="hand_r_spring_proximal_link_geom_visual_0_r_proximal" type="mesh" pos="0.0 0.0 0.0" quat="1.0 0.0 0.0 0.0" mesh="r_proximal" class="visual"/>
													<geom name="hand_r_spring_proximal_link_geom_collision_0_r_proximal" type="mesh" pos="0.0 0.0 0.0" quat="1.0 0.0 0.0 0.0" mesh="r_proximal" class="collision"/>
													<joint name="hand_r_spring_proximal_joint" type="hinge" pos="0.0 0.0 0.0" range="0.0 0.6980000138282776" axis="-1.0 0.0 0.0"/>
													<body name="hand_r_mimic_distal_link" pos="0.0 0.0 0.07000000029802322" quat="1.0 0.0 0.0 0.0">
														<joint name="hand_r_mimic_distal_joint" type="hinge" pos="0.0 0.0 5.551115123125783e-17" range="-0.6980000138282776 -0.0" axis="-1.0 0.0 0.0"/>
														<body name="hand_r_distal_link" pos="0.0 0.0 0.0" quat="1.0 0.0 0.0 0.0">
															<inertial mass="0.024421628564596176" pos="0.15761487185955048 0.06115259975194931 0.8951394557952881" quat="0.21702277660369873 0.3457382321357727 0.7525501251220703 -0.5167538523674011" diaginertia="3.450870281085372e-06 1.9094664821750484e-05 2.1310002921381965e-05"/>
															<geom name="hand_r_distal_link_geom_visual_0_r_distal" type="mesh" pos="0.0 0.0 0.0" quat="1.0 0.0 0.0 0.0" mesh="r_distal" class="visual"/>
															<geom name="hand_r_distal_link_geom_collision_0_r_distal" type="mesh" pos="0.0 0.0 0.0" quat="1.0 0.0 0.0 0.0" mesh="r_distal" class="collision"/>
															<joint name="hand_r_distal_joint" type="hinge" pos="0.0 0.0 0.0" range="-1.2400000095367432 0.7979999780654907" axis="-1.0 0.0 0.0"/>
															<body name="hand_r_finger_tip_frame" pos="0.016750000417232513 -0.019300000742077827 0.03790000081062317" quat="0.7071067690849304 0.7071067690849304 0.0 0.0"/>
														</body>
													</body>
												</body>
											</body>
											<body name="hand_camera_frame" pos="0.039000000804662704 -1.3877787807814457e-17 -0.0044999998062849045" quat="1.0 0.0 0.0 0.0">
												<body name="hand_camera_gazebo_frame" pos="0.0 0.0 0.0" quat="0.5 0.5 -0.5 0.5"/>
											</body>
											<body name="hand_gripper_tool_frame" pos="0.0 0.0 0.07000000029802322" quat="1.0 0.0 0.0 0.0"/>
											<body name="hand_motor_dummy_link" pos="0.0 0.0 0.0" quat="1.0 0.0 0.0 0.0">
												<joint name="hand_motor_joint" type="hinge" pos="0.0 0.0 0.0" range="-0.7979999780654907 1.2400000095367432" axis="1.0 0.0 0.0"/>
											</body>
										</body>
										<body name="wrist_ft_sensor_frame" pos="0.0 0.0 0.07349999994039536" quat="-1.0341155557737347e-13 1.0 0.0 0.0"/>
									</body>
								</body>
							</body>
						</body>
					</body>
					<body name="base_roll_link" pos="0.0 0.0 0.0" quat="1.0 0.0 0.0 0.0">
						<joint name="base_roll_joint" type="hinge" pos="0.0 0.0 0.0" axis="0.0 0.0 1.0"/>
						<body name="base_l_drive_wheel_link" pos="-0.10999999940395355 0.13300000131130219 0.03999999910593033" quat="1.0 0.0 0.0 0.0">
							<inertial mass="0.15079644322395325" pos="-0.10999999940395355 0.13300000131130219 0.03999999910593033" quat="0.0 0.0 0.7071067690849304 -0.7071067690849304" diaginertia="7.162831025198102e-05 7.162831025198102e-05 0.00012063715985277668"/>
							<geom name="base_l_drive_wheel_link_geom_visual_0" type="cylinder" pos="0.0 0.0 0.0" quat="0.7071067690849304 0.7071067690849304 0.0 0.0" size="0.03999999910593033 0.014999999664723873 0.0" class="visual"/>
							<geom name="base_l_drive_wheel_link_geom_collision_0" type="cylinder" pos="0.0 0.0 0.0" quat="0.7071067690849304 0.7071067690849304 0.0 0.0" size="0.03999999910593033 0.014999999664723873 0.0" class="collision"/>
							<joint name="base_l_drive_wheel_joint" type="hinge" pos="0.0 0.0 0.0" axis="0.0 1.0 0.0"/>
						</body>
						<body name="base_l_passive_wheel_x_frame" pos="0.14949999749660492 0.054999999701976776 0.029999999329447746" quat="1.0 0.0 0.0 0.0">
							<joint name="base_l_passive_wheel_x_frame_joint" type="hinge" pos="0.0 0.0 0.0" axis="1.0 0.0 0.0"/>
							<body name="base_l_passive_wheel_y_frame" pos="0.0 0.0 0.0" quat="1.0 0.0 0.0 0.0">
								<joint name="base_l_passive_wheel_y_frame_joint" type="hinge" pos="0.0 0.0 0.0" axis="0.0 1.0 0.0"/>
								<body name="base_l_passive_wheel_z_link" pos="0.0 0.0 0.0" quat="1.0 0.0 0.0 0.0">
									<inertial mass="0.11309733241796494" pos="0.14949999749660492 0.054999999701976776 0.029999999329447746" quat="1.0 0.0 0.0 0.0" diaginertia="4.0715040086070076e-05 4.0715040086070076e-05 4.0715040086070076e-05"/>
									<geom name="base_l_passive_wheel_z_link_geom_visual_0" type="sphere" pos="0.0 0.0 0.0" quat="1.0 0.0 0.0 0.0" size="0.029999999329447746 0.0 0.0" class="visual"/>
									<geom name="base_l_passive_wheel_z_link_geom_collision_0" type="sphere" pos="0.0 0.0 0.0" quat="1.0 0.0 0.0 0.0" size="0.029999999329447746 0.0 0.0" class="collision"/>
									<joint name="base_l_passive_wheel_z_joint" type="hinge" pos="0.0 0.0 0.0" axis="0.0 0.0 1.0"/>
								</body>
							</body>
						</body>
						<body name="base_r_drive_wheel_link" pos="-0.10999999940395355 -0.13300000131130219 0.03999999910593033" quat="1.0 0.0 0.0 0.0">
							<inertial mass="0.15079644322395325" pos="-0.10999999940395355 -0.13300000131130219 0.03999999910593033" quat="0.0 0.0 0.7071067690849304 -0.7071067690849304" diaginertia="7.162831025198102e-05 7.162831025198102e-05 0.00012063715985277668"/>
							<geom name="base_r_drive_wheel_link_geom_visual_0" type="cylinder" pos="0.0 0.0 0.0" quat="0.7071067690849304 0.7071067690849304 0.0 0.0" size="0.03999999910593033 0.014999999664723873 0.0" class="visual"/>
							<geom name="base_r_drive_wheel_link_geom_collision_0" type="cylinder" pos="0.0 0.0 0.0" quat="0.7071067690849304 0.7071067690849304 0.0 0.0" size="0.03999999910593033 0.014999999664723873 0.0" class="collision"/>
							<joint name="base_r_drive_wheel_joint" type="hinge" pos="0.0 0.0 0.0" axis="0.0 1.0 0.0"/>
						</body>
						<body name="base_r_passive_wheel_x_frame" pos="0.14949999749660492 -0.054999999701976776 0.029999999329447746" quat="1.0 0.0 0.0 0.0">
							<joint name="base_r_passive_wheel_x_frame_joint" type="hinge" pos="0.0 0.0 0.0" axis="1.0 0.0 0.0"/>
							<body name="base_r_passive_wheel_y_frame" pos="0.0 0.0 0.0" quat="1.0 0.0 0.0 0.0">
								<joint name="base_r_passive_wheel_y_frame_joint" type="hinge" pos="0.0 0.0 0.0" axis="0.0 1.0 0.0"/>
								<body name="base_r_passive_wheel_z_link" pos="0.0 0.0 0.0" quat="1.0 0.0 0.0 0.0">
									<inertial mass="0.11309733241796494" pos="0.14949999749660492 -0.054999999701976776 0.029999999329447746" quat="1.0 0.0 0.0 0.0" diaginertia="4.0715040086070076e-05 4.0715040086070076e-05 4.0715040086070076e-05"/>
									<geom name="base_r_passive_wheel_z_link_geom_visual_0" type="sphere" pos="0.0 0.0 0.0" quat="1.0 0.0 0.0 0.0" size="0.029999999329447746 0.0 0.0" class="visual"/>
									<geom name="base_r_passive_wheel_z_link_geom_collision_0" type="sphere" pos="0.0 0.0 0.0" quat="1.0 0.0 0.0 0.0" size="0.029999999329447746 0.0 0.0" class="collision"/>
									<joint name="base_r_passive_wheel_z_joint" type="hinge" pos="0.0 0.0 0.0" axis="0.0 0.0 1.0"/>
								</body>
							</body>
						</body>
					</body>
					<body name="base_imu_frame" pos="0.0005000000237487257 0.12960000336170197 0.1809999942779541" quat="-1.0341155557737347e-13 1.0 0.0 0.0"/>
				</body>
			</body>
		</body>
	</worldbody>
	<equality>
        <joint joint1="hand_l_distal_joint" joint2="hand_motor_joint" polycoef="-0.087000 -1.000000  0 0 0" />
        <joint joint1="hand_l_mimic_distal_joint" joint2="hand_l_spring_proximal_joint" polycoef="0.000000 -1.000000  0 0 0" />
        <joint joint1="hand_l_proximal_joint" joint2="hand_motor_joint" polycoef="0.000000 1.000000  0 0 0" />
        <joint joint1="hand_r_distal_joint" joint2="hand_motor_joint" polycoef="-0.087000 -1.000000  0 0 0" />
        <joint joint1="hand_r_mimic_distal_joint" joint2="hand_r_spring_proximal_joint" polycoef="0.000000 -1.000000  0 0 0" />
        <joint joint1="hand_r_proximal_joint" joint2="hand_motor_joint" polycoef="0.000000 1.000000  0 0 0" />
        <joint joint1="torso_lift_joint" joint2="arm_lift_joint" polycoef="0.000000 0.500000  0 0 0" />
    </equality>
	<contact>
		<exclude body1="base_link" body2="torso_lift_link"/>
		<exclude body1="base_link" body2="arm_lift_link"/>
		<exclude body1="base_link" body2="arm_flex_link"/>
		<exclude body1="base_link" body2="base_l_drive_wheel_link"/>
		<exclude body1="base_link" body2="base_r_drive_wheel_link"/>
		<exclude body1="base_link" body2="base_l_passive_wheel_z_link"/>
		<exclude body1="base_link" body2="base_r_passive_wheel_z_link"/>
	</contact>
</mujoco>
