<?xml version="1.0" ?>
<robot name="hsrb" version="1.0">
  <link name="hsrb"/>
  <joint name="base_footprint_joint" type="fixed">
    <origin xyz="0.0 0.0 0.0" rpy="0.0 0.0 0.0"/>
    <parent link="hsrb"/>
    <child link="base_footprint"/>
  </joint>
  <link name="base_footprint"/>
  <joint name="base_link_joint" type="fixed">
    <origin xyz="0.0 0.0 0.0" rpy="0.0 0.0 0.0"/>
    <parent link="base_footprint"/>
    <child link="base_link"/>
  </joint>
  <link name="base_link">
    <inertial>
      <origin xyz="-0.0005745029775425792 0.0030577853322029114 0.3212870657444" rpy="-0.8729721307754517 -1.5546382665634155 0.8929567337036133"/>
      <mass value="5.6116042137146"/>
      <inertia ixx="0.10614228993654251" ixy="0.0" ixz="0.0" iyy="0.7799529433250427" iyz="0.0" izz="0.8271230459213257"/>
    </inertial>
    <visual name="base_link_geom_visual_0_URG_003">
      <origin xyz="0.0 0.0 0.0" rpy="0.0 0.0 0.0"/>
      <geometry>
        <mesh filename="file://hsrb/meshes/obj/URG_003.obj"/>
      </geometry>
    </visual>
    <visual name="base_link_geom_visual_1_Base_007">
      <origin xyz="0.0 0.0 0.0" rpy="0.0 0.0 0.0"/>
      <geometry>
        <mesh filename="file://hsrb/meshes/obj/Base_007.obj"/>
      </geometry>
    </visual>
    <visual name="base_link_geom_visual_2_Torso_Base">
      <origin xyz="0.0 0.0 0.0" rpy="0.0 0.0 0.0"/>
      <geometry>
        <mesh filename="file://hsrb/meshes/obj/Torso_Base.obj"/>
      </geometry>
    </visual>
    <collision name="base_link_geom_collision_0_base">
      <origin xyz="0.0 0.0 0.0" rpy="0.0 0.0 0.0"/>
      <geometry>
        <mesh filename="file://hsrb/meshes/stl/base.stl"/>
      </geometry>
    </collision>
  </link>
  <joint name="base_roll_joint" type="continuous">
    <origin xyz="0.0 0.0 0.0" rpy="0.0 0.0 0.0"/>
    <axis xyz="0.0 0.0 1.0"/>
    <parent link="base_link"/>
    <child link="base_roll_link"/>
  </joint>
  <link name="base_roll_link"/>
  <joint name="base_r_drive_wheel_joint" type="continuous">
    <origin xyz="-0.10999999940395355 -0.13300000131130219 0.03999999910593033" rpy="0.0 0.0 0.0"/>
    <axis xyz="0.0 1.0 0.0"/>
    <parent link="base_roll_link"/>
    <child link="base_r_drive_wheel_link"/>
  </joint>
  <link name="base_r_drive_wheel_link">
    <inertial>
      <origin xyz="-0.10999999940395355 -0.13300000131130219 0.03999999910593033" rpy="-1.5707963705062866 0.0 3.1415927410125732"/>
      <mass value="0.15079644322395325"/>
      <inertia ixx="7.162831025198102e-05" ixy="0.0" ixz="0.0" iyy="7.162831025198102e-05" iyz="0.0" izz="0.00012063715985277668"/>
    </inertial>
    <visual name="base_r_drive_wheel_link_geom_visual_0">
      <origin xyz="0.0 0.0 0.0" rpy="1.5707963705062866 0.0 0.0"/>
      <geometry>
        <cylinder radius="0.03999999910593033" length="0.029999999329447746"/>
      </geometry>
    </visual>
    <collision name="base_r_drive_wheel_link_geom_collision_0">
      <origin xyz="0.0 0.0 0.0" rpy="1.5707963705062866 0.0 0.0"/>
      <geometry>
        <cylinder radius="0.03999999910593033" length="0.029999999329447746"/>
      </geometry>
    </collision>
  </link>
  <joint name="base_l_drive_wheel_joint" type="continuous">
    <origin xyz="-0.10999999940395355 0.13300000131130219 0.03999999910593033" rpy="0.0 0.0 0.0"/>
    <axis xyz="0.0 1.0 0.0"/>
    <parent link="base_roll_link"/>
    <child link="base_l_drive_wheel_link"/>
  </joint>
  <link name="base_l_drive_wheel_link">
    <inertial>
      <origin xyz="-0.10999999940395355 0.13300000131130219 0.03999999910593033" rpy="-1.5707963705062866 0.0 3.1415927410125732"/>
      <mass value="0.15079644322395325"/>
      <inertia ixx="7.162831025198102e-05" ixy="0.0" ixz="0.0" iyy="7.162831025198102e-05" iyz="0.0" izz="0.00012063715985277668"/>
    </inertial>
    <visual name="base_l_drive_wheel_link_geom_visual_0">
      <origin xyz="0.0 0.0 0.0" rpy="1.5707963705062866 0.0 0.0"/>
      <geometry>
        <cylinder radius="0.03999999910593033" length="0.029999999329447746"/>
      </geometry>
    </visual>
    <collision name="base_l_drive_wheel_link_geom_collision_0">
      <origin xyz="0.0 0.0 0.0" rpy="1.5707963705062866 0.0 0.0"/>
      <geometry>
        <cylinder radius="0.03999999910593033" length="0.029999999329447746"/>
      </geometry>
    </collision>
  </link>
  <joint name="base_r_passive_wheel_x_frame_joint" type="continuous">
    <origin xyz="0.14949999749660492 -0.054999999701976776 0.029999999329447746" rpy="0.0 0.0 0.0"/>
    <axis xyz="1.0 0.0 0.0"/>
    <parent link="base_roll_link"/>
    <child link="base_r_passive_wheel_x_frame"/>
  </joint>
  <link name="base_r_passive_wheel_x_frame"/>
  <joint name="base_r_passive_wheel_y_frame_joint" type="continuous">
    <origin xyz="0 0 0" rpy="0 0 0"/>
    <axis xyz="0.0 1.0 0.0"/>
    <parent link="base_r_passive_wheel_x_frame"/>
    <child link="base_r_passive_wheel_y_frame"/>
  </joint>
  <link name="base_r_passive_wheel_y_frame"/>
  <joint name="base_r_passive_wheel_z_joint" type="continuous">
    <origin xyz="0 0 0" rpy="0 0 0"/>
    <axis xyz="0.0 0.0 1.0"/>
    <parent link="base_r_passive_wheel_y_frame"/>
    <child link="base_r_passive_wheel_z_link"/>
  </joint>
  <link name="base_r_passive_wheel_z_link">
    <inertial>
      <origin xyz="0.14949999749660492 -0.054999999701976776 0.029999999329447746" rpy="0.0 0.0 0.0"/>
      <mass value="0.11309733241796494"/>
      <inertia ixx="4.0715040086070076e-05" ixy="0.0" ixz="0.0" iyy="4.0715040086070076e-05" iyz="0.0" izz="4.0715040086070076e-05"/>
    </inertial>
    <visual name="base_r_passive_wheel_z_link_geom_visual_0">
      <origin xyz="0.0 0.0 0.0" rpy="0.0 0.0 0.0"/>
      <geometry>
        <sphere radius="0.029999999329447746"/>
      </geometry>
    </visual>
    <collision name="base_r_passive_wheel_z_link_geom_collision_0">
      <origin xyz="0.0 0.0 0.0" rpy="0.0 0.0 0.0"/>
      <geometry>
        <sphere radius="0.029999999329447746"/>
      </geometry>
    </collision>
  </link>
  <joint name="base_l_passive_wheel_x_frame_joint" type="continuous">
    <origin xyz="0.14949999749660492 0.054999999701976776 0.029999999329447746" rpy="0.0 0.0 0.0"/>
    <axis xyz="1.0 0.0 0.0"/>
    <parent link="base_roll_link"/>
    <child link="base_l_passive_wheel_x_frame"/>
  </joint>
  <link name="base_l_passive_wheel_x_frame"/>
  <joint name="base_l_passive_wheel_y_frame_joint" type="continuous">
    <origin xyz="0 0 0" rpy="0 0 0"/>
    <axis xyz="0.0 1.0 0.0"/>
    <parent link="base_l_passive_wheel_x_frame"/>
    <child link="base_l_passive_wheel_y_frame"/>
  </joint>
  <link name="base_l_passive_wheel_y_frame"/>
  <joint name="base_l_passive_wheel_z_joint" type="continuous">
    <origin xyz="0 0 0" rpy="0 0 0"/>
    <axis xyz="0.0 0.0 1.0"/>
    <parent link="base_l_passive_wheel_y_frame"/>
    <child link="base_l_passive_wheel_z_link"/>
  </joint>
  <link name="base_l_passive_wheel_z_link">
    <inertial>
      <origin xyz="0.14949999749660492 0.054999999701976776 0.029999999329447746" rpy="0.0 0.0 0.0"/>
      <mass value="0.11309733241796494"/>
      <inertia ixx="4.0715040086070076e-05" ixy="0.0" ixz="0.0" iyy="4.0715040086070076e-05" iyz="0.0" izz="4.0715040086070076e-05"/>
    </inertial>
    <visual name="base_l_passive_wheel_z_link_geom_visual_0">
      <origin xyz="0.0 0.0 0.0" rpy="0.0 0.0 0.0"/>
      <geometry>
        <sphere radius="0.029999999329447746"/>
      </geometry>
    </visual>
    <collision name="base_l_passive_wheel_z_link_geom_collision_0">
      <origin xyz="0.0 0.0 0.0" rpy="0.0 0.0 0.0"/>
      <geometry>
        <sphere radius="0.029999999329447746"/>
      </geometry>
    </collision>
  </link>
  <joint name="base_range_sensor_link_joint" type="fixed">
    <origin xyz="0.1675 0.0 0.1844" rpy="0.0 0.0 0.0"/>
    <parent link="base_link"/>
    <child link="base_range_sensor_link"/>
  </joint>
  <link name="base_range_sensor_link">
    <inertial>
      <origin xyz="0.16750000417232513 -2.1491329549316873e-10 0.17934991419315338" rpy="-2.4144394397735596 1.5707963705062866 0.0"/>
      <mass value="0.13287509977817535"/>
      <inertia ixx="4.4946875277673826e-05" ixy="0.0" ixz="0.0" iyy="7.912974979262799e-05" iyz="0.0" izz="7.912974979262799e-05"/>
    </inertial>
    <visual name="base_range_sensor_link_geom_visual_0_Cube_002">
      <origin xyz="0.0 0.0 0.0" rpy="0.0 0.0 0.0"/>
      <geometry>
        <mesh filename="file://hsrb/meshes/obj/Cube_002.obj"/>
      </geometry>
    </visual>
    <collision name="base_range_sensor_link_geom_collision_0_laser">
      <origin xyz="0.0 0.0 0.0" rpy="0.0 0.0 0.0"/>
      <geometry>
        <mesh filename="file://hsrb/meshes/stl/laser.stl"/>
      </geometry>
    </collision>
  </link>
  <joint name="base_imu_frame_joint" type="fixed">
    <origin xyz="0.0005 0.1296 0.181" rpy="-3.1415927410125732 0.0 0.0"/>
    <parent link="base_link"/>
    <child link="base_imu_frame"/>
  </joint>
  <link name="base_imu_frame"/>
  <joint name="torso_lift_joint" type="prismatic">
    <origin xyz="0.0 0.0 0.7519999742507935" rpy="0.0 0.0 0.0"/>
    <axis xyz="0.0 0.0 1.0"/>
    <parent link="base_link"/>
    <child link="torso_lift_link"/>
    <limit effort="100.0" lower="0.0" upper="0.3449999988079071" velocity="0.10000000149011612"/>
  </joint>
  <link name="torso_lift_link">
    <inertial>
      <origin xyz="-0.029833918437361717 -0.0018695452017709613 0.4594580829143524" rpy="-1.5478068590164185 1.4977785348892212 -3.065082550048828"/>
      <mass value="0.44477254152297974"/>
      <inertia ixx="0.0029828965198248625" ixy="0.0" ixz="0.0" iyy="0.05234883725643158" iyz="0.0" izz="0.052781842648983"/>
    </inertial>
    <visual name="torso_lift_link_geom_visual_0_Torso_005">
      <origin xyz="0.0 0.0 0.0" rpy="0.0 0.0 0.0"/>
      <geometry>
        <mesh filename="file://hsrb/meshes/obj/Torso_005.obj"/>
      </geometry>
    </visual>
    <collision name="torso_lift_link_geom_collision_0_torso">
      <origin xyz="0.0 0.0 0.0" rpy="0.0 0.0 0.0"/>
      <geometry>
        <mesh filename="file://hsrb/meshes/stl/torso.stl"/>
      </geometry>
    </collision>
  </link>
  <joint name="head_pan_joint" type="revolute">
    <origin xyz="0.0 0.0 0.0" rpy="0.0 0.0 0.0"/>
    <axis xyz="0.0 0.0 1.0"/>
    <parent link="torso_lift_link"/>
    <child link="head_pan_link"/>
    <limit effort="100.0" lower="-3.8399999141693115" upper="1.75" velocity="1.0"/>
  </joint>
  <link name="head_pan_link">
    <inertial>
      <origin xyz="-0.006927147973328829 -2.5756405648280634e-06 0.723492443561554" rpy="0.0008144741877913475 1.1508769989013672 -3.140512466430664"/>
      <mass value="0.31557589769363403"/>
      <inertia ixx="0.0003908935468643904" ixy="0.0" ixz="0.0" iyy="0.0005272923153825104" iyz="0.0" izz="0.0006329496391117573"/>
    </inertial>
    <visual name="head_pan_link_geom_visual_0_Head_Pan_002">
      <origin xyz="0.0 0.0 0.0" rpy="0.0 0.0 0.0"/>
      <geometry>
        <mesh filename="file://hsrb/meshes/obj/Head_Pan_002.obj"/>
      </geometry>
    </visual>
    <collision name="head_pan_link_geom_collision_0_head_pan">
      <origin xyz="0.0 0.0 0.0" rpy="0.0 0.0 0.0"/>
      <geometry>
        <mesh filename="file://hsrb/meshes/stl/head_pan.stl"/>
      </geometry>
    </collision>
  </link>
  <joint name="head_tilt_joint" type="revolute">
    <origin xyz="0.019999999552965164 0.0 0.0" rpy="0.0 0.0 0.0"/>
    <axis xyz="0.0 -1.0 0.0"/>
    <parent link="head_pan_link"/>
    <child link="head_tilt_link"/>
    <limit effort="100.0" lower="-1.5700000524520874" upper="0.5199999809265137" velocity="1.0"/>
  </joint>
  <link name="head_tilt_link">
    <inertial>
      <origin xyz="-0.06645193696022034 -0.00011767786054406315 0.8911780714988708" rpy="0.0009954882552847266 1.022381067276001 0.0014173000818118453"/>
      <mass value="1.2649989128112793"/>
      <inertia ixx="0.004195534624159336" ixy="0.0" ixz="0.0" iyy="0.039127983152866364" iyz="0.0" izz="0.04236074909567833"/>
    </inertial>
    <visual name="head_tilt_link_geom_visual_0_Head_Upper">
      <origin xyz="0.0 0.0 0.0" rpy="0.0 0.0 0.0"/>
      <geometry>
        <mesh filename="file://hsrb/meshes/obj/Head_Upper.obj"/>
      </geometry>
    </visual>
    <visual name="head_tilt_link_geom_visual_1_Head_Tilt">
      <origin xyz="0.0 0.0 0.0" rpy="0.0 0.0 0.0"/>
      <geometry>
        <mesh filename="file://hsrb/meshes/obj/Head_Tilt.obj"/>
      </geometry>
    </visual>
    <visual name="head_tilt_link_geom_visual_2_Simulator_TabletBase_DR017_S0150_A_000">
      <origin xyz="0.0 0.0 0.0" rpy="0.0 0.0 0.0"/>
      <geometry>
        <mesh filename="file://hsrb/meshes/obj/Simulator_TabletBase_DR017_S0150_A_000.obj"/>
      </geometry>
    </visual>
    <collision name="head_tilt_link_geom_collision_0_head">
      <origin xyz="0.0 0.0 0.0" rpy="0.0 0.0 0.0"/>
      <geometry>
        <mesh filename="file://hsrb/meshes/stl/head.stl"/>
      </geometry>
    </collision>
    <collision name="head_tilt_link_geom_collision_1_tablet">
      <origin xyz="0.0 0.0 0.0" rpy="0.0 0.0 0.0"/>
      <geometry>
        <mesh filename="file://hsrb/meshes/stl/tablet.stl"/>
      </geometry>
    </collision>
  </link>
  <joint name="head_l_stereo_camera_link_joint" type="fixed">
    <origin xyz="0.02 0.07 0.061" rpy="-1.5707963705062866 0.0 -1.5707963705062866"/>
    <parent link="head_tilt_link"/>
    <child link="head_l_stereo_camera_link"/>
  </joint>
  <link name="head_l_stereo_camera_link">
    <inertial>
      <origin xyz="0.00371176446788013 0.0699966549873352 0.06099742650985718" rpy="3.019899368286133 -1.5698167085647583 -3.1120924949645996"/>
      <mass value="0.038347601890563965"/>
      <inertia ixx="6.267971002671402e-06" ixy="0.0" ixz="0.0" iyy="1.8796468793880194e-05" iyz="0.0" izz="1.8810287656378932e-05"/>
    </inertial>
    <visual name="head_l_stereo_camera_link_geom_visual_0_Head_Camera">
      <origin xyz="0.0 0.0 0.0" rpy="0.0 0.0 0.0"/>
      <geometry>
        <mesh filename="file://hsrb/meshes/obj/Head_Camera.obj"/>
      </geometry>
    </visual>
  </link>
  <joint name="head_l_stereo_camera_gazebo_frame_joint" type="fixed">
    <origin xyz="0.0 0.0 0.0" rpy="1.5707963705062866 -1.5707963705062866 0.0"/>
    <parent link="head_l_stereo_camera_link"/>
    <child link="head_l_stereo_camera_gazebo_frame"/>
  </joint>
  <link name="head_l_stereo_camera_gazebo_frame"/>
  <joint name="head_r_stereo_camera_link_joint" type="fixed">
    <origin xyz="0.02 -0.07 0.061" rpy="-1.5707963705062866 0.0 -1.5707963705062866"/>
    <parent link="head_tilt_link"/>
    <child link="head_r_stereo_camera_link"/>
  </joint>
  <link name="head_r_stereo_camera_link">
    <inertial>
      <origin xyz="0.00371176446788013 -0.07000334560871124 0.06099742650985718" rpy="3.019899368286133 -1.5698167085647583 -3.1120924949645996"/>
      <mass value="0.038347601890563965"/>
      <inertia ixx="6.267971002671402e-06" ixy="0.0" ixz="0.0" iyy="1.8796468793880194e-05" iyz="0.0" izz="1.8810287656378932e-05"/>
    </inertial>
    <visual name="head_r_stereo_camera_link_geom_visual_0_Head_Camera">
      <origin xyz="0.0 0.0 0.0" rpy="0.0 0.0 0.0"/>
      <geometry>
        <mesh filename="file://hsrb/meshes/obj/Head_Camera.obj"/>
      </geometry>
    </visual>
  </link>
  <joint name="head_r_stereo_camera_gazebo_frame_joint" type="fixed">
    <origin xyz="0.0 0.0 0.0" rpy="1.5707963705062866 -1.5707963705062866 0.0"/>
    <parent link="head_r_stereo_camera_link"/>
    <child link="head_r_stereo_camera_gazebo_frame"/>
  </joint>
  <link name="head_r_stereo_camera_gazebo_frame"/>
  <joint name="head_center_camera_frame_joint" type="fixed">
    <origin xyz="0.0195 0.0 0.061" rpy="-1.5707963705062866 0.0 -1.5707963705062866"/>
    <parent link="head_tilt_link"/>
    <child link="head_center_camera_frame"/>
  </joint>
  <link name="head_center_camera_frame"/>
  <joint name="head_center_camera_gazebo_frame_joint" type="fixed">
    <origin xyz="0.0 0.0 0.0" rpy="1.5707963705062866 -1.5707963705062866 0.0"/>
    <parent link="head_center_camera_frame"/>
    <child link="head_center_camera_gazebo_frame"/>
  </joint>
  <link name="head_center_camera_gazebo_frame"/>
  <joint name="head_rgbd_sensor_link_joint" type="fixed">
    <origin xyz="-0.079796 0.022 0.215172" rpy="-1.5707963705062866 0.0 -1.5707963705062866"/>
    <parent link="head_tilt_link"/>
    <child link="head_rgbd_sensor_link"/>
  </joint>
  <link name="head_rgbd_sensor_link">
    <inertial>
      <origin xyz="-0.09484199434518814 -1.4280316236181534e-06 0.21517214179039001" rpy="1.5707881450653076 0.12046410888433456 -4.872006229561521e-06"/>
      <mass value="0.15930503606796265"/>
      <inertia ixx="5.5428787163691595e-05" ixy="0.0" ixz="0.0" iyy="0.0004974461044184864" iyz="0.0" izz="0.000536749605089426"/>
    </inertial>
    <visual name="head_rgbd_sensor_link_geom_visual_0_Rgbd_006">
      <origin xyz="0.0 0.0 0.0" rpy="0.0 0.0 0.0"/>
      <geometry>
        <mesh filename="file://hsrb/meshes/obj/Rgbd_006.obj"/>
      </geometry>
    </visual>
    <collision name="head_rgbd_sensor_link_geom_collision_0_rgbd">
      <origin xyz="0.0 0.0 0.0" rpy="0.0 0.0 0.0"/>
      <geometry>
        <mesh filename="file://hsrb/meshes/stl/rgbd.stl"/>
      </geometry>
    </collision>
  </link>
  <joint name="head_rgbd_sensor_gazebo_frame_joint" type="fixed">
    <origin xyz="0.0 0.0 0.0" rpy="1.5707963705062866 -1.5707963705062866 0.0"/>
    <parent link="head_rgbd_sensor_link"/>
    <child link="head_rgbd_sensor_gazebo_frame"/>
  </joint>
  <link name="head_rgbd_sensor_gazebo_frame"/>
  <joint name="arm_lift_joint" type="prismatic">
    <origin xyz="0.0 0.0 0.3400000035762787" rpy="0.0 0.0 0.0"/>
    <axis xyz="0.0 0.0 1.0"/>
    <parent link="base_link"/>
    <child link="arm_lift_link"/>
    <limit effort="100.0" lower="0.0" upper="0.6899999976158142" velocity="0.20000000298023224"/>
  </joint>
  <link name="arm_lift_link">
    <inertial>
      <origin xyz="0.0813228189945221 0.026763053610920906 0.2917323708534241" rpy="-2.430516242980957 0.4805789887905121 0.4823969304561615"/>
      <mass value="0.1369386464357376"/>
      <inertia ixx="0.0009512149845249951" ixy="0.0" ixz="0.0" iyy="0.0017490539466962218" iyz="0.0" izz="0.0022147856652736664"/>
    </inertial>
    <visual name="arm_lift_link_geom_visual_0_Shoulder">
      <origin xyz="0.0 0.0 0.0" rpy="0.0 0.0 0.0"/>
      <geometry>
        <mesh filename="file://hsrb/meshes/obj/Shoulder.obj"/>
      </geometry>
    </visual>
    <collision name="arm_lift_link_geom_collision_0_shoulder">
      <origin xyz="0.0 0.0 0.0" rpy="0.0 0.0 0.0"/>
      <geometry>
        <mesh filename="file://hsrb/meshes/stl/shoulder.stl"/>
      </geometry>
    </collision>
  </link>
  <joint name="arm_flex_joint" type="revolute">
    <origin xyz="0.14100000262260437 0.07800000160932541 0.0" rpy="0.0 0.0 0.0"/>
    <axis xyz="0.0 -1.0 0.0"/>
    <parent link="arm_lift_link"/>
    <child link="arm_flex_link"/>
    <limit effort="100.0" lower="-2.619999885559082" upper="0.0" velocity="1.2000000476837158"/>
  </joint>
  <link name="arm_flex_link">
    <inertial>
      <origin xyz="0.1406947821378708 0.08575395494699478 0.46638625860214233" rpy="1.6921350955963135 1.5083250999450684 -1.454687476158142"/>
      <mass value="0.0956273078918457"/>
      <inertia ixx="0.0002442473778501153" ixy="0.0" ixz="0.0" iyy="0.0022642638068646193" iyz="0.0" izz="0.0023555909283459187"/>
    </inertial>
    <visual name="arm_flex_link_geom_visual_0_Arm_Flex_000">
      <origin xyz="0.0 0.0 0.0" rpy="0.0 0.0 0.0"/>
      <geometry>
        <mesh filename="file://hsrb/meshes/obj/Arm_Flex_000.obj"/>
      </geometry>
    </visual>
    <collision name="arm_flex_link_geom_collision_0_arm_flex">
      <origin xyz="0.0 0.0 0.0" rpy="0.0 0.0 0.0"/>
      <geometry>
        <mesh filename="file://hsrb/meshes/stl/arm_flex.stl"/>
      </geometry>
    </collision>
  </link>
  <joint name="arm_roll_joint" type="revolute">
    <origin xyz="0.004999999888241291 0.0 0.3449999988079071" rpy="0.0 0.0 0.0"/>
    <axis xyz="0.0 0.0 1.0"/>
    <parent link="arm_flex_link"/>
    <child link="arm_roll_link"/>
    <limit effort="100.0" lower="-2.0899999141693115" upper="3.8399999141693115" velocity="2.0"/>
  </joint>
  <link name="arm_roll_link">
    <inertial>
      <origin xyz="0.1384287178516388 0.08344055712223053 0.6361227631568909" rpy="0.8629973530769348 -1.3572900295257568 -0.8861574530601501"/>
      <mass value="0.055637508630752563"/>
      <inertia ixx="0.00013514167221728712" ixy="0.0" ixz="0.0" iyy="0.0002659598831087351" iyz="0.0" izz="0.00031855120323598385"/>
    </inertial>
    <visual name="arm_roll_link_geom_visual_0_Arm_Roll_003">
      <origin xyz="0.0 0.0 0.0" rpy="0.0 0.0 0.0"/>
      <geometry>
        <mesh filename="file://hsrb/meshes/obj/Arm_Roll_003.obj"/>
      </geometry>
    </visual>
    <collision name="arm_roll_link_geom_collision_0_arm_roll">
      <origin xyz="0.0 0.0 0.0" rpy="0.0 0.0 0.0"/>
      <geometry>
        <mesh filename="file://hsrb/meshes/stl/arm_roll.stl"/>
      </geometry>
    </collision>
  </link>
  <joint name="wrist_flex_joint" type="revolute">
    <origin xyz="0.0 0.0 0.0" rpy="0.0 0.0 0.0"/>
    <axis xyz="0.0 -1.0 0.0"/>
    <parent link="arm_roll_link"/>
    <child link="wrist_flex_link"/>
    <limit effort="100.0" lower="-1.9199999570846558" upper="1.2200000286102295" velocity="1.5"/>
  </joint>
  <link name="wrist_flex_link">
    <inertial>
      <origin xyz="0.146077960729599 0.07799923419952393 0.7066903114318848" rpy="1.5566328763961792 1.5692963600158691 -0.015322129242122173"/>
      <mass value="0.03307466208934784"/>
      <inertia ixx="7.535738859587582e-06" ixy="0.0" ixz="0.0" iyy="3.692131576826796e-05" iyz="0.0" izz="3.890189327648841e-05"/>
    </inertial>
    <visual name="wrist_flex_link_geom_visual_0_Wrist_Flex">
      <origin xyz="0.0 0.0 0.0" rpy="0.0 0.0 0.0"/>
      <geometry>
        <mesh filename="file://hsrb/meshes/obj/Wrist_Flex.obj"/>
      </geometry>
    </visual>
    <visual name="wrist_flex_link_geom_visual_1">
      <origin xyz="0.0 0.0 0.03999999910593033" rpy="0.0 0.0 0.0"/>
      <geometry>
        <cylinder radius="0.017000000923871994" length="0.019999999552965164"/>
      </geometry>
    </visual>
    <collision name="wrist_flex_link_geom_collision_0">
      <origin xyz="0.0 0.0 0.029999999329447746" rpy="0.0 0.0 0.0"/>
      <geometry>
        <cylinder radius="0.017000000923871994" length="0.03999999910593033"/>
      </geometry>
    </collision>
  </link>
  <joint name="wrist_roll_joint" type="revolute">
    <origin xyz="0.0 0.0 0.0" rpy="0.0 0.0 0.0"/>
    <axis xyz="0.0 0.0 1.0"/>
    <parent link="wrist_flex_link"/>
    <child link="wrist_roll_link"/>
    <limit effort="100.0" lower="-1.9199999570846558" upper="3.6700000762939453" velocity="1.5"/>
  </joint>
  <link name="wrist_roll_link">
    <inertial>
      <origin xyz="0.13593338429927826 0.07797524333000183 0.7734910845756531" rpy="3.1379220485687256 -1.4284381866455078 -3.1384637355804443"/>
      <mass value="0.06149858608841896"/>
      <inertia ixx="0.00011161583825014532" ixy="0.0" ixz="0.0" iyy="0.0005890678730793297" iyz="0.0" izz="0.000613926793448627"/>
    </inertial>
    <visual name="wrist_roll_link_geom_visual_0_Wrist_Roll">
      <origin xyz="0.0 0.0 0.0" rpy="0.0 0.0 0.0"/>
      <geometry>
        <mesh filename="file://hsrb/meshes/obj/Wrist_Roll.obj"/>
      </geometry>
    </visual>
    <collision name="wrist_roll_link_geom_collision_0_wrist_roll">
      <origin xyz="0.0 0.0 0.0" rpy="0.0 0.0 0.0"/>
      <geometry>
        <mesh filename="file://hsrb/meshes/stl/wrist_roll.stl"/>
      </geometry>
    </collision>
  </link>
  <joint name="wrist_ft_sensor_frame_joint" type="fixed">
    <origin xyz="0.0 0.0 0.0735" rpy="-3.1415927410125732 0.0 0.0"/>
    <parent link="wrist_roll_link"/>
    <child link="wrist_ft_sensor_frame"/>
  </joint>
  <link name="wrist_ft_sensor_frame"/>
  <joint name="hand_palm_link_joint" type="fixed">
    <origin xyz="0.012 0.0 0.1405" rpy="0.0 0.0 -3.1415927410125732"/>
    <parent link="wrist_roll_link"/>
    <child link="hand_palm_link"/>
  </joint>
  <link name="hand_palm_link">
    <inertial>
      <origin xyz="0.01071222499012947 -0.00030466882162727416 0.11583888530731201" rpy="2.7498908042907715 -1.50751531124115 -2.7445483207702637"/>
      <mass value="0.08773984014987946"/>
      <inertia ixx="3.0547216738341376e-05" ixy="0.0" ixz="0.0" iyy="7.715255196671933e-05" iyz="0.0" izz="9.0780173195526e-05"/>
    </inertial>
    <visual name="hand_palm_link_geom_visual_0_palm">
      <origin xyz="0.0 0.0 0.0" rpy="0.0 0.0 0.0"/>
      <geometry>
        <mesh filename="file://hsrb/meshes/stl/palm.stl"/>
      </geometry>
    </visual>
    <collision name="hand_palm_link_geom_collision_0_palm">
      <origin xyz="0.0 0.0 0.0" rpy="0.0 0.0 0.0"/>
      <geometry>
        <mesh filename="file://hsrb/meshes/stl/palm.stl"/>
      </geometry>
    </collision>
  </link>
  <joint name="hand_motor_joint" type="revolute">
    <origin xyz="0 0 0" rpy="0 0 0"/>
    <axis xyz="1.0 0.0 0.0"/>
    <parent link="hand_palm_link"/>
    <child link="hand_motor_dummy_link"/>
    <limit effort="100.0" lower="-0.7979999780654907" upper="1.2400000095367432" velocity="1.0"/>
  </joint>
  <link name="hand_motor_dummy_link"/>
  <joint name="hand_l_proximal_joint" type="revolute">
    <origin xyz="-0.016750000417232513 -0.02449999935925007 -0.017500000074505806" rpy="0.0 0.0 0.0"/>
    <axis xyz="1.0 0.0 0.0"/>
    <parent link="hand_palm_link"/>
    <child link="hand_l_proximal_link"/>
    <limit effort="100.0" lower="-0.7979999780654907" upper="1.2400000095367432" velocity="1.0"/>
  </joint>
  <link name="hand_l_proximal_link"/>
  <joint name="hand_l_spring_proximal_joint" type="revolute">
    <origin xyz="0 0 0" rpy="0 0 0"/>
    <axis xyz="1.0 0.0 0.0"/>
    <parent link="hand_l_proximal_link"/>
    <child link="hand_l_spring_proximal_link"/>
    <limit effort="100.0" lower="0.0" upper="0.6980000138282776" velocity="1.0"/>
  </joint>
  <link name="hand_l_spring_proximal_link">
    <inertial>
      <origin xyz="0.15599320828914642 0.1047016829252243 0.8386635780334473" rpy="-1.532872200012207 -1.1292961835861206 -0.10901301354169846"/>
      <mass value="0.042135074734687805"/>
      <inertia ixx="8.60757427290082e-06" ixy="0.0" ixz="0.0" iyy="7.024005753919482e-05" iyz="0.0" izz="7.688956247875467e-05"/>
    </inertial>
    <visual name="hand_l_spring_proximal_link_geom_visual_0_l_proximal">
      <origin xyz="0.0 0.0 0.0" rpy="0.0 0.0 0.0"/>
      <geometry>
        <mesh filename="file://hsrb/meshes/stl/l_proximal.stl"/>
      </geometry>
    </visual>
    <collision name="hand_l_spring_proximal_link_geom_collision_0_l_proximal">
      <origin xyz="0.0 0.0 0.0" rpy="0.0 0.0 0.0"/>
      <geometry>
        <mesh filename="file://hsrb/meshes/stl/l_proximal.stl"/>
      </geometry>
    </collision>
  </link>
  <joint name="hand_l_mimic_distal_joint" type="revolute">
    <origin xyz="0.0 0.0 0.07000000029802322" rpy="0.0 0.0 0.0"/>
    <axis xyz="1.0 0.0 0.0"/>
    <parent link="hand_l_spring_proximal_link"/>
    <child link="hand_l_mimic_distal_link"/>
    <limit effort="100.0" lower="-0.6980000138282776" upper="-0.0" velocity="1.0"/>
  </joint>
  <link name="hand_l_mimic_distal_link"/>
  <joint name="hand_l_distal_joint" type="revolute">
    <origin xyz="0 0 0" rpy="0 0 0"/>
    <axis xyz="1.0 0.0 0.0"/>
    <parent link="hand_l_mimic_distal_link"/>
    <child link="hand_l_distal_link"/>
    <limit effort="100.0" lower="-1.2400000095367432" upper="0.7979999780654907" velocity="1.0"/>
  </joint>
  <link name="hand_l_distal_link">
    <inertial>
      <origin xyz="0.15949995815753937 0.09806831926107407 0.8973337411880493" rpy="-1.4266875982284546 0.8896632790565491 -2.8373043537139893"/>
      <mass value="0.03458765894174576"/>
      <inertia ixx="6.055272024241276e-06" ixy="0.0" ixz="0.0" iyy="2.712272726057563e-05" iyz="0.0" izz="2.945130836451426e-05"/>
    </inertial>
    <visual name="hand_l_distal_link_geom_visual_0_l_distal">
      <origin xyz="0.0 0.0 0.0" rpy="0.0 0.0 0.0"/>
      <geometry>
        <mesh filename="file://hsrb/meshes/stl/l_distal.stl"/>
      </geometry>
    </visual>
    <collision name="hand_l_distal_link_geom_collision_0_l_distal">
      <origin xyz="0.0 0.0 0.0" rpy="0.0 0.0 0.0"/>
      <geometry>
        <mesh filename="file://hsrb/meshes/stl/l_distal.stl"/>
      </geometry>
    </collision>
  </link>
  <joint name="hand_l_finger_tip_frame_joint" type="fixed">
    <origin xyz="0.01675 0.0193 0.0379" rpy="-1.5707963705062866 0.0 0.0"/>
    <parent link="hand_l_distal_link"/>
    <child link="hand_l_finger_tip_frame"/>
  </joint>
  <link name="hand_l_finger_tip_frame"/>
  <joint name="hand_l_finger_vacuum_frame_joint" type="fixed">
    <origin xyz="0.00475 -0.011539 0.03322" rpy="0.7853981852531433 0.0 0.0"/>
    <parent link="hand_l_distal_link"/>
    <child link="hand_l_finger_vacuum_frame"/>
  </joint>
  <link name="hand_l_finger_vacuum_frame">
    <inertial>
      <origin xyz="0.004749999847263098 -0.004467932041734457 0.026148932054638863" rpy="-0.0 1.570796251296997 0.0"/>
      <mass value="0.0012799999676644802"/>
      <inertia ixx="1.3653333574836779e-08" ixy="0.0" ixz="0.0" iyy="1.7749333380834287e-07" iyz="0.0" izz="1.7749333380834287e-07"/>
    </inertial>
    <visual name="hand_l_finger_vacuum_frame_geom_visual_0">
      <origin xyz="0.0 0.0 -0.009999999776482582" rpy="0.0 0.0 0.0"/>
      <geometry>
        <box size="0.00800000037997961 0.00800000037997961 0.019999999552965164"/>
      </geometry>
    </visual>
  </link>
  <joint name="hand_r_proximal_joint" type="revolute">
    <origin xyz="-0.016750000417232513 0.02449999935925007 -0.017500000074505806" rpy="0.0 0.0 0.0"/>
    <axis xyz="-1.0 0.0 0.0"/>
    <parent link="hand_palm_link"/>
    <child link="hand_r_proximal_link"/>
    <limit effort="100.0" lower="-0.7979999780654907" upper="1.2400000095367432" velocity="1.0"/>
  </joint>
  <link name="hand_r_proximal_link"/>
  <joint name="hand_r_spring_proximal_joint" type="revolute">
    <origin xyz="0 0 0" rpy="0 0 0"/>
    <axis xyz="-1.0 0.0 0.0"/>
    <parent link="hand_r_proximal_link"/>
    <child link="hand_r_spring_proximal_link"/>
    <limit effort="100.0" lower="0.0" upper="0.6980000138282776" velocity="1.0"/>
  </joint>
  <link name="hand_r_spring_proximal_link">
    <inertial>
      <origin xyz="0.15662232041358948 0.05133400484919548 0.8388575911521912" rpy="-1.5883344411849976 -1.1393007040023804 0.11346551030874252"/>
      <mass value="0.04147995635867119"/>
      <inertia ixx="7.921276846900582e-06" ixy="0.0" ixz="0.0" iyy="6.877347186673433e-05" iyz="0.0" izz="7.483593799406663e-05"/>
    </inertial>
    <visual name="hand_r_spring_proximal_link_geom_visual_0_r_proximal">
      <origin xyz="0.0 0.0 0.0" rpy="0.0 0.0 0.0"/>
      <geometry>
        <mesh filename="file://hsrb/meshes/stl/r_proximal.stl"/>
      </geometry>
    </visual>
    <collision name="hand_r_spring_proximal_link_geom_collision_0_r_proximal">
      <origin xyz="0.0 0.0 0.0" rpy="0.0 0.0 0.0"/>
      <geometry>
        <mesh filename="file://hsrb/meshes/stl/r_proximal.stl"/>
      </geometry>
    </collision>
  </link>
  <joint name="hand_r_mimic_distal_joint" type="revolute">
    <origin xyz="0.0 0.0 0.07000000029802322" rpy="0.0 0.0 0.0"/>
    <axis xyz="-1.0 0.0 0.0"/>
    <parent link="hand_r_spring_proximal_link"/>
    <child link="hand_r_mimic_distal_link"/>
    <limit effort="100.0" lower="-0.6980000138282776" upper="-0.0" velocity="1.0"/>
  </joint>
  <link name="hand_r_mimic_distal_link"/>
  <joint name="hand_r_distal_joint" type="revolute">
    <origin xyz="0 0 0" rpy="0 0 0"/>
    <axis xyz="-1.0 0.0 0.0"/>
    <parent link="hand_r_mimic_distal_link"/>
    <child link="hand_r_distal_link"/>
    <limit effort="100.0" lower="-1.2400000095367432" upper="0.7979999780654907" velocity="1.0"/>
  </joint>
  <link name="hand_r_distal_link">
    <inertial>
      <origin xyz="0.15761487185955048 0.06115259975194931 0.8951394557952881" rpy="-2.105471611022949 0.7531828284263611 2.7236809730529785"/>
      <mass value="0.024421628564596176"/>
      <inertia ixx="3.450870281085372e-06" ixy="0.0" ixz="0.0" iyy="1.9094664821750484e-05" iyz="0.0" izz="2.1310002921381965e-05"/>
    </inertial>
    <visual name="hand_r_distal_link_geom_visual_0_r_distal">
      <origin xyz="0.0 0.0 0.0" rpy="0.0 0.0 0.0"/>
      <geometry>
        <mesh filename="file://hsrb/meshes/stl/r_distal.stl"/>
      </geometry>
    </visual>
    <collision name="hand_r_distal_link_geom_collision_0_r_distal">
      <origin xyz="0.0 0.0 0.0" rpy="0.0 0.0 0.0"/>
      <geometry>
        <mesh filename="file://hsrb/meshes/stl/r_distal.stl"/>
      </geometry>
    </collision>
  </link>
  <joint name="hand_r_finger_tip_frame_joint" type="fixed">
    <origin xyz="0.01675 -0.0193 0.0379" rpy="1.5707963705062866 0.0 0.0"/>
    <parent link="hand_r_distal_link"/>
    <child link="hand_r_finger_tip_frame"/>
  </joint>
  <link name="hand_r_finger_tip_frame"/>
  <joint name="hand_camera_frame_joint" type="fixed">
    <origin xyz="0.039 0.0 -0.0045" rpy="0.0 0.0 0.0"/>
    <parent link="hand_palm_link"/>
    <child link="hand_camera_frame"/>
  </joint>
  <link name="hand_camera_frame"/>
  <joint name="hand_camera_gazebo_frame_joint" type="fixed">
    <origin xyz="0.0 0.0 0.0" rpy="1.5707963705062866 -1.5707963705062866 0.0"/>
    <parent link="hand_camera_frame"/>
    <child link="hand_camera_gazebo_frame"/>
  </joint>
  <link name="hand_camera_gazebo_frame"/>
  <joint name="hand_gripper_tool_frame_joint" type="fixed">
    <origin xyz="0.0 0.0 0.07" rpy="0.0 0.0 0.0"/>
    <parent link="hand_palm_link"/>
    <child link="hand_gripper_tool_frame"/>
  </joint>
  <link name="hand_gripper_tool_frame"/>
</robot>