<?xml version="1.0" ?>
<mujoco model="anymal_c">
	<compiler meshdir="anymal_c/meshes" texturedir="anymal_c/textures" angle="radian" autolimits="true" balanceinertia="true" boundmass="0.000001" boundinertia="0.000001"/>
	<default>
		<default class="visual">
			<geom contype="0" conaffinity="0"/>
		</default>
		<default class="collision">
			<geom rgba="1.0 0.0 0.0 0.0"/>
		</default>
	</default>
	<asset>
		<mesh name="base_0" file="stl/base_0.stl" scale="1.0 1.0 1.0"/>
		<mesh name="base_1" file="stl/base_1.stl" scale="1.0 1.0 1.0"/>
		<mesh name="base_2" file="stl/base_2.stl" scale="1.0 1.0 1.0"/>
		<mesh name="base_3" file="stl/base_3.stl" scale="1.0 1.0 1.0"/>
		<mesh name="base_4" file="stl/base_4.stl" scale="1.0 1.0 1.0"/>
		<mesh name="base_5" file="obj/base_5.obj" scale="1.0 1.0 1.0"/>
		<mesh name="top_shell" file="obj/top_shell.obj" scale="1.0 1.0 1.0"/>
		<mesh name="bottom_shell" file="obj/bottom_shell.obj" scale="1.0 1.0 1.0"/>
		<mesh name="remote" file="obj/remote.obj" scale="1.0 1.0 1.0"/>
		<mesh name="handle" file="obj/handle.obj" scale="1.0 1.0 1.0"/>
		<mesh name="face" file="obj/face.obj" scale="1.0 1.0 1.0"/>
		<mesh name="depth_camera" file="obj/depth_camera.obj" scale="1.0 1.0 1.0"/>
		<mesh name="wide_angle_camera" file="obj/wide_angle_camera.obj" scale="1.0 1.0 1.0"/>
		<mesh name="battery" file="obj/battery.obj" scale="1.0 1.0 1.0"/>
		<mesh name="lidar_cage" file="obj/lidar_cage.obj" scale="1.0 1.0 1.0"/>
		<mesh name="lidar" file="obj/lidar.obj" scale="1.0 1.0 1.0"/>
		<mesh name="drive" file="obj/drive.obj" scale="1.0 1.0 1.0"/>
		<mesh name="hatch" file="obj/hatch.obj" scale="1.0 1.0 1.0"/>
		<mesh name="hip_l" file="obj/hip_l.obj" scale="1.0 1.0 1.0"/>
		<mesh name="thigh" file="obj/thigh.obj" scale="1.0 1.0 1.0"/>
		<mesh name="shank_l" file="obj/shank_l.obj" scale="1.0 1.0 1.0"/>
		<mesh name="foot" file="obj/foot.obj" scale="1.0 1.0 1.0"/>
		<mesh name="hip_r" file="obj/hip_r.obj" scale="1.0 1.0 1.0"/>
		<mesh name="shank_r" file="obj/shank_r.obj" scale="1.0 1.0 1.0"/>
		<material name="green" rgba="0.052000001072883606 0.17800000309944153 0.032999999821186066 1.0" emission="0.0" specular="0.0"/>
		<material name="yellow" rgba="0.17800000309944153 0.11900000274181366 0.006000000052154064 1.0" emission="0.0" specular="0.0"/>
		<material name="red" rgba="0.17800000309944153 0.006000000052154064 0.004999999888241291 1.0" emission="0.0" specular="0.0"/>
		<material name="black_plastic" rgba="0.007000000216066837 0.007000000216066837 0.007000000216066837 1.0" emission="0.0" specular="0.0"/>
		<material name="lwl" rgba="0.800000011920929 0.800000011920929 0.800000011920929 1.0" emission="0.0" specular="0.0"/>
		<material name="base" texture="base"/>
		<material name="top_shell" texture="top_shell"/>
		<material name="bottom_shell" texture="bottom_shell"/>
		<material name="remote" texture="remote"/>
		<material name="handle" texture="handle"/>
		<material name="face" texture="face"/>
		<material name="depth_camera" texture="depth_camera"/>
		<material name="wide_angle_camera" texture="wide_angle_camera"/>
		<material name="battery" texture="battery"/>
		<material name="lidar_cage" texture="lidar_cage"/>
		<material name="lidar" texture="lidar"/>
		<material name="drive" texture="drive"/>
		<material name="hatch" texture="hatch"/>
		<material name="hip_l" texture="hip_l"/>
		<material name="thigh" texture="thigh"/>
		<material name="shank_l" texture="shank_l"/>
		<material name="foot" texture="foot"/>
		<material name="hip_r" texture="hip_r"/>
		<material name="shank" texture="shank_r"/>
		<texture name="base" type="2d" file="base.png"/>
		<texture name="top_shell" type="2d" file="top_shell.png"/>
		<texture name="bottom_shell" type="2d" file="bottom_shell.png"/>
		<texture name="remote" type="2d" file="remote.png"/>
		<texture name="handle" type="2d" file="handle.png"/>
		<texture name="face" type="2d" file="face.png"/>
		<texture name="depth_camera" type="2d" file="depth_camera.png"/>
		<texture name="wide_angle_camera" type="2d" file="wide_angle_camera.png"/>
		<texture name="battery" type="2d" file="battery.png"/>
		<texture name="lidar_cage" type="2d" file="lidar_cage.png"/>
		<texture name="lidar" type="2d" file="lidar.png"/>
		<texture name="drive" type="2d" file="drive.png"/>
		<texture name="hatch" type="2d" file="hatch.png"/>
		<texture name="hip_l" type="2d" file="hip_l.png"/>
		<texture name="thigh" type="2d" file="thigh.png"/>
		<texture name="shank_l" type="2d" file="shank_l.png"/>
		<texture name="foot" type="2d" file="foot.png"/>
		<texture name="hip_r" type="2d" file="hip_r.png"/>
		<texture name="shank_r" type="2d" file="shank_r.png"/>
	</asset>
	<worldbody>
		<body name="anymal_c" pos="0.0 0.0 0.0" quat="1.0 0.0 0.0 0.0">
			<body name="base" pos="0.0 0.0 0.0" quat="1.0 0.0 0.0 0.0">
				<geom name="Geom_0" type="mesh" pos="-0.011599770747125149 0.01999977044761181 0.08447550982236862" quat="0.5 0.5 -0.5 0.5" mesh="base_0" material="green" class="visual"/>
				<geom name="Geom_1" type="mesh" pos="-0.011599785648286343 0.019999781623482704 0.07711783796548843" quat="0.5 0.5 -0.5 0.5" mesh="base_1" material="yellow" class="visual"/>
				<geom name="Geom_2" type="mesh" pos="-0.011599860154092312 0.01999989151954651 0.0938289538025856" quat="3.1764270715939347e-06 0.7071042060852051 3.17645026370883e-06 0.7071093916893005" mesh="base_2" material="red" class="visual"/>
				<geom name="Geom_3" type="mesh" pos="-0.011599920690059662 -0.034999456256628036 0.06816615164279938" quat="1.0 0.0 0.0 0.0" mesh="base_3" material="black_plastic" class="visual"/>
				<geom name="Geom_4" type="mesh" pos="-0.011599943973124027 -0.034999407827854156 0.07339996844530106" quat="0.5 0.5 -0.5 0.5" mesh="base_4" material="lwl" class="visual"/>
				<geom name="Geom_5" type="mesh" pos="0.036819808185100555 -2.975935053939338e-09 0.021578945219516754" quat="0.0 0.72342848777771 0.0 0.6903992891311646" mesh="base_5" material="base" class="visual"/>
				<geom name="Geom_6" type="box" pos="0.0 0.0 0.0" quat="1.0 0.0 0.0 0.0" size="0.28999999165534973 0.07000000029802322 0.09000000357627869" class="collision"/>
				<geom name="Geom_7" type="cylinder" pos="0.2175000011920929 0.07000000029802322 0.0" quat="0.7071067690849304 0.0 0.7071067690849304 0.0" size="0.09000000357627869 0.07249999791383743 0.0" class="collision"/>
				<geom name="Geom_8" type="cylinder" pos="-0.2175000011920929 0.07000000029802322 0.0" quat="0.7071067690849304 0.0 0.7071067690849304 0.0" size="0.09000000357627869 0.07249999791383743 0.0" class="collision"/>
				<geom name="Geom_9" type="cylinder" pos="0.2175000011920929 -0.07000000029802322 0.0" quat="0.7071067690849304 0.0 0.7071067690849304 0.0" size="0.09000000357627869 0.07249999791383743 0.0" class="collision"/>
				<geom name="Geom_10" type="cylinder" pos="-0.2175000011920929 -0.07000000029802322 0.0" quat="0.7071067690849304 0.0 0.7071067690849304 0.0" size="0.09000000357627869 0.07249999791383743 0.0" class="collision"/>
				<geom name="Geom_11" type="mesh" pos="-0.0026326263323426247 0.00041710055666044354 0.06210428848862648" quat="-5.8360751609143335e-06 0.7142897844314575 -1.4573529369954485e-05 0.6998500227928162" mesh="top_shell" material="top_shell" class="visual"/>
				<geom name="Geom_12" type="mesh" pos="-0.0006547375814989209 4.4404549726095865e-07 -0.06612871587276459" quat="-1.1017913493560627e-05 0.707190752029419 1.965868978004437e-05 0.7070227861404419" mesh="bottom_shell" material="bottom_shell" class="visual"/>
				<geom name="Geom_13" type="mesh" pos="-0.16322645545005798 1.217122417074279e-06 0.09824134409427643" quat="0.5831565260887146 0.39986345171928406 0.3996984660625458 0.5833342671394348" mesh="remote" material="remote" class="visual"/>
				<geom name="Geom_14" type="mesh" pos="0.3647890090942383 2.5179431872857094e-09 0.11878526210784912" quat="0.7011937499046326 0.7011937499046326 0.09125423431396484 -0.09125423431396484" mesh="handle" material="handle" class="visual"/>
				<geom name="Geom_15" type="mesh" pos="0.45985445380210876 -1.9454962966847233e-05 -0.006234311033040285" quat="0.702586829662323 0.7026491165161133 0.07948784530162811 -0.07960972934961319" mesh="face" material="face" class="visual"/>
				<geom name="Geom_16" type="box" pos="0.46950000524520874 0.0 0.0" quat="1.0 0.0 0.0 0.0" size="0.054999999701976776 0.07000000029802322 0.09000000357627869" class="collision"/>
				<geom name="Geom_17" type="cylinder" pos="0.46950000524520874 0.07000000029802322 0.0" quat="0.7071067690849304 0.0 0.7071067690849304 0.0" size="0.09000000357627869 0.054999999701976776 0.0" class="collision"/>
				<geom name="Geom_18" type="cylinder" pos="0.46950000524520874 -0.07000000029802322 0.0" quat="0.7071067690849304 0.0 0.7071067690849304 0.0" size="0.09000000357627869 0.054999999701976776 0.0" class="collision"/>
				<geom name="Geom_19" type="mesh" pos="0.4747720956802368 0.0 -0.03687187656760216" quat="0.6830127239227295 0.6830127239227295 0.18301263451576233 -0.18301263451576233" mesh="depth_camera" material="depth_camera" class="visual"/>
				<geom name="Geom_20" type="mesh" pos="0.5005862712860107 -2.7428591238276567e-06 0.008976703509688377" quat="0.9979866147041321 -0.00011796713079093024 0.06342367827892303 0.0003027316415682435" mesh="wide_angle_camera" material="wide_angle_camera" class="visual"/>
				<geom name="Geom_21" type="mesh" pos="-0.45985445380210876 1.9454962966847233e-05 -0.006234311033040285" quat="0.07960972934961319 -0.07948784530162811 0.7026491165161133 0.702586829662323" mesh="face" material="face" class="visual"/>
				<geom name="Geom_22" type="box" pos="-0.46950000524520874 0.0 0.0" quat="0.0 0.0 0.0 1.0" size="0.054999999701976776 0.07000000029802322 0.09000000357627869" class="collision"/>
				<geom name="Geom_23" type="cylinder" pos="-0.46950000524520874 -0.07000000029802322 0.0" quat="0.0 -0.7071067690849304 0.0 0.7071067690849304" size="0.09000000357627869 0.054999999701976776 0.0" class="collision"/>
				<geom name="Geom_24" type="cylinder" pos="-0.46950000524520874 0.07000000029802322 0.0" quat="0.0 -0.7071067690849304 0.0 0.7071067690849304" size="0.09000000357627869 0.054999999701976776 0.0" class="collision"/>
				<geom name="Geom_25" type="mesh" pos="-0.4747720956802368 0.0 -0.03687187656760216" quat="0.18301263451576233 -0.18301263451576233 0.6830127239227295 0.6830127239227295" mesh="depth_camera" material="depth_camera" class="visual"/>
				<geom name="Geom_26" type="mesh" pos="-0.5005862712860107 2.7428591238276567e-06 0.008976703509688377" quat="-0.0003027316415682435 -0.06342367827892303 -0.00011796713079093024 0.9979866147041321" mesh="wide_angle_camera" material="wide_angle_camera" class="visual"/>
				<geom name="Geom_27" type="mesh" pos="0.00316600501537323 -5.988961859800439e-19 -0.03308949992060661" quat="0.0 0.7071067690849304 0.0 0.7071067690849304" mesh="battery" material="battery" class="visual"/>
				<geom name="Geom_28" type="mesh" pos="-8.437695129426255e-19 0.08958207815885544 0.021378111094236374" quat="0.6123725175857544 0.3535532057285309 0.6123725175857544 0.3535532057285309" mesh="depth_camera" material="depth_camera" class="visual"/>
				<geom name="Geom_29" type="mesh" pos="-8.437695129426255e-19 -0.08958207815885544 0.021378111094236374" quat="0.3535532057285309 0.6123725175857544 -0.3535532057285309 -0.6123725175857544" mesh="depth_camera" material="depth_camera" class="visual"/>
				<geom name="Geom_30" type="mesh" pos="-0.36216145753860474 6.294024205999449e-05 0.1638614982366562" quat="0.9998769164085388 -0.00061993912095204 -0.015667341649532318 -0.0005074403597973287" mesh="lidar_cage" material="lidar_cage" class="visual"/>
				<geom name="Geom_31" type="cylinder" pos="-0.36399999260902405 0.0 0.13349999487400055" quat="1.0 0.0 0.0 0.0" size="0.07000000029802322 0.05999999865889549 0.0" class="collision"/>
				<geom name="Geom_32" type="mesh" pos="-0.36399999260902405 0.0003928735386580229 0.14043888449668884" quat="0.6377901434898376 0.30532556772232056 -0.6377891898155212 0.3053276836872101" mesh="lidar" material="lidar" class="visual"/>
				<geom name="Geom_33" type="mesh" pos="0.23129335045814514 0.10364477336406708 -0.0006153398426249623" quat="-0.3530530631542206 0.6126502752304077 -0.3540867567062378 0.6120749711990356" mesh="drive" material="drive" class="visual"/>
				<geom name="Geom_34" type="mesh" pos="0.23129335045814514 -0.1036447137594223 -0.0006153053836897016" quat="0.6120780110359192 -0.35404425859451294 0.6126855611801147 -0.3530292212963104" mesh="drive" material="drive" class="visual"/>
				<geom name="Geom_35" type="mesh" pos="-0.23129335045814514 0.1036447137594223 -0.0006153053836897016" quat="-0.3530292212963104 0.6126855611801147 0.35404425859451294 -0.6120780110359192" mesh="drive" material="drive" class="visual"/>
				<geom name="Geom_36" type="mesh" pos="-0.23129335045814514 -0.10364477336406708 -0.0006153398426249623" quat="0.6120749711990356 -0.3540867567062378 -0.6126502752304077 0.3530530631542206" mesh="drive" material="drive" class="visual"/>
				<geom name="Geom_37" type="mesh" pos="0.11599999666213989 -2.804344647125423e-12 0.07641233503818512" quat="0.0 0.7071067690849304 0.0 0.7071067690849304" mesh="hatch" material="hatch" class="visual"/>
				<body name="RF_HIP" pos="0.29989999532699585 -0.10400000214576721 0.0" quat="0.25881895422935486 -0.9659258723258972 0.0 0.0">
					<inertial mass="2.7809998989105225" pos="0.05676329880952835 0.015293999575078487 -0.008297840133309364" quat="0.13523992896080017 0.6790716052055359 0.1279849261045456 0.7100645899772644" diaginertia="0.005859280005097389 0.004920499864965677 0.0032906399574130774"/>
					<geom name="Geom_52" type="mesh" pos="0.07955124974250793 -0.0013034200528636575 -0.0015909073408693075" quat="-0.36329787969589233 0.6085743308067322 -0.34360766410827637 0.6161052584648132" mesh="hip_r" material="hip_r" class="visual"/>
					<geom name="Geom_53" type="mesh" pos="0.05989996716380119 0.01281125657260418 -0.008216958492994308" quat="-0.49927523732185364 0.8664434552192688 -3.0048206099309027e-05 -2.1409646251413506e-06" mesh="drive" material="drive" class="visual"/>
					<geom name="Geom_54" type="cylinder" pos="0.05990000069141388 0.011959799565374851 -0.006905000191181898" quat="-0.35355329513549805 0.6123725175857544 0.6123725175857544 0.35355329513549805" size="0.05000000074505806 0.07000000029802322 0.0" class="collision"/>
					<joint name="RF_HAA" type="hinge" pos="0.0 0.0 0.0" range="-0.49000000953674316 0.7200000286102295" axis="1.0 0.0 0.0"/>
					<body name="RF_THIGH" pos="0.05990000069141388 0.07258159667253494 -0.0419050008058548" quat="0.18301290273666382 0.6830126643180847 0.6830126643180847 -0.18301290273666382">
						<inertial mass="3.071000099182129" pos="0.030814699828624725 4.649949914892204e-05 -0.24569599330425262" quat="0.9927749037742615 -0.005127349402755499 -0.08066849410533905 0.08868108689785004" diaginertia="0.030251100659370422 0.0298932995647192 0.004184499848634005"/>
						<geom name="Geom_55" type="mesh" pos="0.019896067678928375 -3.135157749056816e-05 -0.1903664767742157" quat="0.9995383620262146 -8.072755008470267e-06 0.03038012981414795 0.00025633489713072777" mesh="thigh" material="thigh" class="visual"/>
						<geom name="Geom_56" type="cylinder" pos="0.03999999910593033 0.0 0.0" quat="0.5 0.5 0.5 0.5" size="0.06499999761581421 0.03999999910593033 0.0" class="collision"/>
						<geom name="Geom_57" type="box" pos="0.029999999329447746 0.0 -0.14131399989128113" quat="0.7071067690849304 0.0 0.0 0.7071067690849304" size="0.03750000149011612 0.029999999329447746 0.14131399989128113" class="collision"/>
						<geom name="Geom_58" type="mesh" pos="0.031693343073129654 -3.448225882607403e-08 -0.28428947925567627" quat="0.5003978610038757 0.49958860874176025 0.4995746612548828 0.5004381537437439" mesh="drive" material="drive" class="visual"/>
						<geom name="Geom_59" type="cylinder" pos="0.030300000682473183 0.0 -0.2849999964237213" quat="0.7071067690849304 0.0 0.7071067690849304 0.0" size="0.05000000074505806 0.07000000029802322 0.0" class="collision"/>
						<joint name="RF_HFE" type="hinge" pos="0.0 0.0 0.0" range="-9.424779891967773 9.424779891967773" axis="-1.0 0.0 0.0"/>
						<body name="RF_SHANK" pos="0.10029999911785126 0.0 -0.2849999964237213" quat="1.0 0.0 0.0 0.0">
							<inertial mass="0.5884199738502502" pos="0.005462000146508217 0.06125279888510704 -0.08065979927778244" quat="0.992933988571167 0.11590399593114853 -0.0010548699647188187 0.025442099198698997" diaginertia="0.010163700208067894 0.009238380007445812 0.0011192699894309044"/>
							<geom name="Geom_60" type="mesh" pos="0.006487637292593718 0.034592535346746445 0.0008805529796518385" quat="-0.0017478355439379811 -0.00019462202908471227 0.7092111110687256 0.7049939632415771" mesh="shank_r" material="shank" class="visual"/>
							<geom name="Geom_61" type="cylinder" pos="0.019999999552965164 0.0 0.0" quat="0.5 0.5 0.5 0.5" size="0.05999999865889549 0.019999999552965164 0.0" class="collision"/>
							<geom name="Geom_62" type="box" pos="0.019999999552965164 0.057498998939991 0.0" quat="0.5 0.5 0.5 0.5" size="0.057498998939991 0.03375000134110451 0.01899999938905239" class="collision"/>
							<geom name="Geom_63" type="mesh" pos="0.0019037557067349553 0.09909936040639877 -0.19530461728572845" quat="-0.38260531425476074 -0.007759032770991325 0.01873193122446537 0.9236893653869629" mesh="foot" material="foot" class="visual"/>
							<geom name="Geom_64" type="cylinder" pos="0.013050000183284283 0.08794999867677689 -0.16898499429225922" quat="0.7071067690849304 0.0 0.0 0.7071067690849304" size="0.017500000074505806 0.14125199615955353 0.0" class="collision"/>
							<geom name="Geom_65" type="sphere" pos="0.013050000183284283 0.08794999867677689 -0.31547001004219055" quat="0.7071067690849304 0.0 0.0 0.7071067690849304" size="0.029999999329447746 0.0 0.0" class="collision"/>
							<joint name="RF_KFE" type="hinge" pos="0.0 0.0 0.0" range="-9.424779891967773 9.424779891967773" axis="-1.0 0.0 0.0"/>
						</body>
					</body>
				</body>
				<body name="LH_HIP" pos="-0.29989999532699585 0.10400000214576721 0.0" quat="0.0 0.0 0.9659258723258972 -0.25881895422935486">
					<inertial mass="2.7809998989105225" pos="0.05676329880952835 0.015293999575078487 -0.008297840133309364" quat="0.13523992896080017 0.6790716052055359 0.1279849261045456 0.7100645899772644" diaginertia="0.005859280005097389 0.004920499864965677 0.0032906399574130774"/>
					<geom name="Geom_66" type="mesh" pos="0.07955124974250793 -0.0013034200528636575 -0.0015909073408693075" quat="0.36329787969589233 -0.6085743308067322 0.34360766410827637 -0.6161052584648132" mesh="hip_r" material="hip_r" class="visual"/>
					<geom name="Geom_67" type="mesh" pos="0.05989996716380119 0.01281125657260418 -0.008216958492994308" quat="-0.49927523732185364 0.8664434552192688 -3.0048206099309027e-05 -2.1409646251413506e-06" mesh="drive" material="drive" class="visual"/>
					<geom name="Geom_68" type="cylinder" pos="0.05990000069141388 0.011959799565374851 -0.006905000191181898" quat="-0.35355329513549805 0.6123725175857544 0.6123725175857544 0.35355329513549805" size="0.05000000074505806 0.07000000029802322 0.0" class="collision"/>
					<joint name="LH_HAA" type="hinge" pos="0.0 0.0 0.0" range="-0.7200000286102295 0.49000000953674316" axis="-1.0 0.0 0.0"/>
					<body name="LH_THIGH" pos="0.05990000069141388 0.07258159667253494 -0.0419050008058548" quat="0.18301290273666382 0.6830126643180847 0.6830126643180847 -0.18301290273666382">
						<inertial mass="3.071000099182129" pos="0.030814699828624725 4.649949914892204e-05 -0.24569599330425262" quat="0.9927749037742615 -0.005127349402755499 -0.08066849410533905 0.08868108689785004" diaginertia="0.030251100659370422 0.0298932995647192 0.004184499848634005"/>
						<geom name="Geom_69" type="mesh" pos="0.019896067678928375 -3.135157749056816e-05 -0.1903664767742157" quat="0.9995383620262146 -8.072755008470267e-06 0.03038012981414795 0.00025633489713072777" mesh="thigh" material="thigh" class="visual"/>
						<geom name="Geom_70" type="cylinder" pos="0.03999999910593033 0.0 0.0" quat="0.5 0.5 -0.5 -0.5" size="0.06499999761581421 0.03999999910593033 0.0" class="collision"/>
						<geom name="Geom_71" type="box" pos="0.029999999329447746 0.0 -0.14131399989128113" quat="0.7071067690849304 0.0 0.0 -0.7071067690849304" size="0.03750000149011612 0.029999999329447746 0.14131399989128113" class="collision"/>
						<geom name="Geom_72" type="mesh" pos="0.031693343073129654 -3.448225882607403e-08 -0.28428947925567627" quat="0.5003978610038757 0.49958860874176025 0.4995746612548828 0.5004381537437439" mesh="drive" material="drive" class="visual"/>
						<geom name="Geom_73" type="cylinder" pos="0.030300000682473183 0.0 -0.2849999964237213" quat="0.7071067690849304 0.0 0.7071067690849304 0.0" size="0.05000000074505806 0.07000000029802322 0.0" class="collision"/>
						<joint name="LH_HFE" type="hinge" pos="0.0 0.0 0.0" range="-9.424779891967773 9.424779891967773" axis="1.0 0.0 0.0"/>
						<body name="LH_SHANK" pos="0.10029999911785126 0.0 -0.2849999964237213" quat="1.0 0.0 0.0 0.0">
							<inertial mass="0.5884199738502502" pos="0.005462000146508217 0.06125279888510704 -0.08065979927778244" quat="0.992933988571167 0.11590399593114853 -0.0010548699647188187 0.025442099198698997" diaginertia="0.010163700208067894 0.009238380007445812 0.0011192699894309044"/>
							<geom name="Geom_74" type="mesh" pos="0.006487637292593718 0.034592535346746445 0.0008805529796518385" quat="0.0017478355439379811 0.00019462202908471227 -0.7092111110687256 -0.7049939632415771" mesh="shank_r" material="shank" class="visual"/>
							<geom name="Geom_75" type="cylinder" pos="0.019999999552965164 0.0 0.0" quat="0.5 0.5 -0.5 -0.5" size="0.05999999865889549 0.019999999552965164 0.0" class="collision"/>
							<geom name="Geom_76" type="box" pos="0.019999999552965164 0.057498998939991 0.0" quat="0.5 0.5 -0.5 -0.5" size="0.057498998939991 0.03375000134110451 0.01899999938905239" class="collision"/>
							<geom name="Geom_77" type="mesh" pos="0.0019037557067349553 0.09909936040639877 -0.19530461728572845" quat="0.38260531425476074 0.007759032770991325 -0.01873193122446537 -0.9236893653869629" mesh="foot" material="foot" class="visual"/>
							<geom name="Geom_78" type="cylinder" pos="0.013050000183284283 0.08794999867677689 -0.16898499429225922" quat="0.7071067690849304 0.0 0.0 -0.7071067690849304" size="0.017500000074505806 0.14125199615955353 0.0" class="collision"/>
							<geom name="Geom_79" type="sphere" pos="0.013050000183284283 0.08794999867677689 -0.31547001004219055" quat="0.7071067690849304 0.0 0.0 -0.7071067690849304" size="0.029999999329447746 0.0 0.0" class="collision"/>
							<joint name="LH_KFE" type="hinge" pos="0.0 0.0 0.0" range="-9.424779891967773 9.424779891967773" axis="1.0 0.0 0.0"/>
						</body>
					</body>
				</body>
				<body name="RH_HIP" pos="-0.29989999532699585 -0.10400000214576721 0.0" quat="0.0 0.0 -0.9659258723258972 -0.25881895422935486">
					<inertial mass="2.7809998989105225" pos="0.05666060000658035 -0.015293999575078487 -0.008297840133309364" quat="-0.12797805666923523 0.7097833156585693 -0.13527806103229523 0.6793593168258667" diaginertia="0.005857289768755436 0.004918680060654879 0.0032908099237829447"/>
					<geom name="Geom_80" type="mesh" pos="0.07955124229192734 0.0013034289004281163 -0.0015909208450466394" quat="-0.6161043047904968 0.3436092436313629 -0.6085734963417053 0.3632994294166565" mesh="hip_l" material="hip_l" class="visual"/>
					<geom name="Geom_81" type="mesh" pos="0.059900034219026566 -0.01281125657260418 -0.008216958492994308" quat="-2.1409646251413506e-06 -3.0048206099309027e-05 -0.8664434552192688 0.49927523732185364" mesh="drive" material="drive" class="visual"/>
					<geom name="Geom_82" type="cylinder" pos="0.05990000069141388 -0.011959799565374851 -0.006905000191181898" quat="0.35355329513549805 0.6123725175857544 -0.6123725175857544 0.35355329513549805" size="0.05000000074505806 0.07000000029802322 0.0" class="collision"/>
					<joint name="RH_HAA" type="hinge" pos="0.0 0.0 0.0" range="-0.49000000953674316 0.7200000286102295" axis="-1.0 0.0 0.0"/>
					<body name="RH_THIGH" pos="0.05990000069141388 -0.07258159667253494 -0.0419050008058548" quat="-0.18301290273666382 0.6830126643180847 -0.6830126643180847 -0.18301290273666382">
						<inertial mass="3.071000099182129" pos="0.030814699828624725 4.649949914892204e-05 -0.24569599330425262" quat="0.9931658506393433 -0.0051530892960727215 -0.08065918833017349 0.08419718593358994" diaginertia="0.030249999836087227 0.029894299805164337 0.004184649791568518"/>
						<geom name="Geom_83" type="mesh" pos="0.019896067678928375 -3.135157749056816e-05 -0.1903664767742157" quat="0.9995383620262146 -8.072755008470267e-06 0.03038012981414795 0.00025633489713072777" mesh="thigh" material="thigh" class="visual"/>
						<geom name="Geom_84" type="cylinder" pos="0.03999999910593033 0.0 0.0" quat="0.5 0.5 0.5 0.5" size="0.06499999761581421 0.03999999910593033 0.0" class="collision"/>
						<geom name="Geom_85" type="box" pos="0.029999999329447746 0.0 -0.14131399989128113" quat="0.7071067690849304 0.0 0.0 0.7071067690849304" size="0.03750000149011612 0.029999999329447746 0.14131399989128113" class="collision"/>
						<geom name="Geom_86" type="mesh" pos="0.031693343073129654 -3.448225882607403e-08 -0.28428947925567627" quat="0.5003978610038757 0.49958860874176025 0.4995746612548828 0.5004381537437439" mesh="drive" material="drive" class="visual"/>
						<geom name="Geom_87" type="cylinder" pos="0.030300000682473183 0.0 -0.2849999964237213" quat="0.7071067690849304 0.0 0.7071067690849304 0.0" size="0.05000000074505806 0.07000000029802322 0.0" class="collision"/>
						<joint name="RH_HFE" type="hinge" pos="0.0 0.0 0.0" range="-9.424779891967773 9.424779891967773" axis="-1.0 0.0 0.0"/>
						<body name="RH_SHANK" pos="0.10029999911785126 0.0 -0.2849999964237213" quat="1.0 0.0 0.0 0.0">
							<inertial mass="0.5884199738502502" pos="0.005462000146508217 -0.06125279888510704 -0.08065979927778244" quat="0.992933988571167 -0.11590399593114853 -0.0010548699647188187 -0.025442099198698997" diaginertia="0.010163700208067894 0.009238380007445812 0.0011192699894309044"/>
							<geom name="Geom_88" type="mesh" pos="0.006487672682851553 -0.034592606127262115 0.0008805167744867504" quat="0.7049943208694458 0.7092107534408569 -0.00019440350297372788 -0.0017484832787886262" mesh="shank_l" material="shank_l" class="visual"/>
							<geom name="Geom_89" type="cylinder" pos="0.019999999552965164 0.0 0.0" quat="0.5 0.5 0.5 0.5" size="0.05999999865889549 0.019999999552965164 0.0" class="collision"/>
							<geom name="Geom_90" type="box" pos="0.019999999552965164 -0.057498998939991 0.0" quat="0.5 0.5 0.5 0.5" size="0.057498998939991 0.03375000134110451 0.01899999938905239" class="collision"/>
							<geom name="Geom_91" type="mesh" pos="0.0019006143556907773 -0.09909621626138687 -0.19530461728572845" quat="0.9236893653869629 0.01873193122446537 -0.007759032770991325 -0.38260531425476074" mesh="foot" material="foot" class="visual"/>
							<geom name="Geom_92" type="cylinder" pos="0.013050000183284283 -0.08794999867677689 -0.16898499429225922" quat="0.7071067690849304 0.0 0.0 0.7071067690849304" size="0.017500000074505806 0.14125199615955353 0.0" class="collision"/>
							<geom name="Geom_93" type="sphere" pos="0.013050000183284283 -0.08794999867677689 -0.31547001004219055" quat="0.7071067690849304 0.0 0.0 0.7071067690849304" size="0.029999999329447746 0.0 0.0" class="collision"/>
							<joint name="RH_KFE" type="hinge" pos="0.0 0.0 0.0" range="-9.424779891967773 9.424779891967773" axis="-1.0 0.0 0.0"/>
						</body>
					</body>
				</body>
				<body name="LF_HIP" pos="0.29989999532699585 0.10400000214576721 0.0" quat="0.25881895422935486 0.9659258723258972 0.0 0.0">
					<inertial mass="2.7809998989105225" pos="0.05666060000658035 -0.015293999575078487 -0.008297840133309364" quat="-0.12797805666923523 0.7097833156585693 -0.13527806103229523 0.6793593168258667" diaginertia="0.005857289768755436 0.004918680060654879 0.0032908099237829447"/>
					<geom name="Geom_38" type="mesh" pos="0.07955124229192734 0.0013034289004281163 -0.0015909208450466394" quat="0.6161043047904968 -0.3436092436313629 0.6085734963417053 -0.3632994294166565" mesh="hip_l" material="hip_l" class="visual"/>
					<geom name="Geom_39" type="mesh" pos="0.059900034219026566 -0.01281125657260418 -0.008216958492994308" quat="2.1409646251413506e-06 3.0048206099309027e-05 0.8664434552192688 -0.49927523732185364" mesh="drive" material="drive" class="visual"/>
					<geom name="Geom_40" type="cylinder" pos="0.05990000069141388 -0.011959799565374851 -0.006905000191181898" quat="-0.35355329513549805 -0.6123725175857544 0.6123725175857544 -0.35355329513549805" size="0.05000000074505806 0.07000000029802322 0.0" class="collision"/>
					<joint name="LF_HAA" type="hinge" pos="0.0 0.0 0.0" range="-0.7200000286102295 0.49000000953674316" axis="1.0 0.0 0.0"/>
					<body name="LF_THIGH" pos="0.05990000069141388 -0.07258159667253494 -0.0419050008058548" quat="0.18301290273666382 -0.6830126643180847 0.6830126643180847 0.18301290273666382">
						<inertial mass="3.071000099182129" pos="0.030814699828624725 4.649949914892204e-05 -0.24569599330425262" quat="0.9931658506393433 -0.0051530892960727215 -0.08065918833017349 0.08419718593358994" diaginertia="0.030249999836087227 0.029894299805164337 0.004184649791568518"/>
						<geom name="Geom_41" type="mesh" pos="0.019896067678928375 -3.135157749056816e-05 -0.1903664767742157" quat="0.9995383620262146 -8.072755008470267e-06 0.03038012981414795 0.00025633489713072777" mesh="thigh" material="thigh" class="visual"/>
						<geom name="Geom_42" type="cylinder" pos="0.03999999910593033 0.0 0.0" quat="0.5 0.5 -0.5 -0.5" size="0.06499999761581421 0.03999999910593033 0.0" class="collision"/>
						<geom name="Geom_43" type="box" pos="0.029999999329447746 0.0 -0.14131399989128113" quat="0.7071067690849304 0.0 0.0 -0.7071067690849304" size="0.03750000149011612 0.029999999329447746 0.14131399989128113" class="collision"/>
						<geom name="Geom_44" type="mesh" pos="0.031693343073129654 -3.448225882607403e-08 -0.28428947925567627" quat="0.5003978610038757 0.49958860874176025 0.4995746612548828 0.5004381537437439" mesh="drive" material="drive" class="visual"/>
						<geom name="Geom_45" type="cylinder" pos="0.030300000682473183 0.0 -0.2849999964237213" quat="0.7071067690849304 0.0 0.7071067690849304 0.0" size="0.05000000074505806 0.07000000029802322 0.0" class="collision"/>
						<joint name="LF_HFE" type="hinge" pos="0.0 0.0 0.0" range="-9.424779891967773 9.424779891967773" axis="1.0 0.0 0.0"/>
						<body name="LF_SHANK" pos="0.10029999911785126 0.0 -0.2849999964237213" quat="1.0 0.0 0.0 0.0">
							<inertial mass="0.5884199738502502" pos="0.005462000146508217 -0.06125279888510704 -0.08065979927778244" quat="0.992933988571167 -0.11590399593114853 -0.0010548699647188187 -0.025442099198698997" diaginertia="0.010163700208067894 0.009238380007445812 0.0011192699894309044"/>
							<geom name="Geom_46" type="mesh" pos="0.006487672682851553 -0.034592606127262115 0.0008805167744867504" quat="0.7049943208694458 0.7092107534408569 -0.00019440350297372788 -0.0017484832787886262" mesh="shank_l" material="shank_l" class="visual"/>
							<geom name="Geom_47" type="cylinder" pos="0.019999999552965164 0.0 0.0" quat="0.5 0.5 -0.5 -0.5" size="0.05999999865889549 0.019999999552965164 0.0" class="collision"/>
							<geom name="Geom_48" type="box" pos="0.019999999552965164 -0.057498998939991 0.0" quat="0.5 0.5 -0.5 -0.5" size="0.057498998939991 0.03375000134110451 0.01899999938905239" class="collision"/>
							<geom name="Geom_49" type="mesh" pos="0.0019006143556907773 -0.09909621626138687 -0.19530461728572845" quat="0.9236893653869629 0.01873193122446537 -0.007759032770991325 -0.38260531425476074" mesh="foot" material="foot" class="visual"/>
							<geom name="Geom_50" type="cylinder" pos="0.013050000183284283 -0.08794999867677689 -0.16898499429225922" quat="0.7071067690849304 0.0 0.0 -0.7071067690849304" size="0.017500000074505806 0.14125199615955353 0.0" class="collision"/>
							<geom name="Geom_51" type="sphere" pos="0.013050000183284283 -0.08794999867677689 -0.31547001004219055" quat="0.7071067690849304 0.0 0.0 -0.7071067690849304" size="0.029999999329447746 0.0 0.0" class="collision"/>
							<joint name="LF_KFE" type="hinge" pos="0.0 0.0 0.0" range="-9.424779891967773 9.424779891967773" axis="1.0 0.0 0.0"/>
						</body>
					</body>
				</body>
			</body>
		</body>
	</worldbody>
	<equality/>
</mujoco>
