<?xml version="1.0" ?>
<mujoco model="robotis_op3">
	<compiler meshdir="robotis_op3/meshes" texturedir="robotis_op3/textures" angle="radian" autolimits="true" balanceinertia="true" boundmass="0.000001" boundinertia="0.000001"/>
	<default>
		<default class="visual">
			<geom contype="0" conaffinity="0"/>
		</default>
		<default class="collision">
			<geom rgba="1.0 0.0 0.0 0.0"/>
		</default>
	</default>
	<asset>
		<mesh name="body" file="stl/body.stl" scale="1.0 1.0 1.0"/>
		<mesh name="bodyc" file="stl/bodyc.stl" scale="1.0 1.0 1.0"/>
		<mesh name="body1c" file="stl/body1c.stl" scale="1.0 1.0 1.0"/>
		<mesh name="body2c" file="stl/body2c.stl" scale="1.0 1.0 1.0"/>
		<mesh name="body3c" file="stl/body3c.stl" scale="1.0 1.0 1.0"/>
		<mesh name="body4c" file="stl/body4c.stl" scale="1.0 1.0 1.0"/>
		<mesh name="h1" file="stl/h1.stl" scale="1.0 1.0 1.0"/>
		<mesh name="h1c" file="stl/h1c.stl" scale="1.0 1.0 1.0"/>
		<mesh name="h2" file="stl/h2.stl" scale="1.0 1.0 1.0"/>
		<mesh name="h2c" file="stl/h2c.stl" scale="1.0 1.0 1.0"/>
		<mesh name="h21c" file="stl/h21c.stl" scale="1.0 1.0 1.0"/>
		<mesh name="h22c" file="stl/h22c.stl" scale="1.0 1.0 1.0"/>
		<mesh name="la1" file="stl/la1.stl" scale="1.0 1.0 1.0"/>
		<mesh name="la1c" file="stl/la1c.stl" scale="1.0 1.0 1.0"/>
		<mesh name="la2" file="stl/la2.stl" scale="1.0 1.0 1.0"/>
		<mesh name="la2c" file="stl/la2c.stl" scale="1.0 1.0 1.0"/>
		<mesh name="la3" file="stl/la3.stl" scale="1.0 1.0 1.0"/>
		<mesh name="la3c" file="stl/la3c.stl" scale="1.0 1.0 1.0"/>
		<mesh name="ra1" file="stl/ra1.stl" scale="1.0 1.0 1.0"/>
		<mesh name="ra1c" file="stl/ra1c.stl" scale="1.0 1.0 1.0"/>
		<mesh name="ra2" file="stl/ra2.stl" scale="1.0 1.0 1.0"/>
		<mesh name="ra2c" file="stl/ra2c.stl" scale="1.0 1.0 1.0"/>
		<mesh name="ra3" file="stl/ra3.stl" scale="1.0 1.0 1.0"/>
		<mesh name="ra3c" file="stl/ra3c.stl" scale="1.0 1.0 1.0"/>
		<mesh name="ll1" file="stl/ll1.stl" scale="1.0 1.0 1.0"/>
		<mesh name="ll1c" file="stl/ll1c.stl" scale="1.0 1.0 1.0"/>
		<mesh name="ll2" file="stl/ll2.stl" scale="1.0 1.0 1.0"/>
		<mesh name="ll2c" file="stl/ll2c.stl" scale="1.0 1.0 1.0"/>
		<mesh name="ll3" file="stl/ll3.stl" scale="1.0 1.0 1.0"/>
		<mesh name="ll3c" file="stl/ll3c.stl" scale="1.0 1.0 1.0"/>
		<mesh name="ll4" file="stl/ll4.stl" scale="1.0 1.0 1.0"/>
		<mesh name="ll4c" file="stl/ll4c.stl" scale="1.0 1.0 1.0"/>
		<mesh name="ll5" file="stl/ll5.stl" scale="1.0 1.0 1.0"/>
		<mesh name="ll5c" file="stl/ll5c.stl" scale="1.0 1.0 1.0"/>
		<mesh name="ll6" file="stl/ll6.stl" scale="1.0 1.0 1.0"/>
		<mesh name="rl1" file="stl/rl1.stl" scale="1.0 1.0 1.0"/>
		<mesh name="rl1c" file="stl/rl1c.stl" scale="1.0 1.0 1.0"/>
		<mesh name="rl2" file="stl/rl2.stl" scale="1.0 1.0 1.0"/>
		<mesh name="rl2c" file="stl/rl2c.stl" scale="1.0 1.0 1.0"/>
		<mesh name="rl3" file="stl/rl3.stl" scale="1.0 1.0 1.0"/>
		<mesh name="rl3c" file="stl/rl3c.stl" scale="1.0 1.0 1.0"/>
		<mesh name="rl4" file="stl/rl4.stl" scale="1.0 1.0 1.0"/>
		<mesh name="rl4c" file="stl/rl4c.stl" scale="1.0 1.0 1.0"/>
		<mesh name="rl5" file="stl/rl5.stl" scale="1.0 1.0 1.0"/>
		<mesh name="rl5c" file="stl/rl5c.stl" scale="1.0 1.0 1.0"/>
		<mesh name="rl6" file="stl/rl6.stl" scale="1.0 1.0 1.0"/>
		<material name="black" rgba="0.20000000298023224 0.20000000298023224 0.20000000298023224 1.0" emission="0.0" specular="0.5"/>
	</asset>
	<worldbody>
		<body name="robotis_op3" pos="0.0 0.0 0.0" quat="1.0 0.0 0.0 0.0">
			<body name="body_link" pos="0.0 0.0 0.0" quat="1.0 0.0 0.0 0.0">
				<geom name="Geom_0" type="mesh" pos="-0.015062353573739529 0.00010709041089285165 0.07382681220769882" quat="0.31562358140945435 0.33037233352661133 -0.6202384233474731 0.6376050114631653" mesh="body" material="black" class="visual"/>
				<geom name="Geom_1" type="mesh" pos="-0.01547978911548853 8.47600517772662e-07 0.06837675720453262" quat="0.9998198747634888 1.6580177543801256e-05 0.018978890031576157 -0.00011253798584220931" mesh="bodyc" class="collision"/>
				<geom name="Geom_2" type="mesh" pos="-0.08686629682779312 0.052499834448099136 0.07599484175443649" quat="0.7070932388305664 0.0001319300790783018 0.0001334189873887226 0.7071202993392944" mesh="body1c" class="collision"/>
				<geom name="Geom_3" type="mesh" pos="-0.0868721529841423 -0.05250003933906555 0.07600828260183334" quat="0.7070996761322021 -0.00021320315136108547 -0.00024253582523670048 0.7071138024330139" mesh="body2c" class="collision"/>
				<geom name="Geom_4" type="mesh" pos="0.05340399965643883 0.05198853462934494 0.08048465102910995" quat="0.7076866030693054 -0.000729478255379945 -0.0003954711137339473 0.7065260410308838" mesh="body3c" class="collision"/>
				<geom name="Geom_5" type="mesh" pos="0.053379133343696594 -0.05200115218758583 0.0805167555809021" quat="0.7071372270584106 6.267690332606435e-05 7.622383418492973e-05 0.707076370716095" mesh="body4c" class="collision"/>
				<body name="l_sho_pitch_link" pos="-0.0010000000474974513 0.05999999865889549 0.11100000143051147" quat="1.0 0.0 0.0 0.0">
					<inertial mass="0.011760000139474869" pos="0.0 0.008229999803006649 -0.0023300000466406345" quat="0.24427185952663422 0.6635746359825134 0.24427185952663422 0.6635746359825134" diaginertia="4.234009793435689e-06 3.6059900594409555e-06 1.6499999446750735e-06"/>
					<geom name="Geom_12" type="mesh" pos="-4.0903142206616394e-08 0.010566436685621738 -0.002973126480355859" quat="0.2261854112148285 0.6699541807174683 0.22618435323238373 0.6699568629264832" mesh="la1" material="black" class="visual"/>
					<geom name="Geom_13" type="mesh" pos="-5.168489991547176e-08 0.014937390573322773 -0.004382733721286058" quat="0.21737512946128845 0.6728646755218506 0.21738243103027344 0.6728640198707581" mesh="la1c" class="collision"/>
					<joint name="l_sho_pitch" type="hinge" pos="0.0 0.0 0.0" range="0.0 0.0" axis="0.0 1.0 0.0"/>
					<body name="l_sho_roll_link" pos="0.01899999938905239 0.02850000001490116 -0.009999999776482582" quat="1.0 0.0 0.0 0.0">
						<inertial mass="0.17757999897003174" pos="-0.01844000071287155 0.04513999819755554 0.0002800000074785203" quat="0.5018527507781982 0.500379741191864 -0.49817273020744324 0.4995877146720886" diaginertia="0.00023474199406336993 0.00022803999308962375 3.041829950234387e-05"/>
						<geom name="Geom_14" type="mesh" pos="-0.019178275018930435 0.04488653689622879 0.0007386953802779317" quat="0.5009437799453735 0.49853265285491943 -0.49895212054252625 0.5015649199485779" mesh="la2" material="black" class="visual"/>
						<geom name="Geom_15" type="mesh" pos="-0.017953641712665558 0.04512150213122368 0.0003643354866653681" quat="0.5021325349807739 0.5011329650878906 -0.4978412091732025 0.49888157844543457" mesh="la2c" class="collision"/>
						<joint name="l_sho_roll" type="hinge" pos="0.0 0.0 0.0" range="0.0 0.0" axis="-1.0 0.0 0.0"/>
						<body name="l_el_link" pos="0.0 0.09040000289678574 -9.999999747378752e-05" quat="1.0 0.0 0.0 0.0">
							<inertial mass="0.041269998997449875" pos="-0.01899999938905239 0.07033000141382217 0.003800000064074993" quat="0.48328912258148193 0.5161701440811157 -0.5161701440811157 0.48328912258148193" diaginertia="6.878499698359519e-05 6.196000322233886e-05 1.2065000191796571e-05"/>
							<geom name="Geom_16" type="mesh" pos="-0.018999997526407242 0.07777010649442673 0.003117768792435527" quat="0.4925389885902405 0.507351279258728 -0.507351279258728 0.4925389885902405" mesh="la3" material="black" class="visual"/>
							<geom name="Geom_17" type="mesh" pos="-0.018999997526407242 0.0671701654791832 0.00045586045598611236" quat="0.498165488243103 0.5018261075019836 -0.5018278360366821 0.4981671869754791" mesh="la3c" class="collision"/>
							<joint name="l_el" type="hinge" pos="0.0 0.0 0.0" range="0.0 0.0" axis="1.0 0.0 0.0"/>
						</body>
					</body>
				</body>
				<body name="r_sho_pitch_link" pos="-0.0010000000474974513 -0.05999999865889549 0.11100000143051147" quat="1.0 0.0 0.0 0.0">
					<inertial mass="0.011760000139474869" pos="0.0 -0.008229999803006649 -0.0023300000466406345" quat="-0.24427185952663422 0.6635746359825134 -0.24427185952663422 0.6635746359825134" diaginertia="4.234009793435689e-06 3.6059900594409555e-06 1.6499999446750735e-06"/>
					<geom name="Geom_18" type="mesh" pos="4.0903142206616394e-08 -0.010566436685621738 -0.002973126480355859" quat="-0.22618435323238373 0.6699568629264832 -0.2261854112148285 0.6699541807174683" mesh="ra1" material="black" class="visual"/>
					<geom name="Geom_19" type="mesh" pos="1.7024168741386347e-08 -0.01493731141090393 -0.004382750019431114" quat="-0.21737539768218994 0.6728663444519043 -0.21737487614154816 0.6728647351264954" mesh="ra1c" class="collision"/>
					<joint name="r_sho_pitch" type="hinge" pos="0.0 0.0 0.0" range="0.0 0.0" axis="0.0 -1.0 0.0"/>
					<body name="r_sho_roll_link" pos="0.01899999938905239 -0.02850000001490116 -0.009999999776482582" quat="1.0 0.0 0.0 0.0">
						<inertial mass="0.17757999897003174" pos="-0.01844000071287155 -0.04513999819755554 0.0002800000074785203" quat="0.500379741191864 0.5018527507781982 -0.4995877146720886 0.49817273020744324" diaginertia="0.00023474199406336993 0.00022803999308962375 3.041829950234387e-05"/>
						<geom name="Geom_20" type="mesh" pos="-0.019178282469511032 -0.04488654434680939 0.0007386964280158281" quat="0.4985331892967224 0.5009435415267944 -0.5015642046928406 0.4989525079727173" mesh="ra2" material="black" class="visual"/>
						<geom name="Geom_21" type="mesh" pos="-0.017953014001250267 -0.04512038454413414 0.0003643217496573925" quat="0.5011412501335144 0.5021283030509949 -0.4988856315612793 0.4978330135345459" mesh="ra2c" class="collision"/>
						<joint name="r_sho_roll" type="hinge" pos="0.0 0.0 0.0" range="0.0 0.0" axis="-1.0 0.0 0.0"/>
						<body name="r_el_link" pos="0.0 -0.09040000289678574 -9.999999747378752e-05" quat="1.0 0.0 0.0 0.0">
							<inertial mass="0.041269998997449875" pos="-0.01899999938905239 -0.07033000141382217 0.003800000064074993" quat="0.5161701440811157 0.48328912258148193 -0.48328912258148193 0.5161701440811157" diaginertia="6.878499698359519e-05 6.196000322233886e-05 1.2065000191796571e-05"/>
							<geom name="Geom_22" type="mesh" pos="-0.01900000311434269 -0.07777010649442673 0.003117768792435527" quat="0.507351279258728 0.4925389885902405 -0.4925389885902405 0.507351279258728" mesh="ra3" material="black" class="visual"/>
							<geom name="Geom_23" type="mesh" pos="-0.018999941647052765 -0.0671704038977623 0.00045584727195091546" quat="0.5018273591995239 0.4981687068939209 -0.4981642961502075 0.5018262267112732" mesh="ra3c" class="collision"/>
							<joint name="r_el" type="hinge" pos="0.0 0.0 0.0" range="0.0 0.0" axis="1.0 0.0 0.0"/>
						</body>
					</body>
				</body>
				<body name="l_hip_yaw_link" pos="0.0 0.03500000014901161 0.0" quat="1.0 0.0 0.0 0.0">
					<inertial mass="0.01181000005453825" pos="-0.0015699999639764428 0.0 -0.007739999797195196" quat="0.4990410804748535 0.5009570717811584 0.5009570717811584 0.4990410804748535" diaginertia="4.300000000512227e-06 4.120040102861822e-06 1.509960043222236e-06"/>
					<geom name="Geom_24" type="mesh" pos="-0.0014929076423868537 -1.3410697899396418e-11 -0.010288386605679989" quat="0.5000420808792114 0.49995794892311096 0.49995794892311096 0.5000420808792114" mesh="ll1" material="black" class="visual"/>
					<geom name="Geom_25" type="mesh" pos="-0.00150005123578012 -4.39843219623981e-08 -0.01487430278211832" quat="0.4999925196170807 0.5000094771385193 0.49999815225601196 0.49999985098838806" mesh="ll1c" class="collision"/>
					<joint name="l_hip_yaw" type="hinge" pos="0.0 0.0 0.0" range="0.0 0.0" axis="0.0 0.0 -1.0"/>
					<body name="l_hip_roll_link" pos="-0.024000000208616257 0.0 -0.02850000001490116" quat="1.0 0.0 0.0 0.0">
						<inertial mass="0.17885999381542206" pos="0.0038799999747425318 0.0002800000074785203 -0.012140000239014626" quat="0.5026571154594421 0.49085211753845215 0.49849411845207214 0.5078421235084534" diaginertia="0.00012524299381766468 0.00010859799658646807 4.656930104829371e-05"/>
						<geom name="Geom_26" type="mesh" pos="0.007365824654698372 5.1177201385144144e-05 -0.01213391125202179" quat="0.5124639272689819 0.48538973927497864 0.4855455160140991 0.5157742500305176" mesh="ll2" material="black" class="visual"/>
						<geom name="Geom_27" type="mesh" pos="0.004096889402717352 0.000626525143161416 -0.011638031341135502" quat="0.5108701586723328 0.4849127233028412 0.5008082389831543 0.5030531287193298" mesh="ll2c" class="collision"/>
						<joint name="l_hip_roll" type="hinge" pos="0.0 0.0 0.0" range="0.0 0.0" axis="-1.0 0.0 0.0"/>
						<body name="l_hip_pitch_link" pos="0.02410000003874302 0.01899999938905239 0.0" quat="1.0 0.0 0.0 0.0">
							<inertial mass="0.11542999744415283" pos="0.000590000010561198 -0.019009999930858612 -0.08408000320196152" quat="0.9996820092201233 0.024691499769687653 0.004478250164538622 -0.0024820000398904085" diaginertia="0.0001049959973897785 9.630440035834908e-05 2.4749200747464783e-05"/>
							<geom name="Geom_28" type="mesh" pos="0.0009626309620216489 -0.019421827048063278 -0.07083793729543686" quat="0.9999699592590332 0.007639887742698193 -6.425838364521042e-05 -0.0012871582293882966" mesh="ll3" material="black" class="visual"/>
							<geom name="Geom_29" type="mesh" pos="0.00022433706908486784 -0.01883688010275364 -0.061354782432317734" quat="0.9999703764915466 0.007389495149254799 -0.0020882626995444298 0.0004902370856143534" mesh="ll3c" class="collision"/>
							<joint name="l_hip_pitch" type="hinge" pos="0.0 0.0 0.0" range="0.0 0.0" axis="0.0 1.0 0.0"/>
							<body name="l_knee_link" pos="0.0 0.0 -0.11015000194311142" quat="1.0 0.0 0.0 0.0">
								<inertial mass="0.040150001645088196" pos="0.0 -0.02150999940931797 -0.054999999701976776" quat="1.0 0.0 0.0 0.0" diaginertia="3.7149999116081744e-05 2.750999919953756e-05 1.5110000276763458e-05"/>
								<geom name="Geom_30" type="mesh" pos="1.133239877805503e-12 -0.01982726715505123 -0.054999999701976776" quat="1.0 0.0 0.0 0.0" mesh="ll4" material="black" class="visual"/>
								<geom name="Geom_31" type="mesh" pos="-1.9772162573872265e-08 -0.01967543177306652 -0.055000144988298416" quat="1.0 0.0 0.0 0.0" mesh="ll4c" class="collision"/>
								<joint name="l_knee" type="hinge" pos="0.0 0.0 0.0" range="0.0 0.0" axis="0.0 1.0 0.0"/>
								<body name="l_ank_pitch_link" pos="0.0 0.0 -0.10999999940395355" quat="1.0 0.0 0.0 0.0">
									<inertial mass="0.17885999381542206" pos="-0.02022000029683113 -0.018719999119639397 0.012140000239014626" quat="0.49085211753845215 0.5026571154594421 0.5078421235084534 0.49849411845207214" diaginertia="0.00012524299381766468 0.00010859799658646807 4.656930104829371e-05"/>
									<geom name="Geom_32" type="mesh" pos="-0.016888968646526337 -0.018948335200548172 0.012196226045489311" quat="0.48652714490890503 0.5113601088523865 0.514674961566925 0.4867359399795532" mesh="ll5" material="black" class="visual"/>
									<geom name="Geom_33" type="mesh" pos="-0.020036710426211357 -0.018372967839241028 0.011648035608232021" quat="0.4851568639278412 0.5105876326560974 0.5027398467063904 0.5011743903160095" mesh="ll5c" class="collision"/>
									<joint name="l_ank_pitch" type="hinge" pos="0.0 0.0 0.0" range="0.0 0.0" axis="0.0 -1.0 0.0"/>
									<body name="l_ank_roll_link" pos="-0.02410000003874302 -0.01899999938905239 0.0" quat="1.0 0.0 0.0 0.0">
										<inertial mass="0.06933999806642532" pos="0.023730000481009483 0.010370000265538692 -0.02759999968111515" quat="0.007851498201489449 0.7076008319854736 0.01139649748802185 0.7064768671989441" diaginertia="0.00011581800208659843 7.871349953347817e-05 4.033889854326844e-05"/>
										<geom name="Geom_34" type="mesh" pos="0.02351418510079384 0.010033032856881618 -0.025106150656938553" quat="0.005711215082556009 0.7084949612617493 0.017601266503334045 0.7054731845855713" mesh="ll6" material="black" class="visual"/>
										<geom name="Geom_35" type="box" pos="0.024000000208616257 0.013000000268220901 -0.026499999687075615" quat="1.0 0.0 0.0 0.0" size="0.06350000202655792 0.02800000086426735 0.004000000189989805" class="collision"/>
										<geom name="Geom_36" type="box" pos="0.024000000208616257 0.012500000186264515 -0.026499999687075615" quat="1.0 0.0 0.0 0.0" size="0.05700000002980232 0.039000000804662704 0.004000000189989805" class="collision"/>
										<joint name="l_ank_roll" type="hinge" pos="0.0 0.0 0.0" range="0.0 0.0" axis="1.0 0.0 0.0"/>
									</body>
								</body>
							</body>
						</body>
					</body>
				</body>
				<body name="r_hip_yaw_link" pos="0.0 -0.03500000014901161 0.0" quat="1.0 0.0 0.0 0.0">
					<inertial mass="0.01181000005453825" pos="-0.0015699999639764428 0.0 -0.007739999797195196" quat="0.4990410804748535 0.5009570717811584 0.5009570717811584 0.4990410804748535" diaginertia="4.300000000512227e-06 4.120040102861822e-06 1.509960043222236e-06"/>
					<geom name="Geom_37" type="mesh" pos="-0.0014929076423868537 -1.3410697899396418e-11 -0.010288386605679989" quat="0.5000420808792114 0.49995794892311096 0.49995794892311096 0.5000420808792114" mesh="rl1" material="black" class="visual"/>
					<geom name="Geom_38" type="mesh" pos="-0.00150005123578012 -4.39843219623981e-08 -0.01487430278211832" quat="0.4999925196170807 0.5000094771385193 0.49999815225601196 0.49999985098838806" mesh="rl1c" class="collision"/>
					<joint name="r_hip_yaw" type="hinge" pos="0.0 0.0 0.0" range="0.0 0.0" axis="0.0 0.0 -1.0"/>
					<body name="r_hip_roll_link" pos="-0.024000000208616257 0.0 -0.02850000001490116" quat="1.0 0.0 0.0 0.0">
						<inertial mass="0.17885999381542206" pos="0.0038799999747425318 -0.0002800000074785203 -0.012140000239014626" quat="0.5078421235084534 0.49849411845207214 0.49085211753845215 0.5026571154594421" diaginertia="0.00012524299381766468 0.00010859799658646807 4.656930104829371e-05"/>
						<geom name="Geom_39" type="mesh" pos="0.007365823723375797 -5.1178114517824724e-05 -0.012133914977312088" quat="0.5157740712165833 0.48554569482803345 0.48538967967033386 0.5124640464782715" mesh="rl2" material="black" class="visual"/>
						<geom name="Geom_40" type="mesh" pos="0.004096920136362314 -0.0006264956318773329 -0.011638014577329159" quat="0.5030507445335388 0.5008099675178528 0.48491182923316956 0.5108716487884521" mesh="rl2c" class="collision"/>
						<joint name="r_hip_roll" type="hinge" pos="0.0 0.0 0.0" range="0.0 0.0" axis="-1.0 0.0 0.0"/>
						<body name="r_hip_pitch_link" pos="0.02410000003874302 -0.01899999938905239 0.0" quat="1.0 0.0 0.0 0.0">
							<inertial mass="0.11542999744415283" pos="0.000590000010561198 0.019009999930858612 -0.08408000320196152" quat="0.9996820092201233 -0.024691499769687653 0.004478250164538622 0.0024820000398904085" diaginertia="0.0001049959973897785 9.630440035834908e-05 2.4749200747464783e-05"/>
							<geom name="Geom_41" type="mesh" pos="0.0009626252576708794 0.019421830773353577 -0.07083792984485626" quat="0.9999699592590332 -0.007639843970537186 -6.429859786294401e-05 0.0012870409991592169" mesh="rl3" material="black" class="visual"/>
							<geom name="Geom_42" type="mesh" pos="0.00022432378318626434 0.018836867064237595 -0.06135456636548042" quat="0.9999704360961914 -0.007387716788798571 -0.0020886599086225033 -0.0004885036614723504" mesh="rl3c" class="collision"/>
							<joint name="r_hip_pitch" type="hinge" pos="0.0 0.0 0.0" range="0.0 0.0" axis="0.0 -1.0 0.0"/>
							<body name="r_knee_link" pos="0.0 0.0 -0.11015000194311142" quat="1.0 0.0 0.0 0.0">
								<inertial mass="0.040150001645088196" pos="0.0 0.02150999940931797 -0.054999999701976776" quat="1.0 0.0 0.0 0.0" diaginertia="3.7149999116081744e-05 2.750999919953756e-05 1.5110000276763458e-05"/>
								<geom name="Geom_43" type="mesh" pos="-1.133239877805503e-12 0.01982726715505123 -0.054999999701976776" quat="1.0 0.0 0.0 0.0" mesh="rl4" material="black" class="visual"/>
								<geom name="Geom_44" type="mesh" pos="4.632620953515243e-09 0.019675450399518013 -0.05499984323978424" quat="1.0 0.0 0.0 0.0" mesh="rl4c" class="collision"/>
								<joint name="r_knee" type="hinge" pos="0.0 0.0 0.0" range="0.0 0.0" axis="0.0 -1.0 0.0"/>
								<body name="r_ank_pitch_link" pos="0.0 0.0 -0.10999999940395355" quat="1.0 0.0 0.0 0.0">
									<inertial mass="0.17885999381542206" pos="-0.02022000029683113 0.018719999119639397 0.012140000239014626" quat="0.49849411845207214 0.5078421235084534 0.5026571154594421 0.49085211753845215" diaginertia="0.00012524299381766468 0.00010859799658646807 4.656930104829371e-05"/>
									<geom name="Geom_45" type="mesh" pos="-0.016734184697270393 0.01894882321357727 0.012133914045989513" quat="0.4855455756187439 0.5157741904258728 0.5124638676643372 0.4853897988796234" mesh="rl5" material="black" class="visual"/>
									<geom name="Geom_46" type="mesh" pos="-0.02000303380191326 0.01837349869310856 0.011638008989393711" quat="0.5008053779602051 0.5030527114868164 0.5108705759048462 0.4849156141281128" mesh="rl5c" class="collision"/>
									<joint name="r_ank_pitch" type="hinge" pos="0.0 0.0 0.0" range="0.0 0.0" axis="0.0 1.0 0.0"/>
									<body name="r_ank_roll_link" pos="-0.02410000003874302 0.01899999938905239 0.0" quat="1.0 0.0 0.0 0.0">
										<inertial mass="0.06933999806642532" pos="0.023730000481009483 -0.010370000265538692 -0.02759999968111515" quat="-0.007851498201489449 0.7076008319854736 -0.01139649748802185 0.7064768671989441" diaginertia="0.00011581800208659843 7.871349953347817e-05 4.033889854326844e-05"/>
										<geom name="Geom_47" type="mesh" pos="0.023514186963438988 -0.010033032856881618 -0.025106150656938553" quat="-0.005711216013878584 0.7084949612617493 -0.017601268365979195 0.7054731845855713" mesh="rl6" material="black" class="visual"/>
										<geom name="Geom_48" type="box" pos="0.024000000208616257 -0.013000000268220901 -0.026499999687075615" quat="1.0 0.0 0.0 0.0" size="0.06350000202655792 0.02800000086426735 0.004000000189989805" class="collision"/>
										<geom name="Geom_49" type="box" pos="0.024000000208616257 -0.012500000186264515 -0.026499999687075615" quat="1.0 0.0 0.0 0.0" size="0.05700000002980232 0.039000000804662704 0.004000000189989805" class="collision"/>
										<joint name="r_ank_roll" type="hinge" pos="0.0 0.0 0.0" range="0.0 0.0" axis="1.0 0.0 0.0"/>
									</body>
								</body>
							</body>
						</body>
					</body>
				</body>
				<body name="head_pan_link" pos="-0.0010000000474974513 0.0 0.13650000095367432" quat="1.0 0.0 0.0 0.0">
					<inertial mass="0.011760000139474869" pos="0.0023300000466406345 0.0 0.008229999803006649" quat="0.6635746359825134 0.6635746359825134 0.24427185952663422 -0.24427185952663422" diaginertia="4.234009793435689e-06 3.6059900594409555e-06 1.6499999446750735e-06"/>
					<geom name="Geom_6" type="mesh" pos="0.002973126480355859 4.0903142206616394e-08 0.010566436685621738" quat="0.6699550151824951 0.6699560284614563 0.22618356347084045 -0.22618620097637177" mesh="h1" material="black" class="visual"/>
					<geom name="Geom_7" type="mesh" pos="0.0043823751620948315 -1.181606307909533e-06 0.014936410821974277" quat="0.672756016254425 0.6729751229286194 0.21735230088233948 -0.21739782392978668" mesh="h1c" class="collision"/>
					<joint name="head_pan" type="hinge" pos="0.0 0.0 0.0" range="0.0 0.0" axis="0.0 0.0 1.0"/>
					<body name="head_tilt_link" pos="0.009999999776482582 0.01899999938905239 0.02850000001490116" quat="1.0 0.0 0.0 0.0">
						<inertial mass="0.13630999624729156" pos="0.002300000051036477 -0.018629999831318855 0.027699999511241913" quat="0.9973121285438538 0.009738250635564327 0.07261310517787933 -0.0010270201601088047" diaginertia="0.00010745199688244611 8.722660277271643e-05 4.3941301555605605e-05"/>
						<geom name="Geom_8" type="mesh" pos="0.0029126012232154608 -0.01905038394033909 0.03745144605636597" quat="0.9980869293212891 -0.003525641281157732 0.061723142862319946 0.0005083727883175015" mesh="h2" material="black" class="visual"/>
						<geom name="Geom_9" type="mesh" pos="0.0005553366499952972 -0.01900036446750164 0.031976763159036636" quat="0.9999665021896362 -0.0004889009287580848 0.008167878724634647 -1.3743036106461659e-05" mesh="h2c" class="collision"/>
						<geom name="Geom_10" type="mesh" pos="0.022246643900871277 0.0030046773608773947 0.05925098434090614" quat="0.99552983045578 0.0942888855934143 -0.005383244249969721 0.0010148901492357254" mesh="h21c" class="collision"/>
						<geom name="Geom_11" type="mesh" pos="0.022246643900871277 -0.04099532216787338 0.05925098434090614" quat="0.9955299496650696 0.09428748488426208 -0.005383363924920559 0.0010149070294573903" mesh="h22c" class="collision"/>
						<joint name="head_tilt" type="hinge" pos="0.0 0.0 0.0" range="0.0 0.0" axis="0.0 -1.0 0.0"/>
					</body>
				</body>
			</body>
		</body>
	</worldbody>
	<equality/>
</mujoco>
