<?xml version="1.0" ?>
<mujoco model="z1">
	<compiler meshdir="z1/meshes" texturedir="z1/textures" angle="radian" autolimits="true" balanceinertia="true" boundmass="0.000001" boundinertia="0.000001"/>
	<default>
		<default class="visual">
			<geom contype="0" conaffinity="0"/>
		</default>
		<default class="collision">
			<geom rgba="1.0 0.0 0.0 0.0"/>
		</default>
	</default>
	<asset>
		<mesh name="z1_Link00" file="stl/z1_Link00.stl" scale="1.0 1.0 1.0"/>
		<mesh name="z1_Link01" file="stl/z1_Link01.stl" scale="1.0 1.0 1.0"/>
		<mesh name="z1_Link02" file="stl/z1_Link02.stl" scale="1.0 1.0 1.0"/>
		<mesh name="z1_Link03" file="stl/z1_Link03.stl" scale="1.0 1.0 1.0"/>
		<mesh name="z1_Link04" file="stl/z1_Link04.stl" scale="1.0 1.0 1.0"/>
		<mesh name="z1_Link05" file="stl/z1_Link05.stl" scale="1.0 1.0 1.0"/>
		<mesh name="z1_Link06" file="stl/z1_Link06.stl" scale="1.0 1.0 1.0"/>
	</asset>
	<worldbody>
		<body name="z1" pos="0.0 0.0 0.0" quat="1.0 0.0 0.0 0.0">
			<body name="link00" pos="0.0 0.0 0.0" quat="1.0 0.0 0.0 0.0">
				<geom name="Geom_0" type="mesh" pos="-0.005520758684724569 1.8631500608989882e-07 0.0215991772711277" quat="1.0212026609224267e-05 0.680168092250824 -1.1006088243448175e-05 0.7330561876296997" mesh="z1_Link00" class="visual"/>
				<geom name="Geom_1" type="cylinder" pos="0.0 0.0 0.025499999523162842" quat="1.0 0.0 0.0 0.0" size="0.032499998807907104 0.025499999523162842 0.0" class="collision"/>
				<body name="link01" pos="0.0 0.0 0.05849999934434891" quat="1.0 0.0 0.0 0.0">
					<inertial mass="0.6733260154724121" pos="2.4700000267330324e-06 -0.00025198000366799533 0.023171700537204742" quat="0.7085776925086975 0.7056326866149902 0.00028146186377853155 -0.00035592683707363904" diaginertia="0.001283279969356954 0.0008393619791604578 0.0007193079800345004"/>
					<geom name="Geom_2" type="mesh" pos="-1.1448399561686529e-08 1.5960639032641666e-08 0.02298690192401409" quat="0.5 0.5 -0.5 0.5" mesh="z1_Link01" class="visual"/>
					<joint name="joint1" type="hinge" pos="0.0 0.0 0.0" range="-2.617990016937256 2.617990016937256" axis="0.0 0.0 1.0"/>
					<body name="link02" pos="0.0 0.0 0.04500000178813934" quat="1.0 0.0 0.0 0.0">
						<inertial mass="1.1913199424743652" pos="-0.11012600362300873 0.002400289988145232 0.0015826600138098001" quat="0.0074805766344070435 0.7070916891098022 -0.011447294615209103 0.7069896459579468" diaginertia="0.024661200121045113 0.024311300367116928 0.001004679943434894"/>
						<geom name="Geom_3" type="mesh" pos="-0.12055718153715134 0.0042074634693562984 -1.9866467937390553e-06" quat="0.019285952672362328 0.7068355083465576 -0.01935543678700924 0.7068500518798828" mesh="z1_Link02" class="visual"/>
						<geom name="Geom_4" type="cylinder" pos="0.0 0.0 0.0" quat="0.7071067690849304 0.7071067690849304 0.0 0.0" size="0.032499998807907104 0.050999999046325684 0.0" class="collision"/>
						<geom name="Geom_5" type="cylinder" pos="-0.16249999403953552 0.0 0.0" quat="0.7071067690849304 0.0 0.7071067690849304 0.0" size="0.02250000089406967 0.11749999970197678 0.0" class="collision"/>
						<geom name="Geom_6" type="cylinder" pos="-0.3499999940395355 0.0 0.0" quat="0.7071067690849304 0.7071067690849304 0.0 0.0" size="0.032499998807907104 0.025499999523162842 0.0" class="collision"/>
						<joint name="joint2" type="hinge" pos="0.0 0.0 0.0" range="0.0 2.967060089111328" axis="0.0 1.0 0.0"/>
						<body name="link03" pos="-0.3499999940395355 0.0 0.0" quat="1.0 0.0 0.0 0.0">
							<inertial mass="0.8394089937210083" pos="0.10609199851751328 -0.005418150220066309 0.03476380184292793" quat="0.5405570864677429 0.44357505440711975 0.42631906270980835 0.5738390684127808" diaginertia="0.009543649852275848 0.009387110359966755 0.0005584320169873536"/>
							<geom name="Geom_7" type="mesh" pos="0.1013498529791832 -0.005292060319334269 0.03454930707812309" quat="0.570032000541687 0.4204105734825134 0.453186959028244 0.5412393808364868" mesh="z1_Link03" class="visual"/>
							<geom name="Geom_8" type="cylinder" pos="0.12800000607967377 0.0 0.054999999701976776" quat="0.7071067690849304 0.0 0.7071067690849304 0.0" size="0.019999999552965164 0.057999998331069946 0.0" class="collision"/>
							<geom name="Geom_9" type="cylinder" pos="0.22050000727176666 0.0 0.054999999701976776" quat="0.5 -0.5 0.5 0.5" size="0.032499998807907104 0.029500000178813934 0.0" class="collision"/>
							<joint name="joint3" type="hinge" pos="0.0 0.0 0.0" range="-2.8797900676727295 0.0" axis="0.0 1.0 0.0"/>
							<body name="link04" pos="0.21799999475479126 0.0 0.05700000002980232" quat="1.0 0.0 0.0 0.0">
								<inertial mass="0.5640460252761841" pos="0.04366679862141609 0.003647380042821169 -0.0017019199440255761" quat="0.03908350318670273 0.7264450192451477 -0.05267870053648949 0.6840870380401611" diaginertia="0.0009816560195758939 0.0009405299788340926 0.0003026550111826509"/>
								<geom name="Geom_10" type="mesh" pos="0.05102463439106941 0.007050307933241129 -0.005275116767734289" quat="0.5692657232284546 0.5872085094451904 0.44356632232666016 0.3665674030780792" mesh="z1_Link04" class="visual"/>
								<geom name="Geom_11" type="cylinder" pos="0.07199999690055847 0.0 0.0" quat="1.0 0.0 0.0 0.0" size="0.032499998807907104 0.03350000083446503 0.0" class="collision"/>
								<joint name="joint4" type="hinge" pos="0.0 0.0 0.0" range="-1.5184400081634521 1.5184400081634521" axis="0.0 1.0 0.0"/>
								<body name="link05" pos="0.07000000029802322 0.0 0.0" quat="1.0 0.0 0.0 0.0">
									<inertial mass="0.38938501477241516" pos="0.031215300783514977 0.0 0.006463159807026386" quat="0.46220502257347107 0.535209059715271 0.537850022315979 0.4589500427246094" diaginertia="0.0005589610082097352 0.0005473169730976224 0.0001673319929977879"/>
									<geom name="Geom_12" type="mesh" pos="0.022277723997831345 3.547329470166005e-07 0.01343035139143467" quat="-7.903884579718579e-06 0.8913171887397766 9.391856110596564e-06 0.4533802568912506" mesh="z1_Link05" class="visual"/>
									<joint name="joint5" type="hinge" pos="0.0 0.0 0.0" range="-1.3438999652862549 1.3438999652862549" axis="0.0 0.0 1.0"/>
									<body name="link06" pos="0.04919999837875366 0.0 0.0" quat="1.0 0.0 0.0 0.0">
										<inertial mass="0.2887580096721649" pos="0.024156900122761726 -0.0001735499972710386 -0.0014387599658221006" quat="0.9987789988517761 0.04577350243926048 -0.0066371699795126915 0.017354801297187805" diaginertia="0.0001833300048019737 0.00014746400120202452 0.00014678599836770445"/>
										<geom name="Geom_13" type="mesh" pos="0.024687860161066055 4.7171302867354825e-05 1.948836143128574e-05" quat="0.5553708076477051 0.8315573930740356 -0.004831449128687382 -0.007229561917483807" mesh="z1_Link06" class="visual"/>
										<geom name="Geom_14" type="cylinder" pos="0.025499999523162842 0.0 0.0" quat="0.7071067690849304 0.0 0.7071067690849304 0.0" size="0.032499998807907104 0.025499999523162842 0.0" class="collision"/>
										<joint name="joint6" type="hinge" pos="0.0 0.0 0.0" range="-2.792530059814453 2.792530059814453" axis="1.0 0.0 0.0"/>
									</body>
								</body>
							</body>
						</body>
					</body>
				</body>
			</body>
		</body>
	</worldbody>
	<equality/>
</mujoco>
