<?xml version="1.0" ?>
<robot name="iiwa14" version="1.0">
  <link name="iiwa14"/>
  <joint name="base_joint" type="fixed">
    <origin xyz="0.0 0.0 0.0" rpy="0.0 0.0 0.0"/>
    <parent link="iiwa14"/>
    <child link="base"/>
  </joint>
  <link name="base">
    <visual name="Geom_0">
      <origin xyz="-0.012611671350896358 -3.254423290854902e-07 0.07039070874452591" rpy="-3.1406335830688477 -1.4930812120437622 -0.0008893658523447812"/>
      <geometry>
        <mesh filename="file://iiwa14/meshes/obj/link_0.obj" scale="1.0 1.0 1.0"/>
      </geometry>
    </visual>
    <collision name="Geom_1">
      <origin xyz="0.0 0.0 0.029999999329447746" rpy="0.0 0.0 0.0"/>
      <geometry>
        <sphere radius="0.11999999731779099"/>
      </geometry>
    </collision>
    <collision name="Geom_2">
      <origin xyz="-0.07999999821186066 0.0 0.10300000011920929" rpy="0.0 0.0 0.0"/>
      <geometry>
        <sphere radius="0.07999999821186066"/>
      </geometry>
    </collision>
    <collision name="Geom_3">
      <origin xyz="-0.07999999821186066 0.0 0.03999999910593033" rpy="0.0 0.0 0.0"/>
      <geometry>
        <sphere radius="0.07999999821186066"/>
      </geometry>
    </collision>
    <collision name="Geom_4">
      <origin xyz="0.0 0.0 0.14000000059604645" rpy="0.0 0.0 0.0"/>
      <geometry>
        <sphere radius="0.10000000149011612"/>
      </geometry>
    </collision>
  </link>
  <joint name="joint1" type="revolute">
    <origin xyz="0.0 0.0 0.1574999988079071" rpy="0.0 0.0 0.0"/>
    <axis xyz="0.0 0.0 1.0"/>
    <parent link="base"/>
    <child link="link1"/>
    <limit effort="1000.0" lower="-2.967060089111328" upper="2.967060089111328" velocity="1000.0"/>
  </joint>
  <link name="link1">
    <inertial>
      <origin xyz="0.0 -0.029999999329447746 0.11999999731779099" rpy="0.0 0.0 0.0"/>
      <mass value="5.760000228881836"/>
      <inertia ixx="0.0333000011742115" ixy="0.0" ixz="0.0" iyy="0.032999999821186066" iyz="0.0" izz="0.012299999594688416"/>
    </inertial>
    <visual name="Geom_5">
      <origin xyz="-1.9467224774416536e-06 -0.0335107184946537 0.1230739951133728" rpy="-5.698467430192977e-05 -0.2150438129901886 1.570967674255371"/>
      <geometry>
        <mesh filename="file://iiwa14/meshes/obj/link_1.obj" scale="1.0 1.0 1.0"/>
      </geometry>
    </visual>
    <collision name="Geom_6">
      <origin xyz="0.0 0.0 -0.0005000000237487257" rpy="0.0 0.0 0.0"/>
      <geometry>
        <sphere radius="0.07999999821186066"/>
      </geometry>
    </collision>
    <collision name="Geom_7">
      <origin xyz="0.009999999776482582 -0.02500000037252903 0.042500000447034836" rpy="0.0 0.0 0.0"/>
      <geometry>
        <sphere radius="0.07500000298023224"/>
      </geometry>
    </collision>
    <collision name="Geom_8">
      <origin xyz="-0.009999999776482582 -0.02500000037252903 0.042500000447034836" rpy="0.0 0.0 0.0"/>
      <geometry>
        <sphere radius="0.07500000298023224"/>
      </geometry>
    </collision>
    <collision name="Geom_9">
      <origin xyz="0.009999999776482582 -0.04500000178813934 0.10249999910593033" rpy="0.0 0.0 0.0"/>
      <geometry>
        <sphere radius="0.07000000029802322"/>
      </geometry>
    </collision>
    <collision name="Geom_10">
      <origin xyz="-0.009999999776482582 -0.04500000178813934 0.10249999910593033" rpy="0.0 0.0 0.0"/>
      <geometry>
        <sphere radius="0.07000000029802322"/>
      </geometry>
    </collision>
  </link>
  <joint name="joint2" type="revolute">
    <origin xyz="0.0 0.0 0.20250000059604645" rpy="1.5707963705062866 0.0 3.1415927410125732"/>
    <axis xyz="0.0 0.0 1.0"/>
    <parent link="link1"/>
    <child link="link2"/>
    <limit effort="1000.0" lower="-2.094399929046631" upper="2.094399929046631" velocity="1000.0"/>
  </joint>
  <link name="link2">
    <inertial>
      <origin xyz="0.0003000000142492354 0.05900000035762787 0.041999999433755875" rpy="1.5707963705062866 0.0 3.1415927410125732"/>
      <mass value="6.349999904632568"/>
      <inertia ixx="0.030500000342726707" ixy="0.0" ixz="0.0" iyy="0.030400000512599945" iyz="0.0" izz="0.010999999940395355"/>
    </inertial>
    <visual name="Geom_11">
      <origin xyz="5.833200248162029e-06 -0.0013649110915139318 0.08664810657501221" rpy="-3.141308546066284 -1.366133451461792 -1.570965051651001"/>
      <geometry>
        <mesh filename="file://iiwa14/meshes/obj/link_2_orange.obj" scale="1.0 1.0 1.0"/>
      </geometry>
    </visual>
    <visual name="Geom_12">
      <origin xyz="0.0004379349120426923 0.10289616882801056 0.015210239216685295" rpy="0.0016578161157667637 -1.5322290658950806 1.5691157579421997"/>
      <geometry>
        <mesh filename="file://iiwa14/meshes/obj/link_2_grey.obj" scale="1.0 1.0 1.0"/>
      </geometry>
    </visual>
    <collision name="Geom_13">
      <origin xyz="0.0 0.0 -0.009999999776482582" rpy="0.0 0.0 0.0"/>
      <geometry>
        <sphere radius="0.0949999988079071"/>
      </geometry>
    </collision>
    <collision name="Geom_14">
      <origin xyz="0.0 0.0 0.04500000178813934" rpy="0.0 0.0 0.0"/>
      <geometry>
        <sphere radius="0.09000000357627869"/>
      </geometry>
    </collision>
    <collision name="Geom_15">
      <origin xyz="-0.009999999776482582 0.03999999910593033 0.05400000140070915" rpy="0.0 0.0 0.0"/>
      <geometry>
        <sphere radius="0.07000000029802322"/>
      </geometry>
    </collision>
    <collision name="Geom_16">
      <origin xyz="-0.009999999776482582 0.09000000357627869 0.03999999910593033" rpy="0.0 0.0 0.0"/>
      <geometry>
        <sphere radius="0.06499999761581421"/>
      </geometry>
    </collision>
    <collision name="Geom_17">
      <origin xyz="-0.009999999776482582 0.12999999523162842 0.019999999552965164" rpy="0.0 0.0 0.0"/>
      <geometry>
        <sphere radius="0.06499999761581421"/>
      </geometry>
    </collision>
    <collision name="Geom_18">
      <origin xyz="0.009999999776482582 0.03999999910593033 0.05400000140070915" rpy="0.0 0.0 0.0"/>
      <geometry>
        <sphere radius="0.07000000029802322"/>
      </geometry>
    </collision>
    <collision name="Geom_19">
      <origin xyz="0.009999999776482582 0.09000000357627869 0.03999999910593033" rpy="0.0 0.0 0.0"/>
      <geometry>
        <sphere radius="0.06499999761581421"/>
      </geometry>
    </collision>
    <collision name="Geom_20">
      <origin xyz="0.009999999776482582 0.12999999523162842 0.019999999552965164" rpy="0.0 0.0 0.0"/>
      <geometry>
        <sphere radius="0.06499999761581421"/>
      </geometry>
    </collision>
    <collision name="Geom_21">
      <origin xyz="0.0 0.18000000715255737 0.0" rpy="0.0 0.0 0.0"/>
      <geometry>
        <sphere radius="0.07500000298023224"/>
      </geometry>
    </collision>
  </link>
  <joint name="joint3" type="revolute">
    <origin xyz="0.0 0.2045000046491623 1.232595164407831e-32" rpy="1.5707963705062866 0.0 3.1415927410125732"/>
    <axis xyz="0.0 0.0 1.0"/>
    <parent link="link2"/>
    <child link="link3"/>
    <limit effort="1000.0" lower="-2.967060089111328" upper="2.967060089111328" velocity="1000.0"/>
  </joint>
  <link name="link3">
    <inertial>
      <origin xyz="0.0 0.029999999329447746 0.12999999523162842" rpy="0.0 0.0 0.0"/>
      <mass value="3.5"/>
      <inertia ixx="0.02500000037252903" ixy="0.0" ixz="0.0" iyy="0.023800000548362732" iyz="0.0" izz="0.007600000128149986"/>
    </inertial>
    <visual name="Geom_22">
      <origin xyz="1.407883019055589e-06 0.03297119960188866 0.13639560341835022" rpy="0.0029218513518571854 0.23613841831684113 1.5832918882369995"/>
      <geometry>
        <mesh filename="file://iiwa14/meshes/obj/link_3.obj" scale="1.0 1.0 1.0"/>
      </geometry>
    </visual>
    <visual name="Geom_23">
      <origin xyz="-3.5052686143899336e-05 -1.8385724615654908e-05 0.016549965366721153" rpy="-2.9053919315338135 -1.570749044418335 -0.17498014867305756"/>
      <geometry>
        <mesh filename="file://iiwa14/meshes/obj/band.obj" scale="1.0 1.0 1.0"/>
      </geometry>
    </visual>
    <visual name="Geom_24">
      <origin xyz="1.0515899475649348e-06 -2.8647250474023167e-06 0.01613546535372734" rpy="-1.5399794578552246 -1.5707378387451172 -3.1130802631378174"/>
      <geometry>
        <mesh filename="file://iiwa14/meshes/obj/kuka.obj" scale="1.0 1.0 1.0"/>
      </geometry>
    </visual>
    <collision name="Geom_25">
      <origin xyz="0.0 0.0 0.03550000116229057" rpy="0.0 0.0 0.0"/>
      <geometry>
        <sphere radius="0.07500000298023224"/>
      </geometry>
    </collision>
    <collision name="Geom_26">
      <origin xyz="0.009999999776482582 0.023000000044703484 0.08550000190734863" rpy="0.0 0.0 0.0"/>
      <geometry>
        <sphere radius="0.05999999865889549"/>
      </geometry>
    </collision>
    <collision name="Geom_27">
      <origin xyz="0.009999999776482582 0.04800000041723251 0.12549999356269836" rpy="0.0 0.0 0.0"/>
      <geometry>
        <sphere radius="0.054999999701976776"/>
      </geometry>
    </collision>
    <collision name="Geom_28">
      <origin xyz="0.009999999776482582 0.0560000017285347 0.17550000548362732" rpy="0.0 0.0 0.0"/>
      <geometry>
        <sphere radius="0.05999999865889549"/>
      </geometry>
    </collision>
    <collision name="Geom_29">
      <origin xyz="-0.009999999776482582 0.023000000044703484 0.08550000190734863" rpy="0.0 0.0 0.0"/>
      <geometry>
        <sphere radius="0.05999999865889549"/>
      </geometry>
    </collision>
    <collision name="Geom_30">
      <origin xyz="-0.009999999776482582 0.04800000041723251 0.12549999356269836" rpy="0.0 0.0 0.0"/>
      <geometry>
        <sphere radius="0.054999999701976776"/>
      </geometry>
    </collision>
    <collision name="Geom_31">
      <origin xyz="-0.009999999776482582 0.0560000017285347 0.17550000548362732" rpy="0.0 0.0 0.0"/>
      <geometry>
        <sphere radius="0.05999999865889549"/>
      </geometry>
    </collision>
    <collision name="Geom_32">
      <origin xyz="0.0 0.04500000178813934 0.21549999713897705" rpy="0.0 0.0 0.0"/>
      <geometry>
        <sphere radius="0.07500000298023224"/>
      </geometry>
    </collision>
    <collision name="Geom_33">
      <origin xyz="0.0 0.0 0.21549999713897705" rpy="0.0 0.0 0.0"/>
      <geometry>
        <sphere radius="0.07500000298023224"/>
      </geometry>
    </collision>
  </link>
  <joint name="joint4" type="revolute">
    <origin xyz="0.0 -2.465190328815662e-32 0.21549999713897705" rpy="1.5707963705062866 0.0 0.0"/>
    <axis xyz="0.0 0.0 1.0"/>
    <parent link="link3"/>
    <child link="link4"/>
    <limit effort="1000.0" lower="-2.094399929046631" upper="2.094399929046631" velocity="1000.0"/>
  </joint>
  <link name="link4">
    <inertial>
      <origin xyz="0.0 0.06700000166893005 0.03400000184774399" rpy="1.5707963705062866 0.0 0.0"/>
      <mass value="3.5"/>
      <inertia ixx="0.017000000923871994" ixy="0.0" ixz="0.0" iyy="0.01640000008046627" iyz="0.0" izz="0.006000000052154064"/>
    </inertial>
    <visual name="Geom_34">
      <origin xyz="4.824970801564632e-06 0.00796885509043932 0.07976153492927551" rpy="3.1414122581481934 -1.3520160913467407 -1.570831298828125"/>
      <geometry>
        <mesh filename="file://iiwa14/meshes/obj/link_4_orange.obj" scale="1.0 1.0 1.0"/>
      </geometry>
    </visual>
    <visual name="Geom_35">
      <origin xyz="-7.19085733180691e-07 0.09924633800983429 0.012969840317964554" rpy="0.0023581574205309153 -1.5072370767593384 1.5684106349945068"/>
      <geometry>
        <mesh filename="file://iiwa14/meshes/obj/link_4_grey.obj" scale="1.0 1.0 1.0"/>
      </geometry>
    </visual>
    <collision name="Geom_36">
      <origin xyz="0.0 0.009999999776482582 0.04600000008940697" rpy="0.0 0.0 0.0"/>
      <geometry>
        <sphere radius="0.07800000160932541"/>
      </geometry>
    </collision>
    <collision name="Geom_37">
      <origin xyz="0.009999999776482582 0.05999999865889549 0.052000001072883606" rpy="0.0 0.0 0.0"/>
      <geometry>
        <sphere radius="0.05999999865889549"/>
      </geometry>
    </collision>
    <collision name="Geom_38">
      <origin xyz="0.009999999776482582 0.11999999731779099 0.03400000184774399" rpy="0.0 0.0 0.0"/>
      <geometry>
        <sphere radius="0.06499999761581421"/>
      </geometry>
    </collision>
    <collision name="Geom_39">
      <origin xyz="-0.009999999776482582 0.05999999865889549 0.052000001072883606" rpy="0.0 0.0 0.0"/>
      <geometry>
        <sphere radius="0.05999999865889549"/>
      </geometry>
    </collision>
    <collision name="Geom_40">
      <origin xyz="-0.009999999776482582 0.11999999731779099 0.03400000184774399" rpy="0.0 0.0 0.0"/>
      <geometry>
        <sphere radius="0.06499999761581421"/>
      </geometry>
    </collision>
    <collision name="Geom_41">
      <origin xyz="0.0 0.18400000035762787 0.0" rpy="0.0 0.0 0.0"/>
      <geometry>
        <sphere radius="0.07500000298023224"/>
      </geometry>
    </collision>
  </link>
  <joint name="joint5" type="revolute">
    <origin xyz="0.0 0.18449999392032623 0.0" rpy="1.5707963705062866 0.0 3.1415927410125732"/>
    <axis xyz="0.0 0.0 1.0"/>
    <parent link="link4"/>
    <child link="link5"/>
    <limit effort="1000.0" lower="-2.967060089111328" upper="2.967060089111328" velocity="1000.0"/>
  </joint>
  <link name="link5">
    <inertial>
      <origin xyz="9.999999747378752e-05 0.020999999716877937 0.07599999755620956" rpy="0.0 0.0 0.0"/>
      <mass value="3.5"/>
      <inertia ixx="0.009999999776482582" ixy="0.0" ixz="0.0" iyy="0.008700000122189522" iyz="0.0" izz="0.004490000195801258"/>
    </inertial>
    <visual name="Geom_42">
      <origin xyz="0.0038119491655379534 0.02870779298245907 0.09361015260219574" rpy="-0.058285512030124664 0.4061814844608307 1.5076634883880615"/>
      <geometry>
        <mesh filename="file://iiwa14/meshes/obj/link_5.obj" scale="1.0 1.0 1.0"/>
      </geometry>
    </visual>
    <visual name="Geom_43">
      <origin xyz="-3.5052686143899336e-05 -1.8385724615654908e-05 0.016549965366721153" rpy="-2.9053919315338135 -1.570749044418335 -0.17498014867305756"/>
      <geometry>
        <mesh filename="file://iiwa14/meshes/obj/band.obj" scale="1.0 1.0 1.0"/>
      </geometry>
    </visual>
    <visual name="Geom_44">
      <origin xyz="1.0515899475649348e-06 -2.8647250474023167e-06 0.01613546535372734" rpy="-1.5399794578552246 -1.5707378387451172 -3.1130802631378174"/>
      <geometry>
        <mesh filename="file://iiwa14/meshes/obj/kuka.obj" scale="1.0 1.0 1.0"/>
      </geometry>
    </visual>
    <collision name="Geom_45">
      <origin xyz="0.0 0.0 0.03350000083446503" rpy="0.0 0.0 0.0"/>
      <geometry>
        <sphere radius="0.07500000298023224"/>
      </geometry>
    </collision>
    <collision name="Geom_46">
      <origin xyz="-0.012000000104308128 0.03099999949336052 0.0754999965429306" rpy="0.0 0.0 0.0"/>
      <geometry>
        <sphere radius="0.05000000074505806"/>
      </geometry>
    </collision>
    <collision name="Geom_47">
      <origin xyz="0.012000000104308128 0.03099999949336052 0.0754999965429306" rpy="0.0 0.0 0.0"/>
      <geometry>
        <sphere radius="0.05000000074505806"/>
      </geometry>
    </collision>
    <collision name="Geom_48">
      <origin xyz="-0.012000000104308128 0.05999999865889549 0.11550000309944153" rpy="0.0 0.0 0.0"/>
      <geometry>
        <sphere radius="0.03999999910593033"/>
      </geometry>
    </collision>
    <collision name="Geom_49">
      <origin xyz="0.012000000104308128 0.05999999865889549 0.11550000309944153" rpy="0.0 0.0 0.0"/>
      <geometry>
        <sphere radius="0.03999999910593033"/>
      </geometry>
    </collision>
    <collision name="Geom_50">
      <origin xyz="-0.009999999776482582 0.06499999761581421 0.1655000001192093" rpy="0.0 0.0 0.0"/>
      <geometry>
        <sphere radius="0.03999999910593033"/>
      </geometry>
    </collision>
    <collision name="Geom_51">
      <origin xyz="0.009999999776482582 0.06499999761581421 0.1655000001192093" rpy="0.0 0.0 0.0"/>
      <geometry>
        <sphere radius="0.03999999910593033"/>
      </geometry>
    </collision>
    <collision name="Geom_52">
      <origin xyz="-0.012000000104308128 0.06499999761581421 0.18549999594688416" rpy="0.0 0.0 0.0"/>
      <geometry>
        <sphere radius="0.03500000014901161"/>
      </geometry>
    </collision>
    <collision name="Geom_53">
      <origin xyz="0.012000000104308128 0.06499999761581421 0.18549999594688416" rpy="0.0 0.0 0.0"/>
      <geometry>
        <sphere radius="0.03500000014901161"/>
      </geometry>
    </collision>
  </link>
  <joint name="joint6" type="revolute">
    <origin xyz="0.0 -7.395570986446986e-32 0.21549999713897705" rpy="1.5707963705062866 0.0 0.0"/>
    <axis xyz="0.0 0.0 1.0"/>
    <parent link="link5"/>
    <child link="link6"/>
    <limit effort="1000.0" lower="-2.094399929046631" upper="2.094399929046631" velocity="1000.0"/>
  </joint>
  <link name="link6">
    <inertial>
      <origin xyz="0.0 0.0006000000284984708 0.00039999998989515007" rpy="1.5707963705062866 0.0 0.0"/>
      <mass value="1.7999999523162842"/>
      <inertia ixx="0.004900000058114529" ixy="0.0" ixz="0.0" iyy="0.004699999932199717" iyz="0.0" izz="0.003599999938160181"/>
    </inertial>
    <visual name="Geom_54">
      <origin xyz="-1.1731925724234316e-06 -0.032810576260089874 0.025841152295470238" rpy="3.1404471397399902 -1.0516465902328491 -1.5709595680236816"/>
      <geometry>
        <mesh filename="file://iiwa14/meshes/obj/link_6_orange.obj" scale="1.0 1.0 1.0"/>
      </geometry>
    </visual>
    <visual name="Geom_55">
      <origin xyz="-4.166903636360075e-06 0.029530277475714684 -0.02136475406587124" rpy="3.1413655281066895 -0.9534988403320312 -1.5706843137741089"/>
      <geometry>
        <mesh filename="file://iiwa14/meshes/obj/link_6_grey.obj" scale="1.0 1.0 1.0"/>
      </geometry>
    </visual>
    <collision name="Geom_56">
      <origin xyz="0.0 0.0 -0.05900000035762787" rpy="0.0 0.0 0.0"/>
      <geometry>
        <sphere radius="0.054999999701976776"/>
      </geometry>
    </collision>
    <collision name="Geom_57">
      <origin xyz="0.0 -0.029999999329447746 0.010999999940395355" rpy="0.0 0.0 0.0"/>
      <geometry>
        <sphere radius="0.06499999761581421"/>
      </geometry>
    </collision>
    <collision name="Geom_58">
      <origin xyz="0.0 0.0 0.0" rpy="0.0 0.0 0.0"/>
      <geometry>
        <sphere radius="0.07999999821186066"/>
      </geometry>
    </collision>
  </link>
  <joint name="joint7" type="revolute">
    <origin xyz="0.0 0.08100000023841858 0.0" rpy="1.5707963705062866 0.0 3.1415927410125732"/>
    <axis xyz="0.0 0.0 1.0"/>
    <parent link="link6"/>
    <child link="link7"/>
    <limit effort="1000.0" lower="-3.0543298721313477" upper="3.0543298721313477" velocity="1000.0"/>
  </joint>
  <link name="link7">
    <inertial>
      <origin xyz="0.0 0.0 0.019999999552965164" rpy="0.0 0.0 0.0"/>
      <mass value="1.2000000476837158"/>
      <inertia ixx="0.0010000000474974513" ixy="0.0" ixz="0.0" iyy="0.0010000000474974513" iyz="0.0" izz="0.0010000000474974513"/>
    </inertial>
    <visual name="Geom_59">
      <origin xyz="-9.661049261922017e-06 -9.153581572718394e-07 0.01686968095600605" rpy="1.5715276002883911 -1.5704054832458496 0.0"/>
      <geometry>
        <mesh filename="file://iiwa14/meshes/obj/link_7.obj" scale="1.0 1.0 1.0"/>
      </geometry>
    </visual>
    <collision name="Geom_60">
      <origin xyz="0.0 0.0 0.0010000000474974513" rpy="0.0 0.0 0.0"/>
      <geometry>
        <sphere radius="0.05999999865889549"/>
      </geometry>
    </collision>
  </link>
</robot>