<?xml version="1.0" ?>
<mujoco model="armar6">
	<compiler meshdir="armar6/meshes" texturedir="armar6/textures" angle="radian" autolimits="true" balanceinertia="true" boundmass="0.000001" boundinertia="0.000001"/>
	<default>
		<default class="visual">
			<geom contype="0" conaffinity="0"/>
		</default>
		<default class="collision">
			<geom rgba="0.9 0.9 0.9 1.0"/>
		</default>
	</default>
	<asset>
		<mesh name="platform_01" file="stl/platform_01.stl" scale="1.0 1.0 1.0"/>
		<mesh name="platform_02" file="stl/platform_02.stl" scale="1.0 1.0 1.0"/>
		<mesh name="platform_03" file="stl/platform_03.stl" scale="1.0 1.0 1.0"/>
		<mesh name="platform_04" file="stl/platform_04.stl" scale="1.0 1.0 1.0"/>
		<mesh name="platform_05" file="stl/platform_05.stl" scale="1.0 1.0 1.0"/>
		<mesh name="platform_06" file="stl/platform_06.stl" scale="1.0 1.0 1.0"/>
		<mesh name="platform_07" file="stl/platform_07.stl" scale="1.0 1.0 1.0"/>
		<mesh name="platform_08" file="stl/platform_08.stl" scale="1.0 1.0 1.0"/>
		<mesh name="platform_09" file="stl/platform_09.stl" scale="1.0 1.0 1.0"/>
		<mesh name="torso_1" file="stl/torso_1.stl" scale="1.0 1.0 1.0"/>
		<mesh name="torso_2" file="stl/torso_2.stl" scale="1.0 1.0 1.0"/>
		<mesh name="torso_3" file="stl/torso_3.stl" scale="1.0 1.0 1.0"/>
		<mesh name="torso_4" file="stl/torso_4.stl" scale="1.0 1.0 1.0"/>
		<mesh name="Mesh_2h09010_arml_cla" file="stl/Mesh_2h09010_arml_cla.stl" scale="1.0 1.0 1.0"/>
		<mesh name="Mesh_6a11000_halsbasis_t1" file="stl/Mesh_6a11000_halsbasis_t1.stl" scale="1.0 1.0 1.0"/>
		<mesh name="Mesh_2h09020_arml_t12" file="stl/Mesh_2h09020_arml_t12.stl" scale="1.0 1.0 1.0"/>
		<mesh name="Mesh_2h09030_arml_t23" file="stl/Mesh_2h09030_arml_t23.stl" scale="1.0 1.0 1.0"/>
		<mesh name="Mesh_2h09040_arml_t34" file="stl/Mesh_2h09040_arml_t34.stl" scale="1.0 1.0 1.0"/>
		<mesh name="Mesh_2h09050_arml_t45" file="stl/Mesh_2h09050_arml_t45.stl" scale="1.0 1.0 1.0"/>
		<mesh name="Mesh_2h09060_arml_t56_01" file="stl/Mesh_2h09060_arml_t56_01.stl" scale="1.0 1.0 1.0"/>
		<mesh name="Mesh_2h09060_arml_t56_02" file="stl/Mesh_2h09060_arml_t56_02.stl" scale="1.0 1.0 1.0"/>
		<mesh name="Mesh_2h09060_arml_t56_03" file="stl/Mesh_2h09060_arml_t56_03.stl" scale="1.0 1.0 1.0"/>
		<mesh name="Mesh_2h09070_arml_t67_01" file="stl/Mesh_2h09070_arml_t67_01.stl" scale="1.0 1.0 1.0"/>
		<mesh name="Mesh_2h09070_arml_t67_02" file="stl/Mesh_2h09070_arml_t67_02.stl" scale="1.0 1.0 1.0"/>
		<mesh name="Mesh_2h09070_arml_t67_03" file="stl/Mesh_2h09070_arml_t67_03.stl" scale="1.0 1.0 1.0"/>
		<mesh name="Mesh_2h09070_arml_t67_04" file="stl/Mesh_2h09070_arml_t67_04.stl" scale="1.0 1.0 1.0"/>
		<mesh name="Mesh_2h09070_arml_t67_05" file="stl/Mesh_2h09070_arml_t67_05.stl" scale="1.0 1.0 1.0"/>
		<mesh name="Mesh_2h09070_arml_t67_06" file="stl/Mesh_2h09070_arml_t67_06.stl" scale="1.0 1.0 1.0"/>
		<mesh name="Mesh_2h09070_arml_t67_07" file="stl/Mesh_2h09070_arml_t67_07.stl" scale="1.0 1.0 1.0"/>
		<mesh name="Mesh_2h09070_arml_t67_08" file="stl/Mesh_2h09070_arml_t67_08.stl" scale="1.0 1.0 1.0"/>
		<mesh name="Mesh_2h09070_arml_t67_09" file="stl/Mesh_2h09070_arml_t67_09.stl" scale="1.0 1.0 1.0"/>
		<mesh name="Mesh_2h09070_arml_t67_10" file="stl/Mesh_2h09070_arml_t67_10.stl" scale="1.0 1.0 1.0"/>
		<mesh name="Mesh_2h09080_arml_t78" file="stl/Mesh_2h09080_arml_t78.stl" scale="1.0 1.0 1.0"/>
		<mesh name="Mesh_2h09090_arml_t8_01" file="stl/Mesh_2h09090_arml_t8_01.stl" scale="1.0 1.0 1.0"/>
		<mesh name="Mesh_2h09090_arml_t8_02" file="stl/Mesh_2h09090_arml_t8_02.stl" scale="1.0 1.0 1.0"/>
		<mesh name="Mesh_2h09090_arml_t8_03" file="stl/Mesh_2h09090_arml_t8_03.stl" scale="1.0 1.0 1.0"/>
		<mesh name="Mesh_2h09090_arml_t8_04" file="stl/Mesh_2h09090_arml_t8_04.stl" scale="1.0 1.0 1.0"/>
		<mesh name="Mesh_2h09090_arml_t8_05" file="stl/Mesh_2h09090_arml_t8_05.stl" scale="1.0 1.0 1.0"/>
		<mesh name="Mesh_2h09090_arml_t8_06" file="stl/Mesh_2h09090_arml_t8_06.stl" scale="1.0 1.0 1.0"/>
		<mesh name="Mesh_2h09090_arml_t8_07" file="stl/Mesh_2h09090_arml_t8_07.stl" scale="1.0 1.0 1.0"/>
		<mesh name="palm_l" file="stl/palm_l.stl" scale="1.0 1.0 1.0"/>
		<mesh name="index_prox" file="stl/index_prox.stl" scale="1.0 1.0 1.0"/>
		<mesh name="index_inter" file="stl/index_inter.stl" scale="1.0 1.0 1.0"/>
		<mesh name="index_dist" file="stl/index_dist.stl" scale="1.0 1.0 1.0"/>
		<mesh name="middle_prox" file="stl/middle_prox.stl" scale="1.0 1.0 1.0"/>
		<mesh name="middle_inter" file="stl/middle_inter.stl" scale="1.0 1.0 1.0"/>
		<mesh name="middle_dist" file="stl/middle_dist.stl" scale="1.0 1.0 1.0"/>
		<mesh name="pinky_prox" file="stl/pinky_prox.stl" scale="1.0 1.0 1.0"/>
		<mesh name="pinky_inter" file="stl/pinky_inter.stl" scale="1.0 1.0 1.0"/>
		<mesh name="pinky_dist" file="stl/pinky_dist.stl" scale="1.0 1.0 1.0"/>
		<mesh name="ring_prox" file="stl/ring_prox.stl" scale="1.0 1.0 1.0"/>
		<mesh name="ring_inter" file="stl/ring_inter.stl" scale="1.0 1.0 1.0"/>
		<mesh name="ring_dist" file="stl/ring_dist.stl" scale="1.0 1.0 1.0"/>
		<mesh name="thumb_prox" file="stl/thumb_prox.stl" scale="1.0 1.0 1.0"/>
		<mesh name="thumb_dist" file="stl/thumb_dist.stl" scale="1.0 1.0 1.0"/>
		<mesh name="palm_r" file="stl/palm_r.stl" scale="1.0 1.0 1.0"/>
		<mesh name="Mesh_6a12000_halsmitte_t12" file="stl/Mesh_6a12000_halsmitte_t12.stl" scale="1.0 1.0 1.0"/>
		<mesh name="Mesh_6a13000_halsoben_v13" file="stl/Mesh_6a13000_halsoben_v13.stl" scale="1.0 1.0 1.0"/>
	</asset>
	<worldbody>
		<body name="armar6" pos="0.0 0.0 0.0" quat="1.0 0.0 0.0 0.0">
			<geom name="Geom_0" type="mesh" pos="-0.23908907175064087 0.0011418842477723956 0.30750465393066406" quat="0.9987695813179016 -0.00035170995397493243 0.04766320437192917 0.013688200153410435" mesh="platform_01" class="collision"/>
			<geom name="Geom_1" type="mesh" pos="0.20871004462242126 -3.0155450076563284e-05 0.26197001338005066" quat="0.9861933588981628 -0.0011583680752664804 -0.16559343039989471 -0.0002805482072290033" mesh="platform_02" class="collision"/>
			<geom name="Geom_2" type="mesh" pos="6.449293876720219e-11 -1.9112326304915328e-11 0.14333148300647736" quat="0.7071067690849304 0.0 0.0 -0.7071067690849304" mesh="platform_03" class="collision"/>
			<geom name="Geom_3" type="mesh" pos="-2.2915676254342543e-06 -0.18701200187206268 0.298531174659729" quat="0.9986951351165771 -0.05106906592845917 -1.922875344462227e-05 1.3181876056478359e-05" mesh="platform_04" class="collision"/>
			<geom name="Geom_4" type="mesh" pos="9.5631241947558e-07 -0.07499920576810837 0.14335519075393677" quat="0.7071067690849304 1.3158047295291908e-05 -1.2814010688089184e-06 -0.7071067690849304" mesh="platform_05" class="collision"/>
			<geom name="Geom_5" type="mesh" pos="-3.338966735100257e-06 0.18701665103435516 0.298539400100708" quat="0.9986956119537354 0.05105941742658615 -1.5566569345537573e-05 -1.554261689307168e-05" mesh="platform_06" class="collision"/>
			<geom name="Geom_6" type="mesh" pos="-9.563812000124017e-07 0.07499920576810837 0.14335519075393677" quat="0.7071067690849304 -1.3158811270841397e-05 1.2820058827855974e-06 -0.7071067690849304" mesh="platform_07" class="collision"/>
			<geom name="Geom_7" type="mesh" pos="-2.4181961634894833e-05 -0.032434575259685516 0.3921465277671814" quat="0.7069283127784729 -0.0001096158375730738 -0.00024148341617546976 -0.7072851657867432" mesh="platform_08" class="collision"/>
			<geom name="Geom_8" type="mesh" pos="-2.4532324459869415e-05 0.032434575259685516 0.3921465277671814" quat="0.707281768321991 0.0002405394916422665 0.00011056109360652044 -0.7069317102432251" mesh="platform_09" class="collision"/>
			<body name="link0_7" pos="0.0 0.0 1.1950000524520874" quat="0.7071067690849304 0.0 0.0 -0.7071067690849304">
				<inertial mass="42.921875" pos="-8.60810268932255e-06 0.003858802607282996 0.03855016827583313" quat="0.7072494029998779 0.01781361922621727 -0.017727065831422806 0.7065173387527466" diaginertia="0.8874343633651733 0.7422398328781128 0.29746219515800476"/>
				<geom name="Geom_9" type="mesh" pos="-1.1988852747890633e-05 0.005371134728193283 0.02722056210041046" quat="0.7060954570770264 0.04865260049700737 -0.04827491566538811 0.7047919034957886" mesh="torso_1" class="collision"/>
				<geom name="Geom_10" type="mesh" pos="-0.0759999081492424 -0.00012338596570771188 -0.3070000112056732" quat="0.9999999403953552 -0.00039807689609006047 0.0 0.0" mesh="torso_2" class="collision"/>
				<geom name="Geom_11" type="mesh" pos="1.2635163748608846e-10 -0.0002385206607868895 -0.2995902895927429" quat="0.9992132186889648 -0.00039776507765054703 -1.5786925359861925e-05 -0.0396578423678875" mesh="torso_3" class="collision"/>
				<geom name="Geom_12" type="mesh" pos="0.0759999081492424 -0.0003654528991319239 -0.3069998025894165" quat="0.9999999403953552 -0.00039807771099731326 0.0 0.0" mesh="torso_4" class="collision"/>
				<geom name="Geom_13" type="mesh" pos="-0.08103914558887482 -4.163836820225697e-06 0.10412884503602982" quat="0.7049452066421509 0.02882375754415989 0.02880515716969967 0.7080901861190796" mesh="Mesh_2h09010_arml_cla" class="collision"/>
				<geom name="Geom_14" type="mesh" pos="0.08103914558887482 4.151164375798544e-06 0.10412884503602982" quat="0.7080906629562378 0.02880517765879631 -0.028823737055063248 -0.7049447298049927" mesh="Mesh_2h09010_arml_cla" class="collision"/>
				<geom name="Geom_15" type="mesh" pos="5.643061058435705e-07 6.404436021512083e-07 0.24260690808296204" quat="-0.0004728139901999384 0.7071082592010498 0.0004848051758017391 0.7071049809455872" mesh="Mesh_6a11000_halsbasis_t1" class="collision"/>
				<joint name="TorsoJoint" type="slide" pos="0.0 0.0 0.0" range="-0.5 0.5" axis="0.0 0.0 1.0"/>
				<body name="link0_63" pos="0.09000000357627869 3.3058799431273656e-07 0.10000000149011612" quat="0.7071087956428528 0.0 0.0 -0.7071048021316528">
					<inertial mass="4.641332149505615" pos="-1.9983554011560045e-06 0.11062423884868622 0.02188810519874096" quat="0.9445297718048096 -0.32842549681663513 0.00027361296815797687 0.0003834966628346592" diaginertia="0.024549242109060287 0.01810256391763687 0.014694479294121265"/>
					<geom name="Geom_56" type="mesh" pos="-1.9983554011560045e-06 0.11062423884868622 0.02188810519874096" quat="0.9445297718048096 -0.32842549681663513 0.00027361296815797687 0.0003834966628346592" mesh="Mesh_2h09020_arml_t12" class="collision"/>
					<joint name="ArmR1_Cla1" type="hinge" pos="0.0 0.0 0.0" range="0.0 0.0" axis="0.0 0.0 1.0"/>
					<body name="link0_65" pos="0.0 0.28977999091148376 0.07765000313520432" quat="1.0 0.0 0.0 0.0">
						<inertial mass="6.514058589935303" pos="-0.0026242216117680073 0.00547403609380126 0.0014532019849866629" quat="0.41690516471862793 0.561397135257721 0.44454503059387207 0.5598241686820984" diaginertia="0.025567620992660522 0.022996222600340843 0.022928500548005104"/>
						<geom name="Geom_57" type="mesh" pos="-0.0026242216117680073 0.00547403609380126 0.0014532019849866629" quat="0.41690516471862793 0.561397135257721 0.44454503059387207 0.5598241686820984" mesh="Mesh_2h09030_arml_t23" class="collision"/>
						<joint name="ArmR2_Sho1" type="hinge" pos="0.0 0.0 0.0" range="0.0 0.0" axis="0.0 0.9659258723258972 0.25881895422935486"/>
						<body name="link0_67" pos="0.0 0.0 0.0" quat="0.707105278968811 -0.7071082592010498 0.0 0.0">
							<inertial mass="4.186227321624756" pos="0.0031595618929713964 0.11988010257482529 0.009519310668110847" quat="0.6713733077049255 0.20513257384300232 0.6646022200584412 -0.2558952569961548" diaginertia="0.023510094732046127 0.01641996204853058 0.01437942311167717"/>
							<geom name="Geom_58" type="mesh" pos="0.0031595618929713964 0.11988010257482529 0.009519310668110847" quat="0.6713733077049255 0.20513257384300232 0.6646022200584412 -0.2558952569961548" mesh="Mesh_2h09040_arml_t34" class="collision"/>
							<joint name="ArmR3_Sho2" type="hinge" pos="0.0 0.0 0.0" range="0.0 0.0" axis="1.0 0.0 0.0"/>
							<body name="link0_69" pos="0.0 0.0 0.0" quat="0.4999980032444 -0.5000020265579224 -0.5 -0.5">
								<inertial mass="5.494523525238037" pos="-0.0022166140843182802 -0.03205019235610962 0.3651427626609802" quat="0.6883682012557983 0.14456790685653687 -0.16545535624027252 0.6912842392921448" diaginertia="0.033287789672613144 0.03231581673026085 0.01199717540293932"/>
								<geom name="Geom_59" type="mesh" pos="-0.0022166140843182802 -0.03205019235610962 0.3651427626609802" quat="0.6883682012557983 0.14456790685653687 -0.16545535624027252 0.6912842392921448" mesh="Mesh_2h09050_arml_t45" class="collision"/>
								<joint name="ArmR4_Sho3" type="hinge" pos="0.0 0.0 0.0" range="0.0 0.0" axis="0.0 0.0 1.0"/>
								<body name="link0_71" pos="0.0 -0.054999999701976776 0.4090000092983246" quat="1.0 0.0 0.0 0.0">
									<inertial mass="2.7591729164123535" pos="0.0013214589562267065 0.005565263330936432 0.1098216101527214" quat="0.47372815012931824 0.5198296308517456 0.42536303400993347 0.5695832371711731" diaginertia="0.00866414699703455 0.0074538071639835835 0.0066077555529773235"/>
									<geom name="Geom_60" type="mesh" pos="0.001954891486093402 0.005780649837106466 0.11422663927078247" quat="0.6546503901481628 -0.22352944314479828 0.6924439668655396 -0.20491154491901398" mesh="Mesh_2h09060_arml_t56_01" class="collision"/>
									<geom name="Geom_61" type="mesh" pos="0.07322466373443604 0.00026982248527929187 -0.0017227577045559883" quat="0.6577778458595276 0.7531831860542297 0.004401055630296469 -0.004902516957372427" mesh="Mesh_2h09060_arml_t56_02" class="collision"/>
									<geom name="Geom_62" type="mesh" pos="-0.07043138146400452 0.00014143316366244107 0.0009638782357797027" quat="0.16215890645980835 0.9867645502090454 -9.113234409596771e-05 0.00045004638377577066" mesh="Mesh_2h09060_arml_t56_03" class="collision"/>
									<joint name="ArmR5_Elb1" type="hinge" pos="0.0 0.0 0.0" range="0.0 0.0" axis="1.0 0.0 0.0"/>
									<body name="link0_73" pos="0.0 0.0 0.0" quat="1.0 0.0 0.0 0.0">
										<inertial mass="1.323380708694458" pos="-7.264896703418344e-05 0.026484208181500435 0.269603431224823" quat="0.95482337474823 -0.29717233777046204 2.4389843019889668e-05 -0.0009568182867951691" diaginertia="0.007656598463654518 0.006845767144113779 0.003992720041424036"/>
										<geom name="Geom_63" type="mesh" pos="0.04904818907380104 0.0005475301877595484 0.2278057187795639" quat="0.9972087144851685 -0.03267933055758476 0.06708387285470963 0.0025736528914421797" mesh="Mesh_2h09070_arml_t67_01" class="collision"/>
										<geom name="Geom_64" type="mesh" pos="-1.298043006414673e-08 -0.057883650064468384 0.35432007908821106" quat="0.7070271372795105 -0.010613306425511837 0.010614944621920586 0.7070270776748657" mesh="Mesh_2h09070_arml_t67_02" class="collision"/>
										<geom name="Geom_65" type="mesh" pos="-2.5913489025697345e-06 0.07031302154064178 0.3585358262062073" quat="0.7070667743682861 0.006919998209923506 -0.006110544316470623 0.7070865631103516" mesh="Mesh_2h09070_arml_t67_03" class="collision"/>
										<geom name="Geom_66" type="mesh" pos="0.05108014866709709 -0.038606297224760056 0.296926349401474" quat="0.7465304732322693 0.6477420926094055 -0.13063661754131317 -0.07782396674156189" mesh="Mesh_2h09070_arml_t67_04" class="collision"/>
										<geom name="Geom_67" type="mesh" pos="0.04765205830335617 0.04340628162026405 0.2984026074409485" quat="0.5927656888961792 0.7679161429405212 0.028681503608822823 0.24106216430664062" mesh="Mesh_2h09070_arml_t67_05" class="collision"/>
										<geom name="Geom_68" type="mesh" pos="-1.0616304280119948e-06 0.06732528656721115 0.25963494181632996" quat="0.7061805725097656 -0.03628489002585411 0.03611018508672714 0.7061787843704224" mesh="Mesh_2h09070_arml_t67_06" class="collision"/>
										<geom name="Geom_69" type="mesh" pos="5.9854162827832624e-05 -0.05733291059732437 0.24773843586444855" quat="0.7068926095962524 0.01085700187832117 -0.0044671171344816685 0.7072234749794006" mesh="Mesh_2h09070_arml_t67_07" class="collision"/>
										<geom name="Geom_70" type="mesh" pos="-0.04910891503095627 0.00053496373584494 0.22820699214935303" quat="0.997360348701477 -0.028476828709244728 -0.06675867736339569 -0.0021694861352443695" mesh="Mesh_2h09070_arml_t67_08" class="collision"/>
										<geom name="Geom_71" type="mesh" pos="-0.050927359610795975 -0.03914576768875122 0.2969658672809601" quat="0.7477163672447205 0.6452646255493164 0.1306317150592804 0.08653959631919861" mesh="Mesh_2h09070_arml_t67_09" class="collision"/>
										<geom name="Geom_72" type="mesh" pos="-0.04850269854068756 0.042520198971033096 0.29731738567352295" quat="0.6586331725120544 0.7148585319519043 -0.22018752992153168 -0.08183575421571732" mesh="Mesh_2h09070_arml_t67_10" class="collision"/>
										<joint name="ArmR6_Elb2" type="hinge" pos="0.0 0.0 0.0" range="0.0 0.0" axis="0.0 0.0 1.0"/>
										<body name="link0_75" pos="0.0 0.0 0.36399999260902405" quat="1.0 0.0 0.0 0.0">
											<inertial mass="1.1816606521606445" pos="0.0034763282164931297 -0.0012621578061953187 2.2226204237085767e-05" quat="-0.002658423036336899 0.7067897915840149 0.002487173769623041 0.7074142694473267" diaginertia="0.0017266924260184169 0.0015820622211322188 0.0010909022530540824"/>
											<geom name="Geom_73" type="mesh" pos="0.0034763282164931297 -0.0012621578061953187 2.2226204237085767e-05" quat="-0.002658423036336899 0.7067897915840149 0.002487173769623041 0.7074142694473267" mesh="Mesh_2h09080_arml_t78" class="collision"/>
											<joint name="ArmR7_Wri1" type="hinge" pos="0.0 0.0 0.0" range="0.0 0.0" axis="0.0 -1.0 0.0"/>
											<body name="link0_77" pos="0.0 0.0 0.0" quat="0.707105278968811 0.0 0.0 0.7071082592010498">
												<inertial mass="1.64207923412323" pos="-0.0015873624943196774 -0.002150126500055194 0.16746027767658234" quat="0.9993650913238525 -0.016119277104735374 -0.008230193518102169 -0.030689498409628868" diaginertia="0.009214787743985653 0.008054361678659916 0.0020288401283323765"/>
												<geom name="Geom_74" type="mesh" pos="-2.5014254788402468e-05 0.0006606595125049353 0.12186624854803085" quat="0.0006991556729190052 0.7070338129997253 0.001839448930695653 0.7071769833564758" mesh="Mesh_2h09090_arml_t8_01" class="collision"/>
												<geom name="Geom_75" type="mesh" pos="-6.812727804117458e-08 -0.06317408382892609 0.008618473075330257" quat="0.7070921063423157 -0.004724501632153988 0.004725577775388956 0.7070898413658142" mesh="Mesh_2h09090_arml_t8_02" class="collision"/>
												<geom name="Geom_76" type="mesh" pos="2.647066503413953e-05 0.0626370757818222 0.01715272292494774" quat="0.7071325182914734 -0.00035977462539449334 -6.062036118237302e-05 0.7070809602737427" mesh="Mesh_2h09090_arml_t8_03" class="collision"/>
												<geom name="Geom_77" type="mesh" pos="0.0001532769383629784 -0.04166693985462189 0.11673421412706375" quat="0.7026854753494263 -0.07682538777589798 0.1131587103009224 0.6982306838035583" mesh="Mesh_2h09090_arml_t8_04" class="collision"/>
												<geom name="Geom_78" type="mesh" pos="-0.00010127700807061046 0.04261576384305954 0.1163441613316536" quat="0.7026433944702148 0.08241218328475952 -0.10800295323133469 0.6984524726867676" mesh="Mesh_2h09090_arml_t8_05" class="collision"/>
												<geom name="Geom_79" type="mesh" pos="-1.447715362701274e-06 -0.05752373859286308 0.08827167004346848" quat="-0.23531605303287506 0.6667888760566711 -0.2358095496892929 0.666642963886261" mesh="Mesh_2h09090_arml_t8_06" class="collision"/>
												<geom name="Geom_80" type="mesh" pos="7.302030553546501e-07 0.05815986916422844 0.0874510109424591" quat="0.21441951394081116 0.6738195419311523 0.21392442286014557 0.673964262008667" mesh="Mesh_2h09090_arml_t8_07" class="collision"/>
												<geom name="Geom_81" type="mesh" pos="-0.002640562364831567 -0.0018192088464275002 0.21232052147388458" quat="-0.9980687499046326 -0.023030448704957962 -0.0013556501362472773 0.057675667107105255" mesh="palm_r" class="collision"/>
												<joint name="ArmR8_Wri2" type="hinge" pos="0.0 0.0 0.0" range="0.0 0.0" axis="0.0 -1.0 0.0"/>
												<body name="link0_88" pos="7.646550059803303e-09 -0.007499440107494593 0.2917200028896332" quat="0.4999989867210388 -0.5 0.4999989867210388 -0.5000020265579224">
													<inertial mass="0.02538316138088703" pos="-8.225680176110473e-06 -0.030843479558825493 -8.414039621129632e-05" quat="0.5016137957572937 0.4987810552120209 -0.49807825684547424 0.5015168190002441" diaginertia="8.413370778725948e-06 8.243548109021503e-06 1.0851806564460276e-06"/>
													<geom name="Geom_85" type="mesh" pos="-8.225680176110473e-06 -0.030843479558825493 -8.414039621129632e-05" quat="0.5016137957572937 0.4987810552120209 -0.49807825684547424 0.5015168190002441" mesh="middle_prox" class="collision"/>
													<joint name="Middle_R_1_Joint" type="hinge" pos="0.0 0.0 0.0" range="0.0 0.0" axis="1.0 0.0 0.0"/>
													<body name="link0_90" pos="0.0 -0.05999999865889549 0.0" quat="1.0 0.0 0.0 0.0">
														<inertial mass="0.014561756514012814" pos="-3.4415239497320727e-05 -0.018362386152148247 0.00029420116334222257" quat="0.5047402381896973 0.4994126558303833 -0.49391400814056396 0.5018697381019592" diaginertia="2.5808008103922475e-06 2.520335328881629e-06 9.999999974752427e-07"/>
														<geom name="Geom_86" type="mesh" pos="-3.4415239497320727e-05 -0.018362386152148247 0.00029420116334222257" quat="0.5047402381896973 0.4994126558303833 -0.49391400814056396 0.5018697381019592" mesh="middle_inter" class="collision"/>
														<joint name="Middle_R_2_Joint" type="hinge" pos="0.0 0.0 0.0" range="0.0 0.0" axis="1.0 0.0 0.0"/>
														<body name="link0_92" pos="0.0 -0.039000000804662704 0.0" quat="1.0 0.0 0.0 0.0">
															<inertial mass="0.007588660344481468" pos="-1.4801357792748604e-06 -0.009854770265519619 0.00019601777603384107" quat="0.5127883553504944 0.5100603699684143 0.4869072735309601 -0.4897017776966095" diaginertia="9.999999974752427e-07 9.999999974752427e-07 9.999999974752427e-07"/>
															<geom name="Geom_87" type="mesh" pos="-1.4801357792748604e-06 -0.009854770265519619 0.00019601777603384107" quat="0.5127883553504944 0.5100603699684143 0.4869072735309601 -0.4897017776966095" mesh="middle_dist" class="collision"/>
															<joint name="Middle_R_3_Joint" type="hinge" pos="0.0 0.0 0.0" range="0.0 0.0" axis="1.0 0.0 0.0"/>
														</body>
													</body>
												</body>
												<body name="link0_94" pos="-5.638520050865736e-08 0.055300500243902206 0.27031999826431274" quat="-0.39037084579467773 0.5895857810974121 -0.3903718590736389 0.5895837545394897">
													<inertial mass="0.014701016247272491" pos="-1.8761980754788965e-05 -0.02276996523141861 -7.110893056960776e-05" quat="0.5519939661026001 0.5492344498634338 -0.4416252374649048 0.44565823674201965" diaginertia="3.0928017622500192e-06 3.08664630210842e-06 9.999999974752427e-07"/>
													<geom name="Geom_88" type="mesh" pos="-1.8761980754788965e-05 -0.02276996523141861 -7.110893056960776e-05" quat="0.5519939661026001 0.5492344498634338 -0.4416252374649048 0.44565823674201965" mesh="pinky_prox" class="collision"/>
													<joint name="Pinky_R_1_Joint" type="hinge" pos="0.0 0.0 0.0" range="0.0 0.0" axis="1.0 0.0 0.0"/>
													<body name="link0_96" pos="0.0 -0.04610000178217888 0.0" quat="1.0 0.0 0.0 0.0">
														<inertial mass="0.007457030471414328" pos="4.895448000752367e-06 -0.012241008691489697 0.00026062584947794676" quat="0.7138955593109131 0.7002522349357605 -5.2752973715541884e-05 -5.174480611458421e-05" diaginertia="9.999999974752427e-07 9.999999974752427e-07 9.999999974752427e-07"/>
														<geom name="Geom_89" type="mesh" pos="4.895448000752367e-06 -0.012241008691489697 0.00026062584947794676" quat="0.7138955593109131 0.7002522349357605 -5.2752973715541884e-05 -5.174480611458421e-05" mesh="pinky_inter" class="collision"/>
														<joint name="Pinky_R_2_Joint" type="hinge" pos="0.0 0.0 0.0" range="0.0 0.0" axis="1.0 0.0 0.0"/>
														<body name="link0_98" pos="0.0 -0.027060000225901604 0.0" quat="1.0 0.0 0.0 0.0">
															<inertial mass="0.005034840200096369" pos="-5.06505770658805e-08 -0.00826839730143547 0.00011376729526091367" quat="0.0004965564585290849 0.000483532901853323 -0.7065339684486389 0.7076787948608398" diaginertia="9.999999974752427e-07 9.999999974752427e-07 9.999999974752427e-07"/>
															<geom name="Geom_90" type="mesh" pos="-5.06505770658805e-08 -0.00826839730143547 0.00011376729526091367" quat="0.0004965564585290849 0.000483532901853323 -0.7065339684486389 0.7076787948608398" mesh="pinky_dist" class="collision"/>
															<joint name="Pinky_R_3_Joint" type="hinge" pos="0.0 0.0 0.0" range="0.0 0.0" axis="1.0 0.0 0.0"/>
														</body>
													</body>
												</body>
												<body name="link0_100" pos="-5.638520050865736e-08 0.055300500243902206 0.27031999826431274" quat="-0.39037084579467773 0.5895857810974121 -0.3903718590736389 0.5895837545394897">
													<inertial mass="9.999999974752427e-07" pos="-5.638520050865736e-08 0.055300500243902206 0.27031999826431274" quat="-0.39037084579467773 0.5895857810974121 -0.3903718590736389 0.5895837545394897" diaginertia="9.999999974752427e-07 9.999999974752427e-07 9.999999974752427e-07"/>
													<joint name="RightHandFingers" type="hinge" pos="0.0 0.0 0.0" range="0.0 0.0" axis="1.0 0.0 0.0"/>
												</body>
												<body name="link0_104" pos="-2.6816399767426446e-08 0.026300499215722084 0.28652000427246094" quat="-0.4544900059700012 0.5417010188102722 -0.4544910192489624 0.5416980385780334">
													<inertial mass="0.020584987476468086" pos="-2.5416979951842222e-06 -0.027961574494838715 -8.143818558892235e-05" quat="0.5020254254341125 0.49866124987602234 -0.49790117144584656 0.5013999342918396" diaginertia="5.784392669738736e-06 5.654965207213536e-06 9.999999974752427e-07"/>
													<geom name="Geom_91" type="mesh" pos="-2.5416979951842222e-06 -0.027961574494838715 -8.143818558892235e-05" quat="0.5020254254341125 0.49866124987602234 -0.49790117144584656 0.5013999342918396" mesh="ring_prox" class="collision"/>
													<joint name="Ring_R_1_Joint" type="hinge" pos="0.0 0.0 0.0" range="0.0 0.0" axis="1.0 0.0 0.0"/>
													<body name="link0_106" pos="0.0 -0.055059999227523804 0.0" quat="1.0 0.0 0.0 0.0">
														<inertial mass="0.012723562307655811" pos="-1.7029418813763186e-05 -0.017273511737585068 0.00020274649432394654" quat="0.5036312937736511 0.49794304370880127 -0.49543386697769165 0.502944827079773" diaginertia="2.0468648926907917e-06 1.9947437976952642e-06 9.999999974752427e-07"/>
														<geom name="Geom_92" type="mesh" pos="-1.7029418813763186e-05 -0.017273511737585068 0.00020274649432394654" quat="0.5036312937736511 0.49794304370880127 -0.49543386697769165 0.502944827079773" mesh="ring_inter" class="collision"/>
														<joint name="Ring_R_2_Joint" type="hinge" pos="0.0 0.0 0.0" range="0.0 0.0" axis="1.0 0.0 0.0"/>
														<body name="link0_108" pos="0.0 -0.037039998918771744 0.0" quat="1.0 0.0 0.0 0.0">
															<inertial mass="0.006862672511488199" pos="1.8973385522258468e-05 -0.009891333989799023 8.793917368166149e-05" quat="0.49546316266059875 -0.49590304493904114 -0.5038319230079651 -0.5047274827957153" diaginertia="9.999999974752427e-07 9.999999974752427e-07 9.999999974752427e-07"/>
															<geom name="Geom_93" type="mesh" pos="1.8973385522258468e-05 -0.009891333989799023 8.793917368166149e-05" quat="0.49546316266059875 -0.49590304493904114 -0.5038319230079651 -0.5047274827957153" mesh="ring_dist" class="collision"/>
															<joint name="Ring_R_3_Joint" type="hinge" pos="0.0 0.0 0.0" range="0.0 0.0" axis="1.0 0.0 0.0"/>
														</body>
													</body>
												</body>
												<body name="link0_110" pos="-0.04690999910235405 -0.03949970006942749 0.221110001206398" quat="0.13718491792678833 0.6654515862464905 0.7228155732154846 -0.12606392800807953">
													<inertial mass="0.021300282329320908" pos="-8.096490091702435e-06 -0.023335805162787437 -9.092833352042362e-06" quat="0.5039452314376831 0.4991900622844696 -0.49555057287216187 0.5012764930725098" diaginertia="4.795987479155883e-06 4.712325335276546e-06 1.1131986639156821e-06"/>
													<geom name="Geom_94" type="mesh" pos="-8.096490091702435e-06 -0.023335805162787437 -9.092833352042362e-06" quat="0.5039452314376831 0.4991900622844696 -0.49555057287216187 0.5012764930725098" mesh="thumb_prox" class="collision"/>
													<joint name="Thumb_R_1_Joint" type="hinge" pos="0.0 0.0 0.0" range="0.0 0.0" axis="1.0 0.0 0.0"/>
													<body name="link0_112" pos="-1.9999999494757503e-05 -0.04408000037074089 -4.999999873689376e-05" quat="1.0 0.0 0.0 0.0">
														<inertial mass="0.015970006585121155" pos="-3.8115447296149796e-06 -0.017068609595298767 0.00010753015521913767" quat="0.49813613295555115 0.4996276795864105 0.5031560659408569 -0.49906566739082336" diaginertia="2.969749630210572e-06 2.9179732337070163e-06 9.999999974752427e-07"/>
														<geom name="Geom_95" type="mesh" pos="-3.8115447296149796e-06 -0.017068609595298767 0.00010753015521913767" quat="0.49813613295555115 0.4996276795864105 0.5031560659408569 -0.49906566739082336" mesh="thumb_dist" class="collision"/>
														<joint name="Thumb_R_2_Joint" type="hinge" pos="0.0 0.0 0.0" range="0.0 0.0" axis="1.0 0.0 0.0"/>
													</body>
												</body>
												<body name="link0_82" pos="3.998880160338558e-08 -0.03921949863433838 0.2853100001811981" quat="0.5213448405265808 -0.477701872587204 0.5213448405265808 -0.4777028560638428">
													<inertial mass="0.023887978866696358" pos="-1.2821446034649853e-05 -0.028760356828570366 -8.401661762036383e-05" quat="0.5017666816711426 0.49850502610206604 -0.49765971302986145 0.5020534992218018" diaginertia="7.006298346823314e-06 6.845647476438899e-06 1.0188663281951449e-06"/>
													<geom name="Geom_82" type="mesh" pos="-1.2821446034649853e-05 -0.028760356828570366 -8.401661762036383e-05" quat="0.5017666816711426 0.49850502610206604 -0.49765971302986145 0.5020534992218018" mesh="index_prox" class="collision"/>
													<joint name="Index_R_1_Joint" type="hinge" pos="0.0 0.0 0.0" range="0.0 0.0" axis="1.0 0.0 0.0"/>
													<body name="link0_84" pos="0.0 -0.05595000088214874 0.0" quat="1.0 0.0 0.0 0.0">
														<inertial mass="0.011659549549221992" pos="-2.1045781977591105e-05 -0.01496494933962822 0.00027842738199979067" quat="0.5033544301986694 0.49675804376602173 -0.4951587915420532 0.5046617984771729" diaginertia="1.62892069965892e-06 1.5781483853061218e-06 9.999999974752427e-07"/>
														<geom name="Geom_83" type="mesh" pos="-2.1045781977591105e-05 -0.01496494933962822 0.00027842738199979067" quat="0.5033544301986694 0.49675804376602173 -0.4951587915420532 0.5046617984771729" mesh="index_inter" class="collision"/>
														<joint name="Index_R_2_Joint" type="hinge" pos="0.0 0.0 0.0" range="0.0 0.0" axis="1.0 0.0 0.0"/>
														<body name="link0_86" pos="0.0 -0.03197000175714493 0.0" quat="1.0 0.0 0.0 0.0">
															<inertial mass="0.007011548150330782" pos="1.3895119991502725e-05 -0.008136403746902943 0.00019560322107281536" quat="-0.5024529099464417 -0.49753502011299133 -0.4976828992366791 0.5023064017295837" diaginertia="9.999999974752427e-07 9.999999974752427e-07 9.999999974752427e-07"/>
															<geom name="Geom_84" type="mesh" pos="1.3895119991502725e-05 -0.008136403746902943 0.00019560322107281536" quat="-0.5024529099464417 -0.49753502011299133 -0.4976828992366791 0.5023064017295837" mesh="index_dist" class="collision"/>
															<joint name="Index_R_3_Joint" type="hinge" pos="0.0 0.0 0.0" range="0.0 0.0" axis="1.0 0.0 0.0"/>
														</body>
													</body>
												</body>
												<body name="link0_102" pos="-0.04690999910235405 -0.03949970006942749 0.221110001206398" quat="0.13718491792678833 0.6654515862464905 0.7228155732154846 -0.12606392800807953">
													<inertial mass="9.999999974752427e-07" pos="-0.04690999910235405 -0.03949970006942749 0.221110001206398" quat="0.13718491792678833 0.6654515862464905 0.7228155732154846 -0.12606392800807953" diaginertia="9.999999974752427e-07 9.999999974752427e-07 9.999999974752427e-07"/>
													<joint name="RightHandThumb" type="hinge" pos="0.0 0.0 0.0" range="0.0 0.0" axis="1.0 0.0 0.0"/>
												</body>
											</body>
										</body>
									</body>
								</body>
							</body>
						</body>
					</body>
				</body>
				<body name="link0_115" pos="0.0 0.0 0.3684999942779541" quat="0.707105278968811 0.0 0.0 0.7071082592010498">
					<inertial mass="2.2815744876861572" pos="-1.5621025113432552e-06 -8.244373361776525e-07 -0.009581021964550018" quat="0.7070817351341248 0.7071316838264465 0.0004799511225428432 -7.949338396429084e-06" diaginertia="0.0056670536287128925 0.005523578263819218 0.004320218227803707"/>
					<geom name="Geom_96" type="mesh" pos="-1.5621025113432552e-06 -8.244373361776525e-07 -0.009581021964550018" quat="0.7070817351341248 0.7071316838264465 0.0004799511225428432 -7.949338396429084e-06" mesh="Mesh_6a12000_halsmitte_t12" class="collision"/>
					<joint name="Neck_1_Yaw" type="hinge" pos="0.0 0.0 0.0" range="0.0 0.0" axis="0.0 0.0 1.0"/>
					<body name="link0_117" pos="0.0 0.0 0.0" quat="0.4999980032444 0.5 0.5000020265579224 0.5">
						<inertial mass="31.465810775756836" pos="-0.0008058120729401708 0.17242081463336945 0.07313021272420883" quat="0.5884767770767212 0.41910406947135925 -0.40972715616226196 0.5569295883178711" diaginertia="0.29873722791671753 0.28915438055992126 0.26994428038597107"/>
						<geom name="Geom_97" type="mesh" pos="-0.0008058120729401708 0.17242081463336945 0.07313021272420883" quat="0.5884767770767212 0.41910406947135925 -0.40972715616226196 0.5569295883178711" mesh="Mesh_6a13000_halsoben_v13" class="collision"/>
						<joint name="Neck_2_Pitch" type="hinge" pos="0.0 0.0 0.0" range="0.0 0.0" axis="1.0 0.0 0.0"/>
						<body name="link0_124" pos="0.0 0.17299999296665192 0.16050000488758087" quat="9.381843710798421e-07 0.7071082592010498 -9.381873837810417e-07 0.707105278968811">
							<inertial mass="9.999999974752427e-07" pos="0.0 0.17299999296665192 0.16050000488758087" quat="9.381843710798421e-07 0.7071082592010498 -9.381873837810417e-07 0.707105278968811" diaginertia="9.999999974752427e-07 9.999999974752427e-07 9.999999974752427e-07"/>
							<joint name="VirtualCentralGaze" type="slide" pos="0.0 0.0 0.0" range="-0.5 0.5" axis="1.0 0.0 0.0"/>
						</body>
						<body name="link0_120" pos="0.032999999821186066 0.24779999256134033 0.19300000369548798" quat="0.707105278968811 0.0 -0.7071082592010498 0.0">
							<inertial mass="9.999999974752427e-07" pos="0.032999999821186066 0.24779999256134033 0.19300000369548798" quat="0.707105278968811 0.0 -0.7071082592010498 0.0" diaginertia="9.999999974752427e-07 9.999999974752427e-07 9.999999974752427e-07"/>
							<joint name="VirtualCentralGazeDepthCamera" type="slide" pos="0.0 0.0 0.0" range="-0.5 0.5" axis="1.0 0.0 0.0"/>
						</body>
					</body>
				</body>
				<body name="link0_11" pos="-0.09000000357627869 -3.3058799431273656e-07 0.10000000149011612" quat="0.707105278968811 0.0 0.0 0.7071082592010498">
					<inertial mass="4.641332149505615" pos="-1.9983554011560045e-06 0.11062423884868622 0.02188810519874096" quat="0.9445297718048096 -0.32842549681663513 0.00027361296815797687 0.0003834966628346592" diaginertia="0.024549242109060287 0.01810256391763687 0.014694479294121265"/>
					<geom name="Geom_16" type="mesh" pos="-1.9983554011560045e-06 0.11062423884868622 0.02188810519874096" quat="0.9445297718048096 -0.32842549681663513 0.00027361296815797687 0.0003834966628346592" mesh="Mesh_2h09020_arml_t12" class="collision"/>
					<joint name="ArmL1_Cla1" type="hinge" pos="0.0 0.0 0.0" range="0.0 0.0" axis="0.0 0.0 1.0"/>
					<body name="link0_13" pos="0.0 0.28977999091148376 0.07765000313520432" quat="1.0 0.0 0.0 0.0">
						<inertial mass="6.514058589935303" pos="-0.0026242216117680073 0.00547403609380126 0.0014532019849866629" quat="0.41690516471862793 0.561397135257721 0.44454503059387207 0.5598241686820984" diaginertia="0.025567620992660522 0.022996222600340843 0.022928500548005104"/>
						<geom name="Geom_17" type="mesh" pos="-0.0026242216117680073 0.00547403609380126 0.0014532019849866629" quat="0.41690516471862793 0.561397135257721 0.44454503059387207 0.5598241686820984" mesh="Mesh_2h09030_arml_t23" class="collision"/>
						<joint name="ArmL2_Sho1" type="hinge" pos="0.0 0.0 0.0" range="0.0 0.0" axis="0.0 0.9659258723258972 0.25881895422935486"/>
						<body name="link0_15" pos="0.0 0.0 0.0" quat="0.707105278968811 -0.7071082592010498 0.0 0.0">
							<inertial mass="4.186227321624756" pos="0.0031595618929713964 0.11988010257482529 0.009519310668110847" quat="0.6713733077049255 0.20513257384300232 0.6646022200584412 -0.2558952569961548" diaginertia="0.023510094732046127 0.01641996204853058 0.01437942311167717"/>
							<geom name="Geom_18" type="mesh" pos="0.0031595618929713964 0.11988010257482529 0.009519310668110847" quat="0.6713733077049255 0.20513257384300232 0.6646022200584412 -0.2558952569961548" mesh="Mesh_2h09040_arml_t34" class="collision"/>
							<joint name="ArmL3_Sho2" type="hinge" pos="0.0 0.0 0.0" range="0.0 0.0" axis="1.0 0.0 0.0"/>
							<body name="link0_17" pos="0.0 0.0 0.0" quat="0.5000012516975403 -0.4999992549419403 0.5000022649765015 0.49999725818634033">
								<inertial mass="5.494523525238037" pos="-0.0022166140843182802 -0.03205019235610962 0.3651427626609802" quat="0.6883682012557983 0.14456790685653687 -0.16545535624027252 0.6912842392921448" diaginertia="0.033287789672613144 0.03231581673026085 0.01199717540293932"/>
								<geom name="Geom_19" type="mesh" pos="-0.0022166140843182802 -0.03205019235610962 0.3651427626609802" quat="0.6883682012557983 0.14456790685653687 -0.16545535624027252 0.6912842392921448" mesh="Mesh_2h09050_arml_t45" class="collision"/>
								<joint name="ArmL4_Sho3" type="hinge" pos="0.0 0.0 0.0" range="0.0 0.0" axis="0.0 0.0 1.0"/>
								<body name="link0_19" pos="0.0 -0.054999999701976776 0.4090000092983246" quat="1.0 0.0 0.0 0.0">
									<inertial mass="2.7591729164123535" pos="0.0013214589562267065 0.005565263330936432 0.1098216101527214" quat="0.47372815012931824 0.5198296308517456 0.42536303400993347 0.5695832371711731" diaginertia="0.00866414699703455 0.0074538071639835835 0.0066077555529773235"/>
									<geom name="Geom_20" type="mesh" pos="0.001954891486093402 0.005780649837106466 0.11422663927078247" quat="0.6546503901481628 -0.22352944314479828 0.6924439668655396 -0.20491154491901398" mesh="Mesh_2h09060_arml_t56_01" class="collision"/>
									<geom name="Geom_21" type="mesh" pos="0.07322466373443604 0.00026982248527929187 -0.0017227577045559883" quat="0.6577778458595276 0.7531831860542297 0.004401055630296469 -0.004902516957372427" mesh="Mesh_2h09060_arml_t56_02" class="collision"/>
									<geom name="Geom_22" type="mesh" pos="-0.07043138146400452 0.00014143316366244107 0.0009638782357797027" quat="0.16215890645980835 0.9867645502090454 -9.113234409596771e-05 0.00045004638377577066" mesh="Mesh_2h09060_arml_t56_03" class="collision"/>
									<joint name="ArmL5_Elb1" type="hinge" pos="0.0 0.0 0.0" range="0.0 0.0" axis="1.0 0.0 0.0"/>
									<body name="link0_21" pos="0.0 0.0 0.0" quat="1.0 0.0 0.0 0.0">
										<inertial mass="1.323380708694458" pos="-7.264896703418344e-05 0.026484208181500435 0.269603431224823" quat="0.95482337474823 -0.29717233777046204 2.4389843019889668e-05 -0.0009568182867951691" diaginertia="0.007656598463654518 0.006845767144113779 0.003992720041424036"/>
										<geom name="Geom_23" type="mesh" pos="0.04904818907380104 0.0005475301877595484 0.2278057187795639" quat="0.9972087144851685 -0.03267933055758476 0.06708387285470963 0.0025736528914421797" mesh="Mesh_2h09070_arml_t67_01" class="collision"/>
										<geom name="Geom_24" type="mesh" pos="-1.298043006414673e-08 -0.057883650064468384 0.35432007908821106" quat="0.7070271372795105 -0.010613306425511837 0.010614944621920586 0.7070270776748657" mesh="Mesh_2h09070_arml_t67_02" class="collision"/>
										<geom name="Geom_25" type="mesh" pos="-2.5913489025697345e-06 0.07031302154064178 0.3585358262062073" quat="0.7070667743682861 0.006919998209923506 -0.006110544316470623 0.7070865631103516" mesh="Mesh_2h09070_arml_t67_03" class="collision"/>
										<geom name="Geom_26" type="mesh" pos="0.05108014866709709 -0.038606297224760056 0.296926349401474" quat="0.7465304732322693 0.6477420926094055 -0.13063661754131317 -0.07782396674156189" mesh="Mesh_2h09070_arml_t67_04" class="collision"/>
										<geom name="Geom_27" type="mesh" pos="0.04765205830335617 0.04340628162026405 0.2984026074409485" quat="0.5927656888961792 0.7679161429405212 0.028681503608822823 0.24106216430664062" mesh="Mesh_2h09070_arml_t67_05" class="collision"/>
										<geom name="Geom_28" type="mesh" pos="-1.0616304280119948e-06 0.06732528656721115 0.25963494181632996" quat="0.7061805725097656 -0.03628489002585411 0.03611018508672714 0.7061787843704224" mesh="Mesh_2h09070_arml_t67_06" class="collision"/>
										<geom name="Geom_29" type="mesh" pos="5.9854162827832624e-05 -0.05733291059732437 0.24773843586444855" quat="0.7068926095962524 0.01085700187832117 -0.0044671171344816685 0.7072234749794006" mesh="Mesh_2h09070_arml_t67_07" class="collision"/>
										<geom name="Geom_30" type="mesh" pos="-0.04910891503095627 0.00053496373584494 0.22820699214935303" quat="0.997360348701477 -0.028476828709244728 -0.06675867736339569 -0.0021694861352443695" mesh="Mesh_2h09070_arml_t67_08" class="collision"/>
										<geom name="Geom_31" type="mesh" pos="-0.050927359610795975 -0.03914576768875122 0.2969658672809601" quat="0.7477163672447205 0.6452646255493164 0.1306317150592804 0.08653959631919861" mesh="Mesh_2h09070_arml_t67_09" class="collision"/>
										<geom name="Geom_32" type="mesh" pos="-0.04850269854068756 0.042520198971033096 0.29731738567352295" quat="0.6586331725120544 0.7148585319519043 -0.22018752992153168 -0.08183575421571732" mesh="Mesh_2h09070_arml_t67_10" class="collision"/>
										<joint name="ArmL6_Elb2" type="hinge" pos="0.0 0.0 0.0" range="0.0 0.0" axis="0.0 0.0 1.0"/>
										<body name="link0_23" pos="0.0 0.0 0.36399999260902405" quat="1.0 0.0 0.0 0.0">
											<inertial mass="1.1816606521606445" pos="0.0034763282164931297 -0.0012621578061953187 2.2226204237085767e-05" quat="-0.002658423036336899 0.7067897915840149 0.002487173769623041 0.7074142694473267" diaginertia="0.0017266924260184169 0.0015820622211322188 0.0010909022530540824"/>
											<geom name="Geom_33" type="mesh" pos="0.0034763282164931297 -0.0012621578061953187 2.2226204237085767e-05" quat="-0.002658423036336899 0.7067897915840149 0.002487173769623041 0.7074142694473267" mesh="Mesh_2h09080_arml_t78" class="collision"/>
											<joint name="ArmL7_Wri1" type="hinge" pos="0.0 0.0 0.0" range="0.0 0.0" axis="0.0 -1.0 0.0"/>
											<body name="link0_25" pos="0.0 0.0 0.0" quat="0.707105278968811 0.0 0.0 0.7071082592010498">
												<inertial mass="1.6421962976455688" pos="-0.0015881105791777372 3.55767369910609e-05 0.1674589365720749" quat="0.9989550113677979 -0.034559812396764755 -0.0072171650826931 0.02902379259467125" diaginertia="0.009221725165843964 0.008076636120676994 0.0020144644659012556"/>
												<geom name="Geom_34" type="mesh" pos="-2.5014254788402468e-05 0.0006606595125049353 0.12186624854803085" quat="0.0006991556729190052 0.7070338129997253 0.001839448930695653 0.7071769833564758" mesh="Mesh_2h09090_arml_t8_01" class="collision"/>
												<geom name="Geom_35" type="mesh" pos="-6.812727804117458e-08 -0.06317408382892609 0.008618473075330257" quat="0.7070921063423157 -0.004724501632153988 0.004725577775388956 0.7070898413658142" mesh="Mesh_2h09090_arml_t8_02" class="collision"/>
												<geom name="Geom_36" type="mesh" pos="2.647066503413953e-05 0.0626370757818222 0.01715272292494774" quat="0.7071325182914734 -0.00035977462539449334 -6.062036118237302e-05 0.7070809602737427" mesh="Mesh_2h09090_arml_t8_03" class="collision"/>
												<geom name="Geom_37" type="mesh" pos="0.0001532769383629784 -0.04166693985462189 0.11673421412706375" quat="0.7026854753494263 -0.07682538777589798 0.1131587103009224 0.6982306838035583" mesh="Mesh_2h09090_arml_t8_04" class="collision"/>
												<geom name="Geom_38" type="mesh" pos="-0.00010127700807061046 0.04261576384305954 0.1163441613316536" quat="0.7026433944702148 0.08241218328475952 -0.10800295323133469 0.6984524726867676" mesh="Mesh_2h09090_arml_t8_05" class="collision"/>
												<geom name="Geom_39" type="mesh" pos="-1.447715362701274e-06 -0.05752373859286308 0.08827167004346848" quat="-0.23531605303287506 0.6667888760566711 -0.2358095496892929 0.666642963886261" mesh="Mesh_2h09090_arml_t8_06" class="collision"/>
												<geom name="Geom_40" type="mesh" pos="7.302030553546501e-07 0.05815986916422844 0.0874510109424591" quat="0.21441951394081116 0.6738195419311523 0.21392442286014557 0.673964262008667" mesh="Mesh_2h09090_arml_t8_07" class="collision"/>
												<geom name="Geom_41" type="mesh" pos="-0.002641684142872691 0.0018240727949887514 0.2123129516839981" quat="-0.998072624206543 0.022851545363664627 -0.0012825243175029755 -0.057681504637002945" mesh="palm_l" class="collision"/>
												<joint name="ArmL8_Wri2" type="hinge" pos="0.0 0.0 0.0" range="0.0 0.0" axis="0.0 -1.0 0.0"/>
												<body name="link0_36" pos="-5.638520050865736e-08 0.055300500243902206 0.27031999826431274" quat="-0.39037084579467773 0.5895857810974121 -0.3903718590736389 0.5895837545394897">
													<inertial mass="9.999999974752427e-07" pos="-5.638520050865736e-08 0.055300500243902206 0.27031999826431274" quat="-0.39037084579467773 0.5895857810974121 -0.3903718590736389 0.5895837545394897" diaginertia="9.999999974752427e-07 9.999999974752427e-07 9.999999974752427e-07"/>
													<joint name="LeftHandFingers" type="hinge" pos="0.0 0.0 0.0" range="0.0 0.0" axis="1.0 0.0 0.0"/>
												</body>
												<body name="link0_40" pos="-7.647679822753162e-09 0.007500560022890568 0.2917200028896332" quat="0.4999989867210388 -0.5 0.4999989867210388 -0.5000020265579224">
													<inertial mass="0.02538316138088703" pos="-8.225680176110473e-06 -0.030843479558825493 -8.414039621129632e-05" quat="0.5016137957572937 0.4987810552120209 -0.49807825684547424 0.5015168190002441" diaginertia="8.413370778725948e-06 8.243548109021503e-06 1.0851806564460276e-06"/>
													<geom name="Geom_45" type="mesh" pos="-8.225680176110473e-06 -0.030843479558825493 -8.414039621129632e-05" quat="0.5016137957572937 0.4987810552120209 -0.49807825684547424 0.5015168190002441" mesh="middle_prox" class="collision"/>
													<joint name="Middle_L_1_Joint" type="hinge" pos="0.0 0.0 0.0" range="0.0 0.0" axis="1.0 0.0 0.0"/>
													<body name="link0_42" pos="0.0 -0.05999999865889549 0.0" quat="1.0 0.0 0.0 0.0">
														<inertial mass="0.014561756514012814" pos="-3.4415239497320727e-05 -0.018362386152148247 0.00029420116334222257" quat="0.5047402381896973 0.4994126558303833 -0.49391400814056396 0.5018697381019592" diaginertia="2.5808008103922475e-06 2.520335328881629e-06 9.999999974752427e-07"/>
														<geom name="Geom_46" type="mesh" pos="-3.4415239497320727e-05 -0.018362386152148247 0.00029420116334222257" quat="0.5047402381896973 0.4994126558303833 -0.49391400814056396 0.5018697381019592" mesh="middle_inter" class="collision"/>
														<joint name="Middle_L_2_Joint" type="hinge" pos="0.0 0.0 0.0" range="0.0 0.0" axis="1.0 0.0 0.0"/>
														<body name="link0_44" pos="0.0 -0.039000000804662704 0.0" quat="1.0 0.0 0.0 0.0">
															<inertial mass="0.007588660344481468" pos="-1.427834945388895e-06 -0.009854770265519619 0.00019601777603384107" quat="-0.5127896070480347 -0.510059118270874 -0.48690861463546753 0.48970043659210205" diaginertia="9.999999974752427e-07 9.999999974752427e-07 9.999999974752427e-07"/>
															<geom name="Geom_47" type="mesh" pos="-1.427834945388895e-06 -0.009854770265519619 0.00019601777603384107" quat="-0.5127896070480347 -0.510059118270874 -0.48690861463546753 0.48970043659210205" mesh="middle_dist" class="collision"/>
															<joint name="Middle_L_3_Joint" type="hinge" pos="0.0 0.0 0.0" range="0.0 0.0" axis="1.0 0.0 0.0"/>
														</body>
													</body>
												</body>
												<body name="link0_46" pos="5.638419864339994e-08 -0.05529949814081192 0.27031999826431274" quat="-0.5895848870277405 0.3903719186782837 -0.5895819067955017 0.39037492871284485">
													<inertial mass="0.014701016247272491" pos="-1.8761980754788965e-05 -0.02276996523141861 -7.110893056960776e-05" quat="0.5519939661026001 0.5492344498634338 -0.4416252374649048 0.44565823674201965" diaginertia="3.0928017622500192e-06 3.08664630210842e-06 9.999999974752427e-07"/>
													<geom name="Geom_48" type="mesh" pos="-1.8761980754788965e-05 -0.02276996523141861 -7.110893056960776e-05" quat="0.5519939661026001 0.5492344498634338 -0.4416252374649048 0.44565823674201965" mesh="pinky_prox" class="collision"/>
													<joint name="Pinky_L_1_Joint" type="hinge" pos="0.0 0.0 0.0" range="0.0 0.0" axis="1.0 0.0 0.0"/>
													<body name="link0_48" pos="0.0 -0.04610000178217888 0.0" quat="1.0 0.0 0.0 0.0">
														<inertial mass="0.007457030471414328" pos="4.895448000752367e-06 -0.012241008691489697 0.00026062584947794676" quat="0.7138955593109131 0.7002522349357605 -5.2752973715541884e-05 -5.174480611458421e-05" diaginertia="9.999999974752427e-07 9.999999974752427e-07 9.999999974752427e-07"/>
														<geom name="Geom_49" type="mesh" pos="4.895448000752367e-06 -0.012241008691489697 0.00026062584947794676" quat="0.7138955593109131 0.7002522349357605 -5.2752973715541884e-05 -5.174480611458421e-05" mesh="pinky_inter" class="collision"/>
														<joint name="Pinky_L_2_Joint" type="hinge" pos="0.0 0.0 0.0" range="0.0 0.0" axis="1.0 0.0 0.0"/>
														<body name="link0_50" pos="0.0 -0.027060000225901604 0.0" quat="1.0 0.0 0.0 0.0">
															<inertial mass="0.005034840200096369" pos="-9.453228244638012e-08 -0.008268396370112896 0.00011381117656128481" quat="0.0004984356346540153 0.00048165672342292964 -0.7065321207046509 0.7076806426048279" diaginertia="9.999999974752427e-07 9.999999974752427e-07 9.999999974752427e-07"/>
															<geom name="Geom_50" type="mesh" pos="-9.453228244638012e-08 -0.008268396370112896 0.00011381117656128481" quat="0.0004984356346540153 0.00048165672342292964 -0.7065321207046509 0.7076806426048279" mesh="pinky_dist" class="collision"/>
															<joint name="Pinky_L_3_Joint" type="hinge" pos="0.0 0.0 0.0" range="0.0 0.0" axis="1.0 0.0 0.0"/>
														</body>
													</body>
												</body>
												<body name="link0_52" pos="2.6815300202542858e-08 -0.026299500837922096 0.28652000427246094" quat="-0.5416998863220215 0.45449092984199524 -0.5416958928108215 0.4544939398765564">
													<inertial mass="0.020584987476468086" pos="-2.5416979951842222e-06 -0.027961574494838715 -8.143818558892235e-05" quat="0.5020254254341125 0.49866124987602234 -0.49790117144584656 0.5013999342918396" diaginertia="5.784392669738736e-06 5.654965207213536e-06 9.999999974752427e-07"/>
													<geom name="Geom_51" type="mesh" pos="-2.5416979951842222e-06 -0.027961574494838715 -8.143818558892235e-05" quat="0.5020254254341125 0.49866124987602234 -0.49790117144584656 0.5013999342918396" mesh="ring_prox" class="collision"/>
													<joint name="Ring_L_1_Joint" type="hinge" pos="0.0 0.0 0.0" range="0.0 0.0" axis="1.0 0.0 0.0"/>
													<body name="link0_54" pos="0.0 -0.055059999227523804 0.0" quat="1.0 0.0 0.0 0.0">
														<inertial mass="0.012723562307655811" pos="-1.7029418813763186e-05 -0.017273511737585068 0.00020274649432394654" quat="0.5036312937736511 0.49794304370880127 -0.49543386697769165 0.502944827079773" diaginertia="2.0468648926907917e-06 1.9947437976952642e-06 9.999999974752427e-07"/>
														<geom name="Geom_52" type="mesh" pos="-1.7029418813763186e-05 -0.017273511737585068 0.00020274649432394654" quat="0.5036312937736511 0.49794304370880127 -0.49543386697769165 0.502944827079773" mesh="ring_inter" class="collision"/>
														<joint name="Ring_L_2_Joint" type="hinge" pos="0.0 0.0 0.0" range="0.0 0.0" axis="1.0 0.0 0.0"/>
														<body name="link0_56" pos="0.0 -0.037039998918771744 0.0" quat="1.0 0.0 0.0 0.0">
															<inertial mass="0.006862672511488199" pos="1.8973385522258468e-05 -0.009891333989799023 8.793917368166149e-05" quat="0.49546316266059875 -0.49590304493904114 -0.5038319230079651 -0.5047274827957153" diaginertia="9.999999974752427e-07 9.999999974752427e-07 9.999999974752427e-07"/>
															<geom name="Geom_53" type="mesh" pos="1.8973385522258468e-05 -0.009891333989799023 8.793917368166149e-05" quat="0.49546316266059875 -0.49590304493904114 -0.5038319230079651 -0.5047274827957153" mesh="ring_dist" class="collision"/>
															<joint name="Ring_L_3_Joint" type="hinge" pos="0.0 0.0 0.0" range="0.0 0.0" axis="1.0 0.0 0.0"/>
														</body>
													</body>
												</body>
												<body name="link0_58" pos="-0.04690999910235405 0.03950029984116554 0.221110001206398" quat="-0.12637002766132355 0.7229641675949097 0.6651521325111389 0.1375720351934433">
													<inertial mass="0.021300282329320908" pos="-8.096490091702435e-06 -0.023335805162787437 -9.092833352042362e-06" quat="0.5039452314376831 0.4991900622844696 -0.49555057287216187 0.5012764930725098" diaginertia="4.795987479155883e-06 4.712325335276546e-06 1.1131986639156821e-06"/>
													<geom name="Geom_54" type="mesh" pos="-8.096490091702435e-06 -0.023335805162787437 -9.092833352042362e-06" quat="0.5039452314376831 0.4991900622844696 -0.49555057287216187 0.5012764930725098" mesh="thumb_prox" class="collision"/>
													<joint name="Thumb_L_1_Joint" type="hinge" pos="0.0 0.0 0.0" range="0.0 0.0" axis="1.0 0.0 0.0"/>
													<body name="link0_60" pos="1.9999999494757503e-05 -0.04408000037074089 -4.999999873689376e-05" quat="1.0 0.0 0.0 0.0">
														<inertial mass="0.015970006585121155" pos="-2.3720958779449575e-05 -0.017068609595298767 0.00013753015082329512" quat="-0.4981374740600586 -0.49962636828422546 -0.503157377243042 0.4990643560886383" diaginertia="2.969749630210572e-06 2.9179732337070163e-06 9.999999974752427e-07"/>
														<geom name="Geom_55" type="mesh" pos="-2.3720958779449575e-05 -0.017068609595298767 0.00013753015082329512" quat="-0.4981374740600586 -0.49962636828422546 -0.503157377243042 0.4990643560886383" mesh="thumb_dist" class="collision"/>
														<joint name="Thumb_L_2_Joint" type="hinge" pos="0.0 0.0 0.0" range="0.0 0.0" axis="1.0 0.0 0.0"/>
													</body>
												</body>
												<body name="link0_30" pos="-3.998989939191233e-08 0.039220500737428665 0.2853100001811981" quat="-0.47770002484321594 0.5213470458984375 -0.4777010381221771 0.5213460326194763">
													<inertial mass="0.023887978866696358" pos="-1.2821446034649853e-05 -0.028760356828570366 -8.401661762036383e-05" quat="0.5017666816711426 0.49850502610206604 -0.49765971302986145 0.5020534992218018" diaginertia="7.006298346823314e-06 6.845647476438899e-06 1.0188663281951449e-06"/>
													<geom name="Geom_42" type="mesh" pos="-1.2821446034649853e-05 -0.028760356828570366 -8.401661762036383e-05" quat="0.5017666816711426 0.49850502610206604 -0.49765971302986145 0.5020534992218018" mesh="index_prox" class="collision"/>
													<joint name="Index_L_1_Joint" type="hinge" pos="0.0 0.0 0.0" range="0.0 0.0" axis="1.0 0.0 0.0"/>
													<body name="link0_32" pos="0.0 -0.05595000088214874 0.0" quat="1.0 0.0 0.0 0.0">
														<inertial mass="0.011659549549221992" pos="-2.1045781977591105e-05 -0.01496494933962822 0.00027842738199979067" quat="0.5033544301986694 0.49675804376602173 -0.4951587915420532 0.5046617984771729" diaginertia="1.62892069965892e-06 1.5781483853061218e-06 9.999999974752427e-07"/>
														<geom name="Geom_43" type="mesh" pos="-2.1045781977591105e-05 -0.01496494933962822 0.00027842738199979067" quat="0.5033544301986694 0.49675804376602173 -0.4951587915420532 0.5046617984771729" mesh="index_inter" class="collision"/>
														<joint name="Index_L_2_Joint" type="hinge" pos="0.0 0.0 0.0" range="0.0 0.0" axis="1.0 0.0 0.0"/>
														<body name="link0_34" pos="0.0 -0.03197000175714493 0.0" quat="1.0 0.0 0.0 0.0">
															<inertial mass="0.007011548150330782" pos="1.3895119991502725e-05 -0.008136403746902943 0.00019560322107281536" quat="-0.5024529099464417 -0.49753502011299133 -0.4976828992366791 0.5023064017295837" diaginertia="9.999999974752427e-07 9.999999974752427e-07 9.999999974752427e-07"/>
															<geom name="Geom_44" type="mesh" pos="1.3895119991502725e-05 -0.008136403746902943 0.00019560322107281536" quat="-0.5024529099464417 -0.49753502011299133 -0.4976828992366791 0.5023064017295837" mesh="index_dist" class="collision"/>
															<joint name="Index_L_3_Joint" type="hinge" pos="0.0 0.0 0.0" range="0.0 0.0" axis="1.0 0.0 0.0"/>
														</body>
													</body>
												</body>
												<body name="link0_38" pos="-0.04690999910235405 -0.03949970006942749 0.221110001206398" quat="0.13718491792678833 0.6654515862464905 0.7228155732154846 -0.12606392800807953">
													<inertial mass="9.999999974752427e-07" pos="-0.04690999910235405 -0.03949970006942749 0.221110001206398" quat="0.13718491792678833 0.6654515862464905 0.7228155732154846 -0.12606392800807953" diaginertia="9.999999974752427e-07 9.999999974752427e-07 9.999999974752427e-07"/>
													<joint name="LeftHandThumb" type="hinge" pos="0.0 0.0 0.0" range="0.0 0.0" axis="1.0 0.0 0.0"/>
												</body>
											</body>
										</body>
									</body>
								</body>
							</body>
						</body>
					</body>
				</body>
			</body>
		</body>
	</worldbody>
	<equality/>
</mujoco>
