<?xml version="1.0" ?>
<mujoco model="barkour_vb">
	<compiler meshdir="barkour_vb/meshes" texturedir="barkour_vb/textures" angle="radian" autolimits="true" balanceinertia="true" boundmass="0.000001" boundinertia="0.000001"/>
	<default>
		<default class="visual">
			<geom contype="0" conaffinity="0"/>
		</default>
		<default class="collision">
			<geom rgba="1.0 0.0 0.0 0.0"/>
		</default>
	</default>
	<asset>
		<mesh name="neck" file="stl/neck.stl" scale="1.0 1.0 1.0"/>
		<mesh name="camera_cover" file="stl/camera_cover.stl" scale="1.0 1.0 1.0"/>
		<mesh name="handle" file="stl/handle.stl" scale="1.0 1.0 1.0"/>
		<mesh name="intel_realsense_depth_camera_d435" file="stl/intel_realsense_depth_camera_d435.stl" scale="1.0 1.0 1.0"/>
		<mesh name="torso" file="stl/torso.stl" scale="1.0 1.0 1.0"/>
		<mesh name="abduction" file="stl/abduction.stl" scale="1.0 1.0 1.0"/>
		<mesh name="upper_leg" file="stl/upper_leg.stl" scale="1.0 1.0 1.0"/>
		<mesh name="upper_leg_left" file="stl/upper_leg_left.stl" scale="1.0 1.0 1.0"/>
		<mesh name="foot" file="stl/foot.stl" scale="1.0 1.0 1.0"/>
		<mesh name="lower_leg" file="stl/lower_leg.stl" scale="1.0 1.0 1.0"/>
		<mesh name="upper_leg_right" file="stl/upper_leg_right.stl" scale="1.0 1.0 1.0"/>
	</asset>
	<worldbody>
		<body name="barkour_vb" pos="0.0 0.0 0.0" quat="1.0 0.0 0.0 0.0">
			<body name="torso" pos="0.0 0.0 0.0" quat="1.0 0.0 0.0 0.0">
				<geom name="Geom_0" type="mesh" pos="0.22433894872665405 0.001256005372852087 0.06270846724510193" quat="0.013580454513430595 0.6639434099197388 0.041014961898326874 0.7465336322784424" mesh="neck" class="collision"/>
				<geom name="Geom_1" type="mesh" pos="0.3103097975254059 0.00244314968585968 0.0651232898235321" quat="0.7069939374923706 0.7070602178573608 0.010517138056457043 0.010714893229305744" mesh="camera_cover" class="collision"/>
				<geom name="Geom_2" type="mesh" pos="-0.0028865057975053787 -0.00047825026558712125 0.10888580232858658" quat="0.5006201267242432 0.49939680099487305 0.49969953298568726 0.5002825856208801" mesh="handle" class="collision"/>
				<geom name="Geom_3" type="mesh" pos="0.3089166581630707 0.0015315583441406488 0.0650092139840126" quat="-0.5010220408439636 0.504074215888977 0.49726560711860657 0.4976073205471039" mesh="intel_realsense_depth_camera_d435" class="collision"/>
				<geom name="Geom_4" type="mesh" pos="-0.0017094450304284692 -0.0006751970504410565 0.0019167097052559257" quat="-0.0009203868685290217 0.7075598239898682 -0.0005835552583448589 0.7066525816917419" mesh="torso" class="collision"/>
				<body name="oak_" pos="0.08631999790668488 0.0 0.12129999697208405" quat="0.5 -0.5 0.5 -0.5">
					<inertial mass="0.0" pos="0.08631999790668488 0.0 0.12129999697208405" quat="0.5 -0.5 0.5 -0.5" diaginertia="0.0 0.0 0.0"/>
				</body>
				<body name="leg_hind_left" pos="-0.1718290001153946 0.08924929797649384 -9.800000043469481e-06" quat="0.5 -0.5 -0.5 0.5">
					<inertial mass="0.7870000004768372" pos="0.0054772598668932915 0.0002880340034607798 0.06021910160779953" quat="0.9998374581336975 0.010389205068349838 0.014371506869792938 0.003256561467424035" diaginertia="0.0014383100206032395 0.0011702299816533923 0.001000109943561256"/>
					<geom name="Geom_10" type="mesh" pos="-0.00997156836092472 -1.7550832126289606e-05 0.059116460382938385" quat="0.9997302889823914 -0.01084742322564125 -0.020518342033028603 -0.0008258090820163488" mesh="abduction" class="collision"/>
					<joint name="abduction_hind_left" type="hinge" pos="0.0 0.0 0.0" range="-1.0471999645233154 1.0471999645233154" axis="0.0 0.0 1.0"/>
					<body name="upper_leg_hind_left" pos="0.03085000067949295 0.0 0.06499999761581421" quat="0.0 0.7071067690849304 0.0 -0.7071067690849304">
						<inertial mass="1.1549999713897705" pos="-0.024139700457453728 0.0040242900140583515 -0.04530379921197891" quat="0.0673193410038948 0.6479663848876953 -0.005181422922760248 0.758670449256897" diaginertia="0.005620220210403204 0.005194710101932287 0.0012632999569177628"/>
						<geom name="Geom_11" type="mesh" pos="0.00023322035849560052 -7.406091754091904e-05 -0.023289691656827927" quat="0.2889934480190277 0.6466710567474365 0.28508132696151733 -0.6457770466804504" mesh="upper_leg" class="collision"/>
						<geom name="Geom_12" type="mesh" pos="-0.07915133982896805 0.013468015938997269 -0.06975895911455154" quat="0.000985627411864698 0.7059446573257446 -0.045703209936618805 -0.7067902088165283" mesh="upper_leg_left" class="collision"/>
						<joint name="hip_hind_left" type="hinge" pos="0.0 0.0 0.0" range="-1.5470600128173828 3.029020071029663" axis="0.0 0.0 1.0"/>
						<body name="lower_leg_2" pos="-0.1899999976158142 0.0 -0.06992500275373459" quat="0.0 0.0 1.0 0.0">
							<inertial mass="0.1712380051612854" pos="-0.08954930305480957 -0.030195700004696846 -3.02081986092162e-08" quat="-0.10146502405405045 0.6997891664505005 0.10146502405405045 0.6997891664505005" diaginertia="0.0013740600552409887 0.0013574600452557206 3.055209890590049e-05"/>
							<geom name="Geom_13" type="mesh" pos="-0.07833936810493469 -0.025353308767080307 -1.0863113857340068e-05" quat="0.7025494575500488 0.08089106529951096 -0.7024315595626831 0.08044122904539108" mesh="lower_leg" class="collision"/>
							<geom name="Geom_14" type="mesh" pos="-0.21151316165924072 -0.07480219006538391 1.73156490745896e-06" quat="0.6420331001281738 0.2963016927242279 -0.6421560049057007 0.29603108763694763" mesh="foot" class="collision"/>
							<joint name="knee_hind_left" type="hinge" pos="0.0 0.0 0.0" range="0.0 2.443459987640381" axis="0.0 0.0 1.0"/>
						</body>
					</body>
				</body>
				<body name="leg_front_right" pos="0.17167100310325623 -0.09075070172548294 -9.800000043469481e-06" quat="0.5 -0.5 0.5 -0.5">
					<inertial mass="0.7870000004768372" pos="0.0054772598668932915 0.0002880340034607798 0.06021910160779953" quat="0.9998374581336975 0.010389205068349838 0.014371506869792938 0.003256561467424035" diaginertia="0.0014383100206032395 0.0011702299816533923 0.001000109943561256"/>
					<geom name="Geom_15" type="mesh" pos="-0.00997156836092472 -1.7550832126289606e-05 0.059116460382938385" quat="0.9997302889823914 -0.01084742322564125 -0.020518342033028603 -0.0008258090820163488" mesh="abduction" class="collision"/>
					<joint name="abduction_front_right" type="hinge" pos="0.0 0.0 0.0" range="-1.0471999645233154 1.0471999645233154" axis="0.0 0.0 1.0"/>
					<body name="upper_leg_front_right" pos="0.03085000067949295 0.0 0.06499999761581421" quat="0.0 -0.7071067690849304 0.0 -0.7071067690849304">
						<inertial mass="1.1549999713897705" pos="-0.024139299988746643 0.0032456701155751944 0.045303601771593094" quat="-0.006049833260476589 0.7569693922996521 -0.08545474708080292 0.6478103399276733" diaginertia="0.005631070118397474 0.0051953899674117565 0.0012647199910134077"/>
						<geom name="Geom_16" type="mesh" pos="0.00023322035849560052 7.406091754091904e-05 0.023289691656827927" quat="0.6466710567474365 -0.2889934480190277 -0.6457770466804504 -0.28508132696151733" mesh="upper_leg" class="collision"/>
						<geom name="Geom_17" type="mesh" pos="-0.07893851399421692 0.013406557962298393 0.06972665339708328" quat="0.04658540338277817 -0.7069498896598816 -0.0014878589427098632 0.7057262063026428" mesh="upper_leg_right" class="collision"/>
						<joint name="hip_front_right" type="hinge" pos="0.0 0.0 0.0" range="-1.5470600128173828 3.029020071029663" axis="0.0 0.0 1.0"/>
						<body name="lower_leg_3" pos="-0.1899999976158142 0.0 0.0695749968290329" quat="0.0 0.0 -1.0 0.0">
							<inertial mass="0.1712380051612854" pos="-0.08954930305480957 -0.030195700004696846 -3.02081986092162e-08" quat="-0.10146502405405045 0.6997891664505005 0.10146502405405045 0.6997891664505005" diaginertia="0.0013740600552409887 0.0013574600452557206 3.055209890590049e-05"/>
							<geom name="Geom_18" type="mesh" pos="-0.21151316165924072 -0.07480219006538391 1.73156490745896e-06" quat="0.6420331001281738 0.2963016927242279 -0.6421560049057007 0.29603108763694763" mesh="foot" class="collision"/>
							<geom name="Geom_19" type="mesh" pos="-0.07833936810493469 -0.025353308767080307 -1.0863113857340068e-05" quat="0.7025494575500488 0.08089106529951096 -0.7024315595626831 0.08044122904539108" mesh="lower_leg" class="collision"/>
							<joint name="knee_front_right" type="hinge" pos="0.0 0.0 0.0" range="0.0 2.443459987640381" axis="0.0 0.0 1.0"/>
						</body>
					</body>
				</body>
				<body name="leg_hind_right" pos="-0.1718290001153946 -0.09075070172548294 -9.800000043469481e-06" quat="0.5 -0.5 0.5 -0.5">
					<inertial mass="0.7870000004768372" pos="0.0054772598668932915 -0.0002880340034607798 -0.06001909822225571" quat="0.9998374581336975 0.010389205068349838 -0.014371506869792938 -0.003256561467424035" diaginertia="0.0014383100206032395 0.0011702299816533923 0.001000109943561256"/>
					<geom name="Geom_20" type="mesh" pos="-0.00997156836092472 1.7550832126289606e-05 -0.05891646072268486" quat="0.01084742322564125 0.9997302889823914 0.0008258090820163488 -0.020518342033028603" mesh="abduction" class="collision"/>
					<joint name="abduction_hind_right" type="hinge" pos="0.0 0.0 0.0" range="-1.0471999645233154 1.0471999645233154" axis="0.0 0.0 1.0"/>
					<body name="upper_leg_hind_right" pos="0.03085000067949295 0.0 -0.06480000168085098" quat="0.0 0.7071067690849304 0.0 0.7071067690849304">
						<inertial mass="1.1549999713897705" pos="-0.024139299988746643 0.0032456701155751944 0.045303601771593094" quat="-0.006049833260476589 0.7569693922996521 -0.08545474708080292 0.6478103399276733" diaginertia="0.005631070118397474 0.0051953899674117565 0.0012647199910134077"/>
						<geom name="Geom_21" type="mesh" pos="0.00023322035849560052 7.406091754091904e-05 0.023289691656827927" quat="0.6466710567474365 -0.2889934480190277 -0.6457770466804504 -0.28508132696151733" mesh="upper_leg" class="collision"/>
						<geom name="Geom_22" type="mesh" pos="-0.07893851399421692 0.013406557962298393 0.06972665339708328" quat="0.04658540338277817 -0.7069498896598816 -0.0014878589427098632 0.7057262063026428" mesh="upper_leg_right" class="collision"/>
						<joint name="hip_hind_right" type="hinge" pos="0.0 0.0 0.0" range="-1.5470600128173828 3.029020071029663" axis="0.0 0.0 1.0"/>
						<body name="lower_leg_4" pos="-0.1899999976158142 0.0 0.0695749968290329" quat="0.0 0.0 -1.0 0.0">
							<inertial mass="0.1712380051612854" pos="-0.08954930305480957 -0.030195700004696846 -3.02081986092162e-08" quat="-0.10146502405405045 0.6997891664505005 0.10146502405405045 0.6997891664505005" diaginertia="0.0013740600552409887 0.0013574600452557206 3.055209890590049e-05"/>
							<geom name="Geom_23" type="mesh" pos="-0.07833936810493469 -0.025353308767080307 -1.0863113857340068e-05" quat="0.7025494575500488 0.08089106529951096 -0.7024315595626831 0.08044122904539108" mesh="lower_leg" class="collision"/>
							<geom name="Geom_24" type="mesh" pos="-0.21151316165924072 -0.07480219006538391 1.73156490745896e-06" quat="0.6420331001281738 0.2963016927242279 -0.6421560049057007 0.29603108763694763" mesh="foot" class="collision"/>
							<joint name="knee_hind_right" type="hinge" pos="0.0 0.0 0.0" range="0.0 2.443459987640381" axis="0.0 0.0 1.0"/>
						</body>
					</body>
				</body>
				<body name="Body_2" pos="0.3176000118255615 0.017000000923871994 0.06499999761581421" quat="0.5 -0.5 0.5 -0.5">
					<inertial mass="0.0" pos="0.3176000118255615 0.017000000923871994 0.06499999761581421" quat="0.5 -0.5 0.5 -0.5" diaginertia="0.0 0.0 0.0"/>
				</body>
				<body name="leg_front_left" pos="0.17167100310325623 0.08924929797649384 -9.800000043469481e-06" quat="0.5 -0.5 -0.5 0.5">
					<inertial mass="0.7870000004768372" pos="0.0054772598668932915 -0.0002880340034607798 -0.06021910160779953" quat="0.9998374581336975 0.010389205068349838 -0.014371506869792938 -0.003256561467424035" diaginertia="0.0014383100206032395 0.0011702299816533923 0.001000109943561256"/>
					<geom name="Geom_5" type="mesh" pos="-0.00997156836092472 1.7550832126289606e-05 -0.059116460382938385" quat="0.01084742322564125 0.9997302889823914 0.0008258090820163488 -0.020518342033028603" mesh="abduction" class="collision"/>
					<joint name="abduction_front_left" type="hinge" pos="0.0 0.0 0.0" range="-1.0471999645233154 1.0471999645233154" axis="0.0 0.0 1.0"/>
					<body name="upper_leg_front_left" pos="0.03085000067949295 0.0 -0.06499999761581421" quat="0.0 -0.7071067690849304 0.0 0.7071067690849304">
						<inertial mass="1.1549999713897705" pos="-0.024139700457453728 0.0040242900140583515 -0.04530379921197891" quat="0.0673193410038948 0.6479663848876953 -0.005181422922760248 0.758670449256897" diaginertia="0.005620220210403204 0.005194710101932287 0.0012632999569177628"/>
						<geom name="Geom_6" type="mesh" pos="0.00023322035849560052 -7.406091754091904e-05 -0.023289691656827927" quat="0.2889934480190277 0.6466710567474365 0.28508132696151733 -0.6457770466804504" mesh="upper_leg" class="collision"/>
						<geom name="Geom_7" type="mesh" pos="-0.07915133982896805 0.013468015938997269 -0.06975895911455154" quat="0.000985627411864698 0.7059446573257446 -0.045703209936618805 -0.7067902088165283" mesh="upper_leg_left" class="collision"/>
						<joint name="hip_front_left" type="hinge" pos="0.0 0.0 0.0" range="-1.5470600128173828 3.029020071029663" axis="0.0 0.0 1.0"/>
						<body name="lower_leg_front_left" pos="-0.1899999976158142 0.0 -0.0695749968290329" quat="0.0 0.0 1.0 0.0">
							<inertial mass="0.1712380051612854" pos="-0.08954930305480957 -0.030195700004696846 -3.02081986092162e-08" quat="-0.10146502405405045 0.6997891664505005 0.10146502405405045 0.6997891664505005" diaginertia="0.0013740600552409887 0.0013574600452557206 3.055209890590049e-05"/>
							<geom name="Geom_8" type="mesh" pos="-0.21151316165924072 -0.07480219006538391 1.73156490745896e-06" quat="0.6420331001281738 0.2963016927242279 -0.6421560049057007 0.29603108763694763" mesh="foot" class="collision"/>
							<geom name="Geom_9" type="mesh" pos="-0.07833936810493469 -0.025353308767080307 -1.0863113857340068e-05" quat="0.7025494575500488 0.08089106529951096 -0.7024315595626831 0.08044122904539108" mesh="lower_leg" class="collision"/>
							<joint name="knee_front_left" type="hinge" pos="0.0 0.0 0.0" range="0.0 2.443459987640381" axis="0.0 0.0 1.0"/>
						</body>
					</body>
				</body>
			</body>
		</body>
	</worldbody>
	<equality/>
</mujoco>
