<?xml version="1.0" ?>
<mujoco model="go1">
	<compiler meshdir="go1/meshes" texturedir="go1/textures" angle="radian" autolimits="true" balanceinertia="true" boundmass="0.000001" boundinertia="0.000001"/>
	<default>
		<default class="visual">
			<geom contype="0" conaffinity="0"/>
		</default>
		<default class="collision">
			<geom rgba="1.0 0.0 0.0 0.0"/>
		</default>
	</default>
	<asset>
		<mesh name="trunk" file="stl/trunk.stl" scale="1.0 1.0 1.0"/>
		<mesh name="hip" file="stl/hip.stl" scale="1.0 1.0 1.0"/>
		<mesh name="thigh_mirror" file="stl/thigh_mirror.stl" scale="1.0 1.0 1.0"/>
		<mesh name="calf" file="stl/calf.stl" scale="1.0 1.0 1.0"/>
		<mesh name="thigh" file="stl/thigh.stl" scale="1.0 1.0 1.0"/>
		<material name="dark" rgba="0.10000000149011612 0.10000000149011612 0.10000000149011612 1.0" emission="0.0" specular="0.5"/>
	</asset>
	<worldbody>
		<body name="go1" pos="0.0 0.0 0.0" quat="1.0 0.0 0.0 0.0">
			<body name="trunk" pos="0.0 0.0 0.0" quat="1.0 0.0 0.0 0.0">
				<geom name="Geom_0" type="mesh" pos="0.06456613540649414 -1.7892060100166418e-07 0.0008886185241863132" quat="-1.2763169934260077e-06 0.7020552754402161 1.2946187553097843e-06 0.7121224403381348" mesh="trunk" material="dark" class="visual"/>
				<geom name="Geom_1" type="box" pos="0.0 0.0 0.0" quat="1.0 0.0 0.0 0.0" size="0.125 0.03999999910593033 0.05700000002980232" class="collision"/>
				<geom name="Geom_2" type="cylinder" pos="0.0 -0.03999999910593033 0.0" quat="0.7071067690849304 0.0 0.7071067690849304 0.0" size="0.057999998331069946 0.125 0.0" class="collision"/>
				<geom name="Geom_3" type="cylinder" pos="0.0 0.03999999910593033 0.0" quat="0.7071067690849304 0.0 0.7071067690849304 0.0" size="0.057999998331069946 0.125 0.0" class="collision"/>
				<geom name="Geom_4" type="box" pos="0.25 0.0 0.0" quat="1.0 0.0 0.0 0.0" size="0.004999999888241291 0.05999999865889549 0.05000000074505806" class="collision"/>
				<geom name="Geom_5" type="capsule" pos="0.25 0.05999999865889549 -0.009999999776482582" quat="1.0 0.0 0.0 0.0" size="0.008999999612569809 0.03500000014901161 0.0" class="collision"/>
				<geom name="Geom_6" type="capsule" pos="0.25 -0.05999999865889549 -0.009999999776482582" quat="1.0 0.0 0.0 0.0" size="0.008999999612569809 0.03500000014901161 0.0" class="collision"/>
				<geom name="Geom_7" type="capsule" pos="0.25 0.0 -0.05000000074505806" quat="0.7071067690849304 0.7071067690849304 0.0 0.0" size="0.009999999776482582 0.05999999865889549 0.0" class="collision"/>
				<geom name="Geom_8" type="capsule" pos="0.2549999952316284 0.0 0.03550000116229057" quat="0.7071067690849304 0.7071067690849304 0.0 0.0" size="0.020999999716877937 0.052000001072883606 0.0" class="collision"/>
				<body name="FL_hip" pos="0.18809999525547028 0.04675000160932541 0.0" quat="1.0 0.0 0.0 0.0">
					<inertial mass="0.6800000071525574" pos="-0.004916599951684475 -0.00762614980340004 -8.864999836077914e-05" quat="0.4828909635543823 0.49502697587013245 0.5141689777374268 0.5073409676551819" diaginertia="0.0007340639713220298 0.00046843799646012485 0.0003987190139014274"/>
					<geom name="Geom_20" type="mesh" pos="-0.01287506427615881 -0.0017777803586795926 -1.960473952067332e-07" quat="0.7040685415267944 3.0720868380740285e-05 3.593841756810434e-05 0.7101320028305054" mesh="hip" material="dark" class="visual"/>
					<geom name="Geom_21" type="cylinder" pos="0.0 0.04500000178813934 0.0" quat="0.7071067690849304 0.7071067690849304 0.0 0.0" size="0.04600000008940697 0.019999999552965164 0.0" class="collision"/>
					<geom name="Geom_22" type="cylinder" pos="0.0 0.06499999761581421 0.0" quat="0.7071067690849304 0.7071067690849304 0.0 0.0" size="0.03099999949336052 0.019999999552965164 0.0" class="collision"/>
					<joint name="FL_hip_joint" type="hinge" pos="0.0 0.0 0.0" range="-0.8629999756813049 0.8629999756813049" axis="1.0 0.0 0.0"/>
					<body name="FL_thigh" pos="0.0 0.07999999821186066 0.0" quat="1.0 0.0 0.0 0.0">
						<inertial mass="1.0089999437332153" pos="-0.003047219943255186 -0.019315000623464584 -0.030500400811433792" quat="0.7533828020095825 0.07751257717609406 -0.02723129279911518 0.6524298191070557" diaginertia="0.004787169862538576 0.004609030205756426 0.00070926797343418"/>
						<geom name="Geom_23" type="mesh" pos="-0.0035736847203224897 -0.02361164800822735 -0.04103037714958191" quat="0.8039950728416443 0.08563201129436493 -0.03158499300479889 0.5875895619392395" mesh="thigh" material="dark" class="visual"/>
						<geom name="Geom_24" type="capsule" pos="-0.019999999552965164 0.0 -0.07999999821186066" quat="1.0 0.0 0.0 0.0" size="0.014999999664723873 0.07999999821186066 0.0" class="collision"/>
						<geom name="Geom_25" type="capsule" pos="-0.009999999776482582 0.0 -0.05000000074505806" quat="0.9951333403587341 0.0 0.0985376164317131 0.0" size="0.014999999664723873 0.05099019408226013 0.0" class="collision"/>
						<geom name="Geom_26" type="capsule" pos="-0.009999999776482582 0.0 -0.18000000715255737" quat="0.9732490181922913 0.0 -0.22975291311740875 0.0" size="0.014999999664723873 0.022360680624842644 0.0" class="collision"/>
						<joint name="FL_thigh_joint" type="hinge" pos="0.0 0.0 0.0" range="-0.6859999895095825 4.500999927520752" axis="0.0 1.0 0.0"/>
						<body name="FL_calf" pos="0.0 0.0 -0.21299999952316284" quat="1.0 0.0 0.0 0.0">
							<inertial mass="0.19586199522018433" pos="0.0042986199259757996 0.0009766760049387813 -0.14619700610637665" quat="0.6912462711334229 0.003574671456590295 0.0051111821085214615 0.722592294216156" diaginertia="0.00149766996037215 0.001484679989516735 3.584269870771095e-05"/>
							<geom name="Geom_27" type="mesh" pos="0.006786840967833996 -9.16954718377383e-07 -0.12472491711378098" quat="0.7070883512496948 -0.004390552639961243 -0.004400269128382206 0.7070978879928589" mesh="calf" material="dark" class="visual"/>
							<geom name="Geom_28" type="capsule" pos="0.009999999776482582 0.0 -0.06499999761581421" quat="0.9970886707305908 0.0 -0.0762505829334259 0.0" size="0.009999999776482582 0.06576473265886307 0.0" class="collision"/>
							<geom name="Geom_29" type="capsule" pos="0.009999999776482582 0.0 -0.16500000655651093" quat="0.9903342723846436 0.0 0.13870121538639069 0.0" size="0.009999999776482582 0.03640054911375046 0.0" class="collision"/>
							<geom name="FL" type="sphere" pos="0.0 0.0 -0.21299999952316284" quat="1.0 0.0 0.0 0.0" size="0.023000000044703484 0.0 0.0" class="collision"/>
							<joint name="FL_calf_joint" type="hinge" pos="0.0 0.0 0.0" range="-2.818000078201294 -0.8880000114440918" axis="0.0 1.0 0.0"/>
						</body>
					</body>
				</body>
				<body name="RR_hip" pos="-0.18809999525547028 -0.04675000160932541 0.0" quat="1.0 0.0 0.0 0.0">
					<inertial mass="0.6800000071525574" pos="0.004916599951684475 0.00762614980340004 -8.864999836077914e-05" quat="0.49502697587013245 0.4828909635543823 0.5073409676551819 0.5141689777374268" diaginertia="0.0007340639713220298 0.00046843799646012485 0.0003987190139014274"/>
					<geom name="Geom_31" type="mesh" pos="0.01287506427615881 0.0017777803586795926 -1.960473952067332e-07" quat="0.7101320028305054 3.593841756810434e-05 -3.0720868380740285e-05 -0.7040685415267944" mesh="hip" material="dark" class="visual"/>
					<geom name="Geom_32" type="cylinder" pos="0.0 -0.04500000178813934 0.0" quat="0.7071067690849304 0.7071067690849304 0.0 0.0" size="0.04600000008940697 0.019999999552965164 0.0" class="collision"/>
					<geom name="Geom_33" type="cylinder" pos="0.0 -0.06499999761581421 0.0" quat="0.7071067690849304 0.7071067690849304 0.0 0.0" size="0.03099999949336052 0.019999999552965164 0.0" class="collision"/>
					<geom name="Geom_34" type="cylinder" pos="0.0 0.0 0.0" quat="0.7071067690849304 0.7071067690849304 0.0 0.0" size="0.04600000008940697 0.019999999552965164 0.0" class="collision"/>
					<joint name="RR_hip_joint" type="hinge" pos="0.0 0.0 0.0" range="-0.8629999756813049 0.8629999756813049" axis="1.0 0.0 0.0"/>
					<body name="RR_thigh" pos="0.0 -0.07999999821186066 0.0" quat="1.0 0.0 0.0 0.0">
						<inertial mass="1.0089999437332153" pos="-0.003047219943255186 0.019315000623464584 -0.030500400811433792" quat="0.6524298191070557 -0.02723129279911518 0.07751257717609406 0.7533828020095825" diaginertia="0.004787169862538576 0.004609030205756426 0.00070926797343418"/>
						<geom name="Geom_35" type="mesh" pos="-0.004290462005883455 0.022090628743171692 -0.04642722010612488" quat="0.5726116895675659 -0.0309742484241724 0.09420688450336456 0.8138068318367004" mesh="thigh_mirror" material="dark" class="visual"/>
						<geom name="Geom_36" type="capsule" pos="-0.019999999552965164 0.0 -0.07999999821186066" quat="1.0 0.0 0.0 0.0" size="0.014999999664723873 0.07999999821186066 0.0" class="collision"/>
						<geom name="Geom_37" type="capsule" pos="-0.009999999776482582 0.0 -0.05000000074505806" quat="0.9951333403587341 0.0 0.0985376164317131 0.0" size="0.014999999664723873 0.05099019408226013 0.0" class="collision"/>
						<geom name="Geom_38" type="capsule" pos="-0.009999999776482582 0.0 -0.18000000715255737" quat="0.9732490181922913 0.0 -0.22975291311740875 0.0" size="0.014999999664723873 0.022360680624842644 0.0" class="collision"/>
						<joint name="RR_thigh_joint" type="hinge" pos="0.0 0.0 0.0" range="-0.6859999895095825 4.500999927520752" axis="0.0 1.0 0.0"/>
						<body name="RR_calf" pos="0.0 0.0 -0.21299999952316284" quat="1.0 0.0 0.0 0.0">
							<inertial mass="0.19586199522018433" pos="0.0042986199259757996 0.0009766760049387813 -0.14619700610637665" quat="0.6912462711334229 0.003574671456590295 0.0051111821085214615 0.722592294216156" diaginertia="0.00149766996037215 0.001484679989516735 3.584269870771095e-05"/>
							<geom name="Geom_39" type="mesh" pos="0.006786840967833996 -9.16954718377383e-07 -0.12472491711378098" quat="0.7070883512496948 -0.004390552639961243 -0.004400269128382206 0.7070978879928589" mesh="calf" material="dark" class="visual"/>
							<geom name="Geom_40" type="capsule" pos="0.009999999776482582 0.0 -0.06499999761581421" quat="0.9970886707305908 0.0 -0.0762505829334259 0.0" size="0.009999999776482582 0.06576473265886307 0.0" class="collision"/>
							<geom name="Geom_41" type="capsule" pos="0.009999999776482582 0.0 -0.16500000655651093" quat="0.9903342723846436 0.0 0.13870121538639069 0.0" size="0.009999999776482582 0.03640054911375046 0.0" class="collision"/>
							<geom name="RR" type="sphere" pos="0.0 0.0 -0.21299999952316284" quat="1.0 0.0 0.0 0.0" size="0.023000000044703484 0.0 0.0" class="collision"/>
							<joint name="RR_calf_joint" type="hinge" pos="0.0 0.0 0.0" range="-2.818000078201294 -0.8880000114440918" axis="0.0 1.0 0.0"/>
						</body>
					</body>
				</body>
				<body name="RL_hip" pos="-0.18809999525547028 0.04675000160932541 0.0" quat="1.0 0.0 0.0 0.0">
					<inertial mass="0.6800000071525574" pos="0.004916599951684475 -0.00762614980340004 -8.864999836077914e-05" quat="0.5141689777374268 0.5073409676551819 0.4828909635543823 0.49502697587013245" diaginertia="0.0007340639713220298 0.00046843799646012485 0.0003987190139014274"/>
					<geom name="Geom_43" type="mesh" pos="0.01287506427615881 -0.0017777803586795926 1.960473952067332e-07" quat="-3.593841756810434e-05 0.7101320028305054 0.7040685415267944 -3.0720868380740285e-05" mesh="hip" material="dark" class="visual"/>
					<geom name="Geom_44" type="cylinder" pos="0.0 0.04500000178813934 0.0" quat="0.7071067690849304 0.7071067690849304 0.0 0.0" size="0.04600000008940697 0.019999999552965164 0.0" class="collision"/>
					<geom name="Geom_45" type="cylinder" pos="0.0 0.06499999761581421 0.0" quat="0.7071067690849304 0.7071067690849304 0.0 0.0" size="0.03099999949336052 0.019999999552965164 0.0" class="collision"/>
					<geom name="Geom_46" type="cylinder" pos="0.0 0.0 0.0" quat="0.7071067690849304 0.7071067690849304 0.0 0.0" size="0.04600000008940697 0.019999999552965164 0.0" class="collision"/>
					<joint name="RL_hip_joint" type="hinge" pos="0.0 0.0 0.0" range="-0.8629999756813049 0.8629999756813049" axis="1.0 0.0 0.0"/>
					<body name="RL_thigh" pos="0.0 0.07999999821186066 0.0" quat="1.0 0.0 0.0 0.0">
						<inertial mass="1.0089999437332153" pos="-0.003047219943255186 -0.019315000623464584 -0.030500400811433792" quat="0.7533828020095825 0.07751257717609406 -0.02723129279911518 0.6524298191070557" diaginertia="0.004787169862538576 0.004609030205756426 0.00070926797343418"/>
						<geom name="Geom_47" type="mesh" pos="-0.0035736847203224897 -0.02361164800822735 -0.04103037714958191" quat="0.8039950728416443 0.08563201129436493 -0.03158499300479889 0.5875895619392395" mesh="thigh" material="dark" class="visual"/>
						<geom name="Geom_48" type="capsule" pos="-0.019999999552965164 0.0 -0.07999999821186066" quat="1.0 0.0 0.0 0.0" size="0.014999999664723873 0.07999999821186066 0.0" class="collision"/>
						<geom name="Geom_49" type="capsule" pos="-0.009999999776482582 0.0 -0.05000000074505806" quat="0.9951333403587341 0.0 0.0985376164317131 0.0" size="0.014999999664723873 0.05099019408226013 0.0" class="collision"/>
						<geom name="Geom_50" type="capsule" pos="-0.009999999776482582 0.0 -0.18000000715255737" quat="0.9732490181922913 0.0 -0.22975291311740875 0.0" size="0.014999999664723873 0.022360680624842644 0.0" class="collision"/>
						<joint name="RL_thigh_joint" type="hinge" pos="0.0 0.0 0.0" range="-0.6859999895095825 4.500999927520752" axis="0.0 1.0 0.0"/>
						<body name="RL_calf" pos="0.0 0.0 -0.21299999952316284" quat="1.0 0.0 0.0 0.0">
							<inertial mass="0.19586199522018433" pos="0.0042986199259757996 0.0009766760049387813 -0.14619700610637665" quat="0.6912462711334229 0.003574671456590295 0.0051111821085214615 0.722592294216156" diaginertia="0.00149766996037215 0.001484679989516735 3.584269870771095e-05"/>
							<geom name="Geom_51" type="mesh" pos="0.006786840967833996 -9.16954718377383e-07 -0.12472491711378098" quat="0.7070883512496948 -0.004390552639961243 -0.004400269128382206 0.7070978879928589" mesh="calf" material="dark" class="visual"/>
							<geom name="Geom_52" type="capsule" pos="0.009999999776482582 0.0 -0.06499999761581421" quat="0.9970886707305908 0.0 -0.0762505829334259 0.0" size="0.009999999776482582 0.06576473265886307 0.0" class="collision"/>
							<geom name="Geom_53" type="capsule" pos="0.009999999776482582 0.0 -0.16500000655651093" quat="0.9903342723846436 0.0 0.13870121538639069 0.0" size="0.009999999776482582 0.03640054911375046 0.0" class="collision"/>
							<geom name="RL" type="sphere" pos="0.0 0.0 -0.21299999952316284" quat="1.0 0.0 0.0 0.0" size="0.023000000044703484 0.0 0.0" class="collision"/>
							<joint name="RL_calf_joint" type="hinge" pos="0.0 0.0 0.0" range="-2.818000078201294 -0.8880000114440918" axis="0.0 1.0 0.0"/>
						</body>
					</body>
				</body>
				<body name="FR_hip" pos="0.18809999525547028 -0.04675000160932541 0.0" quat="1.0 0.0 0.0 0.0">
					<inertial mass="0.6800000071525574" pos="-0.004916599951684475 0.00762614980340004 -8.864999836077914e-05" quat="0.5073409676551819 0.5141689777374268 0.49502697587013245 0.4828909635543823" diaginertia="0.0007340639713220298 0.00046843799646012485 0.0003987190139014274"/>
					<geom name="Geom_9" type="mesh" pos="-0.01287506427615881 -0.0017777803586795926 -1.960473952067332e-07" quat="0.7040685415267944 3.0720868380740285e-05 3.593841756810434e-05 0.7101320028305054" mesh="hip" material="dark" class="visual"/>
					<geom name="Geom_10" type="cylinder" pos="0.0 -0.04500000178813934 0.0" quat="0.7071067690849304 0.7071067690849304 0.0 0.0" size="0.04600000008940697 0.019999999552965164 0.0" class="collision"/>
					<geom name="Geom_11" type="cylinder" pos="0.0 -0.06499999761581421 0.0" quat="0.7071067690849304 0.7071067690849304 0.0 0.0" size="0.03099999949336052 0.019999999552965164 0.0" class="collision"/>
					<joint name="FR_hip_joint" type="hinge" pos="0.0 0.0 0.0" range="-0.8629999756813049 0.8629999756813049" axis="1.0 0.0 0.0"/>
					<body name="FR_thigh" pos="0.0 -0.07999999821186066 0.0" quat="1.0 0.0 0.0 0.0">
						<inertial mass="1.0089999437332153" pos="-0.003047219943255186 0.019315000623464584 -0.030500400811433792" quat="0.6524298191070557 -0.02723129279911518 0.07751257717609406 0.7533828020095825" diaginertia="0.004787169862538576 0.004609030205756426 0.00070926797343418"/>
						<geom name="Geom_12" type="mesh" pos="-0.004290462005883455 0.022090628743171692 -0.04642722010612488" quat="0.5726116895675659 -0.0309742484241724 0.09420688450336456 0.8138068318367004" mesh="thigh_mirror" material="dark" class="visual"/>
						<geom name="Geom_13" type="capsule" pos="-0.019999999552965164 0.0 -0.07999999821186066" quat="1.0 0.0 0.0 0.0" size="0.014999999664723873 0.07999999821186066 0.0" class="collision"/>
						<geom name="Geom_14" type="capsule" pos="-0.009999999776482582 0.0 -0.05000000074505806" quat="0.9951333403587341 0.0 0.0985376164317131 0.0" size="0.014999999664723873 0.05099019408226013 0.0" class="collision"/>
						<geom name="Geom_15" type="capsule" pos="-0.009999999776482582 0.0 -0.18000000715255737" quat="0.9732490181922913 0.0 -0.22975291311740875 0.0" size="0.014999999664723873 0.022360680624842644 0.0" class="collision"/>
						<joint name="FR_thigh_joint" type="hinge" pos="0.0 0.0 0.0" range="-0.6859999895095825 4.500999927520752" axis="0.0 1.0 0.0"/>
						<body name="FR_calf" pos="0.0 0.0 -0.21299999952316284" quat="1.0 0.0 0.0 0.0">
							<inertial mass="0.19586199522018433" pos="0.0042986199259757996 0.0009766760049387813 -0.14619700610637665" quat="0.6912462711334229 0.003574671456590295 0.0051111821085214615 0.722592294216156" diaginertia="0.00149766996037215 0.001484679989516735 3.584269870771095e-05"/>
							<geom name="Geom_16" type="mesh" pos="0.006786840967833996 -9.16954718377383e-07 -0.12472491711378098" quat="0.7070883512496948 -0.004390552639961243 -0.004400269128382206 0.7070978879928589" mesh="calf" material="dark" class="visual"/>
							<geom name="Geom_17" type="capsule" pos="0.009999999776482582 0.0 -0.06499999761581421" quat="0.9970886707305908 0.0 -0.0762505829334259 0.0" size="0.009999999776482582 0.06576473265886307 0.0" class="collision"/>
							<geom name="Geom_18" type="capsule" pos="0.009999999776482582 0.0 -0.16500000655651093" quat="0.9903342723846436 0.0 0.13870121538639069 0.0" size="0.009999999776482582 0.03640054911375046 0.0" class="collision"/>
							<geom name="FR" type="sphere" pos="0.0 0.0 -0.21299999952316284" quat="1.0 0.0 0.0 0.0" size="0.023000000044703484 0.0 0.0" class="collision"/>
							<joint name="FR_calf_joint" type="hinge" pos="0.0 0.0 0.0" range="-2.818000078201294 -0.8880000114440918" axis="0.0 1.0 0.0"/>
						</body>
					</body>
				</body>
			</body>
		</body>
	</worldbody>
	<equality/>
</mujoco>
