<?xml version="1.0" ?>
<mujoco model="barkour v0">
	<compiler meshdir="barkour v0/meshes" texturedir="barkour v0/textures" angle="radian" autolimits="true" balanceinertia="true" boundmass="0.000001" boundinertia="0.000001"/>
	<default>
		<default class="visual">
			<geom contype="0" conaffinity="0"/>
		</default>
		<default class="collision">
			<geom rgba="1.0 0.0 0.0 0.0"/>
		</default>
	</default>
	<asset>
		<mesh name="head" file="stl/head.stl" scale="1.0 1.0 1.0"/>
		<mesh name="powercable" file="stl/powercable.stl" scale="1.0 1.0 1.0"/>
		<mesh name="handle" file="stl/handle.stl" scale="1.0 1.0 1.0"/>
		<mesh name="head_mount" file="stl/head_mount.stl" scale="1.0 1.0 1.0"/>
		<mesh name="body" file="stl/body.stl" scale="1.0 1.0 1.0"/>
		<mesh name="abduction" file="stl/abduction.stl" scale="1.0 1.0 1.0"/>
		<mesh name="upper_right_2" file="stl/upper_right_2.stl" scale="1.0 1.0 1.0"/>
		<mesh name="upper_right_3" file="stl/upper_right_3.stl" scale="1.0 1.0 1.0"/>
		<mesh name="upper_right_1" file="stl/upper_right_1.stl" scale="1.0 1.0 1.0"/>
		<mesh name="lower_leg_1to1" file="stl/lower_leg_1to1.stl" scale="1.0 1.0 1.0"/>
		<mesh name="foot" file="stl/foot.stl" scale="1.0 1.0 1.0"/>
		<mesh name="upper_left_2" file="stl/upper_left_2.stl" scale="1.0 1.0 1.0"/>
		<mesh name="upper_left_1" file="stl/upper_left_1.stl" scale="1.0 1.0 1.0"/>
		<mesh name="upper_left_3" file="stl/upper_left_3.stl" scale="1.0 1.0 1.0"/>
	</asset>
	<worldbody>
		<body name="barkour_v0" pos="0.0 0.0 0.0" quat="1.0 0.0 0.0 0.0">
			<body name="chassis" pos="0.0 0.0 0.0" quat="1.0 0.0 0.0 0.0">
				<geom name="Geom_0" type="mesh" pos="0.2530902624130249 8.33469966892153e-05 0.09028945863246918" quat="0.7053528428077698 0.7060047388076782 0.04490462690591812 -0.044924795627593994" mesh="head" class="collision"/>
				<geom name="Geom_1" type="mesh" pos="-0.024854660034179688 0.00014442177780438215 0.11115658283233643" quat="-0.0005914939101785421 0.7188302874565125 -0.0008145030005834997 0.6951848864555359" mesh="powercable" class="collision"/>
				<geom name="Geom_2" type="mesh" pos="0.0370459221303463 -0.0015246681869029999 0.1166631281375885" quat="-0.13158100843429565 0.6992385387420654 0.11509702354669571 0.6931843757629395" mesh="handle" class="collision"/>
				<geom name="Geom_3" type="mesh" pos="0.14102284610271454 -8.848850848153234e-05 0.07858497649431229" quat="0.5589752793312073 0.43497586250305176 0.4338955581188202 0.5568458437919617" mesh="head_mount" class="collision"/>
				<geom name="Geom_4" type="mesh" pos="-0.0022199309896677732 -6.688345365546411e-06 0.0506247952580452" quat="-0.0006346179288811982 0.7080058455467224 0.0003671057347673923 0.706206202507019" mesh="body" class="collision"/>
				<body name="abduction_2" pos="0.13053299486637115 0.0560000017285347 0.05079999938607216" quat="0.1611519306898117 1.0956396181427408e-06 0.9869295954704285 1.0956396181427408e-06">
					<inertial mass="0.6394370198249817" pos="-0.052115198224782944 0.0035091699101030827 0.017191199585795403" quat="0.38787686824798584 0.592261791229248 0.5924918055534363 0.38435786962509155" diaginertia="0.0008660079911351204 0.000565866008400917 0.0004797670117113739"/>
					<geom name="Geom_11" type="mesh" pos="-0.05088985711336136 -0.0035264857579022646 0.016803786158561707" quat="0.3802955150604248 0.572089672088623 0.60170978307724 0.40747275948524475" mesh="abduction" class="collision"/>
					<joint name="abduction_front_left" type="hinge" pos="0.0 0.0 0.0" range="-1.0471999645233154 1.0471999645233154" axis="0.9480598568916321 0.0 -0.3180919587612152"/>
					<body name="upper_left_asm_1" pos="-0.054039400070905685 0.021700000390410423 0.018131200224161148" quat="0.6718177795410156 0.6718208193778992 0.22058694064617157 -0.22058793902397156">
						<inertial mass="0.9387909770011902" pos="0.030656199902296066 0.006291890051215887 -0.046600498259067535" quat="-0.11334196478128433 0.7512937784194946 0.05556408315896988 0.6477838158607483" diaginertia="0.0053815701976418495 0.005184450186789036 0.0007903469959273934"/>
						<geom name="Geom_12" type="mesh" pos="0.0312926322221756 0.0005465516005642712 -0.06781699508428574" quat="-0.080054871737957 0.7073342800140381 0.044316429644823074 0.7009318470954895" mesh="upper_left_2" class="collision"/>
						<geom name="Geom_13" type="mesh" pos="0.0004683269071392715 -0.0013757734559476376 -0.02472984977066517" quat="0.26455551385879517 0.6478133201599121 -0.24149635434150696 0.6723300814628601" mesh="upper_left_1" class="collision"/>
						<geom name="Geom_14" type="mesh" pos="0.20238028466701508 0.05293074622750282 -0.06724870949983597" quat="-0.09295829385519028 0.7030816078186035 0.09636817872524261 0.6983897089958191" mesh="upper_left_3" class="collision"/>
						<joint name="hip_front_left" type="hinge" pos="0.0 0.0 0.0" range="-1.2217299938201904 3.246309995651245" axis="0.0 0.0 1.0"/>
						<body name="lower_leg_1to1_front_left" pos="0.20883500576019287 0.06919539719820023 -0.07919999957084656" quat="0.03862641006708145 0.9952492713928223 0.0893024206161499 0.003465900896117091">
							<inertial mass="0.169623002409935" pos="-0.057750899344682693 -0.007804629858583212 -0.012963900342583656" quat="-0.047102976590394974 0.705358624458313 -0.01024649478495121 0.7072096467018127" diaginertia="0.0008287410018965602 0.000813963997643441 3.499009835650213e-05"/>
							<geom name="Geom_15" type="mesh" pos="-0.19568970799446106 -0.01991048827767372 -0.013959757052361965" quat="0.9459324479103088 -0.26307687163352966 -0.06483010947704315 0.17832399904727936" mesh="foot" class="collision"/>
							<geom name="Geom_16" type="mesh" pos="-0.0702187716960907 -0.008044092915952206 -0.012962114997208118" quat="-0.053995706140995026 0.7050222158432007 -0.007419238332659006 0.7070877552032471" mesh="lower_leg_1to1" class="collision"/>
							<joint name="knee_front_left" type="hinge" pos="0.0 0.0 0.0" range="0.0 2.513200044631958" axis="0.0 -0.07750092446804047 0.996992290019989"/>
						</body>
					</body>
				</body>
				<body name="abduction_3" pos="-0.13466699421405792 -0.0560000017285347 0.05079999938607216" quat="1.3094494306642446e-06 0.9869295954704285 2.138159089781766e-07 -0.1611519306898117">
					<inertial mass="0.6394370198249817" pos="-0.052115198224782944 0.0035091699101030827 0.017191199585795403" quat="0.38787686824798584 0.592261791229248 0.5924918055534363 0.38435786962509155" diaginertia="0.0008660079911351204 0.000565866008400917 0.0004797670117113739"/>
					<geom name="Geom_17" type="mesh" pos="-0.05088985711336136 -0.0035264857579022646 0.016803786158561707" quat="0.3802955150604248 0.572089672088623 0.60170978307724 0.40747275948524475" mesh="abduction" class="collision"/>
					<joint name="abduction_hind_right" type="hinge" pos="0.0 0.0 0.0" range="-1.0471999645233154 1.0471999645233154" axis="0.9480598568916321 0.0 -0.3180919587612152"/>
					<body name="upper_right_asm_2" pos="-0.054039400070905685 0.021700000390410423 0.018131200224161148" quat="0.6472898721694946 0.647291898727417 0.2846299409866333 -0.2846309542655945">
						<inertial mass="0.9421550035476685" pos="-0.025365499779582024 -0.017937399446964264 -0.046502698212862015" quat="-0.2456890344619751 0.6390070915222168 0.15335102379322052 0.7125940918922424" diaginertia="0.005394029896706343 0.005194029770791531 0.0007952980231493711"/>
						<geom name="Geom_18" type="mesh" pos="-0.02156836912035942 -0.022057760506868362 -0.06744057685136795" quat="-0.2454206794500351 0.6742171049118042 0.20137302577495575 0.6668199896812439" mesh="upper_right_2" class="collision"/>
						<geom name="Geom_19" type="mesh" pos="-0.17723383009433746 -0.1111007109284401 -0.06725139915943146" quat="-0.19026902318000793 0.6779831647872925 0.19170896708965302 0.6836550235748291" mesh="upper_right_3" class="collision"/>
						<geom name="Geom_20" type="mesh" pos="0.0005172314122319221 -0.001469491864554584 -0.024606628343462944" quat="0.2697412073612213 0.6452414393424988 -0.2455632984638214 0.6712688207626343" mesh="upper_right_1" class="collision"/>
						<joint name="hip_hind_right" type="hinge" pos="0.0 0.0 0.0" range="-1.9896800518035889 2.4609100818634033" axis="0.0 0.0 -1.0"/>
						<body name="lower_leg_1to1_hind_right" pos="-0.19352300465106964 -0.10463699698448181 -0.07919999957084656" quat="0.31274205446243286 -0.012137101963162422 0.03683140501379967 -0.9490461349487305">
							<inertial mass="0.169623002409935" pos="-0.057750899344682693 -0.009703399613499641 0.011462399736046791" quat="-0.047102976590394974 0.705358624458313 -0.01024649478495121 0.7072096467018127" diaginertia="0.0008287410018965602 0.000813963997643441 3.499009835650213e-05"/>
							<geom name="Geom_21" type="mesh" pos="-0.0702187716960907 -0.009942793287336826 0.011464185081422329" quat="-0.053995706140995026 0.7050222158432007 -0.007419238332659006 0.7070877552032471" mesh="lower_leg_1to1" class="collision"/>
							<geom name="Geom_22" type="mesh" pos="-0.19568970799446106 -0.021809188649058342 0.010466543026268482" quat="0.9459324479103088 -0.26307687163352966 -0.06483010947704315 0.17832399904727936" mesh="foot" class="collision"/>
							<joint name="knee_hind_right" type="hinge" pos="0.0 0.0 0.0" range="0.0 2.513200044631958" axis="0.0 -0.07750092446804047 0.996992290019989"/>
						</body>
					</body>
				</body>
				<body name="abduction_4" pos="-0.13466699421405792 0.0560000017285347 0.05079999938607216" quat="0.9869295954704285 0.0 -0.1611519306898117 0.0">
					<inertial mass="0.6394370198249817" pos="-0.052115198224782944 0.0035091699101030827 0.017191199585795403" quat="0.38787686824798584 0.592261791229248 0.5924918055534363 0.38435786962509155" diaginertia="0.0008660079911351204 0.000565866008400917 0.0004797670117113739"/>
					<geom name="Geom_23" type="mesh" pos="-0.05088985711336136 -0.0035264857579022646 0.016803786158561707" quat="0.3802955150604248 0.572089672088623 0.60170978307724 0.40747275948524475" mesh="abduction" class="collision"/>
					<joint name="abduction_hind_left" type="hinge" pos="0.0 0.0 0.0" range="-1.0471999645233154 1.0471999645233154" axis="-0.9480598568916321 0.0 0.3180919587612152"/>
					<body name="upper_left_asm_2" pos="-0.054039400070905685 0.021700000390410423 0.018131200224161148" quat="-0.2205870896577835 -0.2205880880355835 0.6718202829360962 -0.6718182563781738">
						<inertial mass="0.9387909770011902" pos="0.030656199902296066 0.006291890051215887 -0.046600498259067535" quat="-0.11334196478128433 0.7512937784194946 0.05556408315896988 0.6477838158607483" diaginertia="0.0053815701976418495 0.005184450186789036 0.0007903469959273934"/>
						<geom name="Geom_24" type="mesh" pos="0.0004683269071392715 -0.0013757734559476376 -0.02472984977066517" quat="0.26455551385879517 0.6478133201599121 -0.24149635434150696 0.6723300814628601" mesh="upper_left_1" class="collision"/>
						<geom name="Geom_25" type="mesh" pos="0.20238028466701508 0.05293074622750282 -0.06724870949983597" quat="-0.09295829385519028 0.7030816078186035 0.09636817872524261 0.6983897089958191" mesh="upper_left_3" class="collision"/>
						<geom name="Geom_26" type="mesh" pos="0.0312926322221756 0.0005465516005642712 -0.06781699508428574" quat="-0.080054871737957 0.7073342800140381 0.044316429644823074 0.7009318470954895" mesh="upper_left_2" class="collision"/>
						<joint name="hip_hind_left" type="hinge" pos="0.0 0.0 0.0" range="-1.9896800518035889 2.4609100818634033" axis="0.0 0.0 1.0"/>
						<body name="lower_leg_1to1_hind_left" pos="0.20883500576019287 0.06919539719820023 -0.07919999957084656" quat="0.03862641006708145 0.9952492713928223 0.0893024206161499 0.003465900896117091">
							<inertial mass="0.169623002409935" pos="-0.057750899344682693 -0.007804629858583212 -0.012963900342583656" quat="-0.047102976590394974 0.705358624458313 -0.01024649478495121 0.7072096467018127" diaginertia="0.0008287410018965602 0.000813963997643441 3.499009835650213e-05"/>
							<geom name="Geom_27" type="mesh" pos="-0.19568970799446106 -0.01991048827767372 -0.013959757052361965" quat="0.9459324479103088 -0.26307687163352966 -0.06483010947704315 0.17832399904727936" mesh="foot" class="collision"/>
							<geom name="Geom_28" type="mesh" pos="-0.0702187716960907 -0.008044092915952206 -0.012962114997208118" quat="-0.053995706140995026 0.7050222158432007 -0.007419238332659006 0.7070877552032471" mesh="lower_leg_1to1" class="collision"/>
							<joint name="knee_hind_left" type="hinge" pos="0.0 0.0 0.0" range="0.0 2.513200044631958" axis="0.0 -0.07750092446804047 0.996992290019989"/>
						</body>
					</body>
				</body>
				<body name="abduction_1" pos="0.13053299486637115 -0.0560000017285347 0.05079999938607216" quat="1.3094494306642446e-06 0.1611519306898117 -2.138159089781766e-07 0.9869295954704285">
					<inertial mass="0.6394370198249817" pos="-0.052115198224782944 0.0035091699101030827 0.017191199585795403" quat="0.38787686824798584 0.592261791229248 0.5924918055534363 0.38435786962509155" diaginertia="0.0008660079911351204 0.000565866008400917 0.0004797670117113739"/>
					<geom name="Geom_5" type="mesh" pos="-0.05088985711336136 -0.0035264857579022646 0.016803786158561707" quat="0.3802955150604248 0.572089672088623 0.60170978307724 0.40747275948524475" mesh="abduction" class="collision"/>
					<joint name="abduction_front_right" type="hinge" pos="0.0 0.0 0.0" range="-1.0471999645233154 1.0471999645233154" axis="-0.9480598568916321 0.0 0.3180919587612152"/>
					<body name="upper_right_asm_1" pos="-0.054039400070905685 0.021700000390410423 0.018131200224161148" quat="0.28463214635849 0.28462913632392883 -0.6472923159599304 0.6472893357276917">
						<inertial mass="0.9421550035476685" pos="-0.025365499779582024 -0.017937399446964264 -0.046502698212862015" quat="-0.2456890344619751 0.6390070915222168 0.15335102379322052 0.7125940918922424" diaginertia="0.005394029896706343 0.005194029770791531 0.0007952980231493711"/>
						<geom name="Geom_6" type="mesh" pos="-0.02156836912035942 -0.022057760506868362 -0.06744057685136795" quat="-0.2454206794500351 0.6742171049118042 0.20137302577495575 0.6668199896812439" mesh="upper_right_2" class="collision"/>
						<geom name="Geom_7" type="mesh" pos="-0.17723383009433746 -0.1111007109284401 -0.06725139915943146" quat="-0.19026902318000793 0.6779831647872925 0.19170896708965302 0.6836550235748291" mesh="upper_right_3" class="collision"/>
						<geom name="Geom_8" type="mesh" pos="0.0005172314122319221 -0.001469491864554584 -0.024606628343462944" quat="0.2697412073612213 0.6452414393424988 -0.2455632984638214 0.6712688207626343" mesh="upper_right_1" class="collision"/>
						<joint name="hip_front_right" type="hinge" pos="0.0 0.0 0.0" range="-1.2217299938201904 3.246309995651245" axis="0.0 0.0 -1.0"/>
						<body name="lower_leg_1to1_front_right" pos="-0.19352300465106964 -0.10463699698448181 -0.07919999957084656" quat="0.31274205446243286 -0.012137101963162422 0.03683140501379967 -0.9490461349487305">
							<inertial mass="0.169623002409935" pos="-0.057750899344682693 -0.009703399613499641 0.011462399736046791" quat="-0.047102976590394974 0.705358624458313 -0.01024649478495121 0.7072096467018127" diaginertia="0.0008287410018965602 0.000813963997643441 3.499009835650213e-05"/>
							<geom name="Geom_9" type="mesh" pos="-0.0702187716960907 -0.009942793287336826 0.011464185081422329" quat="-0.053995706140995026 0.7050222158432007 -0.007419238332659006 0.7070877552032471" mesh="lower_leg_1to1" class="collision"/>
							<geom name="Geom_10" type="mesh" pos="-0.19568970799446106 -0.021809188649058342 0.010466543026268482" quat="0.9459324479103088 -0.26307687163352966 -0.06483010947704315 0.17832399904727936" mesh="foot" class="collision"/>
							<joint name="knee_front_right" type="hinge" pos="0.0 0.0 0.0" range="0.0 2.513200044631958" axis="0.0 -0.07750092446804047 0.996992290019989"/>
						</body>
					</body>
				</body>
			</body>
		</body>
	</worldbody>
	<equality/>
</mujoco>
