<?xml version="1.0" ?>
<robot name="h1" version="1.0">
  <link name="h1"/>
  <joint name="pelvis_joint" type="fixed">
    <origin xyz="0.0 0.0 0.0" rpy="0.0 0.0 0.0"/>
    <parent link="h1"/>
    <child link="pelvis"/>
  </joint>
  <link name="pelvis">
    <visual name="Geom_0">
      <origin xyz="1.4959405234549195e-06 2.051345518339076e-06 -0.04126008599996567" rpy="1.6107969284057617 -1.5705887079238892 -0.039993882179260254"/>
      <geometry>
        <mesh filename="file://h1/meshes/obj/pelvis.obj" scale="1.0 1.0 1.0"/>
      </geometry>
    </visual>
    <collision name="Geom_1">
      <origin xyz="1.4959405234549195e-06 2.051345518339076e-06 -0.04126008599996567" rpy="1.6107969284057617 -1.5705887079238892 -0.039993882179260254"/>
      <geometry>
        <mesh filename="file://h1/meshes/stl/pelvis.stl" scale="1.0 1.0 1.0"/>
      </geometry>
    </collision>
  </link>
  <joint name="left_hip_yaw" type="revolute">
    <origin xyz="0.0 0.08749999850988388 -0.17419999837875366" rpy="0.0 0.0 0.0"/>
    <axis xyz="0.0 0.0 1.0"/>
    <parent link="pelvis"/>
    <child link="left_hip_yaw_link"/>
    <limit effort="1000.0" lower="-0.4300000071525574" upper="0.4300000071525574" velocity="1000.0"/>
  </joint>
  <link name="left_hip_yaw_link">
    <inertial>
      <origin xyz="-0.049229998141527176 9.999999747378752e-05 0.007199999876320362" rpy="0.6504185199737549 0.04391371086239815 1.502997875213623"/>
      <mass value="2.24399995803833"/>
      <inertia ixx="0.0030449400655925274" ixy="0.0" ixz="0.0" iyy="0.002968850079923868" iyz="0.0" izz="0.0018920099828392267"/>
    </inertial>
    <visual name="Geom_2">
      <origin xyz="-0.03807055205106735 -3.327455033286242e-06 0.03356019780039787" rpy="-9.174742444884032e-05 0.6569103002548218 -1.9461067495285533e-05"/>
      <geometry>
        <mesh filename="file://h1/meshes/obj/left_hip_yaw_link.obj" scale="1.0 1.0 1.0"/>
      </geometry>
    </visual>
    <collision name="Geom_3">
      <origin xyz="-0.06700000166893005 0.0 0.0" rpy="0.0 1.5707496404647827 0.0"/>
      <geometry>
        <cylinder radius="0.05999999865889549" length="0.07000000029802322"/>
      </geometry>
    </collision>
  </link>
  <joint name="left_hip_roll" type="revolute">
    <origin xyz="0.03946800157427788 0.0 0.0" rpy="0.0 0.0 0.0"/>
    <axis xyz="1.0 0.0 0.0"/>
    <parent link="left_hip_yaw_link"/>
    <child link="left_hip_roll_link"/>
    <limit effort="1000.0" lower="-0.4300000071525574" upper="0.4300000071525574" velocity="1000.0"/>
  </joint>
  <link name="left_hip_roll_link">
    <inertial>
      <origin xyz="-0.005799999926239252 -0.0031900000758469105 -9.000000136438757e-05" rpy="-1.8351385593414307 -1.5289748907089233 -1.47176194190979"/>
      <mass value="2.2320001125335693"/>
      <inertia ixx="0.002432639943435788" ixy="0.0" ixz="0.0" iyy="0.0022532499860972166" iyz="0.0" izz="0.0020549199543893337"/>
    </inertial>
    <visual name="Geom_4">
      <origin xyz="-0.020227232947945595 -0.009204677306115627 3.911885869456455e-06" rpy="1.5705249309539795 0.00022608792642131448 1.3235301971435547"/>
      <geometry>
        <mesh filename="file://h1/meshes/obj/left_hip_roll_link.obj" scale="1.0 1.0 1.0"/>
      </geometry>
    </visual>
    <collision name="Geom_5">
      <origin xyz="-0.020227232947945595 -0.009204677306115627 3.911885869456455e-06" rpy="1.5705249309539795 0.00022608792642131448 1.3235301971435547"/>
      <geometry>
        <mesh filename="file://h1/meshes/stl/left_hip_roll_link.stl" scale="1.0 1.0 1.0"/>
      </geometry>
    </collision>
  </link>
  <joint name="left_hip_pitch" type="revolute">
    <origin xyz="0.0 0.11535999923944473 0.0" rpy="0.0 0.0 0.0"/>
    <axis xyz="0.0 1.0 0.0"/>
    <parent link="left_hip_roll_link"/>
    <child link="left_hip_pitch_link"/>
    <limit effort="1000.0" lower="-1.5700000524520874" upper="1.5700000524520874" velocity="1000.0"/>
  </joint>
  <link name="left_hip_pitch_link">
    <inertial>
      <origin xyz="0.007459999993443489 -0.02346000075340271 -0.0819299966096878" rpy="0.10738416016101837 -0.01352748367935419 -0.3884797990322113"/>
      <mass value="4.1519999504089355"/>
      <inertia ixx="0.08295030146837234" ixy="0.0" ixz="0.0" iyy="0.08214569836854935" iyz="0.0" izz="0.005109089892357588"/>
    </inertial>
    <visual name="Geom_6">
      <origin xyz="0.012151024304330349 -0.019641246646642685 -0.130537211894989" rpy="0.1103617399930954 -0.02140846475958824 -0.36656108498573303"/>
      <geometry>
        <mesh filename="file://h1/meshes/obj/left_hip_pitch_link.obj" scale="1.0 1.0 1.0"/>
      </geometry>
    </visual>
    <collision name="Geom_7">
      <origin xyz="0.012151024304330349 -0.019641246646642685 -0.130537211894989" rpy="0.1103617399930954 -0.02140846475958824 -0.36656108498573303"/>
      <geometry>
        <mesh filename="file://h1/meshes/stl/left_hip_pitch_link.stl" scale="1.0 1.0 1.0"/>
      </geometry>
    </collision>
  </link>
  <joint name="left_knee" type="revolute">
    <origin xyz="0.0 0.0 -0.4000000059604645" rpy="0.0 0.0 0.0"/>
    <axis xyz="0.0 1.0 0.0"/>
    <parent link="left_hip_pitch_link"/>
    <child link="left_knee_link"/>
    <limit effort="1000.0" lower="-0.2600000202655792" upper="2.049999952316284" velocity="1000.0"/>
  </joint>
  <link name="left_knee_link">
    <inertial>
      <origin xyz="-0.0013599999947473407 -0.005119999870657921 -0.13840000331401825" rpy="-0.10783059895038605 0.0011182109592482448 1.7860283851623535"/>
      <mass value="1.7209999561309814"/>
      <inertia ixx="0.012523699551820755" ixy="0.0" ixz="0.0" iyy="0.012310399673879147" iyz="0.0" izz="0.0019428000086918473"/>
    </inertial>
    <visual name="Geom_8">
      <origin xyz="0.007670897524803877 -0.0017604113090783358 -0.16003209352493286" rpy="-0.050767578184604645 -0.0021995985880494118 1.664547085762024"/>
      <geometry>
        <mesh filename="file://h1/meshes/obj/left_knee_link.obj" scale="1.0 1.0 1.0"/>
      </geometry>
    </visual>
    <collision name="Geom_9">
      <origin xyz="0.007670897524803877 -0.0017604113090783358 -0.16003209352493286" rpy="-0.050767578184604645 -0.0021995985880494118 1.664547085762024"/>
      <geometry>
        <mesh filename="file://h1/meshes/stl/left_knee_link.stl" scale="1.0 1.0 1.0"/>
      </geometry>
    </collision>
  </link>
  <joint name="left_ankle" type="revolute">
    <origin xyz="0.0 0.0 -0.4000000059604645" rpy="0.0 0.0 0.0"/>
    <axis xyz="0.0 1.0 0.0"/>
    <parent link="left_knee_link"/>
    <child link="left_ankle_link"/>
    <limit effort="1000.0" lower="-0.8700000047683716" upper="0.5200000405311584" velocity="1000.0"/>
  </joint>
  <link name="left_ankle_link">
    <inertial>
      <origin xyz="0.06722000241279602 0.0001500000071246177 -0.04496999830007553" rpy="1.718996524810791 0.11798209697008133 1.586050033569336"/>
      <mass value="0.44600000977516174"/>
      <inertia ixx="0.0022084799129515886" ixy="0.0" ixz="0.0" iyy="0.002189609920606017" iyz="0.0" izz="0.00021420199482236058"/>
    </inertial>
    <visual name="Geom_10">
      <origin xyz="0.0714942142367363 1.047239379659004e-07 -0.04708452895283699" rpy="3.1358635425567627 -1.4449570178985596 0.005759225692600012"/>
      <geometry>
        <mesh filename="file://h1/meshes/obj/left_ankle_link.obj" scale="1.0 1.0 1.0"/>
      </geometry>
    </visual>
    <collision name="Geom_11">
      <origin xyz="0.0714942142367363 1.047239379659004e-07 -0.04708452895283699" rpy="3.1358635425567627 -1.4449570178985596 0.005759225692600012"/>
      <geometry>
        <mesh filename="file://h1/meshes/stl/left_ankle_link.stl" scale="1.0 1.0 1.0"/>
      </geometry>
    </collision>
  </link>
  <joint name="right_hip_yaw" type="revolute">
    <origin xyz="0.0 -0.08749999850988388 -0.17419999837875366" rpy="0.0 0.0 0.0"/>
    <axis xyz="0.0 0.0 1.0"/>
    <parent link="pelvis"/>
    <child link="right_hip_yaw_link"/>
    <limit effort="1000.0" lower="-0.4300000071525574" upper="0.4300000071525574" velocity="1000.0"/>
  </joint>
  <link name="right_hip_yaw_link">
    <inertial>
      <origin xyz="-0.049229998141527176 -9.999999747378752e-05 0.007199999876320362" rpy="0.6504185199737549 -0.04391371086239815 1.6385948657989502"/>
      <mass value="2.24399995803833"/>
      <inertia ixx="0.0030449400655925274" ixy="0.0" ixz="0.0" iyy="0.002968850079923868" iyz="0.0" izz="0.0018920099828392267"/>
    </inertial>
    <visual name="Geom_12">
      <origin xyz="-0.03807106986641884 3.4278398288734024e-06 0.033565454185009" rpy="0.00020859525830019265 0.6569957733154297 0.0002115319512085989"/>
      <geometry>
        <mesh filename="file://h1/meshes/obj/right_hip_yaw_link.obj" scale="1.0 1.0 1.0"/>
      </geometry>
    </visual>
    <collision name="Geom_13">
      <origin xyz="-0.06700000166893005 0.0 0.0" rpy="0.0 1.5707496404647827 0.0"/>
      <geometry>
        <cylinder radius="0.05999999865889549" length="0.07000000029802322"/>
      </geometry>
    </collision>
  </link>
  <joint name="right_hip_roll" type="revolute">
    <origin xyz="0.03946800157427788 0.0 0.0" rpy="0.0 0.0 0.0"/>
    <axis xyz="1.0 0.0 0.0"/>
    <parent link="right_hip_yaw_link"/>
    <child link="right_hip_roll_link"/>
    <limit effort="1000.0" lower="-0.4300000071525574" upper="0.4300000071525574" velocity="1000.0"/>
  </joint>
  <link name="right_hip_roll_link">
    <inertial>
      <origin xyz="-0.005799999926239252 0.0031900000758469105 -9.000000136438757e-05" rpy="1.8351385593414307 -1.5289748907089233 1.47176194190979"/>
      <mass value="2.2320001125335693"/>
      <inertia ixx="0.002432639943435788" ixy="0.0" ixz="0.0" iyy="0.0022532499860972166" iyz="0.0" izz="0.0020549199543893337"/>
    </inertial>
    <visual name="Geom_14">
      <origin xyz="-0.020227110013365746 0.00920272059738636 1.7128593299275963e-06" rpy="1.5705137252807617 -0.00036306839319877326 1.8181883096694946"/>
      <geometry>
        <mesh filename="file://h1/meshes/obj/right_hip_roll_link.obj" scale="1.0 1.0 1.0"/>
      </geometry>
    </visual>
    <collision name="Geom_15">
      <origin xyz="-0.020227110013365746 0.00920272059738636 1.7128593299275963e-06" rpy="1.5705137252807617 -0.00036306839319877326 1.8181883096694946"/>
      <geometry>
        <mesh filename="file://h1/meshes/stl/right_hip_roll_link.stl" scale="1.0 1.0 1.0"/>
      </geometry>
    </collision>
  </link>
  <joint name="right_hip_pitch" type="revolute">
    <origin xyz="0.0 -0.11535999923944473 0.0" rpy="0.0 0.0 0.0"/>
    <axis xyz="0.0 1.0 0.0"/>
    <parent link="right_hip_roll_link"/>
    <child link="right_hip_pitch_link"/>
    <limit effort="1000.0" lower="-1.5700000524520874" upper="1.5700000524520874" velocity="1000.0"/>
  </joint>
  <link name="right_hip_pitch_link">
    <inertial>
      <origin xyz="0.007459999993443489 0.02346000075340271 -0.0819299966096878" rpy="-0.10738416016101837 -0.01352748367935419 0.3884797990322113"/>
      <mass value="4.1519999504089355"/>
      <inertia ixx="0.08295030146837234" ixy="0.0" ixz="0.0" iyy="0.08214569836854935" iyz="0.0" izz="0.005109089892357588"/>
    </inertial>
    <visual name="Geom_16">
      <origin xyz="0.012151695787906647 0.01963897980749607 -0.13054850697517395" rpy="-0.11036311835050583 -0.02138403058052063 0.3667833209037781"/>
      <geometry>
        <mesh filename="file://h1/meshes/obj/right_hip_pitch_link.obj" scale="1.0 1.0 1.0"/>
      </geometry>
    </visual>
    <collision name="Geom_17">
      <origin xyz="0.012151695787906647 0.01963897980749607 -0.13054850697517395" rpy="-0.11036311835050583 -0.02138403058052063 0.3667833209037781"/>
      <geometry>
        <mesh filename="file://h1/meshes/stl/right_hip_pitch_link.stl" scale="1.0 1.0 1.0"/>
      </geometry>
    </collision>
  </link>
  <joint name="right_knee" type="revolute">
    <origin xyz="0.0 0.0 -0.4000000059604645" rpy="0.0 0.0 0.0"/>
    <axis xyz="0.0 1.0 0.0"/>
    <parent link="right_hip_pitch_link"/>
    <child link="right_knee_link"/>
    <limit effort="1000.0" lower="-0.2600000202655792" upper="2.049999952316284" velocity="1000.0"/>
  </joint>
  <link name="right_knee_link">
    <inertial>
      <origin xyz="-0.0013599999947473407 0.005119999870657921 -0.13840000331401825" rpy="-0.10783059895038605 -0.0011182109592482448 1.3555643558502197"/>
      <mass value="1.7209999561309814"/>
      <inertia ixx="0.012523699551820755" ixy="0.0" ixz="0.0" iyy="0.012310399673879147" iyz="0.0" izz="0.0019428000086918473"/>
    </inertial>
    <visual name="Geom_18">
      <origin xyz="0.0076714251190423965 0.0017608820926398039 -0.16004091501235962" rpy="-0.0507693737745285 0.002180330455303192 1.4770429134368896"/>
      <geometry>
        <mesh filename="file://h1/meshes/obj/right_knee_link.obj" scale="1.0 1.0 1.0"/>
      </geometry>
    </visual>
    <collision name="Geom_19">
      <origin xyz="0.0076714251190423965 0.0017608820926398039 -0.16004091501235962" rpy="-0.0507693737745285 0.002180330455303192 1.4770429134368896"/>
      <geometry>
        <mesh filename="file://h1/meshes/stl/right_knee_link.stl" scale="1.0 1.0 1.0"/>
      </geometry>
    </collision>
  </link>
  <joint name="right_ankle" type="revolute">
    <origin xyz="0.0 0.0 -0.4000000059604645" rpy="0.0 0.0 0.0"/>
    <axis xyz="0.0 1.0 0.0"/>
    <parent link="right_knee_link"/>
    <child link="right_ankle_link"/>
    <limit effort="1000.0" lower="-0.8700000047683716" upper="0.5200000405311584" velocity="1000.0"/>
  </joint>
  <link name="right_ankle_link">
    <inertial>
      <origin xyz="0.06722000241279602 -0.0001500000071246177 -0.04496999830007553" rpy="1.718996524810791 -0.11798209697008133 1.5555427074432373"/>
      <mass value="0.44600000977516174"/>
      <inertia ixx="0.0022084799129515886" ixy="0.0" ixz="0.0" iyy="0.002189609920606017" iyz="0.0" izz="0.00021420199482236058"/>
    </inertial>
    <visual name="Geom_20">
      <origin xyz="0.07149466872215271 3.012107754329918e-07 -0.047084417194128036" rpy="-3.1407830715179443 -1.4449551105499268 -0.0008142106817103922"/>
      <geometry>
        <mesh filename="file://h1/meshes/obj/right_ankle_link.obj" scale="1.0 1.0 1.0"/>
      </geometry>
    </visual>
    <collision name="Geom_21">
      <origin xyz="0.07149466872215271 3.012107754329918e-07 -0.047084417194128036" rpy="-3.1407830715179443 -1.4449551105499268 -0.0008142106817103922"/>
      <geometry>
        <mesh filename="file://h1/meshes/stl/right_ankle_link.stl" scale="1.0 1.0 1.0"/>
      </geometry>
    </collision>
  </link>
  <joint name="torso" type="revolute">
    <origin xyz="0.0 0.0 0.0" rpy="0.0 0.0 0.0"/>
    <axis xyz="0.0 0.0 1.0"/>
    <parent link="pelvis"/>
    <child link="torso_link"/>
    <limit effort="1000.0" lower="-2.3499999046325684" upper="2.3499999046325684" velocity="1000.0"/>
  </joint>
  <link name="torso_link">
    <inertial>
      <origin xyz="0.0004889999981969595 0.0027970001101493835 0.20484000444412231" rpy="-0.002596466103568673 -0.0056548817083239555 -0.006974807009100914"/>
      <mass value="17.788999557495117"/>
      <inertia ixx="0.48731499910354614" ixy="0.0" ixz="0.0" iyy="0.4096280038356781" iyz="0.0" izz="0.12783700227737427"/>
    </inertial>
    <visual name="Geom_22">
      <origin xyz="0.015564000234007835 2.529602170397993e-06 0.38950976729393005" rpy="1.5143251403060276e-05 0.08273289352655411 0.00036148555227555335"/>
      <geometry>
        <mesh filename="file://h1/meshes/obj/torso_link.obj" scale="1.0 1.0 1.0"/>
      </geometry>
    </visual>
    <collision name="Geom_23">
      <origin xyz="0.015564000234007835 2.529602170397993e-06 0.38950976729393005" rpy="1.5143251403060276e-05 0.08273289352655411 0.00036148555227555335"/>
      <geometry>
        <mesh filename="file://h1/meshes/stl/torso_link.stl" scale="1.0 1.0 1.0"/>
      </geometry>
    </collision>
    <visual name="Geom_24">
      <origin xyz="-1.66760273714317e-05 0.0012330973986536264 0.3837130665779114" rpy="-1.5110241174697876 -1.5546302795410156 -1.7146497964859009"/>
      <geometry>
        <mesh filename="file://h1/meshes/obj/logo_link.obj" scale="1.0 1.0 1.0"/>
      </geometry>
    </visual>
  </link>
  <joint name="left_shoulder_pitch" type="revolute">
    <origin xyz="0.005499999970197678 0.155349999666214 0.4299899935722351" rpy="0.4363292157649994 0.0 0.0"/>
    <axis xyz="0.0 1.0 0.0"/>
    <parent link="torso_link"/>
    <child link="left_shoulder_pitch_link"/>
    <limit effort="1000.0" lower="-2.870000123977661" upper="2.870000123977661" velocity="1000.0"/>
  </joint>
  <link name="left_shoulder_pitch_link">
    <inertial>
      <origin xyz="0.005044999998062849 0.05365699902176857 -0.01571499928832054" rpy="1.2363550662994385 -0.021921830251812935 -0.03857455775141716"/>
      <mass value="1.0329999923706055"/>
      <inertia ixx="0.0012993599520996213" ixy="0.0" ixz="0.0" iyy="0.0009871129877865314" iyz="0.0" izz="0.0008581979782320559"/>
    </inertial>
    <visual name="Geom_25">
      <origin xyz="-0.005670230370014906 0.04951075464487076 -0.014470953494310379" rpy="1.2507362365722656 0.014680511318147182 0.0730733871459961"/>
      <geometry>
        <mesh filename="file://h1/meshes/obj/left_shoulder_pitch_link.obj" scale="1.0 1.0 1.0"/>
      </geometry>
    </visual>
    <collision name="Geom_26">
      <origin xyz="-0.005670230370014906 0.04951075464487076 -0.014470953494310379" rpy="1.2507362365722656 0.014680511318147182 0.0730733871459961"/>
      <geometry>
        <mesh filename="file://h1/meshes/stl/left_shoulder_pitch_link.stl" scale="1.0 1.0 1.0"/>
      </geometry>
    </collision>
  </link>
  <joint name="left_shoulder_roll" type="revolute">
    <origin xyz="-0.005499999970197678 0.05649999901652336 -0.016499999910593033" rpy="-0.4363291561603546 0.0 0.0"/>
    <axis xyz="1.0 0.0 0.0"/>
    <parent link="left_shoulder_pitch_link"/>
    <child link="left_shoulder_roll_link"/>
    <limit effort="1000.0" lower="-0.3399999737739563" upper="3.1100001335144043" velocity="1000.0"/>
  </joint>
  <link name="left_shoulder_roll_link">
    <inertial>
      <origin xyz="0.000678999989759177 0.0011500000255182385 -0.0940760001540184" rpy="0.1180100366473198 0.10007335245609283 1.4971070289611816"/>
      <mass value="0.7929999828338623"/>
      <inertia ixx="0.0017038800287991762" ixy="0.0" ixz="0.0" iyy="0.0015825600130483508" iyz="0.0" izz="0.0010033600265160203"/>
    </inertial>
    <visual name="Geom_27">
      <origin xyz="0.013247874565422535 -0.001250272965990007 -0.08504226803779602" rpy="-0.023235851898789406 0.443729430437088 0.06914247572422028"/>
      <geometry>
        <mesh filename="file://h1/meshes/obj/left_shoulder_roll_link.obj" scale="1.0 1.0 1.0"/>
      </geometry>
    </visual>
    <collision name="Geom_28">
      <origin xyz="0.013247874565422535 -0.001250272965990007 -0.08504226803779602" rpy="-0.023235851898789406 0.443729430437088 0.06914247572422028"/>
      <geometry>
        <mesh filename="file://h1/meshes/stl/left_shoulder_roll_link.stl" scale="1.0 1.0 1.0"/>
      </geometry>
    </collision>
  </link>
  <joint name="left_shoulder_yaw" type="revolute">
    <origin xyz="0.0 0.0 -0.13429999351501465" rpy="0.0 0.0 0.0"/>
    <axis xyz="0.0 0.0 1.0"/>
    <parent link="left_shoulder_roll_link"/>
    <child link="left_shoulder_yaw_link"/>
    <limit effort="1000.0" lower="-1.2999999523162842" upper="4.449999809265137" velocity="1000.0"/>
  </joint>
  <link name="left_shoulder_yaw_link">
    <inertial>
      <origin xyz="0.013650000095367432 0.002767000114545226 -0.16266000270843506" rpy="-0.1139453873038292 -0.01960502751171589 1.5800683498382568"/>
      <mass value="0.8389999866485596"/>
      <inertia ixx="0.004080379847437143" ixy="0.0" ixz="0.0" iyy="0.003703670110553503" iyz="0.0" izz="0.0006226869882084429"/>
    </inertial>
    <visual name="Geom_29">
      <origin xyz="0.009968684054911137 0.0004950409638695419 -0.13347001373767853" rpy="-0.12338769435882568 -0.009365823119878769 1.5772429704666138"/>
      <geometry>
        <mesh filename="file://h1/meshes/obj/left_shoulder_yaw_link.obj" scale="1.0 1.0 1.0"/>
      </geometry>
    </visual>
    <collision name="Geom_30">
      <origin xyz="0.009968684054911137 0.0004950409638695419 -0.13347001373767853" rpy="-0.12338769435882568 -0.009365823119878769 1.5772429704666138"/>
      <geometry>
        <mesh filename="file://h1/meshes/stl/left_shoulder_yaw_link.stl" scale="1.0 1.0 1.0"/>
      </geometry>
    </collision>
  </link>
  <joint name="left_elbow" type="revolute">
    <origin xyz="0.01850000023841858 0.0 -0.1979999989271164" rpy="0.0 0.0 0.0"/>
    <axis xyz="0.0 1.0 0.0"/>
    <parent link="left_shoulder_yaw_link"/>
    <child link="left_elbow_link"/>
    <limit effort="1000.0" lower="-1.2500001192092896" upper="2.609999895095825" velocity="1000.0"/>
  </joint>
  <link name="left_elbow_link">
    <inertial>
      <origin xyz="0.15907999873161316 -0.00014400000509340316 -0.015776000916957855" rpy="1.7972631454467773 -1.3357229232788086 1.3568445444107056"/>
      <mass value="0.6690000295639038"/>
      <inertia ixx="0.00601828983053565" ixy="0.0" ixz="0.0" iyy="0.006005790084600449" iyz="0.0" izz="0.0004083050007466227"/>
    </inertial>
    <visual name="Geom_31">
      <origin xyz="0.16968630254268646 6.118328747106716e-05 -0.015091080218553543" rpy="-2.5652523040771484 -1.5133321285247803 -0.5753892660140991"/>
      <geometry>
        <mesh filename="file://h1/meshes/obj/left_elbow_link.obj" scale="1.0 1.0 1.0"/>
      </geometry>
    </visual>
    <collision name="Geom_32">
      <origin xyz="0.16968630254268646 6.118328747106716e-05 -0.015091080218553543" rpy="-2.5652523040771484 -1.5133321285247803 -0.5753892660140991"/>
      <geometry>
        <mesh filename="file://h1/meshes/stl/left_elbow_link.stl" scale="1.0 1.0 1.0"/>
      </geometry>
    </collision>
  </link>
  <joint name="right_shoulder_pitch" type="revolute">
    <origin xyz="0.005499999970197678 -0.155349999666214 0.4299899935722351" rpy="-0.4363292157649994 0.0 0.0"/>
    <axis xyz="0.0 1.0 0.0"/>
    <parent link="torso_link"/>
    <child link="right_shoulder_pitch_link"/>
    <limit effort="1000.0" lower="-2.870000123977661" upper="2.870000123977661" velocity="1000.0"/>
  </joint>
  <link name="right_shoulder_pitch_link">
    <inertial>
      <origin xyz="0.005044999998062849 -0.05365699902176857 -0.01571499928832054" rpy="1.9052376747131348 -0.021921830251812935 0.03857455775141716"/>
      <mass value="1.0329999923706055"/>
      <inertia ixx="0.0012993599520996213" ixy="0.0" ixz="0.0" iyy="0.0009871129877865314" iyz="0.0" izz="0.0008581979782320559"/>
    </inertial>
    <visual name="Geom_33">
      <origin xyz="-0.0056705777533352375 -0.049511924386024475 -0.01447086501866579" rpy="1.8908884525299072 0.0146695701405406 -0.07308123260736465"/>
      <geometry>
        <mesh filename="file://h1/meshes/obj/right_shoulder_pitch_link.obj" scale="1.0 1.0 1.0"/>
      </geometry>
    </visual>
    <collision name="Geom_34">
      <origin xyz="-0.0056705777533352375 -0.049511924386024475 -0.01447086501866579" rpy="1.8908884525299072 0.0146695701405406 -0.07308123260736465"/>
      <geometry>
        <mesh filename="file://h1/meshes/stl/right_shoulder_pitch_link.stl" scale="1.0 1.0 1.0"/>
      </geometry>
    </collision>
  </link>
  <joint name="right_shoulder_roll" type="revolute">
    <origin xyz="-0.005499999970197678 -0.05649999901652336 -0.016499999910593033" rpy="0.4363291561603546 0.0 0.0"/>
    <axis xyz="1.0 0.0 0.0"/>
    <parent link="right_shoulder_pitch_link"/>
    <child link="right_shoulder_roll_link"/>
    <limit effort="1000.0" lower="-3.1100001335144043" upper="0.3399999737739563" velocity="1000.0"/>
  </joint>
  <link name="right_shoulder_roll_link">
    <inertial>
      <origin xyz="0.000678999989759177 -0.0011500000255182385 -0.0940760001540184" rpy="0.1180100366473198 -0.10007335245609283 1.644485592842102"/>
      <mass value="0.7929999828338623"/>
      <inertia ixx="0.0017038800287991762" ixy="0.0" ixz="0.0" iyy="0.0015825600130483508" iyz="0.0" izz="0.0010033600265160203"/>
    </inertial>
    <visual name="Geom_35">
      <origin xyz="0.013244586065411568 0.0012510847300291061 -0.08504389971494675" rpy="0.022891849279403687 0.44368886947631836 -0.06972770392894745"/>
      <geometry>
        <mesh filename="file://h1/meshes/obj/right_shoulder_roll_link.obj" scale="1.0 1.0 1.0"/>
      </geometry>
    </visual>
    <collision name="Geom_36">
      <origin xyz="0.013244586065411568 0.0012510847300291061 -0.08504389971494675" rpy="0.022891849279403687 0.44368886947631836 -0.06972770392894745"/>
      <geometry>
        <mesh filename="file://h1/meshes/stl/right_shoulder_roll_link.stl" scale="1.0 1.0 1.0"/>
      </geometry>
    </collision>
  </link>
  <joint name="right_shoulder_yaw" type="revolute">
    <origin xyz="0.0 0.0 -0.13429999351501465" rpy="0.0 0.0 0.0"/>
    <axis xyz="0.0 0.0 1.0"/>
    <parent link="right_shoulder_roll_link"/>
    <child link="right_shoulder_yaw_link"/>
    <limit effort="1000.0" lower="-4.449999809265137" upper="1.2999999523162842" velocity="1000.0"/>
  </joint>
  <link name="right_shoulder_yaw_link">
    <inertial>
      <origin xyz="0.013650000095367432 -0.002767000114545226 -0.16266000270843506" rpy="-0.1139453873038292 0.01960502751171589 1.5615242719650269"/>
      <mass value="0.8389999866485596"/>
      <inertia ixx="0.004080379847437143" ixy="0.0" ixz="0.0" iyy="0.003703670110553503" iyz="0.0" izz="0.0006226869882084429"/>
    </inertial>
    <visual name="Geom_37">
      <origin xyz="0.009967150166630745 -0.0004951314185746014 -0.13347332179546356" rpy="-0.12335117161273956 0.009374386630952358 1.5643353462219238"/>
      <geometry>
        <mesh filename="file://h1/meshes/obj/right_shoulder_yaw_link.obj" scale="1.0 1.0 1.0"/>
      </geometry>
    </visual>
    <collision name="Geom_38">
      <origin xyz="0.009967150166630745 -0.0004951314185746014 -0.13347332179546356" rpy="-0.12335117161273956 0.009374386630952358 1.5643353462219238"/>
      <geometry>
        <mesh filename="file://h1/meshes/stl/right_shoulder_yaw_link.stl" scale="1.0 1.0 1.0"/>
      </geometry>
    </collision>
  </link>
  <joint name="right_elbow" type="revolute">
    <origin xyz="0.01850000023841858 0.0 -0.1979999989271164" rpy="0.0 0.0 0.0"/>
    <axis xyz="0.0 1.0 0.0"/>
    <parent link="right_shoulder_yaw_link"/>
    <child link="right_elbow_link"/>
    <limit effort="1000.0" lower="-1.2500001192092896" upper="2.609999895095825" velocity="1000.0"/>
  </joint>
  <link name="right_elbow_link">
    <inertial>
      <origin xyz="0.15907999873161316 0.00014400000509340316 -0.015776000916957855" rpy="-1.7972631454467773 -1.3357229232788086 -1.3568445444107056"/>
      <mass value="0.6690000295639038"/>
      <inertia ixx="0.00601828983053565" ixy="0.0" ixz="0.0" iyy="0.006005790084600449" iyz="0.0" izz="0.0004083050007466227"/>
    </inertial>
    <visual name="Geom_39">
      <origin xyz="0.16968615353107452 -6.167552783153951e-05 -0.01509109791368246" rpy="2.5637741088867188 -1.5132794380187988 0.5768687129020691"/>
      <geometry>
        <mesh filename="file://h1/meshes/obj/right_elbow_link.obj" scale="1.0 1.0 1.0"/>
      </geometry>
    </visual>
    <collision name="Geom_40">
      <origin xyz="0.16968615353107452 -6.167552783153951e-05 -0.01509109791368246" rpy="2.5637741088867188 -1.5132794380187988 0.5768687129020691"/>
      <geometry>
        <mesh filename="file://h1/meshes/stl/right_elbow_link.stl" scale="1.0 1.0 1.0"/>
      </geometry>
    </collision>
  </link>
</robot>