<?xml version="1.0" ?>
<mujoco model="h1">
	<compiler meshdir="h1/meshes" texturedir="h1/textures" angle="radian" autolimits="true" balanceinertia="true" boundmass="0.000001" boundinertia="0.000001"/>
	<default>
		<default class="visual">
			<geom contype="0" conaffinity="0"/>
		</default>
		<default class="collision">
			<geom rgba="1.0 0.0 0.0 0.0"/>
		</default>
	</default>
	<asset>
		<mesh name="pelvis" file="stl/pelvis.stl" scale="1.0 1.0 1.0"/>
		<mesh name="left_hip_yaw_link" file="stl/left_hip_yaw_link.stl" scale="1.0 1.0 1.0"/>
		<mesh name="left_hip_roll_link" file="stl/left_hip_roll_link.stl" scale="1.0 1.0 1.0"/>
		<mesh name="left_hip_pitch_link" file="stl/left_hip_pitch_link.stl" scale="1.0 1.0 1.0"/>
		<mesh name="left_knee_link" file="stl/left_knee_link.stl" scale="1.0 1.0 1.0"/>
		<mesh name="left_ankle_link" file="stl/left_ankle_link.stl" scale="1.0 1.0 1.0"/>
		<mesh name="right_hip_yaw_link" file="stl/right_hip_yaw_link.stl" scale="1.0 1.0 1.0"/>
		<mesh name="right_hip_roll_link" file="stl/right_hip_roll_link.stl" scale="1.0 1.0 1.0"/>
		<mesh name="right_hip_pitch_link" file="stl/right_hip_pitch_link.stl" scale="1.0 1.0 1.0"/>
		<mesh name="right_knee_link" file="stl/right_knee_link.stl" scale="1.0 1.0 1.0"/>
		<mesh name="right_ankle_link" file="stl/right_ankle_link.stl" scale="1.0 1.0 1.0"/>
		<mesh name="torso_link" file="stl/torso_link.stl" scale="1.0 1.0 1.0"/>
		<mesh name="logo_link" file="stl/logo_link.stl" scale="1.0 1.0 1.0"/>
		<mesh name="left_shoulder_pitch_link" file="stl/left_shoulder_pitch_link.stl" scale="1.0 1.0 1.0"/>
		<mesh name="left_shoulder_roll_link" file="stl/left_shoulder_roll_link.stl" scale="1.0 1.0 1.0"/>
		<mesh name="left_shoulder_yaw_link" file="stl/left_shoulder_yaw_link.stl" scale="1.0 1.0 1.0"/>
		<mesh name="left_elbow_link" file="stl/left_elbow_link.stl" scale="1.0 1.0 1.0"/>
		<mesh name="right_shoulder_pitch_link" file="stl/right_shoulder_pitch_link.stl" scale="1.0 1.0 1.0"/>
		<mesh name="right_shoulder_roll_link" file="stl/right_shoulder_roll_link.stl" scale="1.0 1.0 1.0"/>
		<mesh name="right_shoulder_yaw_link" file="stl/right_shoulder_yaw_link.stl" scale="1.0 1.0 1.0"/>
		<mesh name="right_elbow_link" file="stl/right_elbow_link.stl" scale="1.0 1.0 1.0"/>
		<material name="black" rgba="0.10000000149011612 0.10000000149011612 0.10000000149011612 1.0" emission="0.0" specular="0.5"/>
		<material name="white" rgba="1.0 1.0 1.0 1.0" emission="0.0" specular="0.5"/>
	</asset>
	<worldbody>
		<body name="h1" pos="0.0 0.0 0.0" quat="1.0 0.0 0.0 0.0">
			<body name="pelvis" pos="0.0 0.0 0.0" quat="1.0 0.0 0.0 0.0">
				<geom name="Geom_0" type="mesh" pos="1.4959405234549195e-06 2.051345518339076e-06 -0.04126008599996567" quat="0.5000481009483337 0.5000556111335754 -0.49994853138923645 0.499947726726532" mesh="pelvis" material="black" class="visual"/>
				<geom name="Geom_1" type="mesh" pos="1.4959405234549195e-06 2.051345518339076e-06 -0.04126008599996567" quat="0.5000481009483337 0.5000556111335754 -0.49994853138923645 0.499947726726532" mesh="pelvis" class="collision"/>
				<body name="right_hip_yaw_link" pos="0.0 -0.08749999850988388 -0.17419999837875366" quat="1.0 0.0 0.0 0.0">
					<inertial mass="2.24399995803833" pos="-0.049229998141527176 -9.999999747378752e-05 0.007199999876320362" quat="0.6416670083999634 0.2332870066165924 0.2191929966211319 0.6969900131225586" diaginertia="0.0030449400655925274 0.002968850079923868 0.0018920099828392267"/>
					<geom name="Geom_12" type="mesh" pos="-0.03807106986641884 3.4278398288734024e-06 0.033565454185009" quat="0.9465280175209045 6.459824362536892e-05 0.322621613740921 6.646179099334404e-05" mesh="right_hip_yaw_link" material="black" class="visual"/>
					<geom name="Geom_13" type="cylinder" pos="-0.06700000166893005 0.0 0.0" quat="0.7071232795715332 0.0 0.7070902585983276 0.0" size="0.05999999865889549 0.03500000014901161 0.0" class="collision"/>
					<joint name="right_hip_yaw" type="hinge" pos="0.0 0.0 0.0" range="-0.4300000071525574 0.4300000071525574" axis="0.0 0.0 1.0"/>
					<body name="right_hip_roll_link" pos="0.03946800157427788 0.0 0.0" quat="1.0 0.0 0.0 0.0">
						<inertial mass="2.2320001125335693" pos="-0.005799999926239252 0.0031900000758469105 -9.000000136438757e-05" quat="-0.0438242144882679 0.7072102427482605 0.07290752232074738 0.7018672227859497" diaginertia="0.002432639943435788 0.0022532499860972166 0.0020549199543893337"/>
						<geom name="Geom_14" type="mesh" pos="-0.020227110013365746 0.00920272059738636 1.7128593299275963e-06" quat="0.4344494640827179 0.434529185295105 0.5577123165130615 0.5580277442932129" mesh="right_hip_roll_link" material="black" class="visual"/>
						<geom name="Geom_15" type="mesh" pos="-0.020227110013365746 0.00920272059738636 1.7128593299275963e-06" quat="0.4344494640827179 0.434529185295105 0.5577123165130615 0.5580277442932129" mesh="right_hip_roll_link" class="collision"/>
						<joint name="right_hip_roll" type="hinge" pos="0.0 0.0 0.0" range="-0.4300000071525574 0.4300000071525574" axis="1.0 0.0 0.0"/>
						<body name="right_hip_pitch_link" pos="0.0 -0.11535999923944473 0.0" quat="1.0 0.0 0.0 0.0">
							<inertial mass="4.1519999504089355" pos="0.007459999993443489 0.02346000075340271 -0.0819299966096878" quat="0.9798283576965332 -0.05135221779346466 -0.01698540523648262 0.1923820674419403" diaginertia="0.08295030146837234 0.08214569836854935 0.005109089892357588"/>
							<geom name="Geom_16" type="mesh" pos="0.012151695787906647 0.01963897980749607 -0.13054850697517395" quat="0.9817856550216675 -0.052278731018304825 -0.020554043352603912 0.18149760365486145" mesh="right_hip_pitch_link" material="black" class="visual"/>
							<geom name="Geom_17" type="mesh" pos="0.012151695787906647 0.01963897980749607 -0.13054850697517395" quat="0.9817856550216675 -0.052278731018304825 -0.020554043352603912 0.18149760365486145" mesh="right_hip_pitch_link" class="collision"/>
							<joint name="right_hip_pitch" type="hinge" pos="0.0 0.0 0.0" range="-1.5700000524520874 1.5700000524520874" axis="0.0 1.0 0.0"/>
							<body name="right_knee_link" pos="0.0 0.0 -0.4000000059604645" quat="1.0 0.0 0.0 0.0">
								<inertial mass="1.7209999561309814" pos="-0.0013599999947473407 0.005119999870657921 -0.13840000331401825" quat="0.7778522372245789 -0.04162771254777908 -0.03422700986266136 0.6261321902275085" diaginertia="0.012523699551820755 0.012310399673879147 0.0019428000086918473"/>
								<geom name="Geom_18" type="mesh" pos="0.0076714251190423965 0.0017608820926398039 -0.16004091501235962" quat="0.7392074465751648 -0.019502710551023483 -0.0162811279296875 0.6729984879493713" mesh="right_knee_link" material="black" class="visual"/>
								<geom name="Geom_19" type="mesh" pos="0.0076714251190423965 0.0017608820926398039 -0.16004091501235962" quat="0.7392074465751648 -0.019502710551023483 -0.0162811279296875 0.6729984879493713" mesh="right_knee_link" class="collision"/>
								<joint name="right_knee" type="hinge" pos="0.0 0.0 0.0" range="-0.25999999046325684 2.049999952316284" axis="0.0 1.0 0.0"/>
								<body name="right_ankle_link" pos="0.0 0.0 -0.4000000059604645" quat="1.0 0.0 0.0 0.0">
									<inertial mass="0.44600000977516174" pos="0.06722000241279602 -0.0001500000071246177 -0.04496999830007553" quat="0.4329717755317688 0.5657817125320435 0.5031967163085938 0.48910075426101685" diaginertia="0.0022084799129515886 0.002189609920606017 0.00021420199482236058"/>
									<geom name="Geom_20" type="mesh" pos="0.07149466872215271 3.012107754329918e-07 -0.047084417194128036" quat="-3.448139614192769e-05 0.7501697540283203 -3.771793490159325e-05 0.6612452864646912" mesh="right_ankle_link" material="black" class="visual"/>
									<geom name="Geom_21" type="mesh" pos="0.07149466872215271 3.012107754329918e-07 -0.047084417194128036" quat="-3.448139614192769e-05 0.7501697540283203 -3.771793490159325e-05 0.6612452864646912" mesh="right_ankle_link" class="collision"/>
									<joint name="right_ankle" type="hinge" pos="0.0 0.0 0.0" range="-0.8700000047683716 0.5199999809265137" axis="0.0 1.0 0.0"/>
								</body>
							</body>
						</body>
					</body>
				</body>
				<body name="torso_link" pos="0.0 0.0 0.0" quat="1.0 0.0 0.0 0.0">
					<inertial mass="17.788999557495117" pos="0.0004889999981969595 0.0027970001101493835 0.20484000444412231" quat="0.9999890923500061 -0.0013080800417810678 -0.002822890179231763 -0.0034910503309220076" diaginertia="0.48731499910354614 0.4096280038356781 0.12783700227737427"/>
					<geom name="Geom_22" type="mesh" pos="0.015564000234007835 2.529602170397993e-06 0.38950976729393005" quat="0.9991444945335388 9.059405670086562e-08 0.04135465249419212 0.00018027501937467605" mesh="torso_link" material="black" class="visual"/>
					<geom name="Geom_23" type="mesh" pos="0.015564000234007835 2.529602170397993e-06 0.38950976729393005" quat="0.9991444945335388 9.059405670086562e-08 0.04135465249419212 0.00018027501937467605" mesh="torso_link" class="collision"/>
					<geom name="Geom_24" type="mesh" pos="-1.66760273714317e-05 0.0012330973986536264 0.3837130665779114" quat="0.024031583219766617 0.7058780193328857 -0.03540341183543205 0.7070398330688477" mesh="logo_link" material="white" class="visual"/>
					<joint name="torso" type="hinge" pos="0.0 0.0 0.0" range="-2.3499999046325684 2.3499999046325684" axis="0.0 0.0 1.0"/>
					<body name="right_shoulder_pitch_link" pos="0.005499999970197678 -0.155349999666214 0.4299899935722351" quat="0.9762963652610779 -0.21643806993961334 0.0 0.0">
						<inertial mass="1.0329999923706055" pos="0.005044999998062849 -0.05365699902176857 -0.01571499928832054" quat="0.5792360305786133 0.8148580193519592 0.009364880621433258 0.020107200369238853" diaginertia="0.0012993599520996213 0.0009871129877865314 0.0008581979782320559"/>
						<geom name="Geom_33" type="mesh" pos="-0.0056705777533352375 -0.049511924386024475 -0.01447086501866579" quat="0.5847590565681458 0.8103508949279785 -0.025327419862151146 -0.02732761763036251" mesh="right_shoulder_pitch_link" material="black" class="visual"/>
						<geom name="Geom_34" type="mesh" pos="-0.0056705777533352375 -0.049511924386024475 -0.01447086501866579" quat="0.5847590565681458 0.8103508949279785 -0.025327419862151146 -0.02732761763036251" mesh="right_shoulder_pitch_link" class="collision"/>
						<joint name="right_shoulder_pitch" type="hinge" pos="0.0 0.0 0.0" range="-2.869999885559082 2.869999885559082" axis="0.0 1.0 0.0"/>
						<body name="right_shoulder_roll_link" pos="-0.005499999970197678 -0.05649999901652336 -0.016499999910593033" quat="0.9762963652610779 0.21643806993961334 0.0 0.0">
							<inertial mass="0.7929999828338623" pos="0.000678999989759177 -0.0011500000255182385 -0.0940760001540184" quat="0.6763839721679688 0.07666559517383575 0.009171789512038231 0.7324909567832947" diaginertia="0.0017038800287991762 0.0015825600130483508 0.0010033600265160203"/>
							<geom name="Geom_35" type="mesh" pos="0.013244586065411568 0.0012510847300291061 -0.08504389971494675" quat="0.9747488498687744 0.0188274048268795 0.21949194371700287 -0.0365171916782856" mesh="right_shoulder_roll_link" material="black" class="visual"/>
							<geom name="Geom_36" type="mesh" pos="0.013244586065411568 0.0012510847300291061 -0.08504389971494675" quat="0.9747488498687744 0.0188274048268795 0.21949194371700287 -0.0365171916782856" mesh="right_shoulder_roll_link" class="collision"/>
							<joint name="right_shoulder_roll" type="hinge" pos="0.0 0.0 0.0" range="-3.109999895095825 0.3400000035762787" axis="1.0 0.0 0.0"/>
							<body name="right_shoulder_yaw_link" pos="0.0 0.0 -0.13429999351501465" quat="1.0 0.0 0.0 0.0">
								<inertial mass="0.8389999866485596" pos="0.013650000095367432 -0.002767000114545226 -0.16266000270843506" quat="0.708797812461853 -0.047336187213659286 -0.033122893422842026 0.7030418515205383" diaginertia="0.004080379847437143 0.003703670110553503 0.0006226869882084429"/>
								<geom name="Geom_37" type="mesh" pos="0.009967150166630745 -0.0004951314185746014 -0.13347332179546356" quat="0.7078272104263306 -0.04702099785208702 -0.04012338072061539 0.7036759257316589" mesh="right_shoulder_yaw_link" material="black" class="visual"/>
								<geom name="Geom_38" type="mesh" pos="0.009967150166630745 -0.0004951314185746014 -0.13347332179546356" quat="0.7078272104263306 -0.04702099785208702 -0.04012338072061539 0.7036759257316589" mesh="right_shoulder_yaw_link" class="collision"/>
								<joint name="right_shoulder_yaw" type="hinge" pos="0.0 0.0 0.0" range="-4.449999809265137 1.2999999523162842" axis="0.0 0.0 1.0"/>
								<body name="right_elbow_link" pos="0.01850000023841858 0.0 -0.1979999989271164" quat="1.0 0.0 0.0 0.0">
									<inertial mass="0.6690000295639038" pos="0.15907999873161316 0.00014400000509340316 -0.015776000916957855" quat="-0.07652318477630615 0.720326840877533 -0.08531158417463303 0.6841018795967102" diaginertia="0.00601828983053565 0.006005790084600449 0.0004083050007466227"/>
									<geom name="Geom_39" type="mesh" pos="0.16968615353107452 -6.167552783153951e-05 -0.01509109791368246" quat="0.011433186940848827 0.7238512635231018 0.010761781595647335 0.6897773742675781" mesh="right_elbow_link" material="black" class="visual"/>
									<geom name="Geom_40" type="mesh" pos="0.16968615353107452 -6.167552783153951e-05 -0.01509109791368246" quat="0.011433186940848827 0.7238512635231018 0.010761781595647335 0.6897773742675781" mesh="right_elbow_link" class="collision"/>
									<joint name="right_elbow" type="hinge" pos="0.0 0.0 0.0" range="-1.25 2.609999895095825" axis="0.0 1.0 0.0"/>
								</body>
							</body>
						</body>
					</body>
					<body name="left_shoulder_pitch_link" pos="0.005499999970197678 0.155349999666214 0.4299899935722351" quat="0.9762963652610779 0.21643806993961334 0.0 0.0">
						<inertial mass="1.0329999923706055" pos="0.005044999998062849 0.05365699902176857 -0.01571499928832054" quat="0.8148580193519592 0.5792360305786133 -0.020107200369238853 -0.009364880621433258" diaginertia="0.0012993599520996213 0.0009871129877865314 0.0008581979782320559"/>
						<geom name="Geom_25" type="mesh" pos="-0.005670230370014906 0.04951075464487076 -0.014470953494310379" quat="0.8103417158126831 0.5847719311714172 0.02733016200363636 0.02532060258090496" mesh="left_shoulder_pitch_link" material="black" class="visual"/>
						<geom name="Geom_26" type="mesh" pos="-0.005670230370014906 0.04951075464487076 -0.014470953494310379" quat="0.8103417158126831 0.5847719311714172 0.02733016200363636 0.02532060258090496" mesh="left_shoulder_pitch_link" class="collision"/>
						<joint name="left_shoulder_pitch" type="hinge" pos="0.0 0.0 0.0" range="-2.869999885559082 2.869999885559082" axis="0.0 1.0 0.0"/>
						<body name="left_shoulder_roll_link" pos="-0.005499999970197678 0.05649999901652336 -0.016499999910593033" quat="0.9762963652610779 -0.21643806993961334 0.0 0.0">
							<inertial mass="0.7929999828338623" pos="0.000678999989759177 0.0011500000255182385 -0.0940760001540184" quat="0.7324909567832947 0.009171789512038231 0.07666559517383575 0.6763839721679688" diaginertia="0.0017038800287991762 0.0015825600130483508 0.0010033600265160203"/>
							<geom name="Geom_27" type="mesh" pos="0.013247874565422535 -0.001250272965990007 -0.08504226803779602" quat="0.9747517704963684 -0.018931468948721886 0.2195109724998474 0.036269791424274445" mesh="left_shoulder_roll_link" material="black" class="visual"/>
							<geom name="Geom_28" type="mesh" pos="0.013247874565422535 -0.001250272965990007 -0.08504226803779602" quat="0.9747517704963684 -0.018931468948721886 0.2195109724998474 0.036269791424274445" mesh="left_shoulder_roll_link" class="collision"/>
							<joint name="left_shoulder_roll" type="hinge" pos="0.0 0.0 0.0" range="-0.3400000035762787 3.109999895095825" axis="1.0 0.0 0.0"/>
							<body name="left_shoulder_yaw_link" pos="0.0 0.0 -0.13429999351501465" quat="1.0 0.0 0.0 0.0">
								<inertial mass="0.8389999866485596" pos="0.013650000095367432 0.002767000114545226 -0.16266000270843506" quat="0.7030418515205383 -0.033122893422842026 -0.047336187213659286 0.708797812461853" diaginertia="0.004080379847437143 0.003703670110553503 0.0006226869882084429"/>
								<geom name="Geom_29" type="mesh" pos="0.009968684054911137 0.0004950409638695419 -0.13347001373767853" quat="0.7036800980567932 -0.04013960063457489 -0.047030624002218246 0.7078214883804321" mesh="left_shoulder_yaw_link" material="black" class="visual"/>
								<geom name="Geom_30" type="mesh" pos="0.009968684054911137 0.0004950409638695419 -0.13347001373767853" quat="0.7036800980567932 -0.04013960063457489 -0.047030624002218246 0.7078214883804321" mesh="left_shoulder_yaw_link" class="collision"/>
								<joint name="left_shoulder_yaw" type="hinge" pos="0.0 0.0 0.0" range="-1.2999999523162842 4.449999809265137" axis="0.0 0.0 1.0"/>
								<body name="left_elbow_link" pos="0.01850000023841858 0.0 -0.1979999989271164" quat="1.0 0.0 0.0 0.0">
									<inertial mass="0.6690000295639038" pos="0.15907999873161316 -0.00014400000509340316 -0.015776000916957855" quat="0.07652318477630615 0.720326840877533 0.08531158417463303 0.6841018795967102" diaginertia="0.00601828983053565 0.006005790084600449 0.0004083050007466227"/>
									<geom name="Geom_31" type="mesh" pos="0.16968630254268646 6.118328747106716e-05 -0.015091080218553543" quat="-0.011398239992558956 0.7238525152206421 -0.010725995525717735 0.6897771954536438" mesh="left_elbow_link" material="black" class="visual"/>
									<geom name="Geom_32" type="mesh" pos="0.16968630254268646 6.118328747106716e-05 -0.015091080218553543" quat="-0.011398239992558956 0.7238525152206421 -0.010725995525717735 0.6897771954536438" mesh="left_elbow_link" class="collision"/>
									<joint name="left_elbow" type="hinge" pos="0.0 0.0 0.0" range="-1.25 2.609999895095825" axis="0.0 1.0 0.0"/>
								</body>
							</body>
						</body>
					</body>
				</body>
				<body name="left_hip_yaw_link" pos="0.0 0.08749999850988388 -0.17419999837875366" quat="1.0 0.0 0.0 0.0">
					<inertial mass="2.24399995803833" pos="-0.049229998141527176 9.999999747378752e-05 0.007199999876320362" quat="0.6969900131225586 0.2191929966211319 0.2332870066165924 0.6416670083999634" diaginertia="0.0030449400655925274 0.002968850079923868 0.0018920099828392267"/>
					<geom name="Geom_2" type="mesh" pos="-0.03807055205106735 -3.327455033286242e-06 0.03356019780039787" quat="0.9465417861938477 -4.02824989578221e-05 0.3225811719894409 5.5876375881780405e-06" mesh="left_hip_yaw_link" material="black" class="visual"/>
					<geom name="Geom_3" type="cylinder" pos="-0.06700000166893005 0.0 0.0" quat="0.7071232795715332 0.0 0.7070902585983276 0.0" size="0.05999999865889549 0.03500000014901161 0.0" class="collision"/>
					<joint name="left_hip_yaw" type="hinge" pos="0.0 0.0 0.0" range="-0.4300000071525574 0.4300000071525574" axis="0.0 0.0 1.0"/>
					<body name="left_hip_roll_link" pos="0.03946800157427788 0.0 0.0" quat="1.0 0.0 0.0 0.0">
						<inertial mass="2.2320001125335693" pos="-0.005799999926239252 -0.0031900000758469105 -9.000000136438757e-05" quat="0.0438242144882679 0.7072102427482605 -0.07290752232074738 0.7018672227859497" diaginertia="0.002432639943435788 0.0022532499860972166 0.0020549199543893337"/>
						<geom name="Geom_4" type="mesh" pos="-0.020227232947945595 -0.009204677306115627 3.911885869456455e-06" quat="0.5579675436019897 0.5577179193496704 0.43452849984169006 0.43452030420303345" mesh="left_hip_roll_link" material="black" class="visual"/>
						<geom name="Geom_5" type="mesh" pos="-0.020227232947945595 -0.009204677306115627 3.911885869456455e-06" quat="0.5579675436019897 0.5577179193496704 0.43452849984169006 0.43452030420303345" mesh="left_hip_roll_link" class="collision"/>
						<joint name="left_hip_roll" type="hinge" pos="0.0 0.0 0.0" range="-0.4300000071525574 0.4300000071525574" axis="1.0 0.0 0.0"/>
						<body name="left_hip_pitch_link" pos="0.0 0.11535999923944473 0.0" quat="1.0 0.0 0.0 0.0">
							<inertial mass="4.1519999504089355" pos="0.007459999993443489 -0.02346000075340271 -0.0819299966096878" quat="0.9798283576965332 0.05135221779346466 -0.01698540523648262 -0.1923820674419403" diaginertia="0.08295030146837234 0.08214569836854935 0.005109089892357588"/>
							<geom name="Geom_6" type="mesh" pos="0.012151024304330349 -0.019641246646642685 -0.130537211894989" quat="0.9818058609962463 0.05227810889482498 -0.02056010253727436 -0.18138784170150757" mesh="left_hip_pitch_link" material="black" class="visual"/>
							<geom name="Geom_7" type="mesh" pos="0.012151024304330349 -0.019641246646642685 -0.130537211894989" quat="0.9818058609962463 0.05227810889482498 -0.02056010253727436 -0.18138784170150757" mesh="left_hip_pitch_link" class="collision"/>
							<joint name="left_hip_pitch" type="hinge" pos="0.0 0.0 0.0" range="-1.5700000524520874 1.5700000524520874" axis="0.0 1.0 0.0"/>
							<body name="left_knee_link" pos="0.0 0.0 -0.4000000059604645" quat="1.0 0.0 0.0 0.0">
								<inertial mass="1.7209999561309814" pos="-0.0013599999947473407 -0.005119999870657921 -0.13840000331401825" quat="0.6261321902275085 -0.03422700986266136 -0.04162771254777908 0.7778522372245789" diaginertia="0.012523699551820755 0.012310399673879147 0.0019428000086918473"/>
								<geom name="Geom_8" type="mesh" pos="0.007670897524803877 -0.0017604113090783358 -0.16003209352493286" quat="0.6729996800422668 -0.01627342775464058 -0.01950850896537304 0.7392063736915588" mesh="left_knee_link" material="black" class="visual"/>
								<geom name="Geom_9" type="mesh" pos="0.007670897524803877 -0.0017604113090783358 -0.16003209352493286" quat="0.6729996800422668 -0.01627342775464058 -0.01950850896537304 0.7392063736915588" mesh="left_knee_link" class="collision"/>
								<joint name="left_knee" type="hinge" pos="0.0 0.0 0.0" range="-0.25999999046325684 2.049999952316284" axis="0.0 1.0 0.0"/>
								<body name="left_ankle_link" pos="0.0 0.0 -0.4000000059604645" quat="1.0 0.0 0.0 0.0">
									<inertial mass="0.44600000977516174" pos="0.06722000241279602 0.0001500000071246177 -0.04496999830007553" quat="0.48910075426101685 0.5031967163085938 0.5657817125320435 0.4329717755317688" diaginertia="0.0022084799129515886 0.002189609920606017 0.00021420199482236058"/>
									<geom name="Geom_10" type="mesh" pos="0.0714942142367363 1.047239379659004e-07 -0.04708452895283699" quat="0.0002447657170705497 0.7501683831214905 0.00026602079742588103 0.6612467169761658" mesh="left_ankle_link" material="black" class="visual"/>
									<geom name="Geom_11" type="mesh" pos="0.0714942142367363 1.047239379659004e-07 -0.04708452895283699" quat="0.0002447657170705497 0.7501683831214905 0.00026602079742588103 0.6612467169761658" mesh="left_ankle_link" class="collision"/>
									<joint name="left_ankle" type="hinge" pos="0.0 0.0 0.0" range="-0.8700000047683716 0.5199999809265137" axis="0.0 1.0 0.0"/>
								</body>
							</body>
						</body>
					</body>
				</body>
			</body>
		</body>
	</worldbody>
	<equality/>
</mujoco>
