<?xml version="1.0" ?>
<mujoco model="cassie">
	<compiler meshdir="cassie/meshes" texturedir="cassie/textures" angle="radian" autolimits="true" balanceinertia="true" boundmass="0.000001" boundinertia="0.000001"/>
	<default>
		<default class="visual">
			<geom contype="0" conaffinity="0"/>
		</default>
		<default class="collision">
			<geom rgba="1.0 0.0 0.0 0.0"/>
		</default>
	</default>
	<asset>
		<mesh name="cassie_pelvis" file="obj/cassie_pelvis.obj" scale="1.0 1.0 1.0"/>
		<mesh name="left_hip_roll" file="obj/left_hip_roll.obj" scale="1.0 1.0 1.0"/>
		<mesh name="left_hip_yaw" file="obj/left_hip_yaw.obj" scale="1.0 1.0 1.0"/>
		<mesh name="left_hip_pitch" file="obj/left_hip_pitch.obj" scale="1.0 1.0 1.0"/>
		<mesh name="left_achilles_rod" file="obj/left_achilles_rod.obj" scale="1.0 1.0 1.0"/>
		<mesh name="left_knee" file="obj/left_knee.obj" scale="1.0 1.0 1.0"/>
		<mesh name="left_knee_spring" file="obj/left_knee_spring.obj" scale="1.0 1.0 1.0"/>
		<mesh name="left_shin" file="obj/left_shin.obj" scale="1.0 1.0 1.0"/>
		<mesh name="left_tarsus" file="obj/left_tarsus.obj" scale="1.0 1.0 1.0"/>
		<mesh name="left_heel_spring" file="obj/left_heel_spring.obj" scale="1.0 1.0 1.0"/>
		<mesh name="left_foot_crank" file="obj/left_foot_crank.obj" scale="1.0 1.0 1.0"/>
		<mesh name="left_plantar_rod" file="obj/left_plantar_rod.obj" scale="1.0 1.0 1.0"/>
		<mesh name="left_foot" file="obj/left_foot.obj" scale="1.0 1.0 1.0"/>
		<mesh name="right_hip_roll" file="obj/right_hip_roll.obj" scale="1.0 1.0 1.0"/>
		<mesh name="right_hip_yaw" file="obj/right_hip_yaw.obj" scale="1.0 1.0 1.0"/>
		<mesh name="right_hip_pitch" file="obj/right_hip_pitch.obj" scale="1.0 1.0 1.0"/>
		<mesh name="right_achilles_rod" file="obj/right_achilles_rod.obj" scale="1.0 1.0 1.0"/>
		<mesh name="right_knee" file="obj/right_knee.obj" scale="1.0 1.0 1.0"/>
		<mesh name="right_knee_spring" file="obj/right_knee_spring.obj" scale="1.0 1.0 1.0"/>
		<mesh name="right_shin" file="obj/right_shin.obj" scale="1.0 1.0 1.0"/>
		<mesh name="right_tarsus" file="obj/right_tarsus.obj" scale="1.0 1.0 1.0"/>
		<mesh name="right_heel_spring" file="obj/right_heel_spring.obj" scale="1.0 1.0 1.0"/>
		<mesh name="right_foot_crank" file="obj/right_foot_crank.obj" scale="1.0 1.0 1.0"/>
		<mesh name="right_plantar_rod" file="obj/right_plantar_rod.obj" scale="1.0 1.0 1.0"/>
		<mesh name="right_foot" file="obj/right_foot.obj" scale="1.0 1.0 1.0"/>
		<material name="cassie" texture="cassie"/>
		<texture name="cassie" type="2d" file="cassie.png"/>
	</asset>
	<worldbody>
		<body name="cassie" pos="0.0 0.0 0.0" quat="1.0 0.0 0.0 0.0">
			<body name="cassie_pelvis" pos="0.0 0.0 0.0" quat="1.0 0.0 0.0 0.0">
				<geom name="Geom_0" type="mesh" pos="0.015332476235926151 -4.5823806431144476e-05 0.03643164783716202" quat="0.533416748046875 0.5333025455474854 -0.46415409445762634 0.46434471011161804" mesh="cassie_pelvis" material="cassie" class="visual"/>
				<geom name="Geom_1" type="ellipsoid" pos="0.029999999329447746 0.0 0.029999999329447746" quat="1.0 0.0 0.0 0.0" size="0.15000000596046448 0.11999999731779099 0.12999999523162842" class="collision"/>
				<geom name="Geom_2" type="capsule" pos="-0.009999999776482582 0.14000000059604645 0.009999999776482582" quat="0.7071067690849304 0.0 -0.7071067690849304 0.0" size="0.0949999988079071 0.029999999329447746 0.0" class="collision"/>
				<geom name="Geom_3" type="capsule" pos="-0.009999999776482582 -0.14000000059604645 0.009999999776482582" quat="0.7071067690849304 0.0 -0.7071067690849304 0.0" size="0.0949999988079071 0.029999999329447746 0.0" class="collision"/>
				<body name="right_hip_roll" pos="0.020999999716877937 -0.13500000536441803 0.0" quat="0.7071067690849304 0.0 0.7071067690849304 0.0">
					<inertial mass="1.8200000524520874" pos="-0.01792999915778637 9.999999747378752e-05 -0.044280000030994415" quat="0.9737591743469238 0.0044553508050739765 0.22640548646450043 0.022667817771434784" diaginertia="0.00384400668554008 0.0037928964011371136 0.0017220970476046205"/>
					<geom name="Geom_24" type="mesh" pos="-0.030032241716980934 -0.0027302380185574293 -0.06367003172636032" quat="0.8552268743515015 -0.10761242359876633 0.5061758756637573 -0.02815181203186512" mesh="right_hip_roll" material="cassie" class="visual"/>
					<joint name="right_hip_roll" type="hinge" pos="0.0 0.0 0.0" range="-0.39269909262657166 0.2617993950843811" axis="0.0 0.0 1.0"/>
					<body name="right_hip_yaw" pos="0.0 0.0 -0.07000000029802322" quat="0.7071067690849304 0.0 -0.7071067690849304 0.0">
						<inertial mass="1.1710000038146973" pos="0.0 9.999999747378752e-06 -0.03427699953317642" quat="0.7071460485458374 -4.9481481255497783e-05 -5.925715231569484e-05 0.7070674896240234" diaginertia="0.0028029999230057 0.0024429999757558107 0.0008419999503530562"/>
						<geom name="Geom_25" type="mesh" pos="6.4623468460922595e-06 -1.1435130545578431e-05 -0.07286112010478973" quat="0.7070610523223877 0.00026250959490425885 0.00012019480345770717 0.7071524262428284" mesh="right_hip_yaw" material="cassie" class="visual"/>
						<joint name="right_hip_yaw" type="hinge" pos="0.0 0.0 0.0" range="-0.39269909262657166 0.39269909262657166" axis="0.0 0.0 1.0"/>
						<body name="right_hip_pitch" pos="0.0 0.0 -0.09000000357627869" quat="-0.5 -0.5 -0.5 0.5">
							<inertial mass="5.519999980926514" pos="0.059459999203681946 4.999999873689376e-05 0.03581000119447708" quat="-0.011534487828612328 0.7081465125083923 -0.0015279552899301052 0.7059696316719055" diaginertia="0.03025735355913639 0.029717599973082542 0.010894046165049076"/>
							<geom name="Geom_26" type="mesh" pos="0.06051911786198616 0.0006756202201358974 0.055080264806747437" quat="0.48246756196022034 0.46817469596862793 0.5233864188194275 0.5235495567321777" mesh="right_hip_pitch" material="cassie" class="visual"/>
							<geom name="Geom_27" type="capsule" pos="0.05999999865889549 0.0 0.05000000074505806" quat="0.7071067690849304 0.0 -0.7071067690849304 0.0" size="0.07999999821186066 0.05999999865889549 0.0" class="collision"/>
							<joint name="right_hip_pitch" type="hinge" pos="0.0 0.0 0.0" range="-0.8726646304130554 1.3962633609771729" axis="0.0 0.0 1.0"/>
							<body name="right_knee" pos="0.11999999731779099 0.0 -0.0044999998062849045" quat="0.9238795042037964 0.0 -0.0 -0.3826834261417389">
								<inertial mass="0.7577999830245972" pos="0.023000000044703484 0.03206999972462654 0.0021810000762343407" quat="0.6387827396392822 0.32988274097442627 -0.6058588027954102 0.340689092874527" diaginertia="0.0021669911220669746 0.0016374749829992652 0.0007687339675612748"/>
								<geom name="Geom_29" type="mesh" pos="0.019954698160290718 0.03638797253370285 0.0024124563205987215" quat="0.586346447467804 -0.38111579418182373 0.6153823733329773 0.3636661767959595" mesh="right_knee" material="cassie" class="visual"/>
								<joint name="right_knee" type="hinge" pos="0.0 0.0 0.0" range="-2.862339973449707 -0.6457718014717102" axis="0.0 0.0 1.0"/>
								<body name="right_shin" pos="0.060679998248815536 0.04741000011563301 0.0" quat="1.0 0.0 0.0 0.0">
									<inertial mass="0.5770000219345093" pos="0.18337999284267426 0.0011690000537782907 -0.00021230000129435211" quat="0.4919813871383667 0.5006417036056519 0.4985664486885071 0.5086685419082642" diaginertia="0.014731071889400482 0.01470702700316906 0.0003562912461347878"/>
									<geom name="Geom_31" type="mesh" pos="0.15889368951320648 0.00558572169393301 -0.0006726673454977572" quat="0.7087695002555847 0.04382702708244324 0.7035410404205322 0.027477525174617767" mesh="right_shin" material="cassie" class="visual"/>
									<geom name="Geom_32" type="capsule" pos="0.054999999701976776 -0.004999999888241291 0.0" quat="0.7071067690849304 -0.03071475587785244 -0.7064393758773804 0.0" size="0.03999999910593033 0.11510864645242691 0.0" class="collision"/>
									<geom name="Geom_33" type="capsule" pos="0.2750000059604645 -0.011500000022351742 0.0" quat="0.7071067690849304 0.07698467373847961 -0.7029035091400146 0.0" size="0.027000000700354576 0.1056278869509697 0.0" class="collision"/>
									<geom name="Geom_34" type="capsule" pos="0.19487999379634857 0.02250000089406967 0.0" quat="0.7071067690849304 -0.06603457778692245 -0.7040166258811951 0.0" size="0.02500000037252903 0.2409329116344452 0.0" class="collision"/>
									<joint name="right_shin" type="hinge" pos="0.0 0.0 0.0" range="-0.3490658402442932 0.3490658402442932" axis="0.0 0.0 1.0"/>
									<body name="right_tarsus" pos="0.4347600042819977 0.019999999552965164 0.0" quat="0.8746196031570435 0.0 0.0 0.4848097860813141">
										<inertial mass="0.7820000052452087" pos="0.11045999825000763 -0.030579999089241028 0.0013099999632686377" quat="0.032995183020830154 0.7081351280212402 0.02044411189854145 0.7050092220306396" diaginertia="0.013674619607627392 0.013598802499473095 0.0003879580763168633"/>
										<geom name="Geom_35" type="mesh" pos="0.1457228660583496 -0.037279460579156876 0.0011771515710279346" quat="0.7049259543418884 0.020050836727023125 0.7087810039520264 0.017517762258648872" mesh="right_tarsus" material="cassie" class="visual"/>
										<geom name="Geom_36" type="capsule" pos="0.11999999731779099 -0.035294998437166214 0.0004600000102072954" quat="0.7085824012756348 -0.030154068022966385 -0.7049835324287415 0.0" size="0.02800000086426735 0.11010153591632843 0.0" class="collision"/>
										<geom name="Geom_37" type="capsule" pos="0.12399999797344208 -0.054999999701976776 0.0004600000102072954" quat="0.7090101838111877 0.1239672526717186 -0.6942166090011597 0.0" size="0.032999999821186066 0.08533001691102982 0.0" class="collision"/>
										<geom name="Geom_38" type="capsule" pos="0.3190000057220459 -0.03999999910593033 0.0" quat="0.7071067690849304 0.0 -0.7071067690849304 0.0" size="0.019999999552965164 0.11100000143051147 0.0" class="collision"/>
										<joint name="right_tarsus" type="hinge" pos="0.0 0.0 0.0" range="0.8726646304130554 2.96705961227417" axis="0.0 0.0 1.0"/>
										<body name="right_foot_crank" pos="0.057999998331069946 -0.03400000184774399 -0.022749999538064003" quat="1.0 0.0 0.0 0.0">
											<inertial mass="0.12610000371932983" pos="0.0049299998208880424 1.9999999494757503e-05 0.00215000007301569" quat="0.00019792407692875713 0.7439479827880859 0.0003257011703681201 0.6682374477386475" diaginertia="6.378808757290244e-05 4.9620994104770944e-05 2.6514919227338396e-05"/>
											<geom name="Geom_40" type="mesh" pos="0.017089499160647392 4.9604419473325834e-05 -0.0044750855304300785" quat="0.7465254068374634 0.0007349675288423896 0.6653565168380737 -0.00013087251863908023" mesh="right_foot_crank" material="cassie" class="visual"/>
											<joint name="right_foot_crank" type="hinge" pos="0.0 0.0 0.0" range="-2.4434609413146973 -0.5235987901687622" axis="0.0 0.0 1.0"/>
											<body name="right_plantar_rod" pos="0.054999999701976776 0.0 0.007910000160336494" quat="1.0 0.0 0.0 0.0">
												<inertial mass="0.11860000342130661" pos="0.17791999876499176 0.0 0.0" quat="-4.670861471822718e-06 0.7071083784103394 4.67088284494821e-06 0.7071051597595215" diaginertia="0.0017750000115484 0.0017740000039339066 2.7789997147920076e-06"/>
												<geom name="Geom_41" type="mesh" pos="0.17513571679592133 4.083452154191036e-07 1.9617338864463818e-07" quat="0.7071117162704468 3.855780596495606e-05 0.7071018815040588 4.209459075354971e-05" mesh="right_plantar_rod" material="cassie" class="visual"/>
												<joint name="right_plantar_rod" type="hinge" pos="0.0 0.0 0.0" range="0.0 0.0" axis="0.0 0.0 1.0"/>
											</body>
										</body>
										<body name="right_foot" pos="0.40799999237060547 -0.03999999910593033 0.0" quat="1.0 0.0 0.0 0.0">
											<inertial mass="0.14980000257492065" pos="0.004739999771118164 0.027480000630021095 0.00014000000373926014" quat="0.2700909376144409 0.6479209661483765 -0.27926790714263916 0.655178427696228" diaginertia="0.0003326265432406217 0.0002890713803935796 5.272209091344848e-05"/>
											<geom name="Geom_42" type="mesh" pos="0.008884768933057785 0.027471691370010376 -0.00010202051635133103" quat="0.6528940200805664 0.26759615540504456 0.6552407145500183 -0.2697799801826477" mesh="right_foot" material="cassie" class="visual"/>
											<geom name="Geom_43" type="capsule" pos="0.00846249982714653 0.04119899868965149 0.0" quat="0.7071067690849304 -0.454519659280777 -0.5416750311851501 0.0" size="0.019999999552965164 0.07999995350837708 0.0" class="collision"/>
											<joint name="right_foot" type="hinge" pos="0.0 0.0 0.0" range="-2.4434609413146973 -0.5235987901687622" axis="0.0 0.0 1.0"/>
										</body>
										<body name="right_heel_spring" pos="-0.012690000236034393 -0.03058999963104725 -0.0009200000204145908" quat="0.20935484766960144 -0.010860571637749672 0.03755583241581917 0.977057933807373">
											<inertial mass="0.12600000202655792" pos="0.08100000023841858 0.002199999988079071 0.0" quat="0.5091446042060852 0.5091936588287354 0.49242454767227173 0.4888882040977478" diaginertia="0.0002225751813966781 0.0002007018483709544 2.9322971386136487e-05"/>
											<geom name="Geom_39" type="mesh" pos="0.08624786883592606 0.001640240428969264 0.0001932189188664779" quat="0.5092779994010925 0.5121040940284729 0.485395610332489 0.4927234649658203" mesh="right_heel_spring" material="cassie" class="visual"/>
											<joint name="right_heel_spring" type="hinge" pos="0.0 0.0 0.0" range="0.0 0.0" axis="0.0 0.0 1.0"/>
										</body>
									</body>
								</body>
								<body name="right_knee_spring" pos="0.060679998248815536 0.08241000026464462 0.0" quat="1.0 0.0 0.0 0.0">
									<inertial mass="0.1860000044107437" pos="0.0835999995470047 0.0034000000450760126 0.0" quat="0.5047470331192017 0.5047470331192017 0.4952074885368347 0.4952074885368347" diaginertia="0.00041218107799068093 0.00036689999978989363 5.201890962780453e-05"/>
									<geom name="Geom_30" type="mesh" pos="0.09774613380432129 0.0020233020186424255 3.4393519854347687e-06" quat="0.5099207162857056 0.5099120736122131 0.4898744225502014 0.4898914098739624" mesh="right_knee_spring" material="cassie" class="visual"/>
								</body>
							</body>
							<body name="right_achilles_rod" pos="0.0 0.0 -0.04500000178813934" quat="0.9465141892433167 0.014506509527564049 -0.04298104718327522 -0.3194575607776642">
								<inertial mass="0.156700000166893" pos="0.24718999862670898 0.0 0.0" quat="-2.9493990041373763e-06 0.7071080207824707 2.949409690700122e-06 0.7071055173873901" diaginertia="0.004488000180572271 0.004486999940127134 3.7539996355917538e-06"/>
								<geom name="Geom_28" type="mesh" pos="0.2505268156528473 9.135010827776568e-07 1.7718425624480005e-06" quat="0.7071101665496826 -0.00046224944526329637 0.7071031332015991 -0.0004669354821089655" mesh="right_achilles_rod" material="cassie" class="visual"/>
								<joint name="right_achilles_rod" type="ball" pos="0.0 0.0 0.0"/>
							</body>
						</body>
					</body>
				</body>
				<body name="left_hip_roll" pos="0.020999999716877937 0.13500000536441803 0.0" quat="0.7071067690849304 0.0 0.7071067690849304 0.0">
					<inertial mass="1.8200000524520874" pos="-0.01792999915778637 9.999999747378752e-05 -0.044280000030994415" quat="0.9737591743469238 -0.0044553508050739765 0.22640548646450043 -0.022667817771434784" diaginertia="0.00384400668554008 0.0037928964011371136 0.0017220970476046205"/>
					<geom name="Geom_4" type="mesh" pos="-0.030032241716980934 0.0027302380185574293 -0.06367003172636032" quat="-0.028151806443929672 0.5061758756637573 -0.10761241614818573 0.8552268743515015" mesh="left_hip_roll" material="cassie" class="visual"/>
					<joint name="left_hip_roll" type="hinge" pos="0.0 0.0 0.0" range="-0.2617993950843811 0.39269909262657166" axis="0.0 0.0 1.0"/>
					<body name="left_hip_yaw" pos="0.0 0.0 -0.07000000029802322" quat="0.7071067690849304 0.0 -0.7071067690849304 0.0">
						<inertial mass="1.1710000038146973" pos="0.0 -9.999999747378752e-06 -0.03427699953317642" quat="0.7070674896240234 -5.925715231569484e-05 -4.9481481255497783e-05 0.7071460485458374" diaginertia="0.0028029999230057 0.0024429999757558107 0.0008419999503530562"/>
						<geom name="Geom_5" type="mesh" pos="6.462473265855806e-06 1.143508870882215e-05 -0.07286112010478973" quat="0.00026251093368045986 0.7070610523223877 -0.7071524262428284 -0.00012019567657262087" mesh="left_hip_yaw" material="cassie" class="visual"/>
						<joint name="left_hip_yaw" type="hinge" pos="0.0 0.0 0.0" range="-0.39269909262657166 0.39269909262657166" axis="0.0 0.0 1.0"/>
						<body name="left_hip_pitch" pos="0.0 0.0 -0.09000000357627869" quat="-0.5 -0.5 -0.5 0.5">
							<inertial mass="5.519999980926514" pos="0.059459999203681946 4.999999873689376e-05 -0.03581000119447708" quat="0.0015279552899301052 0.7059696316719055 0.011534487828612328 0.7081465125083923" diaginertia="0.03025735355913639 0.029717599973082542 0.010894046165049076"/>
							<geom name="Geom_6" type="mesh" pos="0.06051911786198616 0.0006756202201358974 -0.055080264806747437" quat="-0.5233864188194275 0.5235495567321777 -0.48246756196022034 0.46817469596862793" mesh="left_hip_pitch" material="cassie" class="visual"/>
							<geom name="Geom_7" type="capsule" pos="0.05999999865889549 0.0 -0.05000000074505806" quat="0.7071067690849304 0.0 -0.7071067690849304 0.0" size="0.07999999821186066 0.05999999865889549 0.0" class="collision"/>
							<joint name="left_hip_pitch" type="hinge" pos="0.0 0.0 0.0" range="-0.8726646304130554 1.3962633609771729" axis="0.0 0.0 1.0"/>
							<body name="left_knee" pos="0.11999999731779099 0.0 0.0044999998062849045" quat="0.9238795042037964 0.0 -0.0 -0.3826834261417389">
								<inertial mass="0.7577999830245972" pos="0.023000000044703484 0.03206999972462654 -0.0021810000762343407" quat="0.6058588027954102 0.340689092874527 -0.6387827396392822 0.32988274097442627" diaginertia="0.0021669911220669746 0.0016374749829992652 0.0007687339675612748"/>
								<geom name="Geom_9" type="mesh" pos="0.019954698160290718 0.03638797253370285 -0.0024124563205987215" quat="0.586346447467804 0.38111579418182373 -0.6153823733329773 0.3636661767959595" mesh="left_knee" material="cassie" class="visual"/>
								<joint name="left_knee" type="hinge" pos="0.0 0.0 0.0" range="-2.862339973449707 -0.6457718014717102" axis="0.0 0.0 1.0"/>
								<body name="left_shin" pos="0.060679998248815536 0.04741000011563301 0.0" quat="1.0 0.0 0.0 0.0">
									<inertial mass="0.5770000219345093" pos="0.18337999284267426 0.0011690000537782907 0.00021230000129435211" quat="0.5006417036056519 0.4919813871383667 0.5086685419082642 0.4985664486885071" diaginertia="0.014731071889400482 0.01470702700316906 0.0003562912461347878"/>
									<geom name="Geom_11" type="mesh" pos="0.15889368951320648 0.00558572169393301 0.0006726673454977572" quat="0.043827030807733536 0.7087695002555847 0.027477527037262917 0.7035410404205322" mesh="left_shin" material="cassie" class="visual"/>
									<geom name="Geom_12" type="capsule" pos="0.054999999701976776 -0.004999999888241291 0.0" quat="0.7071067690849304 -0.03071475587785244 -0.7064393758773804 0.0" size="0.03999999910593033 0.11510864645242691 0.0" class="collision"/>
									<geom name="Geom_13" type="capsule" pos="0.2750000059604645 -0.011500000022351742 0.0" quat="0.7071067690849304 0.07698467373847961 -0.7029035091400146 0.0" size="0.027000000700354576 0.1056278869509697 0.0" class="collision"/>
									<geom name="Geom_14" type="capsule" pos="0.19487999379634857 0.02250000089406967 0.0" quat="0.7071067690849304 -0.06603457778692245 -0.7040166258811951 0.0" size="0.02500000037252903 0.2409329116344452 0.0" class="collision"/>
									<joint name="left_shin" type="hinge" pos="0.0 0.0 0.0" range="-0.3490658402442932 0.3490658402442932" axis="0.0 0.0 1.0"/>
									<body name="left_tarsus" pos="0.4347600042819977 0.019999999552965164 0.0" quat="0.8746196031570435 0.0 0.0 0.4848097860813141">
										<inertial mass="0.7820000052452087" pos="0.11045999825000763 -0.030579999089241028 -0.0013099999632686377" quat="-0.02044411189854145 0.7050092220306396 -0.032995183020830154 0.7081351280212402" diaginertia="0.013674619607627392 0.013598802499473095 0.0003879580763168633"/>
										<geom name="Geom_15" type="mesh" pos="0.1457228809595108 -0.037279460579156876 -0.0011771516874432564" quat="0.020050836727023125 0.7049259543418884 0.017517762258648872 0.7087810039520264" mesh="left_tarsus" material="cassie" class="visual"/>
										<geom name="Geom_16" type="capsule" pos="0.11999999731779099 -0.035294998437166214 0.0004600000102072954" quat="0.7085824012756348 -0.030154068022966385 -0.7049835324287415 0.0" size="0.02800000086426735 0.11010153591632843 0.0" class="collision"/>
										<geom name="Geom_17" type="capsule" pos="0.12399999797344208 -0.054999999701976776 0.0004600000102072954" quat="0.7090101838111877 0.1239672526717186 -0.6942166090011597 0.0" size="0.032999999821186066 0.08533001691102982 0.0" class="collision"/>
										<geom name="Geom_18" type="capsule" pos="0.3190000057220459 -0.03999999910593033 0.0" quat="0.7071067690849304 0.0 -0.7071067690849304 0.0" size="0.019999999552965164 0.11100000143051147 0.0" class="collision"/>
										<joint name="left_tarsus" type="hinge" pos="0.0 0.0 0.0" range="0.8726646304130554 2.96705961227417" axis="0.0 0.0 1.0"/>
										<body name="left_foot_crank" pos="0.057999998331069946 -0.03400000184774399 0.022749999538064003" quat="1.0 0.0 0.0 0.0">
											<inertial mass="0.12610000371932983" pos="0.0049299998208880424 1.9999999494757503e-05 -0.00215000007301569" quat="-0.0003257011703681201 0.6682374477386475 -0.00019792407692875713 0.7439479827880859" diaginertia="6.378808757290244e-05 4.9620994104770944e-05 2.6514919227338396e-05"/>
											<geom name="Geom_20" type="mesh" pos="0.017089499160647392 4.9604455853113905e-05 0.0044750855304300785" quat="0.0007349673542194068 0.7465254068374634 -0.0001308723003603518 0.6653565168380737" mesh="left_foot_crank" material="cassie" class="visual"/>
											<joint name="left_foot_crank" type="hinge" pos="0.0 0.0 0.0" range="-2.4434609413146973 -0.5235987901687622" axis="0.0 0.0 1.0"/>
											<body name="left_plantar_rod" pos="0.054999999701976776 0.0 -0.007910000160336494" quat="1.0 0.0 0.0 0.0">
												<inertial mass="0.11860000342130661" pos="0.17791999876499176 0.0 0.0" quat="-4.67088284494821e-06 0.7071051597595215 4.670861471822718e-06 0.7071083784103394" diaginertia="0.0017750000115484 0.0017740000039339066 2.7789997147920076e-06"/>
												<geom name="Geom_21" type="mesh" pos="0.17513571679592133 4.08341804813972e-07 -1.9616099677932652e-07" quat="3.855827162624337e-05 0.7071117162704468 4.2095060052815825e-05 0.7071018815040588" mesh="left_plantar_rod" material="cassie" class="visual"/>
												<joint name="left_plantar_rod" type="hinge" pos="0.0 0.0 0.0" range="0.0 0.0" axis="0.0 0.0 1.0"/>
											</body>
										</body>
										<body name="left_foot" pos="0.40799999237060547 -0.03999999910593033 0.0" quat="1.0 0.0 0.0 0.0">
											<inertial mass="0.14980000257492065" pos="0.004739999771118164 0.027480000630021095 -0.00014000000373926014" quat="0.27926790714263916 0.655178427696228 -0.2700909376144409 0.6479209661483765" diaginertia="0.0003326265432406217 0.0002890713803935796 5.272209091344848e-05"/>
											<geom name="Geom_22" type="mesh" pos="0.008884768933057785 0.027471691370010376 0.00010202053817920387" quat="0.26759615540504456 0.6528940200805664 -0.2697799801826477 0.6552407145500183" mesh="left_foot" material="cassie" class="visual"/>
											<geom name="Geom_23" type="capsule" pos="0.00846249982714653 0.04119899868965149 0.0" quat="0.7071067690849304 -0.454519659280777 -0.5416750311851501 0.0" size="0.019999999552965164 0.07999995350837708 0.0" class="collision"/>
											<joint name="left_foot" type="hinge" pos="0.0 0.0 0.0" range="-2.4434609413146973 -0.5235987901687622" axis="0.0 0.0 1.0"/>
										</body>
										<body name="left_heel_spring" pos="-0.012690000236034393 -0.03058999963104725 0.0009200000204145908" quat="0.20935484766960144 0.010860571637749672 -0.03755583241581917 0.977057933807373">
											<inertial mass="0.12600000202655792" pos="0.08100000023841858 0.002199999988079071 0.0" quat="0.5091936588287354 0.5091446042060852 0.4888882040977478 0.49242454767227173" diaginertia="0.0002225751813966781 0.0002007018483709544 2.9322971386136487e-05"/>
											<geom name="Geom_19" type="mesh" pos="0.08624786883592606 0.001640240428969264 -0.00019321887521073222" quat="-0.485395610332489 0.4927234649658203 -0.5092779994010925 0.5121040940284729" mesh="left_heel_spring" material="cassie" class="visual"/>
											<joint name="left_heel_spring" type="hinge" pos="0.0 0.0 0.0" range="0.0 0.0" axis="0.0 0.0 1.0"/>
										</body>
									</body>
								</body>
								<body name="left_knee_spring" pos="0.060679998248815536 0.08241000026464462 0.0" quat="1.0 0.0 0.0 0.0">
									<inertial mass="0.1860000044107437" pos="0.0835999995470047 0.0034000000450760126 0.0" quat="0.5047470331192017 0.5047470331192017 0.4952074885368347 0.4952074885368347" diaginertia="0.00041218107799068093 0.00036689999978989363 5.201890962780453e-05"/>
									<geom name="Geom_10" type="mesh" pos="0.09774612635374069 0.0020233020186424255 -3.4393210626149084e-06" quat="-0.4898744225502014 0.4898914098739624 -0.5099207162857056 0.5099120736122131" mesh="left_knee_spring" material="cassie" class="visual"/>
								</body>
							</body>
							<body name="left_achilles_rod" pos="0.0 0.0 0.04500000178813934" quat="0.9465141892433167 -0.014506509527564049 0.04298104718327522 -0.3194575607776642">
								<inertial mass="0.156700000166893" pos="0.24718999862670898 0.0 0.0" quat="-2.949409690700122e-06 0.7071055173873901 2.9493990041373763e-06 0.7071080207824707" diaginertia="0.004488000180572271 0.004486999940127134 3.7539996355917538e-06"/>
								<geom name="Geom_8" type="mesh" pos="0.2505268156528473 9.135077334576636e-07 -1.7718090248308727e-06" quat="-0.0004622502892743796 0.7071101665496826 -0.00046693632612004876 0.7071031332015991" mesh="left_achilles_rod" material="cassie" class="visual"/>
								<joint name="left_achilles_rod" type="ball" pos="0.0 0.0 0.0"/>
							</body>
						</body>
					</body>
				</body>
			</body>
		</body>
	</worldbody>
	<equality/>
</mujoco>
