<?xml version="1.0" ?>
<mujoco model="left_shadow_hand">
	<compiler meshdir="left_shadow_hand/meshes" texturedir="left_shadow_hand/textures" angle="radian" autolimits="true" balanceinertia="true" boundmass="0.000001" boundinertia="0.000001"/>
	<default>
		<default class="visual">
			<geom contype="0" conaffinity="0"/>
		</default>
		<default class="collision">
			<geom rgba="1.0 0.0 0.0 0.0"/>
		</default>
	</default>
	<asset>
		<mesh name="forearm_0" file="stl/forearm_0.stl" scale="1.0 1.0 1.0"/>
		<mesh name="forearm_1" file="stl/forearm_1.stl" scale="1.0 1.0 1.0"/>
		<mesh name="forearm_collision" file="stl/forearm_collision.stl" scale="1.0 1.0 1.0"/>
		<mesh name="wrist" file="stl/wrist.stl" scale="1.0 1.0 1.0"/>
		<mesh name="palm" file="stl/palm.stl" scale="1.0 1.0 1.0"/>
		<mesh name="f_knuckle" file="stl/f_knuckle.stl" scale="1.0 1.0 1.0"/>
		<mesh name="f_proximal" file="stl/f_proximal.stl" scale="1.0 1.0 1.0"/>
		<mesh name="f_middle" file="stl/f_middle.stl" scale="1.0 1.0 1.0"/>
		<mesh name="f_distal_pst" file="stl/f_distal_pst.stl" scale="1.0 1.0 1.0"/>
		<mesh name="lf_metacarpal" file="stl/lf_metacarpal.stl" scale="1.0 1.0 1.0"/>
		<mesh name="th_proximal" file="stl/th_proximal.stl" scale="1.0 1.0 1.0"/>
		<mesh name="th_middle" file="stl/th_middle.stl" scale="1.0 1.0 1.0"/>
		<mesh name="th_distal_pst" file="stl/th_distal_pst.stl" scale="1.0 1.0 1.0"/>
		<material name="gray" rgba="0.8084800243377686 0.8084800243377686 0.8084800243377686 1.0" emission="0.0" specular="0.0"/>
		<material name="black" rgba="0.16355000436306 0.16355000436306 0.16355000436306 1.0" emission="0.0" specular="0.5"/>
		<material name="metallic" rgba="0.8999999761581421 0.8999999761581421 0.8999999761581421 1.0" emission="0.0" specular="0.0"/>
	</asset>
	<worldbody>
		<body name="left_shadow_hand" pos="0.0 0.0 0.0" quat="1.0 0.0 0.0 0.0">
			<body name="lh_forearm" pos="0.0 0.0 0.0" quat="1.0 0.0 0.0 0.0">
				<geom name="Geom_0" type="mesh" pos="-0.0006274281768128276 2.5023158741532825e-05 0.006174841895699501" quat="0.006112334318459034 0.7070778608322144 -0.006098461803048849 0.707082986831665" mesh="forearm_0" material="gray" class="visual"/>
				<geom name="Geom_1" type="mesh" pos="0.0008932988857850432 4.971852831658907e-07 0.10642138868570328" quat="0.7048231363296509 0.014883364550769329 0.01477573812007904 0.709073007106781" mesh="forearm_1" material="black" class="visual"/>
				<geom name="Geom_2" type="mesh" pos="-2.3000312765475428e-08 -2.1648977721611118e-08 0.09274562448263168" quat="1.0 0.0 0.0 0.0" mesh="forearm_collision" class="collision"/>
				<geom name="Geom_3" type="box" pos="0.009999999776482582 0.0 0.1809999942779541" quat="0.38018807768821716 0.9249091744422913 0.0 0.0" size="0.03500000014901161 0.03500000014901161 0.03500000014901161" class="collision"/>
				<body name="lh_wrist" pos="0.009999999776482582 0.0 0.2130099982023239" quat="0.7071067690849304 0.0 0.0 0.7071067690849304">
					<inertial mass="0.10000000149011612" pos="0.0 0.0 0.028999999165534973" quat="0.5 0.5 0.5 0.5" diaginertia="6.399999983841553e-05 4.3799998820759356e-05 3.5000000934815034e-05"/>
					<geom name="Geom_4" type="mesh" pos="-0.002649368019774556 2.261926420032978e-05 0.016064314171671867" quat="0.4955274760723114 0.5043715834617615 0.5036556124687195 0.49637970328330994" mesh="wrist" material="metallic" class="visual"/>
					<geom name="Geom_5" type="cylinder" pos="0.0 0.0 0.0" quat="0.4999980032444 0.5 0.5 -0.5000020265579224" size="0.013500000350177288 0.014999999664723873 0.0" class="collision"/>
					<geom name="Geom_6" type="cylinder" pos="0.026000000536441803 0.0 0.03400000184774399" quat="0.7071067690849304 0.0 0.7071067690849304 0.0" size="0.010999999940395355 0.004999999888241291 0.0" class="collision"/>
					<geom name="Geom_7" type="cylinder" pos="-0.03099999949336052 0.0 0.03400000184774399" quat="0.7071067690849304 0.0 0.7071067690849304 0.0" size="0.010999999940395355 0.004999999888241291 0.0" class="collision"/>
					<geom name="Geom_8" type="box" pos="0.020999999716877937 0.0 0.010999999940395355" quat="-0.9238792657852173 0.0 0.3826841115951538 0.0" size="0.013500000350177288 0.008999999612569809 0.004999999888241291" class="collision"/>
					<geom name="Geom_9" type="box" pos="-0.026000000536441803 0.0 0.009999999776482582" quat="-0.9238792657852173 0.0 -0.3826841115951538 0.0" size="0.013500000350177288 0.008999999612569809 0.004999999888241291" class="collision"/>
					<joint name="lh_WRJ2" type="hinge" pos="0.0 0.0 0.0" range="-0.5235990285873413 0.17453299462795258" axis="0.0 -1.0 0.0"/>
					<body name="lh_palm" pos="0.0 0.0 0.03400000184774399" quat="1.0 0.0 0.0 0.0">
						<inertial mass="0.30000001192092896" pos="0.0 0.0 0.03500000014901161" quat="0.7071067690849304 0.0 0.0 0.7071067690849304" diaginertia="0.0005287000094540417 0.0003580999909900129 0.00019099999917671084"/>
						<geom name="Geom_10" type="mesh" pos="-0.005374445114284754 -0.0022442906629294157 0.0320129431784153" quat="0.6922619938850403 -0.10281900316476822 -0.04589544236660004 0.7128079533576965" mesh="palm" material="black" class="visual"/>
						<geom name="Geom_11" type="box" pos="-0.010999999940395355 0.008500000461935997 0.03799999877810478" quat="1.0 0.0 0.0 0.0" size="0.03099999949336052 0.0035000001080334187 0.04899999871850014" class="collision"/>
						<geom name="Geom_12" type="box" pos="0.0020000000949949026 -0.0035000001080334187 0.03799999877810478" quat="1.0 0.0 0.0 0.0" size="0.017999999225139618 0.008500000461935997 0.04899999871850014" class="collision"/>
						<geom name="Geom_13" type="box" pos="-0.028999999165534973 -0.0035000001080334187 0.0820000022649765" quat="1.0 0.0 0.0 0.0" size="0.013000000268220901 0.008500000461935997 0.004999999888241291" class="collision"/>
						<geom name="Geom_14" type="box" pos="-0.026499999687075615 -0.0010000000474974513 0.07000000029802322" quat="0.9872407913208008 0.0990544781088829 0.012446697801351547 -0.12405197322368622" size="0.013000000268220901 0.007000000216066837 0.008999999612569809" class="collision"/>
						<geom name="Geom_15" type="box" pos="-0.03150000050663948 -0.008500000461935997 0.0010000000474974513" quat="1.0 0.0 0.0 0.0" size="0.010499999858438969 0.013500000350177288 0.01119999960064888" class="collision"/>
						<geom name="Geom_16" type="box" pos="-0.012500000186264515 -0.014999999664723873 0.004000000189989805" quat="-0.9713379144668579 0.0 0.0 -0.23770296573638916" size="0.010999999940395355 0.0024999999441206455 0.014999999664723873" class="collision"/>
						<geom name="Geom_17" type="box" pos="-0.010999999940395355 0.0 0.08900000154972076" quat="1.0 0.0 0.0 0.0" size="0.008999999612569809 0.012000000104308128 0.0020000000949949026" class="collision"/>
						<geom name="Geom_18" type="box" pos="0.029999999329447746 0.0 0.008999999612569809" quat="1.0 0.0 0.0 0.0" size="0.009999999776482582 0.012000000104308128 0.019999999552965164" class="collision"/>
						<joint name="lh_WRJ1" type="hinge" pos="0.0 0.0 0.0" range="-0.6981319785118103 0.4886919856071472" axis="1.0 0.0 0.0"/>
						<body name="lh_mfknuckle" pos="-0.010999999940395355 0.0 0.0989999994635582" quat="1.0 0.0 0.0 0.0">
							<inertial mass="0.00800000037997961" pos="0.0 0.0 0.0" quat="0.5 0.5 -0.5 0.5" diaginertia="3.199999980552093e-07 2.6000000730164174e-07 2.6000000730164174e-07"/>
							<geom name="Geom_27" type="mesh" pos="-8.015944331418723e-06 0.0002838333311956376 0.00031411449890583754" quat="0.971768319606781 0.23584166169166565 0.0022045928053557873 -0.006343154236674309" mesh="f_knuckle" material="metallic" class="visual"/>
							<geom name="Geom_28" type="cylinder" pos="0.0 0.0 0.0" quat="0.7071067690849304 0.0 0.7071067690849304 0.0" size="0.008999999612569809 0.008999999612569809 0.0" class="collision"/>
							<joint name="lh_MFJ4" type="hinge" pos="0.0 0.0 0.0" range="-0.34906598925590515 0.34906598925590515" axis="0.0 1.0 0.0"/>
							<body name="lh_mfproximal" pos="0.0 0.0 0.0" quat="1.0 0.0 0.0 0.0">
								<inertial mass="0.029999999329447746" pos="0.0 0.0 0.02250000089406967" quat="0.7071067690849304 0.0 0.0 0.7071067690849304" diaginertia="9.999999747378752e-06 9.800000043469481e-06 1.7999999499807018e-06"/>
								<geom name="Geom_29" type="mesh" pos="1.2104673032808932e-06 9.761753062775824e-06 0.02288065291941166" quat="0.7071643471717834 -0.004207220859825611 0.0042030117474496365 0.7070241570472717" mesh="f_proximal" material="black" class="visual"/>
								<geom name="Geom_30" type="capsule" pos="0.0 0.0 0.02500000037252903" quat="1.0 0.0 0.0 0.0" size="0.008999999612569809 0.019999999552965164 0.0" class="collision"/>
								<joint name="lh_MFJ3" type="hinge" pos="0.0 0.0 0.0" range="-0.26179900765419006 1.5707999467849731" axis="1.0 0.0 0.0"/>
								<body name="lh_mfmiddle" pos="0.0 0.0 0.04500000178813934" quat="1.0 0.0 0.0 0.0">
									<inertial mass="0.017000000923871994" pos="0.0 0.0 0.012500000186264515" quat="0.7071067690849304 0.0 0.0 0.7071067690849304" diaginertia="2.7000000955013093e-06 2.6000000161729986e-06 8.700000080352766e-07"/>
									<geom name="Geom_31" type="mesh" pos="-2.7197406780032907e-06 -3.219283462385647e-05 0.011511409655213356" quat="0.7071067690849304 8.541106944903731e-05 -9.612595022190362e-05 0.7071067690849304" mesh="f_middle" material="black" class="visual"/>
									<geom name="Geom_32" type="capsule" pos="0.0 0.0 0.012500000186264515" quat="1.0 0.0 0.0 0.0" size="0.008999999612569809 0.012500000186264515 0.0" class="collision"/>
									<joint name="lh_MFJ2" type="hinge" pos="0.0 0.0 0.0" range="0.0 1.5707999467849731" axis="1.0 0.0 0.0"/>
									<body name="lh_mfdistal" pos="0.0 0.0 0.02500000037252903" quat="1.0 0.0 0.0 0.0">
										<inertial mass="0.013000000268220901" pos="0.0 0.0 0.013076899573206902" quat="0.7071067690849304 0.0 0.0 0.7071067690849304" diaginertia="1.2809199461116805e-06 1.1209200465600588e-06 5.300000225361146e-07"/>
										<geom name="Geom_33" type="mesh" pos="-2.3984350264072418e-05 0.0004207325691822916 0.01764647476375103" quat="0.703035831451416 -0.0009495581034570932 0.0009524950874038041 0.7111531496047974" mesh="f_distal_pst" material="black" class="visual"/>
										<geom name="Geom_34" type="mesh" pos="-2.3984350264072418e-05 0.0004207325691822916 0.01764647476375103" quat="0.703035831451416 -0.0009495581034570932 0.0009524950874038041 0.7111531496047974" mesh="f_distal_pst" class="collision"/>
										<joint name="lh_MFJ1" type="hinge" pos="0.0 0.0 0.0" range="0.0 1.5707999467849731" axis="1.0 0.0 0.0"/>
									</body>
								</body>
							</body>
						</body>
						<body name="lh_rfknuckle" pos="0.010999999940395355 0.0 0.0949999988079071" quat="1.0 0.0 0.0 0.0">
							<inertial mass="0.00800000037997961" pos="0.0 0.0 0.0" quat="0.5 0.5 -0.5 0.5" diaginertia="3.199999980552093e-07 2.6000000730164174e-07 2.6000000730164174e-07"/>
							<geom name="Geom_35" type="mesh" pos="-8.015944331418723e-06 0.0002838333311956376 0.00031411449890583754" quat="0.971768319606781 0.23584166169166565 0.0022045928053557873 -0.006343154236674309" mesh="f_knuckle" material="metallic" class="visual"/>
							<geom name="Geom_36" type="cylinder" pos="0.0 0.0 0.0" quat="0.7071067690849304 0.0 0.7071067690849304 0.0" size="0.008999999612569809 0.008999999612569809 0.0" class="collision"/>
							<joint name="lh_RFJ4" type="hinge" pos="0.0 0.0 0.0" range="-0.34906598925590515 0.34906598925590515" axis="0.0 -1.0 0.0"/>
							<body name="lh_rfproximal" pos="0.0 0.0 0.0" quat="1.0 0.0 0.0 0.0">
								<inertial mass="0.029999999329447746" pos="0.0 0.0 0.02250000089406967" quat="0.7071067690849304 0.0 0.0 0.7071067690849304" diaginertia="9.999999747378752e-06 9.800000043469481e-06 1.7999999499807018e-06"/>
								<geom name="Geom_37" type="mesh" pos="1.2104673032808932e-06 9.761753062775824e-06 0.02288065291941166" quat="0.7071643471717834 -0.004207220859825611 0.0042030117474496365 0.7070241570472717" mesh="f_proximal" material="black" class="visual"/>
								<geom name="Geom_38" type="capsule" pos="0.0 0.0 0.02500000037252903" quat="1.0 0.0 0.0 0.0" size="0.008999999612569809 0.019999999552965164 0.0" class="collision"/>
								<joint name="lh_RFJ3" type="hinge" pos="0.0 0.0 0.0" range="-0.26179900765419006 1.5707999467849731" axis="1.0 0.0 0.0"/>
								<body name="lh_rfmiddle" pos="0.0 0.0 0.04500000178813934" quat="1.0 0.0 0.0 0.0">
									<inertial mass="0.017000000923871994" pos="0.0 0.0 0.012500000186264515" quat="0.7071067690849304 0.0 0.0 0.7071067690849304" diaginertia="2.7000000955013093e-06 2.6000000161729986e-06 8.700000080352766e-07"/>
									<geom name="Geom_39" type="mesh" pos="-2.7197406780032907e-06 -3.219283462385647e-05 0.011511409655213356" quat="0.7071067690849304 8.541106944903731e-05 -9.612595022190362e-05 0.7071067690849304" mesh="f_middle" material="black" class="visual"/>
									<geom name="Geom_40" type="capsule" pos="0.0 0.0 0.012500000186264515" quat="1.0 0.0 0.0 0.0" size="0.008999999612569809 0.012500000186264515 0.0" class="collision"/>
									<joint name="lh_RFJ2" type="hinge" pos="0.0 0.0 0.0" range="0.0 1.5707999467849731" axis="1.0 0.0 0.0"/>
									<body name="lh_rfdistal" pos="0.0 0.0 0.02500000037252903" quat="1.0 0.0 0.0 0.0">
										<inertial mass="0.013000000268220901" pos="0.0 0.0 0.013076899573206902" quat="0.7071067690849304 0.0 0.0 0.7071067690849304" diaginertia="1.2809199461116805e-06 1.1209200465600588e-06 5.300000225361146e-07"/>
										<geom name="Geom_41" type="mesh" pos="-2.3984350264072418e-05 0.0004207325691822916 0.01764647476375103" quat="0.703035831451416 -0.0009495581034570932 0.0009524950874038041 0.7111531496047974" mesh="f_distal_pst" material="black" class="visual"/>
										<geom name="Geom_42" type="mesh" pos="-2.3984350264072418e-05 0.0004207325691822916 0.01764647476375103" quat="0.703035831451416 -0.0009495581034570932 0.0009524950874038041 0.7111531496047974" mesh="f_distal_pst" class="collision"/>
										<joint name="lh_RFJ1" type="hinge" pos="0.0 0.0 0.0" range="0.0 1.5707999467849731" axis="1.0 0.0 0.0"/>
									</body>
								</body>
							</body>
						</body>
						<body name="lh_lfmetacarpal" pos="0.032999999821186066 0.0 0.02071000076830387" quat="1.0 0.0 0.0 0.0">
							<inertial mass="0.029999999329447746" pos="0.0 0.0 0.03999999910593033" quat="0.7071067690849304 0.0 0.0 0.7071067690849304" diaginertia="1.6379999578930438e-05 1.4500000361294951e-05 4.271999841876095e-06"/>
							<geom name="Geom_43" type="mesh" pos="-0.002477748552337289 0.0006623357185162604 0.03647977486252785" quat="0.6964011788368225 0.06640015542507172 0.09600429236888885 0.7080957889556885" mesh="lf_metacarpal" material="black" class="visual"/>
							<geom name="Geom_44" type="box" pos="-0.0020000000949949026 0.0 0.032999999821186066" quat="1.0 0.0 0.0 0.0" size="0.010999999940395355 0.012000000104308128 0.02500000037252903" class="collision"/>
							<joint name="lh_LFJ5" type="hinge" pos="0.0 0.0 0.0" range="0.0 0.785398006439209" axis="0.5735761523246765 0.0 -0.8191522359848022"/>
							<body name="lh_lfknuckle" pos="0.0 0.0 0.06578999757766724" quat="1.0 0.0 0.0 0.0">
								<inertial mass="0.00800000037997961" pos="0.0 0.0 0.0" quat="0.5 0.5 -0.5 0.5" diaginertia="3.199999980552093e-07 2.6000000730164174e-07 2.6000000730164174e-07"/>
								<geom name="Geom_45" type="mesh" pos="-8.015944331418723e-06 0.0002838333311956376 0.00031411449890583754" quat="0.971768319606781 0.23584166169166565 0.0022045928053557873 -0.006343154236674309" mesh="f_knuckle" material="metallic" class="visual"/>
								<geom name="Geom_46" type="cylinder" pos="0.0 0.0 0.0" quat="0.7071067690849304 0.0 0.7071067690849304 0.0" size="0.008999999612569809 0.008999999612569809 0.0" class="collision"/>
								<joint name="lh_LFJ4" type="hinge" pos="0.0 0.0 0.0" range="-0.34906598925590515 0.34906598925590515" axis="0.0 -1.0 0.0"/>
								<body name="lh_lfproximal" pos="0.0 0.0 0.0" quat="1.0 0.0 0.0 0.0">
									<inertial mass="0.029999999329447746" pos="0.0 0.0 0.02250000089406967" quat="0.7071067690849304 0.0 0.0 0.7071067690849304" diaginertia="9.999999747378752e-06 9.800000043469481e-06 1.7999999499807018e-06"/>
									<geom name="Geom_47" type="mesh" pos="1.2104673032808932e-06 9.761753062775824e-06 0.02288065291941166" quat="0.7071643471717834 -0.004207220859825611 0.0042030117474496365 0.7070241570472717" mesh="f_proximal" material="black" class="visual"/>
									<geom name="Geom_48" type="capsule" pos="0.0 0.0 0.02500000037252903" quat="1.0 0.0 0.0 0.0" size="0.008999999612569809 0.019999999552965164 0.0" class="collision"/>
									<joint name="lh_LFJ3" type="hinge" pos="0.0 0.0 0.0" range="-0.26179900765419006 1.5707999467849731" axis="1.0 0.0 0.0"/>
									<body name="lh_lfmiddle" pos="0.0 0.0 0.04500000178813934" quat="1.0 0.0 0.0 0.0">
										<inertial mass="0.017000000923871994" pos="0.0 0.0 0.012500000186264515" quat="0.7071067690849304 0.0 0.0 0.7071067690849304" diaginertia="2.7000000955013093e-06 2.6000000161729986e-06 8.700000080352766e-07"/>
										<geom name="Geom_49" type="mesh" pos="-2.7197406780032907e-06 -3.219283462385647e-05 0.011511409655213356" quat="0.7071067690849304 8.541106944903731e-05 -9.612595022190362e-05 0.7071067690849304" mesh="f_middle" material="black" class="visual"/>
										<geom name="Geom_50" type="capsule" pos="0.0 0.0 0.012500000186264515" quat="1.0 0.0 0.0 0.0" size="0.008999999612569809 0.012500000186264515 0.0" class="collision"/>
										<joint name="lh_LFJ2" type="hinge" pos="0.0 0.0 0.0" range="0.0 1.5707999467849731" axis="1.0 0.0 0.0"/>
										<body name="lh_lfdistal" pos="0.0 0.0 0.02500000037252903" quat="1.0 0.0 0.0 0.0">
											<inertial mass="0.013000000268220901" pos="0.0 0.0 0.013076899573206902" quat="0.7071067690849304 0.0 0.0 0.7071067690849304" diaginertia="1.2809199461116805e-06 1.1209200465600588e-06 5.300000225361146e-07"/>
											<geom name="Geom_51" type="mesh" pos="-2.3984350264072418e-05 0.0004207325691822916 0.01764647476375103" quat="0.703035831451416 -0.0009495581034570932 0.0009524950874038041 0.7111531496047974" mesh="f_distal_pst" material="black" class="visual"/>
											<geom name="Geom_52" type="mesh" pos="-2.3984350264072418e-05 0.0004207325691822916 0.01764647476375103" quat="0.703035831451416 -0.0009495581034570932 0.0009524950874038041 0.7111531496047974" mesh="f_distal_pst" class="collision"/>
											<joint name="lh_LFJ1" type="hinge" pos="0.0 0.0 0.0" range="0.0 1.5707999467849731" axis="1.0 0.0 0.0"/>
										</body>
									</body>
								</body>
							</body>
						</body>
						<body name="lh_thbase" pos="-0.03400000184774399 -0.008580000139772892 0.028999999165534973" quat="0.0 -0.3826828896999359 0.0 0.9238797426223755">
							<inertial mass="0.009999999776482582" pos="0.0 0.0 0.0" quat="1.0 0.0 0.0 0.0" diaginertia="1.5999999902760464e-07 1.5999999902760464e-07 1.5999999902760464e-07"/>
							<geom name="Geom_53" type="sphere" pos="0.0 0.0 0.0" quat="1.0 0.0 0.0 0.0" size="0.013000000268220901 0.0 0.0" class="collision"/>
							<joint name="lh_THJ5" type="hinge" pos="0.0 0.0 0.0" range="-1.0471999645233154 1.0471999645233154" axis="0.0 0.0 1.0"/>
							<body name="lh_thproximal" pos="0.0 0.0 0.0" quat="1.0 0.0 0.0 0.0">
								<inertial mass="0.03999999910593033" pos="0.0 0.0 0.01899999938905239" quat="1.0 0.0 0.0 0.0" diaginertia="1.359999987471383e-05 1.359999987471383e-05 3.130000095552532e-06"/>
								<geom name="Geom_54" type="mesh" pos="-6.37889388599433e-06 -2.603128450573422e-05 0.01671529933810234" quat="0.981552004814148 -0.00010685295274015516 0.0005376083427108824 0.19119460880756378" mesh="th_proximal" material="black" class="visual"/>
								<geom name="Geom_55" type="capsule" pos="0.0 0.0 0.019999999552965164" quat="1.0 0.0 0.0 0.0" size="0.010499999858438969 0.008999999612569809 0.0" class="collision"/>
								<joint name="lh_THJ4" type="hinge" pos="0.0 0.0 0.0" range="0.0 1.2217299938201904" axis="-1.0 0.0 0.0"/>
								<body name="lh_thhub" pos="0.0 0.0 0.03799999877810478" quat="1.0 0.0 0.0 0.0">
									<inertial mass="0.004999999888241291" pos="0.0 0.0 0.0" quat="1.0 0.0 0.0 0.0" diaginertia="9.999999974752427e-07 9.999999974752427e-07 3.000000106112566e-07"/>
									<geom name="Geom_56" type="sphere" pos="0.0 0.0 0.0" quat="1.0 0.0 0.0 0.0" size="0.010999999940395355 0.0 0.0" class="collision"/>
									<joint name="lh_THJ3" type="hinge" pos="0.0 0.0 0.0" range="-0.20943999290466309 0.20943999290466309" axis="-1.0 0.0 0.0"/>
									<body name="lh_thmiddle" pos="0.0 0.0 0.0" quat="1.0 0.0 0.0 0.0">
										<inertial mass="0.019999999552965164" pos="0.0 0.0 0.01600000075995922" quat="1.0 0.0 0.0 0.0" diaginertia="5.100000180391362e-06 5.100000180391362e-06 1.2100000503778574e-06"/>
										<geom name="Geom_57" type="mesh" pos="7.479629857698455e-05 -4.5069777115713805e-05 0.015348398126661777" quat="0.9999998807907104 0.0 -0.0004517743072938174 0.0" mesh="th_middle" material="black" class="visual"/>
										<geom name="Geom_58" type="capsule" pos="0.0 0.0 0.012000000104308128" quat="1.0 0.0 0.0 0.0" size="0.008999999612569809 0.008999999612569809 0.0" class="collision"/>
										<geom name="Geom_59" type="sphere" pos="0.0 0.0 0.029999999329447746" quat="1.0 0.0 0.0 0.0" size="0.009999999776482582 0.0 0.0" class="collision"/>
										<joint name="lh_THJ2" type="hinge" pos="0.0 0.0 0.0" range="-0.6981319785118103 0.6981319785118103" axis="0.0 -1.0 0.0"/>
										<body name="lh_thdistal" pos="0.0 0.0 0.03200000151991844" quat="0.7071067690849304 0.0 0.0 -0.7071067690849304">
											<inertial mass="0.017000000923871994" pos="0.0 0.0 0.01455879956483841" quat="0.7071067690849304 0.0 0.0 0.7071067690849304" diaginertia="2.377940063524875e-06 2.277939984196564e-06 9.999999974752427e-07"/>
											<geom name="Geom_60" type="mesh" pos="-8.254509680227784e-07 0.0008025187416933477 0.019553372636437416" quat="0.7071506977081299 -0.0011598747223615646 0.001084130140952766 0.7070610523223877" mesh="th_distal_pst" material="black" class="visual"/>
											<geom name="Geom_61" type="mesh" pos="-8.254509680227784e-07 0.0008025187416933477 0.019553372636437416" quat="0.7071506977081299 -0.0011598747223615646 0.001084130140952766 0.7070610523223877" mesh="th_distal_pst" class="collision"/>
											<joint name="lh_THJ1" type="hinge" pos="0.0 0.0 0.0" range="-0.26179900765419006 1.5707999467849731" axis="1.0 0.0 0.0"/>
										</body>
									</body>
								</body>
							</body>
						</body>
						<body name="lh_ffknuckle" pos="-0.032999999821186066 0.0 0.0949999988079071" quat="1.0 0.0 0.0 0.0">
							<inertial mass="0.00800000037997961" pos="0.0 0.0 0.0" quat="0.5 0.5 -0.5 0.5" diaginertia="3.199999980552093e-07 2.6000000730164174e-07 2.6000000730164174e-07"/>
							<geom name="Geom_19" type="mesh" pos="-8.015944331418723e-06 0.0002838333311956376 0.00031411449890583754" quat="0.971768319606781 0.23584166169166565 0.0022045928053557873 -0.006343154236674309" mesh="f_knuckle" material="metallic" class="visual"/>
							<geom name="Geom_20" type="cylinder" pos="0.0 0.0 0.0" quat="0.7071067690849304 0.0 0.7071067690849304 0.0" size="0.008999999612569809 0.008999999612569809 0.0" class="collision"/>
							<joint name="lh_FFJ4" type="hinge" pos="0.0 0.0 0.0" range="-0.34906598925590515 0.34906598925590515" axis="0.0 1.0 0.0"/>
							<body name="lh_ffproximal" pos="0.0 0.0 0.0" quat="1.0 0.0 0.0 0.0">
								<inertial mass="0.029999999329447746" pos="0.0 0.0 0.02250000089406967" quat="0.7071067690849304 0.0 0.0 0.7071067690849304" diaginertia="9.999999747378752e-06 9.800000043469481e-06 1.7999999499807018e-06"/>
								<geom name="Geom_21" type="mesh" pos="1.2104673032808932e-06 9.761753062775824e-06 0.02288065291941166" quat="0.7071643471717834 -0.004207220859825611 0.0042030117474496365 0.7070241570472717" mesh="f_proximal" material="black" class="visual"/>
								<geom name="Geom_22" type="capsule" pos="0.0 0.0 0.02500000037252903" quat="1.0 0.0 0.0 0.0" size="0.008999999612569809 0.019999999552965164 0.0" class="collision"/>
								<joint name="lh_FFJ3" type="hinge" pos="0.0 0.0 0.0" range="-0.26179900765419006 1.5707999467849731" axis="1.0 0.0 0.0"/>
								<body name="lh_ffmiddle" pos="0.0 0.0 0.04500000178813934" quat="1.0 0.0 0.0 0.0">
									<inertial mass="0.017000000923871994" pos="0.0 0.0 0.012500000186264515" quat="0.7071067690849304 0.0 0.0 0.7071067690849304" diaginertia="2.7000000955013093e-06 2.6000000161729986e-06 8.700000080352766e-07"/>
									<geom name="Geom_23" type="mesh" pos="-2.7197406780032907e-06 -3.219283462385647e-05 0.011511409655213356" quat="0.7071067690849304 8.541106944903731e-05 -9.612595022190362e-05 0.7071067690849304" mesh="f_middle" material="black" class="visual"/>
									<geom name="Geom_24" type="capsule" pos="0.0 0.0 0.012500000186264515" quat="1.0 0.0 0.0 0.0" size="0.008999999612569809 0.012500000186264515 0.0" class="collision"/>
									<joint name="lh_FFJ2" type="hinge" pos="0.0 0.0 0.0" range="0.0 1.5707999467849731" axis="1.0 0.0 0.0"/>
									<body name="lh_ffdistal" pos="0.0 0.0 0.02500000037252903" quat="1.0 0.0 0.0 0.0">
										<inertial mass="0.013000000268220901" pos="0.0 0.0 0.013076899573206902" quat="0.7071067690849304 0.0 0.0 0.7071067690849304" diaginertia="1.2809199461116805e-06 1.1209200465600588e-06 5.300000225361146e-07"/>
										<geom name="Geom_25" type="mesh" pos="-2.3984350264072418e-05 0.0004207325691822916 0.01764647476375103" quat="0.703035831451416 -0.0009495581034570932 0.0009524950874038041 0.7111531496047974" mesh="f_distal_pst" material="black" class="visual"/>
										<geom name="Geom_26" type="mesh" pos="-2.3984350264072418e-05 0.0004207325691822916 0.01764647476375103" quat="0.703035831451416 -0.0009495581034570932 0.0009524950874038041 0.7111531496047974" mesh="f_distal_pst" class="collision"/>
										<joint name="lh_FFJ1" type="hinge" pos="0.0 0.0 0.0" range="0.0 1.5707999467849731" axis="1.0 0.0 0.0"/>
									</body>
								</body>
							</body>
						</body>
					</body>
				</body>
			</body>
		</body>
	</worldbody>
	<equality/>
</mujoco>
