<?xml version="1.0" ?>
<mujoco model="vx300s">
	<compiler meshdir="vx300s/meshes" texturedir="vx300s/textures" angle="radian" autolimits="true" balanceinertia="true" boundmass="0.000001" boundinertia="0.000001"/>
	<default>
		<default class="visual">
			<geom contype="0" conaffinity="0"/>
		</default>
		<default class="collision">
			<geom rgba="1.0 0.0 0.0 0.0"/>
		</default>
	</default>
	<asset>
		<mesh name="vx300s_1_base" file="stl/vx300s_1_base.stl" scale="1.0 1.0 1.0"/>
		<mesh name="vx300s_2_shoulder" file="stl/vx300s_2_shoulder.stl" scale="1.0 1.0 1.0"/>
		<mesh name="vx300s_3_upper_arm" file="stl/vx300s_3_upper_arm.stl" scale="1.0 1.0 1.0"/>
		<mesh name="vx300s_4_upper_forearm" file="stl/vx300s_4_upper_forearm.stl" scale="1.0 1.0 1.0"/>
		<mesh name="vx300s_5_lower_forearm" file="stl/vx300s_5_lower_forearm.stl" scale="1.0 1.0 1.0"/>
		<mesh name="vx300s_6_wrist" file="stl/vx300s_6_wrist.stl" scale="1.0 1.0 1.0"/>
		<mesh name="vx300s_7_gripper" file="stl/vx300s_7_gripper.stl" scale="1.0 1.0 1.0"/>
		<mesh name="vx300s_9_gripper_bar" file="stl/vx300s_9_gripper_bar.stl" scale="1.0 1.0 1.0"/>
		<mesh name="vx300s_8_gripper_prop" file="stl/vx300s_8_gripper_prop.stl" scale="1.0 1.0 1.0"/>
		<mesh name="vx300s_10_gripper_finger" file="stl/vx300s_10_gripper_finger.stl" scale="1.0 1.0 1.0"/>
		<material name="black" rgba="1.0 1.0 1.0 1.0" emission="0.0" specular="0.5"/>
	</asset>
	<worldbody>
		<body name="vx300s" pos="0.0 0.0 0.0" quat="1.0 0.0 0.0 0.0">
			<body name="base_link" pos="0.0 0.0 0.0" quat="1.0 0.0 0.0 0.0">
				<geom name="Geom_0" type="mesh" pos="-0.03784382715821266 2.87049459757327e-08 0.029133988544344902" quat="0.0 0.6969158053398132 0.0 0.7171529531478882" mesh="vx300s_1_base" material="black" class="visual"/>
				<geom name="Geom_1" type="mesh" pos="-0.03784382715821266 2.87049459757327e-08 0.029133988544344902" quat="0.0 0.6969158053398132 0.0 0.7171529531478882" mesh="vx300s_1_base" class="collision"/>
				<body name="shoulder_link" pos="0.0 0.0 0.07900000363588333" quat="1.0 0.0 0.0 0.0">
					<inertial mass="0.7986140251159668" pos="0.0002592329983599484 -3.3552000786585268e-06 0.011612899601459503" quat="-0.4761188328266144 0.47608283162117004 0.5227898359298706 0.5228258371353149" diaginertia="0.0012015600223094225 0.0011374399764463305 0.0009387999889440835"/>
					<geom name="Geom_2" type="mesh" pos="0.0006325716967694461 -2.2884038414217045e-12 0.02039145678281784" quat="-0.5 0.5 0.5 0.5" mesh="vx300s_2_shoulder" material="black" class="visual"/>
					<geom name="Geom_3" type="mesh" pos="0.0006325716967694461 -2.2884038414217045e-12 0.02039145678281784" quat="-0.5 0.5 0.5 0.5" mesh="vx300s_2_shoulder" class="collision"/>
					<joint name="waist" type="hinge" pos="0.0 0.0 0.0" range="-3.141580104827881 3.141580104827881" axis="0.0 0.0 1.0"/>
					<body name="upper_arm_link" pos="0.0 0.0 0.04805000126361847" quat="1.0 0.0 0.0 0.0">
						<inertial mass="0.7925919890403748" pos="0.020694900304079056 4.000000053405728e-10 0.22645899653434753" quat="0.0 0.07284581661224365 0.0 0.9973432421684265" diaginertia="0.009113379754126072 0.008925000205636024 0.0007593170157633722"/>
						<geom name="Geom_4" type="mesh" pos="0.018794847652316093 9.543430490310811e-10 0.20381388068199158" quat="0.0 0.06868105381727219 0.0 0.9976386427879333" mesh="vx300s_3_upper_arm" material="black" class="visual"/>
						<geom name="Geom_5" type="mesh" pos="0.018794847652316093 9.543430490310811e-10 0.20381388068199158" quat="0.0 0.06868105381727219 0.0 0.9976386427879333" mesh="vx300s_3_upper_arm" class="collision"/>
						<joint name="shoulder" type="hinge" pos="0.0 0.0 0.0" range="-1.8500499725341797 1.2566399574279785" axis="0.0 1.0 0.0"/>
						<body name="upper_forearm_link" pos="0.05954999849200249 0.0 0.30000001192092896" quat="1.0 0.0 0.0 0.0">
							<inertial mass="0.32222801446914673" pos="0.10572300106287003 0.0 0.0" quat="-0.0006216310430318117 0.7047240734100342 0.010529201477766037 0.7094030976295471" diaginertia="0.0014410699950531125 0.0013422799529507756 0.0001520469959359616"/>
							<geom name="Geom_6" type="mesh" pos="0.09150298684835434 4.662075525629916e-08 5.335134645179096e-08" quat="-6.086713710828917e-07 0.7071062326431274 6.086723374210123e-07 0.7071073651313782" mesh="vx300s_4_upper_forearm" material="black" class="visual"/>
							<geom name="Geom_7" type="mesh" pos="0.09150298684835434 4.662075525629916e-08 5.335134645179096e-08" quat="-6.086713710828917e-07 0.7071062326431274 6.086723374210123e-07 0.7071073651313782" mesh="vx300s_4_upper_forearm" class="collision"/>
							<joint name="elbow" type="hinge" pos="0.0 0.0 0.0" range="-1.762779951095581 1.6057000160217285" axis="0.0 1.0 0.0"/>
							<body name="lower_forearm_link" pos="0.20000000298023224 0.0 0.0" quat="1.0 0.0 0.0 0.0">
								<inertial mass="0.4148229956626892" pos="0.051347699016332626 0.006804619915783405 0.0" quat="-0.7026039361953735 -0.07967239618301392 -0.7026039361953735 0.07967239618301392" diaginertia="0.0005911000189371407 0.0005464929854497313 0.00015570700634270906"/>
								<geom name="Geom_8" type="mesh" pos="0.04686346650123596 0.0060616107657551765 -3.6068836379854474e-06" quat="-0.7044361233711243 -0.05985187739133835 -0.7046372294425964 0.060612332075834274" mesh="vx300s_5_lower_forearm" material="black" class="visual"/>
								<geom name="Geom_9" type="mesh" pos="0.04686346650123596 0.0060616107657551765 -3.6068836379854474e-06" quat="-0.7044361233711243 -0.05985187739133835 -0.7046372294425964 0.060612332075834274" mesh="vx300s_5_lower_forearm" class="collision"/>
								<joint name="forearm_roll" type="hinge" pos="0.0 0.0 0.0" range="-3.141580104827881 3.141580104827881" axis="1.0 0.0 0.0"/>
								<body name="wrist_link" pos="0.10000000149011612 0.0 0.0" quat="1.0 0.0 0.0 0.0">
									<inertial mass="0.11539500206708908" pos="0.0467430017888546 -7.665200428164098e-06 0.010564999654889107" quat="-0.0010019101900979877 0.5445860624313354 0.002658300334587693 0.8387001156806946" diaginertia="5.457070074044168e-05 4.631009869626723e-05 4.326919952291064e-05"/>
									<geom name="Geom_10" type="mesh" pos="0.04164133220911026 -0.00016056399908848107 0.007847931236028671" quat="0.0 0.6176437139511108 0.0 0.7864580154418945" mesh="vx300s_6_wrist" material="black" class="visual"/>
									<geom name="Geom_11" type="mesh" pos="0.04164133220911026 -0.00016056399908848107 0.007847931236028671" quat="0.0 0.6176437139511108 0.0 0.7864580154418945" mesh="vx300s_6_wrist" class="collision"/>
									<joint name="wrist_angle" type="hinge" pos="0.0 0.0 0.0" range="-1.8674999475479126 2.2340199947357178" axis="0.0 1.0 0.0"/>
									<body name="gripper_link" pos="0.06974399834871292 0.0 0.0" quat="1.0 0.0 0.0 0.0">
										<inertial mass="0.2516520023345947" pos="0.039566200226545334 -2.5631101152612246e-07 0.004006490111351013" quat="0.6203300356864929 0.6199160218238831 -0.339682012796402 0.33986902236938477" diaginertia="0.0006895459955558181 0.0006503160111606121 0.00046814201050437987"/>
										<geom name="Geom_12" type="mesh" pos="0.019865669310092926 -7.045326544385944e-09 0.010150989517569542" quat="0.684739351272583 0.17644278705120087 0.17644278705120087 0.684739351272583" mesh="vx300s_7_gripper" material="black" class="visual"/>
										<geom name="Geom_13" type="mesh" pos="0.019865669310092926 -7.045326544385944e-09 0.010150989517569542" quat="0.684739351272583 0.17644278705120087 0.17644278705120087 0.684739351272583" mesh="vx300s_7_gripper" class="collision"/>
										<geom name="Geom_14" type="mesh" pos="0.04932825639843941 -4.465221081773052e-07 -0.0012095709098502994" quat="-0.06845773011445999 0.06845780462026596 0.7037239670753479 0.7038463354110718" mesh="vx300s_9_gripper_bar" material="black" class="visual"/>
										<geom name="Geom_15" type="mesh" pos="0.04932825639843941 -4.465221081773052e-07 -0.0012095709098502994" quat="-0.06845773011445999 0.06845780462026596 0.7037239670753479 0.7038463354110718" mesh="vx300s_9_gripper_bar" class="collision"/>
										<joint name="wrist_rotate" type="hinge" pos="0.0 0.0 0.0" range="-3.141580104827881 3.141580104827881" axis="1.0 0.0 0.0"/>
										<body name="left_finger_link" pos="0.06870000064373016 0.0 0.0" quat="1.0 0.0 0.0 0.0">
											<inertial mass="0.03479599952697754" pos="0.017343999817967415 -0.006069200113415718 0.0" quat="0.4493638575077057 0.4493638575077057 -0.5459598302841187 -0.5459598302841187" diaginertia="2.4800299797789194e-05 1.4170000213198364e-05 1.2079700354661327e-05"/>
											<geom name="Geom_18" type="mesh" pos="0.017321372404694557 -0.005584105383604765 3.1368177499935257e-10" quat="-0.6409380435943604 0.0 0.0 0.7675926089286804" mesh="vx300s_10_gripper_finger" material="black" class="visual"/>
											<geom name="left_finger_pad_0" type="box" pos="0.04780000075697899 -0.012500000186264515 0.010599999688565731" quat="0.6530107855796814 0.6530107855796814 -0.2712506353855133 0.2712506353855133" size="0.014050000347197056 0.014050000347197056 0.0010000000474974513" class="collision"/>
											<geom name="left_finger_pad_1" type="box" pos="0.04780000075697899 -0.012500000186264515 -0.010599999688565731" quat="0.6530107855796814 0.6530107855796814 -0.2712506353855133 0.2712506353855133" size="0.014050000347197056 0.014050000347197056 0.0010000000474974513" class="collision"/>
											<geom name="left_finger_pad_2" type="box" pos="0.057100001722574234 -0.012500000186264515 0.0" quat="0.7071067690849304 0.7071067690849304 0.0 0.0" size="0.010579999536275864 0.010579999536275864 0.0010000000474974513" class="collision"/>
											<geom name="left_finger_pad_3" type="box" pos="0.03779999911785126 -0.012500000186264515 0.0" quat="0.7071067690849304 0.7071067690849304 0.0 0.0" size="0.009999999776482582 0.010499999858438969 0.0010000000474974513" class="collision"/>
											<geom name="left_finger_pad_4" type="box" pos="0.012799999676644802 -0.012500000186264515 0.0" quat="0.7071067690849304 0.7071067690849304 0.0 0.0" size="0.014999999664723873 0.010499999858438969 0.0010000000474974513" class="collision"/>
											<geom name="left_finger_pad_5" type="box" pos="0.03779999911785126 -0.012500000186264515 0.019999999552965164" quat="0.7071067690849304 0.7071067690849304 0.0 0.0" size="0.009999999776482582 0.010499999858438969 0.0010000000474974513" class="collision"/>
											<geom name="left_finger_pad_6" type="box" pos="0.012799999676644802 -0.012500000186264515 0.019999999552965164" quat="0.7071067690849304 0.7071067690849304 0.0 0.0" size="0.014999999664723873 0.010499999858438969 0.0010000000474974513" class="collision"/>
											<geom name="left_finger_pad_7" type="box" pos="0.03779999911785126 -0.012500000186264515 -0.019999999552965164" quat="0.7071067690849304 0.7071067690849304 0.0 0.0" size="0.009999999776482582 0.010499999858438969 0.0010000000474974513" class="collision"/>
											<geom name="left_finger_pad_8" type="box" pos="0.012799999676644802 -0.012500000186264515 -0.019999999552965164" quat="0.7071067690849304 0.7071067690849304 0.0 0.0" size="0.014999999664723873 0.010499999858438969 0.0010000000474974513" class="collision"/>
											<joint name="left_finger" type="slide" pos="0.0 0.0 0.0" range="0.020999999716877937 0.05700000002980232" axis="0.0 1.0 0.0"/>
										</body>
										<body name="gripper_prop_link" pos="0.048500001430511475 0.0 0.0" quat="1.0 0.0 0.0 0.0">
											<inertial mass="0.00800899975001812" pos="0.002377999946475029 2.8500000581743734e-08 0.0" quat="0.0 0.0 0.8976981043815613 0.4406110644340515" diaginertia="4.297899977245834e-06 2.8868000754300738e-06 1.53140001657448e-06"/>
											<geom name="Geom_16" type="mesh" pos="2.7583901829331126e-09 0.00024063170712906867 -0.0005006406572647393" quat="0.0 0.0 -0.02795681729912758 0.999609112739563" mesh="vx300s_8_gripper_prop" material="black" class="visual"/>
											<geom name="Geom_17" type="mesh" pos="2.7583901829331126e-09 0.00024063170712906867 -0.0005006406572647393" quat="0.0 0.0 -0.02795681729912758 0.999609112739563" mesh="vx300s_8_gripper_prop" class="collision"/>
										</body>
										<body name="right_finger_link" pos="0.06870000064373016 0.0 0.0" quat="1.0 0.0 0.0 0.0">
											<inertial mass="0.03479599952697754" pos="0.017343999817967415 0.006069200113415718 0.0" quat="0.449369877576828 -0.449369877576828 0.5459548830986023 -0.5459548830986023" diaginertia="2.4800199753372e-05 1.4170000213198364e-05 1.2079800399078522e-05"/>
											<geom name="Geom_28" type="mesh" pos="0.017321372404694557 0.005584105383604765 -3.1368177499935257e-10" quat="0.0 0.6409380435943604 0.7675926089286804 0.0" mesh="vx300s_10_gripper_finger" material="black" class="visual"/>
											<geom name="right_finger_pad_0" type="box" pos="0.04780000075697899 0.012500000186264515 0.010599999688565731" quat="0.6530107855796814 0.6530107855796814 -0.2712506353855133 0.2712506353855133" size="0.014050000347197056 0.014050000347197056 0.0010000000474974513" class="collision"/>
											<geom name="right_finger_pad_1" type="box" pos="0.04780000075697899 0.012500000186264515 -0.010599999688565731" quat="0.6530107855796814 0.6530107855796814 -0.2712506353855133 0.2712506353855133" size="0.014050000347197056 0.014050000347197056 0.0010000000474974513" class="collision"/>
											<geom name="right_finger_pad_2" type="box" pos="0.057100001722574234 0.012500000186264515 0.0" quat="0.7071067690849304 0.7071067690849304 0.0 0.0" size="0.010579999536275864 0.010579999536275864 0.0010000000474974513" class="collision"/>
											<geom name="right_finger_pad_3" type="box" pos="0.03779999911785126 0.012500000186264515 0.0" quat="0.7071067690849304 0.7071067690849304 0.0 0.0" size="0.009999999776482582 0.010499999858438969 0.0010000000474974513" class="collision"/>
											<geom name="right_finger_pad_4" type="box" pos="0.012799999676644802 0.012500000186264515 0.0" quat="0.7071067690849304 0.7071067690849304 0.0 0.0" size="0.014999999664723873 0.010499999858438969 0.0010000000474974513" class="collision"/>
											<geom name="right_finger_pad_5" type="box" pos="0.03779999911785126 0.012500000186264515 0.019999999552965164" quat="0.7071067690849304 0.7071067690849304 0.0 0.0" size="0.009999999776482582 0.010499999858438969 0.0010000000474974513" class="collision"/>
											<geom name="right_finger_pad_6" type="box" pos="0.012799999676644802 0.012500000186264515 0.019999999552965164" quat="0.7071067690849304 0.7071067690849304 0.0 0.0" size="0.014999999664723873 0.010499999858438969 0.0010000000474974513" class="collision"/>
											<geom name="right_finger_pad_7" type="box" pos="0.03779999911785126 0.012500000186264515 -0.019999999552965164" quat="0.7071067690849304 0.7071067690849304 0.0 0.0" size="0.009999999776482582 0.010499999858438969 0.0010000000474974513" class="collision"/>
											<geom name="right_finger_pad_8" type="box" pos="0.012799999676644802 0.012500000186264515 -0.019999999552965164" quat="0.7071067690849304 0.7071067690849304 0.0 0.0" size="0.014999999664723873 0.010499999858438969 0.0010000000474974513" class="collision"/>
											<joint name="right_finger" type="slide" pos="0.0 0.0 0.0" range="-0.05700000002980232 -0.020999999716877937" axis="0.0 1.0 0.0"/>
										</body>
									</body>
								</body>
							</body>
						</body>
					</body>
				</body>
			</body>
		</body>
	</worldbody>
	<equality>
		<joint name="Equality_0" joint1="left_finger" joint2="right_finger" polycoef="0.0 -1.0 0.0 0.0 0.0"/>
	</equality>
</mujoco>
