<?xml version="1.0" ?>
<mujoco model="sawyer">
	<compiler meshdir="sawyer/meshes" texturedir="sawyer/textures" angle="radian" autolimits="true" balanceinertia="true" boundmass="0.000001" boundinertia="0.000001"/>
	<default>
		<default class="visual">
			<geom contype="0" conaffinity="0"/>
		</default>
		<default class="collision">
			<geom rgba="1.0 0.0 0.0 0.0"/>
		</default>
	</default>
	<asset>
		<mesh name="base_0" file="stl/base_0.stl" scale="1.0 1.0 1.0"/>
		<mesh name="base_1" file="stl/base_1.stl" scale="1.0 1.0 1.0"/>
		<mesh name="l0_0" file="stl/l0_0.stl" scale="1.0 1.0 1.0"/>
		<mesh name="l0_1" file="stl/l0_1.stl" scale="1.0 1.0 1.0"/>
		<mesh name="l0_2" file="stl/l0_2.stl" scale="1.0 1.0 1.0"/>
		<mesh name="l0_3" file="stl/l0_3.stl" scale="1.0 1.0 1.0"/>
		<mesh name="l0_4" file="stl/l0_4.stl" scale="1.0 1.0 1.0"/>
		<mesh name="l0_5" file="stl/l0_5.stl" scale="1.0 1.0 1.0"/>
		<mesh name="l0_6" file="stl/l0_6.stl" scale="1.0 1.0 1.0"/>
		<mesh name="head_0" file="stl/head_0.stl" scale="1.0 1.0 1.0"/>
		<mesh name="head_2" file="stl/head_2.stl" scale="1.0 1.0 1.0"/>
		<mesh name="head_3" file="stl/head_3.stl" scale="1.0 1.0 1.0"/>
		<mesh name="head_5" file="stl/head_5.stl" scale="1.0 1.0 1.0"/>
		<mesh name="head_6" file="stl/head_6.stl" scale="1.0 1.0 1.0"/>
		<mesh name="head_7" file="stl/head_7.stl" scale="1.0 1.0 1.0"/>
		<mesh name="head_8" file="stl/head_8.stl" scale="1.0 1.0 1.0"/>
		<mesh name="head_9" file="stl/head_9.stl" scale="1.0 1.0 1.0"/>
		<mesh name="l1_0" file="stl/l1_0.stl" scale="1.0 1.0 1.0"/>
		<mesh name="l1_1" file="stl/l1_1.stl" scale="1.0 1.0 1.0"/>
		<mesh name="l1_2" file="stl/l1_2.stl" scale="1.0 1.0 1.0"/>
		<mesh name="l2_0" file="stl/l2_0.stl" scale="1.0 1.0 1.0"/>
		<mesh name="l2_1" file="stl/l2_1.stl" scale="1.0 1.0 1.0"/>
		<mesh name="l2_2" file="stl/l2_2.stl" scale="1.0 1.0 1.0"/>
		<mesh name="l2_3" file="stl/l2_3.stl" scale="1.0 1.0 1.0"/>
		<mesh name="l2_4" file="stl/l2_4.stl" scale="1.0 1.0 1.0"/>
		<mesh name="l3_0" file="stl/l3_0.stl" scale="1.0 1.0 1.0"/>
		<mesh name="l3_1" file="stl/l3_1.stl" scale="1.0 1.0 1.0"/>
		<mesh name="l3_2" file="stl/l3_2.stl" scale="1.0 1.0 1.0"/>
		<mesh name="l3_3" file="stl/l3_3.stl" scale="1.0 1.0 1.0"/>
		<mesh name="l4_0" file="stl/l4_0.stl" scale="1.0 1.0 1.0"/>
		<mesh name="l4_1" file="stl/l4_1.stl" scale="1.0 1.0 1.0"/>
		<mesh name="l4_2" file="stl/l4_2.stl" scale="1.0 1.0 1.0"/>
		<mesh name="l4_3" file="stl/l4_3.stl" scale="1.0 1.0 1.0"/>
		<mesh name="l4_4" file="stl/l4_4.stl" scale="1.0 1.0 1.0"/>
		<mesh name="l4_5" file="stl/l4_5.stl" scale="1.0 1.0 1.0"/>
		<mesh name="l4_6" file="stl/l4_6.stl" scale="1.0 1.0 1.0"/>
		<mesh name="l4_7" file="stl/l4_7.stl" scale="1.0 1.0 1.0"/>
		<mesh name="l5_0" file="stl/l5_0.stl" scale="1.0 1.0 1.0"/>
		<mesh name="l5_1" file="stl/l5_1.stl" scale="1.0 1.0 1.0"/>
		<mesh name="l5_2" file="stl/l5_2.stl" scale="1.0 1.0 1.0"/>
		<mesh name="l5_3" file="stl/l5_3.stl" scale="1.0 1.0 1.0"/>
		<mesh name="l5_4" file="stl/l5_4.stl" scale="1.0 1.0 1.0"/>
		<mesh name="l6_0" file="stl/l6_0.stl" scale="1.0 1.0 1.0"/>
		<mesh name="l6_1" file="stl/l6_1.stl" scale="1.0 1.0 1.0"/>
		<mesh name="l6_2" file="stl/l6_2.stl" scale="1.0 1.0 1.0"/>
		<mesh name="l6_3" file="stl/l6_3.stl" scale="1.0 1.0 1.0"/>
		<mesh name="l6_4" file="stl/l6_4.stl" scale="1.0 1.0 1.0"/>
		<mesh name="l6_5" file="stl/l6_5.stl" scale="1.0 1.0 1.0"/>
		<material name="black" rgba="0.20000000298023224 0.20000000298023224 0.20000000298023224 1.0" emission="0.0" specular="0.5"/>
		<material name="red" rgba="0.5 0.10000000149011612 0.10000000149011612 1.0" emission="0.0" specular="0.5"/>
		<material name="Mtl7" rgba="0.2509799897670746 0.2509799897670746 0.2509799897670746 1.0" emission="0.0" specular="0.5"/>
		<material name="off_white" rgba="0.792156994342804 0.8196079730987549 0.9294120073318481 1.0" emission="0.0" specular="0.5"/>
		<material name="Mtl4" rgba="1.0 0.4039219915866852 0.12156900018453598 1.0" emission="0.0" specular="0.5"/>
		<material name="Mtl3" rgba="0.16862699389457703 0.1529410034418106 0.1411760002374649 1.0" emission="0.0" specular="0.5"/>
		<material name="white" rgba="1.0 1.0 1.0 1.0" emission="0.0" specular="0.5"/>
		<material name="dark_black" rgba="0.0 0.0 0.0 1.0" emission="0.0" specular="0.0"/>
		<material name="Mtl5_001" rgba="0.5019609928131104 0.5019609928131104 0.5019609928131104 1.0" emission="0.0" specular="0.5"/>
		<material name="Mtl5_002" rgba="0.10588199645280838 0.10588199645280838 0.10588199645280838 1.0" emission="0.0" specular="0.5"/>
		<material name="Mtl6_002" rgba="0.749019980430603 0.749019980430603 0.749019980430603 1.0" emission="0.0" specular="0.5"/>
		<material name="Mtl4_001" rgba="0.8666669726371765 0.9058820009231567 1.0 1.0" emission="0.0" specular="0.5"/>
	</asset>
	<worldbody>
		<body name="sawyer" pos="0.0 0.0 0.0" quat="1.0 0.0 0.0 0.0">
			<body name="base" pos="0.0 0.0 0.0" quat="1.0 0.0 0.0 0.0">
				<geom name="Geom_0" type="mesh" pos="-0.07485772669315338 -1.478894091633265e-06 0.04059053584933281" quat="0.707025408744812 0.7070662975311279 0.009282732382416725 -0.009283269755542278" mesh="base_0" material="black" class="visual"/>
				<geom name="Geom_1" type="mesh" pos="0.0020945481956005096 -3.3228158713427547e-07 0.032897233963012695" quat="0.5008381009101868 0.5009832978248596 -0.499013751745224 0.4991615116596222" mesh="base_1" material="red" class="visual"/>
				<body name="right_l0" pos="0.0 0.0 0.07999999821186066" quat="1.0 0.0 0.0 0.0">
					<inertial mass="5.321300029754639" pos="0.024364499375224113 0.010968799702823162 0.1436309963464737" quat="0.8948211073875427 0.00899450108408928 -0.17028002440929413 0.4125760495662689" diaginertia="0.06515990197658539 0.051095400005578995 0.018622100353240967"/>
					<geom name="Geom_2" type="mesh" pos="-0.041641995310783386 0.015453800559043884 0.21742893755435944" quat="1.0 0.0 0.0 0.0" mesh="l0_0" material="Mtl7" class="visual"/>
					<geom name="Geom_3" type="mesh" pos="0.04999122396111488 -0.07890910655260086 0.17386884987354279" quat="0.32064926624298096 0.5709735155105591 0.630225419998169 0.41712018847465515" mesh="l0_1" material="off_white" class="visual"/>
					<geom name="Geom_4" type="mesh" pos="0.024971013888716698 -0.005032683257013559 0.17073991894721985" quat="0.6750409007072449 0.052845682948827744 0.12056156247854233 0.7259421348571777" mesh="l0_2" material="red" class="visual"/>
					<geom name="Geom_5" type="mesh" pos="-0.06431664526462555 -0.01801265962421894 0.05516261234879494" quat="1.0 0.0 0.0 0.0" mesh="l0_3" material="Mtl4" class="visual"/>
					<geom name="Geom_6" type="mesh" pos="-0.06594432145357132 0.018639573827385902 0.04154329001903534" quat="0.38285180926322937 0.9159631729125977 -0.04633520171046257 -0.11085579544305801" mesh="l0_4" material="Mtl3" class="visual"/>
					<geom name="Geom_7" type="mesh" pos="0.00893645454198122 0.009335929527878761 0.07952547073364258" quat="0.5870007872581482 0.03247741609811783 0.1206262856721878 0.7998903393745422" mesh="l0_5" material="white" class="visual"/>
					<geom name="Geom_8" type="mesh" pos="0.04399951174855232 -0.03097422979772091 0.1974749118089676" quat="0.7764089107513428 0.2554095983505249 0.2455173134803772 0.5212258100509644" mesh="l0_6" material="black" class="visual"/>
					<geom name="Geom_9" type="capsule" pos="0.0 0.0 0.12250000238418579" quat="6.123234262925839e-17 1.0 0.0 0.0" size="0.07000000029802322 0.1274999976158142 0.0" class="collision"/>
					<joint name="right_j0" type="hinge" pos="0.0 0.0 0.0" range="-3.050299882888794 3.050299882888794" axis="0.0 0.0 1.0"/>
					<body name="right_l1" pos="0.08100000023841858 0.05000000074505806 0.2370000034570694" quat="0.5 -0.5 0.5 0.5">
						<inertial mass="4.505000114440918" pos="-0.00308490009047091 -0.02681099995970726 0.09252099692821503" quat="0.424888014793396 0.8919870257377625 0.13236400485038757 -0.07942940294742584" diaginertia="0.022433899343013763 0.02216240018606186 0.009709710255265236"/>
						<geom name="Geom_20" type="mesh" pos="-7.629238098161295e-06 0.016234004870057106 0.15072041749954224" quat="0.6250988245010376 0.330392450094223 -0.3303552567958832 0.6252661347389221" mesh="l1_0" material="black" class="visual"/>
						<geom name="Geom_21" type="mesh" pos="-4.439407803147333e-06 -0.020526036620140076 0.09934993833303452" quat="0.6474507451057434 0.28391146659851074 -0.2838706076145172 0.6477802395820618" mesh="l1_1" material="red" class="visual"/>
						<geom name="Geom_22" type="mesh" pos="-3.6162049354970804e-07 -0.0600593127310276 0.07451558858156204" quat="0.657308042049408 0.2606419622898102 -0.2606435716152191 0.6573255658149719" mesh="l1_2" material="white" class="visual"/>
						<geom name="Geom_23" type="capsule" pos="0.0 0.0 0.03500000014901161" quat="6.123234262925839e-17 1.0 0.0 0.0" size="0.06800000369548798 0.0949999988079071 0.0" class="collision"/>
						<joint name="right_j1" type="hinge" pos="0.0 0.0 0.0" range="-3.809499979019165 2.2736001014709473" axis="0.0 0.0 1.0"/>
						<body name="right_l2" pos="0.0 -0.14000000059604645 0.14249999821186066" quat="0.7071067690849304 0.7071067690849304 0.0 0.0">
							<inertial mass="1.7450000047683716" pos="-0.00016044000221882015 -0.014967000111937523 0.13582000136375427" quat="0.7078312635421753 -0.05247611925005913 0.0516006164252758 0.7025372385978699" diaginertia="0.02579279989004135 0.025505999103188515 0.0029251601081341505"/>
							<geom name="Geom_24" type="mesh" pos="0.00020539479737635702 0.011755594052374363 0.23551559448242188" quat="0.3904694616794586 0.5895240902900696 0.3904353678226471 0.5895380973815918" mesh="l2_0" material="off_white" class="visual"/>
							<geom name="Geom_25" type="mesh" pos="-0.00020235597912687808 0.011688808910548687 0.23461543023586273" quat="0.3857412338256836 0.5924391746520996 0.39733511209487915 0.5851020216941833" mesh="l2_1" material="Mtl5_002" class="visual"/>
							<geom name="Geom_26" type="mesh" pos="2.1128652161195305e-09 -0.009260267950594425 0.05906962975859642" quat="0.7048347592353821 0.056638848036527634 -0.056638848036527634 0.7048347592353821" mesh="l2_2" material="white" class="visual"/>
							<geom name="Geom_27" type="mesh" pos="-1.680450736785133e-06 0.01580784283578396 0.25848978757858276" quat="0.6962909698486328 0.12316566705703735 -0.12302659451961517 0.6963286399841309" mesh="l2_3" material="black" class="visual"/>
							<geom name="Geom_28" type="mesh" pos="1.8811221025316627e-06 -0.0024170365650206804 0.13505710661411285" quat="0.7064913511276245 0.03650054335594177 -0.03649716079235077 0.705836832523346" mesh="l2_4" material="red" class="visual"/>
							<geom name="Geom_29" type="capsule" pos="0.0 0.0 0.054999999701976776" quat="6.123234262925839e-17 1.0 0.0 0.0" size="0.054999999701976776 0.20499999821186066 0.0" class="collision"/>
							<joint name="right_j2" type="hinge" pos="0.0 0.0 0.0" range="-3.04259991645813 3.04259991645813" axis="0.0 0.0 1.0"/>
							<body name="right_l3" pos="0.0 -0.041999999433755875 0.25999999046325684" quat="0.7071067690849304 -0.7071067690849304 0.0 0.0">
								<inertial mass="2.509700059890747" pos="-0.004813500214368105 -0.02810000069439411 -0.08415400236845016" quat="0.9029988646507263 0.3853909373283386 -0.08809008449316025 0.16824696958065033" diaginertia="0.010240400210022926 0.009699700400233269 0.0036962199956178665"/>
								<geom name="Geom_30" type="mesh" pos="0.0008621378801763058 0.04723334684967995 -0.06765618175268173" quat="0.5 0.5 0.5 0.5" mesh="l3_0" material="off_white" class="visual"/>
								<geom name="Geom_31" type="mesh" pos="-8.467022780678235e-06 -0.02452612854540348 -0.08430895209312439" quat="0.659473180770874 -0.2549700140953064 0.25486281514167786 0.6596441268920898" mesh="l3_1" material="red" class="visual"/>
								<geom name="Geom_32" type="mesh" pos="-1.0522006732571754e-06 -0.05722404643893242 -0.06923932582139969" quat="0.6575967073440552 -0.26001739501953125 0.2599969208240509 0.6575402021408081" mesh="l3_2" material="white" class="visual"/>
								<geom name="Geom_33" type="mesh" pos="1.524305616840138e-06 0.014440644532442093 -0.13098832964897156" quat="0.2853597104549408 0.6469870805740356 -0.6469313502311707 0.28540751338005066" mesh="l3_3" material="black" class="visual"/>
								<geom name="Geom_34" type="capsule" pos="0.0 0.0 -0.042500000447034836" quat="6.123234262925839e-17 1.0 0.0 0.0" size="0.054999999701976776 0.07249999791383743 0.0" class="collision"/>
								<joint name="right_j3" type="hinge" pos="0.0 0.0 0.0" range="-3.0439000129699707 3.0439000129699707" axis="0.0 0.0 1.0"/>
								<body name="right_l4" pos="0.0 -0.125 -0.1264999955892563" quat="0.7071067690849304 0.7071067690849304 0.0 0.0">
									<inertial mass="1.1136000156402588" pos="-0.0018891700310632586 0.006899479776620865 0.1340949982404709" quat="0.8032470345497131 0.031244002282619476 -0.029840901494026184 0.5940770506858826" diaginertia="0.013655499555170536 0.013549800030887127 0.001273849979043007"/>
									<geom name="Geom_35" type="mesh" pos="-0.04113747924566269 -0.0004640524566639215 0.07782932370901108" quat="0.9999693632125854 0.0077166929841041565 0.0012960745953023434 1.0001715963880997e-05" mesh="l4_0" material="Mtl7" class="visual"/>
									<geom name="Geom_36" type="mesh" pos="-0.0385700948536396 0.0036621461622416973 0.08737674355506897" quat="0.9903295636177063 -0.09333489835262299 0.02273738570511341 -0.10009501129388809" mesh="l4_1" material="black" class="visual"/>
									<geom name="Geom_37" type="mesh" pos="-0.03828736022114754 -0.00014584316522814333 0.08496664464473724" quat="0.9999420642852783 0.0020595381502062082 0.006528248079121113 -0.008309401571750641" mesh="l4_2" material="Mtl6_002" class="visual"/>
									<geom name="Geom_38" type="mesh" pos="-0.041894566267728806 0.0001418930769432336 0.08472036570310593" quat="0.9999272227287292 -0.005081682465970516 0.006391556933522224 -0.008878039196133614" mesh="l4_3" material="white" class="visual"/>
									<geom name="Geom_39" type="mesh" pos="-0.03830757737159729 -2.7441590191301657e-06 0.08568595349788666" quat="0.9999224543571472 -0.0004176835936959833 0.00545007036998868 -0.011192242614924908" mesh="l4_4" material="off_white" class="visual"/>
									<geom name="Geom_40" type="mesh" pos="-0.009125388227403164 0.002550688339397311 0.19675889611244202" quat="0.7409397959709167 0.02689535543322563 0.06831380724906921 0.6675463318824768" mesh="l4_5" material="dark_black" class="visual"/>
									<geom name="Geom_41" type="mesh" pos="0.0007641560514457524 0.008371501229703426 0.12936623394489288" quat="0.7119211554527283 -0.034897901117801666 0.0328463576734066 0.7006222605705261" mesh="l4_6" material="red" class="visual"/>
									<geom name="Geom_42" type="mesh" pos="0.0005165478796698153 -0.002769012004137039 0.1395190805196762" quat="0.7065168023109436 0.011982783675193787 -0.014483349397778511 0.7074465751647949" mesh="l4_7" material="black" class="visual"/>
									<geom name="Geom_43" type="capsule" pos="0.0 0.0 0.07000000029802322" quat="6.123234262925839e-17 1.0 0.0 0.0" size="0.04500000178813934 0.20000000298023224 0.0" class="collision"/>
									<joint name="right_j4" type="hinge" pos="0.0 0.0 0.0" range="-2.976099967956543 2.976099967956543" axis="0.0 0.0 1.0"/>
									<body name="right_l5" pos="0.0 0.03099999949336052 0.2750000059604645" quat="0.7071067690849304 -0.7071067690849304 0.0 0.0">
										<inertial mass="1.5625" pos="0.00611330009996891 -0.02369699999690056 0.0764160007238388" quat="0.40407586097717285 0.9134997129440308 0.04731248319149017 0.001583349541760981" diaginertia="0.004741310141980648 0.004228570032864809 0.0019067199900746346"/>
										<geom name="Geom_44" type="mesh" pos="0.04532376676797867 -0.03356976807117462 0.08241508156061172" quat="0.7071067690849304 0.7071067690849304 0.0 0.0" mesh="l5_0" material="Mtl5_001" class="visual"/>
										<geom name="Geom_45" type="mesh" pos="-0.0050115324556827545 5.399343081080588e-06 0.009804404340684414" quat="0.49733591079711914 0.5040051937103271 -0.49598079919815063 0.5026319026947021" mesh="l5_1" material="Mtl4_001" class="visual"/>
										<geom name="Geom_46" type="mesh" pos="0.0093096774071455 -0.006783002987504005 0.01736132614314556" quat="0.8707842826843262 0.13466234505176544 0.38698503375053406 -0.2717413902282715" mesh="l5_2" material="white" class="visual"/>
										<geom name="Geom_47" type="mesh" pos="-0.00015255381003953516 -0.016654599457979202 0.07227076590061188" quat="0.6317414045333862 0.2615343928337097 -0.25651729106903076 0.6831554770469666" mesh="l5_3" material="red" class="visual"/>
										<geom name="Geom_48" type="mesh" pos="0.002254846040159464 0.009424086660146713 0.11999830603599548" quat="0.6269304156303406 0.3770274519920349 -0.33140110969543457 0.5958035588264465" mesh="l5_4" material="black" class="visual"/>
										<geom name="Geom_49" type="capsule" pos="0.0 0.0 0.03999999910593033" quat="6.123234262925839e-17 1.0 0.0 0.0" size="0.04500000178813934 0.05999999865889549 0.0" class="collision"/>
										<geom name="Geom_50" type="capsule" pos="0.0 -0.04100000113248825 0.10499999672174454" quat="0.7071067690849304 -0.7071067690849304 0.0 0.0" size="0.04500000178813934 0.04100000113248825 0.0" class="collision"/>
										<joint name="right_j5" type="hinge" pos="0.0 0.0 0.0" range="-2.976099967956543 2.976099967956543" axis="0.0 0.0 1.0"/>
										<body name="right_l6" pos="0.0 -0.10999999940395355 0.10530000180006027" quat="0.061624810099601746 0.0616300106048584 -0.7044160962104797 0.7044160962104797">
											<inertial mass="0.32919999957084656" pos="-8.072600394370966e-06 0.008583799935877323 -0.0049565997906029224" quat="0.4790440499782562 0.5156360864639282 -0.5130690336227417 0.49132105708122253" diaginertia="0.0003602679935283959 0.00031107800896279514 0.00021498400019481778"/>
											<geom name="Geom_51" type="mesh" pos="-0.003610120387747884 0.06668666750192642 -0.0009112398256547749" quat="1.0 0.0 0.0 0.0" mesh="l6_0" material="Mtl4" class="visual"/>
											<geom name="Geom_52" type="mesh" pos="5.573861017182935e-06 0.06600774824619293 0.000615371682215482" quat="0.4921293258666992 0.5077487230300903 0.4900192618370056 0.5097853541374207" mesh="l6_1" material="white" class="visual"/>
											<geom name="Geom_53" type="mesh" pos="0.004251166246831417 0.06655088067054749 0.0012765834107995033" quat="1.0 0.0 0.0 0.0" mesh="l6_2" material="red" class="visual"/>
											<geom name="Geom_54" type="mesh" pos="-1.0324153087992727e-08 4.289119104328165e-08 -0.03616039454936981" quat="0.4648391902446747 0.532845675945282 -0.4648391902446747 0.532845675945282" mesh="l6_3" material="black" class="visual"/>
											<geom name="Geom_55" type="mesh" pos="9.632401543058222e-07 0.008206682279706001 -0.028984084725379944" quat="0.48383134603500366 0.5161692500114441 -0.5158120393753052 0.4831298291683197" mesh="l6_4" material="black" class="visual"/>
											<geom name="Geom_56" type="mesh" pos="-9.154856343229767e-06 0.010640062391757965 -0.006468773819506168" quat="0.5111276507377625 0.4895099699497223 -0.4889838993549347 0.5099247694015503" mesh="l6_5" material="black" class="visual"/>
											<geom name="Geom_57" type="cylinder" pos="0.0 0.0 0.0" quat="1.0 0.0 0.0 0.0" size="0.04500000178813934 0.019999999552965164 0.0" class="collision"/>
											<joint name="right_j6" type="hinge" pos="0.0 0.0 0.0" range="-4.712399959564209 4.712399959564209" axis="0.0 0.0 1.0"/>
										</body>
									</body>
								</body>
							</body>
						</body>
					</body>
					<body name="head" pos="0.0 0.0 0.29649999737739563" quat="1.0 0.0 0.0 0.0">
						<inertial mass="1.5794999599456787" pos="0.005322259850800037 -2.654730087670032e-05 0.10209999978542328" quat="0.9999933242797852 7.083842501742765e-05 -0.003598121227696538 -0.0006262672250159085" diaginertia="0.011833400465548038 0.008270969614386559 0.004965819884091616"/>
						<geom name="Geom_10" type="mesh" pos="3.682423965756243e-08 3.697168438066001e-08 0.001067510456778109" quat="0.33674782514572144 0.6217724084854126 -0.33674782514572144 0.6217724084854126" mesh="head_0" material="black" class="visual"/>
						<geom name="Geom_11" type="mesh" pos="0.006682465318590403 0.018973087891936302 0.05824505537748337" quat="0.9860661625862122 0.15271791815757751 0.06594937294721603 0.0011813943274319172" mesh="head_2" material="off_white" class="visual"/>
						<geom name="Geom_12" type="mesh" pos="0.01214071549475193 -0.0018325537675991654 0.09827320277690887" quat="0.9991581439971924 -0.04081937298178673 -0.0012028103228658438 -0.003922765608876944" mesh="head_3" material="Mtl7" class="visual"/>
						<geom name="Geom_13" type="mesh" pos="-0.007736013736575842 -3.1440943075722316e-06 0.10534539073705673" quat="0.9998405575752258 6.34340030956082e-05 -0.017855286598205566 0.00022112914302852005" mesh="head_5" material="black" class="visual"/>
						<geom name="Geom_14" type="mesh" pos="0.01654263772070408 2.3454672373190988e-06 0.14433149993419647" quat="0.9977629780769348 0.0001240648125531152 -0.06685063242912292 2.1837355234310962e-05" mesh="head_6" material="white" class="visual"/>
						<geom name="Geom_15" type="mesh" pos="0.02796252630650997 1.1137315595988184e-05 0.1012677326798439" quat="0.7070940732955933 0.7071194648742676 2.147517807316035e-05 -2.147594750567805e-05" mesh="head_7" material="dark_black" class="visual"/>
						<geom name="Geom_16" type="mesh" pos="0.006564076989889145 6.432921054511098e-06 0.03852730244398117" quat="0.9983767867088318 -0.00018446671310812235 0.056953758001327515 2.3310265532927588e-05" mesh="head_8" material="red" class="visual"/>
						<geom name="Geom_17" type="mesh" pos="0.028526650741696358 -0.04999541863799095 0.1081274151802063" quat="0.9356042742729187 -0.35305044054985046 -0.0002723135403357446 0.00010275756358169019" mesh="head_9" material="Mtl5_001" class="visual"/>
						<geom name="Geom_18" type="capsule" pos="-0.004999999888241291 0.0 0.11249999701976776" quat="6.123234262925839e-17 1.0 0.0 0.0" size="0.03999999910593033 0.0925000011920929 0.0" class="collision"/>
						<geom name="Geom_19" type="box" pos="0.02500000037252903 0.0 0.10000000149011612" quat="1.0 0.0 0.0 0.0" size="0.009999999776482582 0.12999999523162842 0.07999999821186066" class="collision"/>
					</body>
				</body>
			</body>
		</body>
	</worldbody>
	<equality/>
</mujoco>
